Workbook

Sheet Parametros
B2: Producto | C2: Convenios
B4: Año | C4: 2026
B6: Lista Fechas | C6: =EOMONTH(DATE($C$4,1,1),0) -> 46053 | E6: Segmentos | F6: Renta_Alta
C7: =EOMONTH(C6,1) -> 46081 | F7: Masivo
C8: =EOMONTH(C7,1) -> 46112 | F8: Consumo_Inicial
C9: =EOMONTH(C8,1) -> 46142 | F9: Total_Producto
C10: =EOMONTH(C9,1) -> 46173
C11: =EOMONTH(C10,1) -> 46203
C12: =EOMONTH(C11,1) -> 46234
C13: =EOMONTH(C12,1) -> 46265
C14: =EOMONTH(C13,1) -> 46295
C15: =EOMONTH(C14,1) -> 46326
C16: =EOMONTH(C15,1) -> 46356
C17: =EOMONTH(C16,1) -> 46387

Sheet Indicadores
C1: Mensual | P1: Acumulado
J2: Variación % | W2: Variación %
B3: =Desempeño_Financiero!C6 -> Total_Producto | C3: =Desempeño_Financiero!D6 -> 46173 | D3: =Desempeño_Financiero!E6 -> 46173 | E3: =Desempeño_Financiero!F6 -> 46142 | F3: =Desempeño_Financiero!G6 -> 45808 | G3: =Desempeño_Financiero!H6 -> 45443 | H3: =Desempeño_Financiero!I6 -> 45077 | J3: =D3 -> 46173 | K3: =E3 -> 46142 | L3: =F3 -> 45808 | M3: =G3 -> 45443 | N3: =H3 -> 45077 | P3: =C3 -> 46173 | Q3: =D3 -> 46173 | R3: =E3 -> 46142 | S3: =F3 -> 45808 | T3: =G3 -> 45443 | U3: =H3 -> 45077 | W3: =Q3 -> 46173 | X3: =R3 -> 46142 | Y3: =S3 -> 45808 | Z3: =T3 -> 45443 | AA3: =U3 -> 45077
B5: Eficiencia | C5: =IFERROR((-Desempeño_Financiero!D214)/(Desempeño_Financiero!D176+Desempeño_Financiero!D195),0) -> 0 | D5: =IFERROR((-Desempeño_Financiero!E214)/(Desempeño_Financiero!E176+Desempeño_Financiero!E195),0) -> 3.8423302 | E5: =IFERROR((-Desempeño_Financiero!F214)/(Desempeño_Financiero!F176+Desempeño_Financiero!F195),0) -> 0 | F5: =IFERROR((-Desempeño_Financiero!G214)/(Desempeño_Financiero!G176+Desempeño_Financiero!G195),0) -> 0 | G5: =IFERROR((-Desempeño_Financiero!H214)/(Desempeño_Financiero!H176+Desempeño_Financiero!H195),0) -> 0 | H5: =IFERROR((-Desempeño_Financiero!I214)/(Desempeño_Financiero!I176+Desempeño_Financiero!I195),0) -> 0 | J5: =IFERROR(($C5-D5)*10000,0) -> -38423.302 | K5: =IFERROR(($C5-E5)*10000,0) -> 0 | L5: =IFERROR(($C5-F5)*10000,0) -> 0 | M5: =IFERROR(($C5-G5)*10000,0) -> 0 | N5: =IFERROR(($C5-H5)*10000,0) -> 0 | P5: =IFERROR((-Desempeño_Financiero!W214)/(Desempeño_Financiero!W176+Desempeño_Financiero!W195),0) -> 0 | Q5: =IFERROR((-Desempeño_Financiero!X214)/(Desempeño_Financiero!X176+Desempeño_Financiero!X195),0) -> 3.9536841 | R5: =IFERROR((-Desempeño_Financiero!Y214)/(Desempeño_Financiero!Y176+Desempeño_Financiero!Y195),0) -> 0 | S5: =IFERROR((-Desempeño_Financiero!Z214)/(Desempeño_Financiero!Z176+Desempeño_Financiero!Z195),0) -> 0 | T5: =IFERROR((-Desempeño_Financiero!AA214)/(Desempeño_Financiero!AA176+Desempeño_Financiero!AA195),0) -> 0 | U5: =IFERROR((-Desempeño_Financiero!AB214)/(Desempeño_Financiero!AB176+Desempeño_Financiero!AB195),0) -> 0 | W5: =IFERROR(($P5-Q5)*10000,0) -> -39536.841 | X5: =IFERROR(($P5-R5)*10000,0) -> 0 | Y5: =IFERROR(($P5-S5)*10000,0) -> 0 | Z5: =IFERROR(($P5-T5)*10000,0) -> 0 | AA5: =IFERROR(($P5-U5)*10000,0) -> 0
B7: Rendimiento de Colocaciones | C7: =Desempeño_Financiero!D100 -> 0 | D7: =Desempeño_Financiero!E100 -> 0.042497138 | E7: =Desempeño_Financiero!F100 -> 0 | F7: =Desempeño_Financiero!G100 -> 0 | G7: =Desempeño_Financiero!H100 -> 0 | H7: =Desempeño_Financiero!I100 -> 0 | J7: =IFERROR(($C7-D7)*10000,0) -> -424.97138 | K7: =IFERROR(($C7-E7)*10000,0) -> 0 | L7: =IFERROR(($C7-F7)*10000,0) -> 0 | M7: =IFERROR(($C7-G7)*10000,0) -> 0 | N7: =IFERROR(($C7-H7)*10000,0) -> 0 | P7: =Desempeño_Financiero!W100 -> 0 | Q7: =Desempeño_Financiero!X100 -> 0.04252755 | R7: =Desempeño_Financiero!Y100 -> 0 | S7: =Desempeño_Financiero!Z100 -> 0 | T7: =Desempeño_Financiero!AA100 -> 0 | U7: =Desempeño_Financiero!AB100 -> 0 | W7: =IFERROR(($P7-Q7)*10000,0) -> -425.2755 | X7: =IFERROR(($P7-R7)*10000,0) -> 0 | Y7: =IFERROR(($P7-S7)*10000,0) -> 0 | Z7: =IFERROR(($P7-T7)*10000,0) -> 0 | AA7: =IFERROR(($P7-U7)*10000,0) -> 0
B9: INOF / Ingresos Totales | C9: =IFERROR((Desempeño_Financiero!D195)/(Desempeño_Financiero!D119+Desempeño_Financiero!D195),0) -> 0 | D9: =IFERROR((Desempeño_Financiero!E195)/(Desempeño_Financiero!E119+Desempeño_Financiero!E195),0) -> -0.21797554 | E9: =IFERROR((Desempeño_Financiero!F195)/(Desempeño_Financiero!F119+Desempeño_Financiero!F195),0) -> 0 | F9: =IFERROR((Desempeño_Financiero!G195)/(Desempeño_Financiero!G119+Desempeño_Financiero!G195),0) -> 0 | G9: =IFERROR((Desempeño_Financiero!H195)/(Desempeño_Financiero!H119+Desempeño_Financiero!H195),0) -> 0 | H9: =IFERROR((Desempeño_Financiero!I195)/(Desempeño_Financiero!I119+Desempeño_Financiero!I195),0) -> 0 | J9: =IFERROR(($C9-D9)*10000,0) -> 2179.7554 | K9: =IFERROR(($C9-E9)*10000,0) -> 0 | L9: =IFERROR(($C9-F9)*10000,0) -> 0 | M9: =IFERROR(($C9-G9)*10000,0) -> 0 | N9: =IFERROR(($C9-H9)*10000,0) -> 0 | P9: =IFERROR((Desempeño_Financiero!W195)/(Desempeño_Financiero!W119+Desempeño_Financiero!W195),0) -> 0 | Q9: =IFERROR((Desempeño_Financiero!X195)/(Desempeño_Financiero!X119+Desempeño_Financiero!X195),0) -> -0.26479328 | R9: =IFERROR((Desempeño_Financiero!Y195)/(Desempeño_Financiero!Y119+Desempeño_Financiero!Y195),0) -> 0 | S9: =IFERROR((Desempeño_Financiero!Z195)/(Desempeño_Financiero!Z119+Desempeño_Financiero!Z195),0) -> 0 | T9: =IFERROR((Desempeño_Financiero!AA195)/(Desempeño_Financiero!AA119+Desempeño_Financiero!AA195),0) -> 0 | U9: =IFERROR((Desempeño_Financiero!AB195)/(Desempeño_Financiero!AB119+Desempeño_Financiero!AB195),0) -> 0 | W9: =IFERROR(($P9-Q9)*10000,0) -> 2647.9328 | X9: =IFERROR(($P9-R9)*10000,0) -> 0 | Y9: =IFERROR(($P9-S9)*10000,0) -> 0 | Z9: =IFERROR(($P9-T9)*10000,0) -> 0 | AA9: =IFERROR(($P9-U9)*10000,0) -> 0
B11: INOF / Gasto Operativo | C11: =IFERROR((Desempeño_Financiero!D195/Desempeño_Financiero!D214),0) -> 0 | D11: =IFERROR((Desempeño_Financiero!E195/Desempeño_Financiero!E214),0) -> 0.068773845 | E11: =IFERROR((Desempeño_Financiero!F195/Desempeño_Financiero!F214),0) -> 0 | F11: =IFERROR((Desempeño_Financiero!G195/Desempeño_Financiero!G214),0) -> 0 | G11: =IFERROR((Desempeño_Financiero!H195/Desempeño_Financiero!H214),0) -> 0 | H11: =IFERROR((Desempeño_Financiero!I195/Desempeño_Financiero!I214),0) -> 0 | J11: =IFERROR(($C11-D11)*10000,0) -> -687.73845 | K11: =IFERROR(($C11-E11)*10000,0) -> 0 | L11: =IFERROR(($C11-F11)*10000,0) -> 0 | M11: =IFERROR(($C11-G11)*10000,0) -> 0 | N11: =IFERROR(($C11-H11)*10000,0) -> 0 | P11: =IFERROR((Desempeño_Financiero!W195/Desempeño_Financiero!W214),0) -> 0 | Q11: =IFERROR((Desempeño_Financiero!X195/Desempeño_Financiero!X214),0) -> 0.082357865 | R11: =IFERROR((Desempeño_Financiero!Y195/Desempeño_Financiero!Y214),0) -> 0 | S11: =IFERROR((Desempeño_Financiero!Z195/Desempeño_Financiero!Z214),0) -> 0 | T11: =IFERROR((Desempeño_Financiero!AA195/Desempeño_Financiero!AA214),0) -> 0 | U11: =IFERROR((Desempeño_Financiero!AB195/Desempeño_Financiero!AB214),0) -> 0 | W11: =IFERROR(($P11-Q11)*10000,0) -> -823.57865 | X11: =IFERROR(($P11-R11)*10000,0) -> 0 | Y11: =IFERROR(($P11-S11)*10000,0) -> 0 | Z11: =IFERROR(($P11-T11)*10000,0) -> 0 | AA11: =IFERROR(($P11-U11)*10000,0) -> 0
B13: Gasto Operativo / Activo | C13: =IFERROR(-Desempeño_Financiero!D214/Desempeño_Financiero!D43*12,0) -> 0 | D13: =IFERROR(-Desempeño_Financiero!E214/Desempeño_Financiero!E43*12,0) -> 0.11211293 | E13: =IFERROR(-Desempeño_Financiero!F214/Desempeño_Financiero!F43*12,0) -> 0 | F13: =IFERROR(-Desempeño_Financiero!G214/Desempeño_Financiero!G43*12,0) -> 0 | G13: =IFERROR(-Desempeño_Financiero!H214/Desempeño_Financiero!H43*12,0) -> 0 | H13: =IFERROR(-Desempeño_Financiero!I214/Desempeño_Financiero!I43*12,0) -> 0 | J13: =IFERROR(($C13-D13)*10000,0) -> -1121.1293 | K13: =IFERROR(($C13-E13)*10000,0) -> 0 | L13: =IFERROR(($C13-F13)*10000,0) -> 0 | M13: =IFERROR(($C13-G13)*10000,0) -> 0 | N13: =IFERROR(($C13-H13)*10000,0) -> 0 | P13: =IFERROR(-Desempeño_Financiero!W214/Desempeño_Financiero!W43*12,0) -> 0 | Q13: =IFERROR(-Desempeño_Financiero!X214/Desempeño_Financiero!X43*12,0) -> 0.53381666 | R13: =IFERROR(-Desempeño_Financiero!Y214/Desempeño_Financiero!Y43*12,0) -> 0 | S13: =IFERROR(-Desempeño_Financiero!Z214/Desempeño_Financiero!Z43*12,0) -> 0 | T13: =IFERROR(-Desempeño_Financiero!AA214/Desempeño_Financiero!AA43*12,0) -> 0 | U13: =IFERROR(-Desempeño_Financiero!AB214/Desempeño_Financiero!AB43*12,0) -> 0 | W13: =IFERROR(($P13-Q13)*10000,0) -> -5338.1666 | X13: =IFERROR(($P13-R13)*10000,0) -> 0 | Y13: =IFERROR(($P13-S13)*10000,0) -> 0 | Z13: =IFERROR(($P13-T13)*10000,0) -> 0 | AA13: =IFERROR(($P13-U13)*10000,0) -> 0
B15: ROE
B17: ROA

Sheet Desempeño_Financiero
B1: 46173 | D1: Mensual | W1: Acumulado
B2: Desempeño Financiero
B3: En S/. Miles | C3: N° dias T.Imp | D3: =DAY(D6) -> 31 | E3: =DAY(E6) -> 31 | F3: =DAY(F6) -> 30 | G3: =DAY(G6) -> 31 | H3: =DAY(H6) -> 31 | I3: =DAY(I6) -> 31
C4: N° dias FTP | D4: =DAY(D6) -> 31 | E4: =DAY(E6) -> 31 | F4: =DAY(F6) -> 30 | G4: =DAY(G6) -> 31 | H4: =DAY(H6) -> 31 | I4: =DAY(I6) -> 31
C5: Tipo | D5: R | E5: P | F5: R | G5: R | H5: R | I5: R | K5: Variación S/. | Q5: Variación % | AD5: Variación S/. | AJ5: Variación %
C6: Total_Producto | D6: =$B$1 -> 46173 | E6: =D6 -> 46173 | F6: =EOMONTH(D6,-1) -> 46142 | G6: =EOMONTH(D6,-12) -> 45808 | H6: =EOMONTH(D6,-24) -> 45443 | I6: =EOMONTH(D6,-36) -> 45077 | K6: =E6 -> 46173 | L6: =F6 -> 46142 | M6: =G6 -> 45808 | N6: =H6 -> 45443 | O6: =I6 -> 45077 | Q6: =K6 -> 46173 | R6: =L6 -> 46142 | S6: =M6 -> 45808 | T6: =N6 -> 45443 | U6: =O6 -> 45077 | W6: =$B$1 -> 46173 | X6: =W6 -> 46173 | Y6: =EOMONTH(W6,-1) -> 46142 | Z6: =EOMONTH(W6,-12) -> 45808 | AA6: =EOMONTH(W6,-24) -> 45443 | AB6: =EOMONTH(W6,-36) -> 45077 | AD6: =X6 -> 46173 | AE6: =Y6 -> 46142 | AF6: =Z6 -> 45808 | AG6: =AA6 -> 45443 | AH6: =AB6 -> 45077 | AJ6: =AD6 -> 46173 | AK6: =AE6 -> 46142 | AL6: =AF6 -> 45808 | AM6: =AG6 -> 45443 | AN6: =AH6 -> 45077
A8: SALDO_FDP | C8: Cuenta Sueldo | D8: {=_xlfn.XLOOKUP(1, (INDIRECT("'"&$C$6&"'!$6:$6")=D$6)* (INDIRECT("'"&$C$6&"'!$5:$5")=D$5), INDIRECT("'"&$C$6&"'!"&ROW()&":"&ROW()) )} -> 0 | E8: {=_xlfn.XLOOKUP(1, (INDIRECT("'"&$C$6&"'!$6:$6")=E$6)* (INDIRECT("'"&$C$6&"'!$5:$5")=E$5), INDIRECT("'"&$C$6&"'!"&ROW()&":"&ROW()) )} -> 1963709.7 | F8: {=_xlfn.XLOOKUP(1, (INDIRECT("'"&$C$6&"'!$6:$6")=F$6)* (INDIRECT("'"&$C$6&"'!$5:$5")=F$5), INDIRECT("'"&$C$6&"'!"&ROW()&":"&ROW()) )} -> 0 | G8: {=_xlfn.XLOOKUP(1, (INDIRECT("'"&$C$6&"'!$6:$6")=G$6)* (INDIRECT("'"&$C$6&"'!$5:$5")=G$5), INDIRECT("'"&$C$6&"'!"&ROW()&":"&ROW()) )} -> 0 | H8: {=_xlfn.XLOOKUP(1, (INDIRECT("'"&$C$6&"'!$6:$6")=H$6)* (INDIRECT("'"&$C$6&"'!$5:$5")=H$5), INDIRECT("'"&$C$6&"'!"&ROW()&":"&ROW()) )} -> 0 | I8: {=_xlfn.XLOOKUP(1, (INDIRECT("'"&$C$6&"'!$6:$6")=I$6)* (INDIRECT("'"&$C$6&"'!$5:$5")=I$5), INDIRECT("'"&$C$6&"'!"&ROW()&":"&ROW()) )} -> 0 | K8: =$D8-E8 -> -1963709.7 | L8: =$D8-F8 -> 0 | M8: =$D8-G8 -> 0 | N8: =$D8-H8 -> 0 | O8: =$D8-I8 -> 0 | Q8: =IFERROR($D8/E8-1,0) -> -1 | R8: =IFERROR($D8/F8-1,0) -> 0 | S8: =IFERROR($D8/G8-1,0) -> 0 | T8: =IFERROR($D8/H8-1,0) -> 0 | U8: =IFERROR($D8/I8-1,0) -> 0 | W8: {=INDIRECT("'"&$C$6&"'!"&ADDRESS(ROW(),COLUMN()+44))} -> 0 | X8: {=INDIRECT("'"&$C$6&"'!"&ADDRESS(ROW(),COLUMN()+44))} -> 1963709.7 | Y8: {=INDIRECT("'"&$C$6&"'!"&ADDRESS(ROW(),COLUMN()+44))} -> 0 | Z8: {=INDIRECT("'"&$C$6&"'!"&ADDRESS(ROW(),COLUMN()+44))} -> 0 | AA8: {=INDIRECT("'"&$C$6&"'!"&ADDRESS(ROW(),COLUMN()+44))} -> 0 | AB8: {=INDIRECT("'"&$C$6&"'!"&ADDRESS(ROW(),COLUMN()+44))} -> 0 | AD8: =$W8-X8 -> -1963709.7 | AE8: =$W8-Y8 -> 0 | AF8: =$W8-Z8 -> 0 | AG8: =$W8-AA8 -> 0 | AH8: =$W8-AB8 -> 0 | AJ8: =IFERROR($W8/X8-1,0) -> -1 | AK8: =IFERROR($W8/Y8-1,0) -> 0 | AL8: =IFERROR($W8/Z8-1,0) -> 0 | AM8: =IFERROR($W8/AA8-1,0) -> 0 | AN8: =IFERROR($W8/AB8-1,0) -> 0
A9: SALDO_FDP | D9: {=_xlfn.XLOOKUP(1, (INDIRECT("'"&$C$6&"'!$6:$6")=D$6)* (INDIRECT("'"&$C$6&"'!$5:$5")=D$5), INDIRECT("'"&$C$6&"'!"&ROW()&":"&ROW()) )} -> 0 | E9: {=_xlfn.XLOOKUP(1, (INDIRECT("'"&$C$6&"'!$6:$6")=E$6)* (INDIRECT("'"&$C$6&"'!$5:$5")=E$5), INDIRECT("'"&$C$6&"'!"&ROW()&":"&ROW()) )} -> 0 | F9: {=_xlfn.XLOOKUP(1, (INDIRECT("'"&$C$6&"'!$6:$6")=F$6)* (INDIRECT("'"&$C$6&"'!$5:$5")=F$5), INDIRECT("'"&$C$6&"'!"&ROW()&":"&ROW()) )} -> 0 | G9: {=_xlfn.XLOOKUP(1, (INDIRECT("'"&$C$6&"'!$6:$6")=G$6)* (INDIRECT("'"&$C$6&"'!$5:$5")=G$5), INDIRECT("'"&$C$6&"'!"&ROW()&":"&ROW()) )} -> 0 | H9: {=_xlfn.XLOOKUP(1, (INDIRECT("'"&$C$6&"'!$6:$6")=H$6)* (INDIRECT("'"&$C$6&"'!$5:$5")=H$5), INDIRECT("'"&$C$6&"'!"&ROW()&":"&ROW()) )} -> 0 | I9: {=_xlfn.XLOOKUP(1, (INDIRECT("'"&$C$6&"'!$6:$6")=I$6)* (INDIRECT("'"&$C$6&"'!$5:$5")=I$5), INDIRECT("'"&$C$6&"'!"&ROW()&":"&ROW()) )} -> 0 | K9: =$D9-E9 -> 0 | L9: =$D9-F9 -> 0 | M9: =$D9-G9 -> 0 | N9: =$D9-H9 -> 0 | O9: =$D9-I9 -> 0 | Q9: =IFERROR($D9/E9-1,0) -> 0 | R9: =IFERROR($D9/F9-1,0) -> 0 | S9: =IFERROR($D9/G9-1,0) -> 0 | T9: =IFERROR($D9/H9-1,0) -> 0 | U9: =IFERROR($D9/I9-1,0) -> 0 | W9: {=INDIRECT("'"&$C$6&"'!"&ADDRESS(ROW(),COLUMN()+44))} -> 0 | X9: {=INDIRECT("'"&$C$6&"'!"&ADDRESS(ROW(),COLUMN()+44))} -> 0 | Y9: {=INDIRECT("'"&$C$6&"'!"&ADDRESS(ROW(),COLUMN()+44))} -> 0 | Z9: {=INDIRECT("'"&$C$6&"'!"&ADDRESS(ROW(),COLUMN()+44))} -> 0 | AA9: {=INDIRECT("'"&$C$6&"'!"&ADDRESS(ROW(),COLUMN()+44))} -> 0 | AB9: {=INDIRECT("'"&$C$6&"'!"&ADDRESS(ROW(),COLUMN()+44))} -> 0 | AD9: =$W9-X9 -> 0 | AE9: =$W9-Y9 -> 0 | AF9: =$W9-Z9 -> 0 | AG9: =$W9-AA9 -> 0 | AH9: =$W9-AB9 -> 0 | AJ9: =IFERROR($W9/X9-1,0) -> 0 | AK9: =IFERROR($W9/Y9-1,0) -> 0 | AL9: =IFERROR($W9/Z9-1,0) -> 0 | AM9: =IFERROR($W9/AA9-1,0) -> 0 | AN9: =IFERROR($W9/AB9-1,0) -> 0
A10: SALDO_FDP | D10: {=_xlfn.XLOOKUP(1, (INDIRECT("'"&$C$6&"'!$6:$6")=D$6)* (INDIRECT("'"&$C$6&"'!$5:$5")=D$5), INDIRECT("'"&$C$6&"'!"&ROW()&":"&ROW()) )} -> 0 | E10: {=_xlfn.XLOOKUP(1, (INDIRECT("'"&$C$6&"'!$6:$6")=E$6)* (INDIRECT("'"&$C$6&"'!$5:$5")=E$5), INDIRECT("'"&$C$6&"'!"&ROW()&":"&ROW()) )} -> 0 | F10: {=_xlfn.XLOOKUP(1, (INDIRECT("'"&$C$6&"'!$6:$6")=F$6)* (INDIRECT("'"&$C$6&"'!$5:$5")=F$5), INDIRECT("'"&$C$6&"'!"&ROW()&":"&ROW()) )} -> 0 | G10: {=_xlfn.XLOOKUP(1, (INDIRECT("'"&$C$6&"'!$6:$6")=G$6)* (INDIRECT("'"&$C$6&"'!$5:$5")=G$5), INDIRECT("'"&$C$6&"'!"&ROW()&":"&ROW()) )} -> 0 | H10: {=_xlfn.XLOOKUP(1, (INDIRECT("'"&$C$6&"'!$6:$6")=H$6)* (INDIRECT("'"&$C$6&"'!$5:$5")=H$5), INDIRECT("'"&$C$6&"'!"&ROW()&":"&ROW()) )} -> 0 | I10: {=_xlfn.XLOOKUP(1, (INDIRECT("'"&$C$6&"'!$6:$6")=I$6)* (INDIRECT("'"&$C$6&"'!$5:$5")=I$5), INDIRECT("'"&$C$6&"'!"&ROW()&":"&ROW()) )} -> 0 | K10: =$D10-E10 -> 0 | L10: =$D10-F10 -> 0 | M10: =$D10-G10 -> 0 | N10: =$D10-H10 -> 0 | O10: =$D10-I10 -> 0 | Q10: =IFERROR($D10/E10-1,0) -> 0 | R10: =IFERROR($D10/F10-1,0) -> 0 | S10: =IFERROR($D10/G10-1,0) -> 0 | T10: =IFERROR($D10/H10-1,0) -> 0 | U10: =IFERROR($D10/I10-1,0) -> 0 | W10: {=INDIRECT("'"&$C$6&"'!"&ADDRESS(ROW(),COLUMN()+44))} -> 0 | X10: {=INDIRECT("'"&$C$6&"'!"&ADDRESS(ROW(),COLUMN()+44))} -> 0 | Y10: {=INDIRECT("'"&$C$6&"'!"&ADDRESS(ROW(),COLUMN()+44))} -> 0 | Z10: {=INDIRECT("'"&$C$6&"'!"&ADDRESS(ROW(),COLUMN()+44))} -> 0 | AA10: {=INDIRECT("'"&$C$6&"'!"&ADDRESS(ROW(),COLUMN()+44))} -> 0 | AB10: {=INDIRECT("'"&$C$6&"'!"&ADDRESS(ROW(),COLUMN()+44))} -> 0 | AD10: =$W10-X10 -> 0 | AE10: =$W10-Y10 -> 0 | AF10: =$W10-Z10 -> 0 | AG10: =$W10-AA10 -> 0 | AH10: =$W10-AB10 -> 0 | AJ10: =IFERROR($W10/X10-1,0) -> 0 | AK10: =IFERROR($W10/Y10-1,0) -> 0 | AL10: =IFERROR($W10/Z10-1,0) -> 0 | AM10: =IFERROR($W10/AA10-1,0) -> 0 | AN10: =IFERROR($W10/AB10-1,0) -> 0
A11: SALDO_FDP | D11: {=_xlfn.XLOOKUP(1, (INDIRECT("'"&$C$6&"'!$6:$6")=D$6)* (INDIRECT("'"&$C$6&"'!$5:$5")=D$5), INDIRECT("'"&$C$6&"'!"&ROW()&":"&ROW()) )} -> 0 | E11: {=_xlfn.XLOOKUP(1, (INDIRECT("'"&$C$6&"'!$6:$6")=E$6)* (INDIRECT("'"&$C$6&"'!$5:$5")=E$5), INDIRECT("'"&$C$6&"'!"&ROW()&":"&ROW()) )} -> 0 | F11: {=_xlfn.XLOOKUP(1, (INDIRECT("'"&$C$6&"'!$6:$6")=F$6)* (INDIRECT("'"&$C$6&"'!$5:$5")=F$5), INDIRECT("'"&$C$6&"'!"&ROW()&":"&ROW()) )} -> 0 | G11: {=_xlfn.XLOOKUP(1, (INDIRECT("'"&$C$6&"'!$6:$6")=G$6)* (INDIRECT("'"&$C$6&"'!$5:$5")=G$5), INDIRECT("'"&$C$6&"'!"&ROW()&":"&ROW()) )} -> 0 | H11: {=_xlfn.XLOOKUP(1, (INDIRECT("'"&$C$6&"'!$6:$6")=H$6)* (INDIRECT("'"&$C$6&"'!$5:$5")=H$5), INDIRECT("'"&$C$6&"'!"&ROW()&":"&ROW()) )} -> 0 | I11: {=_xlfn.XLOOKUP(1, (INDIRECT("'"&$C$6&"'!$6:$6")=I$6)* (INDIRECT("'"&$C$6&"'!$5:$5")=I$5), INDIRECT("'"&$C$6&"'!"&ROW()&":"&ROW()) )} -> 0 | K11: =$D11-E11 -> 0 | L11: =$D11-F11 -> 0 | M11: =$D11-G11 -> 0 | N11: =$D11-H11 -> 0 | O11: =$D11-I11 -> 0 | Q11: =IFERROR($D11/E11-1,0) -> 0 | R11: =IFERROR($D11/F11-1,0) -> 0 | S11: =IFERROR($D11/G11-1,0) -> 0 | T11: =IFERROR($D11/H11-1,0) -> 0 | U11: =IFERROR($D11/I11-1,0) -> 0 | W11: {=INDIRECT("'"&$C$6&"'!"&ADDRESS(ROW(),COLUMN()+44))} -> 0 | X11: {=INDIRECT("'"&$C$6&"'!"&ADDRESS(ROW(),COLUMN()+44))} -> 0 | Y11: {=INDIRECT("'"&$C$6&"'!"&ADDRESS(ROW(),COLUMN()+44))} -> 0 | Z11: {=INDIRECT("'"&$C$6&"'!"&ADDRESS(ROW(),COLUMN()+44))} -> 0 | AA11: {=INDIRECT("'"&$C$6&"'!"&ADDRESS(ROW(),COLUMN()+44))} -> 0 | AB11: {=INDIRECT("'"&$C$6&"'!"&ADDRESS(ROW(),COLUMN()+44))} -> 0 | AD11: =$W11-X11 -> 0 | AE11: =$W11-Y11 -> 0 | AF11: =$W11-Z11 -> 0 | AG11: =$W11-AA11 -> 0 | AH11: =$W11-AB11 -> 0 | AJ11: =IFERROR($W11/X11-1,0) -> 0 | AK11: =IFERROR($W11/Y11-1,0) -> 0 | AL11: =IFERROR($W11/Z11-1,0) -> 0 | AM11: =IFERROR($W11/AA11-1,0) -> 0 | AN11: =IFERROR($W11/AB11-1,0) -> 0
A12: SALDO_FDP | D12: {=_xlfn.XLOOKUP(1, (INDIRECT("'"&$C$6&"'!$6:$6")=D$6)* (INDIRECT("'"&$C$6&"'!$5:$5")=D$5), INDIRECT("'"&$C$6&"'!"&ROW()&":"&ROW()) )} -> 0 | E12: {=_xlfn.XLOOKUP(1, (INDIRECT("'"&$C$6&"'!$6:$6")=E$6)* (INDIRECT("'"&$C$6&"'!$5:$5")=E$5), INDIRECT("'"&$C$6&"'!"&ROW()&":"&ROW()) )} -> 0 | F12: {=_xlfn.XLOOKUP(1, (INDIRECT("'"&$C$6&"'!$6:$6")=F$6)* (INDIRECT("'"&$C$6&"'!$5:$5")=F$5), INDIRECT("'"&$C$6&"'!"&ROW()&":"&ROW()) )} -> 0 | G12: {=_xlfn.XLOOKUP(1, (INDIRECT("'"&$C$6&"'!$6:$6")=G$6)* (INDIRECT("'"&$C$6&"'!$5:$5")=G$5), INDIRECT("'"&$C$6&"'!"&ROW()&":"&ROW()) )} -> 0 | H12: {=_xlfn.XLOOKUP(1, (INDIRECT("'"&$C$6&"'!$6:$6")=H$6)* (INDIRECT("'"&$C$6&"'!$5:$5")=H$5), INDIRECT("'"&$C$6&"'!"&ROW()&":"&ROW()) )} -> 0 | I12: {=_xlfn.XLOOKUP(1, (INDIRECT("'"&$C$6&"'!$6:$6")=I$6)* (INDIRECT("'"&$C$6&"'!$5:$5")=I$5), INDIRECT("'"&$C$6&"'!"&ROW()&":"&ROW()) )} -> 0 | K12: =$D12-E12 -> 0 | L12: =$D12-F12 -> 0 | M12: =$D12-G12 -> 0 | N12: =$D12-H12 -> 0 | O12: =$D12-I12 -> 0 | Q12: =IFERROR($D12/E12-1,0) -> 0 | R12: =IFERROR($D12/F12-1,0) -> 0 | S12: =IFERROR($D12/G12-1,0) -> 0 | T12: =IFERROR($D12/H12-1,0) -> 0 | U12: =IFERROR($D12/I12-1,0) -> 0 | W12: {=INDIRECT("'"&$C$6&"'!"&ADDRESS(ROW(),COLUMN()+44))} -> 0 | X12: {=INDIRECT("'"&$C$6&"'!"&ADDRESS(ROW(),COLUMN()+44))} -> 0 | Y12: {=INDIRECT("'"&$C$6&"'!"&ADDRESS(ROW(),COLUMN()+44))} -> 0 | Z12: {=INDIRECT("'"&$C$6&"'!"&ADDRESS(ROW(),COLUMN()+44))} -> 0 | AA12: {=INDIRECT("'"&$C$6&"'!"&ADDRESS(ROW(),COLUMN()+44))} -> 0 | AB12: {=INDIRECT("'"&$C$6&"'!"&ADDRESS(ROW(),COLUMN()+44))} -> 0 | AD12: =$W12-X12 -> 0 | AE12: =$W12-Y12 -> 0 | AF12: =$W12-Z12 -> 0 | AG12: =$W12-AA12 -> 0 | AH12: =$W12-AB12 -> 0 | AJ12: =IFERROR($W12/X12-1,0) -> 0 | AK12: =IFERROR($W12/Y12-1,0) -> 0 | AL12: =IFERROR($W12/Z12-1,0) -> 0 | AM12: =IFERROR($W12/AA12-1,0) -> 0 | AN12: =IFERROR($W12/AB12-1,0) -> 0
A13: SALDO_FDP | D13: {=_xlfn.XLOOKUP(1, (INDIRECT("'"&$C$6&"'!$6:$6")=D$6)* (INDIRECT("'"&$C$6&"'!$5:$5")=D$5), INDIRECT("'"&$C$6&"'!"&ROW()&":"&ROW()) )} -> 0 | E13: {=_xlfn.XLOOKUP(1, (INDIRECT("'"&$C$6&"'!$6:$6")=E$6)* (INDIRECT("'"&$C$6&"'!$5:$5")=E$5), INDIRECT("'"&$C$6&"'!"&ROW()&":"&ROW()) )} -> 0 | F13: {=_xlfn.XLOOKUP(1, (INDIRECT("'"&$C$6&"'!$6:$6")=F$6)* (INDIRECT("'"&$C$6&"'!$5:$5")=F$5), INDIRECT("'"&$C$6&"'!"&ROW()&":"&ROW()) )} -> 0 | G13: {=_xlfn.XLOOKUP(1, (INDIRECT("'"&$C$6&"'!$6:$6")=G$6)* (INDIRECT("'"&$C$6&"'!$5:$5")=G$5), INDIRECT("'"&$C$6&"'!"&ROW()&":"&ROW()) )} -> 0 | H13: {=_xlfn.XLOOKUP(1, (INDIRECT("'"&$C$6&"'!$6:$6")=H$6)* (INDIRECT("'"&$C$6&"'!$5:$5")=H$5), INDIRECT("'"&$C$6&"'!"&ROW()&":"&ROW()) )} -> 0 | I13: {=_xlfn.XLOOKUP(1, (INDIRECT("'"&$C$6&"'!$6:$6")=I$6)* (INDIRECT("'"&$C$6&"'!$5:$5")=I$5), INDIRECT("'"&$C$6&"'!"&ROW()&":"&ROW()) )} -> 0 | K13: =$D13-E13 -> 0 | L13: =$D13-F13 -> 0 | M13: =$D13-G13 -> 0 | N13: =$D13-H13 -> 0 | O13: =$D13-I13 -> 0 | Q13: =IFERROR($D13/E13-1,0) -> 0 | R13: =IFERROR($D13/F13-1,0) -> 0 | S13: =IFERROR($D13/G13-1,0) -> 0 | T13: =IFERROR($D13/H13-1,0) -> 0 | U13: =IFERROR($D13/I13-1,0) -> 0 | W13: {=INDIRECT("'"&$C$6&"'!"&ADDRESS(ROW(),COLUMN()+44))} -> 0 | X13: {=INDIRECT("'"&$C$6&"'!"&ADDRESS(ROW(),COLUMN()+44))} -> 0 | Y13: {=INDIRECT("'"&$C$6&"'!"&ADDRESS(ROW(),COLUMN()+44))} -> 0 | Z13: {=INDIRECT("'"&$C$6&"'!"&ADDRESS(ROW(),COLUMN()+44))} -> 0 | AA13: {=INDIRECT("'"&$C$6&"'!"&ADDRESS(ROW(),COLUMN()+44))} -> 0 | AB13: {=INDIRECT("'"&$C$6&"'!"&ADDRESS(ROW(),COLUMN()+44))} -> 0 | AD13: =$W13-X13 -> 0 | AE13: =$W13-Y13 -> 0 | AF13: =$W13-Z13 -> 0 | AG13: =$W13-AA13 -> 0 | AH13: =$W13-AB13 -> 0 | AJ13: =IFERROR($W13/X13-1,0) -> 0 | AK13: =IFERROR($W13/Y13-1,0) -> 0 | AL13: =IFERROR($W13/Z13-1,0) -> 0 | AM13: =IFERROR($W13/AA13-1,0) -> 0 | AN13: =IFERROR($W13/AB13-1,0) -> 0
A14: SALDO_FDP | D14: {=_xlfn.XLOOKUP(1, (INDIRECT("'"&$C$6&"'!$6:$6")=D$6)* (INDIRECT("'"&$C$6&"'!$5:$5")=D$5), INDIRECT("'"&$C$6&"'!"&ROW()&":"&ROW()) )} -> 0 | E14: {=_xlfn.XLOOKUP(1, (INDIRECT("'"&$C$6&"'!$6:$6")=E$6)* (INDIRECT("'"&$C$6&"'!$5:$5")=E$5), INDIRECT("'"&$C$6&"'!"&ROW()&":"&ROW()) )} -> 0 | F14: {=_xlfn.XLOOKUP(1, (INDIRECT("'"&$C$6&"'!$6:$6")=F$6)* (INDIRECT("'"&$C$6&"'!$5:$5")=F$5), INDIRECT("'"&$C$6&"'!"&ROW()&":"&ROW()) )} -> 0 | G14: {=_xlfn.XLOOKUP(1, (INDIRECT("'"&$C$6&"'!$6:$6")=G$6)* (INDIRECT("'"&$C$6&"'!$5:$5")=G$5), INDIRECT("'"&$C$6&"'!"&ROW()&":"&ROW()) )} -> 0 | H14: {=_xlfn.XLOOKUP(1, (INDIRECT("'"&$C$6&"'!$6:$6")=H$6)* (INDIRECT("'"&$C$6&"'!$5:$5")=H$5), INDIRECT("'"&$C$6&"'!"&ROW()&":"&ROW()) )} -> 0 | I14: {=_xlfn.XLOOKUP(1, (INDIRECT("'"&$C$6&"'!$6:$6")=I$6)* (INDIRECT("'"&$C$6&"'!$5:$5")=I$5), INDIRECT("'"&$C$6&"'!"&ROW()&":"&ROW()) )} -> 0 | K14: =$D14-E14 -> 0 | L14: =$D14-F14 -> 0 | M14: =$D14-G14 -> 0 | N14: =$D14-H14 -> 0 | O14: =$D14-I14 -> 0 | Q14: =IFERROR($D14/E14-1,0) -> 0 | R14: =IFERROR($D14/F14-1,0) -> 0 | S14: =IFERROR($D14/G14-1,0) -> 0 | T14: =IFERROR($D14/H14-1,0) -> 0 | U14: =IFERROR($D14/I14-1,0) -> 0 | W14: {=INDIRECT("'"&$C$6&"'!"&ADDRESS(ROW(),COLUMN()+44))} -> 0 | X14: {=INDIRECT("'"&$C$6&"'!"&ADDRESS(ROW(),COLUMN()+44))} -> 0 | Y14: {=INDIRECT("'"&$C$6&"'!"&ADDRESS(ROW(),COLUMN()+44))} -> 0 | Z14: {=INDIRECT("'"&$C$6&"'!"&ADDRESS(ROW(),COLUMN()+44))} -> 0 | AA14: {=INDIRECT("'"&$C$6&"'!"&ADDRESS(ROW(),COLUMN()+44))} -> 0 | AB14: {=INDIRECT("'"&$C$6&"'!"&ADDRESS(ROW(),COLUMN()+44))} -> 0 | AD14: =$W14-X14 -> 0 | AE14: =$W14-Y14 -> 0 | AF14: =$W14-Z14 -> 0 | AG14: =$W14-AA14 -> 0 | AH14: =$W14-AB14 -> 0 | AJ14: =IFERROR($W14/X14-1,0) -> 0 | AK14: =IFERROR($W14/Y14-1,0) -> 0 | AL14: =IFERROR($W14/Z14-1,0) -> 0 | AM14: =IFERROR($W14/AA14-1,0) -> 0 | AN14: =IFERROR($W14/AB14-1,0) -> 0
A15: SALDO_FDP | D15: {=_xlfn.XLOOKUP(1, (INDIRECT("'"&$C$6&"'!$6:$6")=D$6)* (INDIRECT("'"&$C$6&"'!$5:$5")=D$5), INDIRECT("'"&$C$6&"'!"&ROW()&":"&ROW()) )} -> 0 | E15: {=_xlfn.XLOOKUP(1, (INDIRECT("'"&$C$6&"'!$6:$6")=E$6)* (INDIRECT("'"&$C$6&"'!$5:$5")=E$5), INDIRECT("'"&$C$6&"'!"&ROW()&":"&ROW()) )} -> 0 | F15: {=_xlfn.XLOOKUP(1, (INDIRECT("'"&$C$6&"'!$6:$6")=F$6)* (INDIRECT("'"&$C$6&"'!$5:$5")=F$5), INDIRECT("'"&$C$6&"'!"&ROW()&":"&ROW()) )} -> 0 | G15: {=_xlfn.XLOOKUP(1, (INDIRECT("'"&$C$6&"'!$6:$6")=G$6)* (INDIRECT("'"&$C$6&"'!$5:$5")=G$5), INDIRECT("'"&$C$6&"'!"&ROW()&":"&ROW()) )} -> 0 | H15: {=_xlfn.XLOOKUP(1, (INDIRECT("'"&$C$6&"'!$6:$6")=H$6)* (INDIRECT("'"&$C$6&"'!$5:$5")=H$5), INDIRECT("'"&$C$6&"'!"&ROW()&":"&ROW()) )} -> 0 | I15: {=_xlfn.XLOOKUP(1, (INDIRECT("'"&$C$6&"'!$6:$6")=I$6)* (INDIRECT("'"&$C$6&"'!$5:$5")=I$5), INDIRECT("'"&$C$6&"'!"&ROW()&":"&ROW()) )} -> 0 | K15: =$D15-E15 -> 0 | L15: =$D15-F15 -> 0 | M15: =$D15-G15 -> 0 | N15: =$D15-H15 -> 0 | O15: =$D15-I15 -> 0 | Q15: =IFERROR($D15/E15-1,0) -> 0 | R15: =IFERROR($D15/F15-1,0) -> 0 | S15: =IFERROR($D15/G15-1,0) -> 0 | T15: =IFERROR($D15/H15-1,0) -> 0 | U15: =IFERROR($D15/I15-1,0) -> 0 | W15: {=INDIRECT("'"&$C$6&"'!"&ADDRESS(ROW(),COLUMN()+44))} -> 0 | X15: {=INDIRECT("'"&$C$6&"'!"&ADDRESS(ROW(),COLUMN()+44))} -> 0 | Y15: {=INDIRECT("'"&$C$6&"'!"&ADDRESS(ROW(),COLUMN()+44))} -> 0 | Z15: {=INDIRECT("'"&$C$6&"'!"&ADDRESS(ROW(),COLUMN()+44))} -> 0 | AA15: {=INDIRECT("'"&$C$6&"'!"&ADDRESS(ROW(),COLUMN()+44))} -> 0 | AB15: {=INDIRECT("'"&$C$6&"'!"&ADDRESS(ROW(),COLUMN()+44))} -> 0 | AD15: =$W15-X15 -> 0 | AE15: =$W15-Y15 -> 0 | AF15: =$W15-Z15 -> 0 | AG15: =$W15-AA15 -> 0 | AH15: =$W15-AB15 -> 0 | AJ15: =IFERROR($W15/X15-1,0) -> 0 | AK15: =IFERROR($W15/Y15-1,0) -> 0 | AL15: =IFERROR($W15/Z15-1,0) -> 0 | AM15: =IFERROR($W15/AA15-1,0) -> 0 | AN15: =IFERROR($W15/AB15-1,0) -> 0
A16: SALDO_FDP | D16: =SUM(D8:D15) -> 0 | E16: =SUM(E8:E15) -> 1963709.7 | F16: =SUM(F8:F15) -> 0 | G16: =SUM(G8:G15) -> 0 | H16: =SUM(H8:H15) -> 0 | I16: =SUM(I8:I15) -> 0 | K16: =$D16-E16 -> -1963709.7 | L16: =$D16-F16 -> 0 | M16: =$D16-G16 -> 0 | N16: =$D16-H16 -> 0 | O16: =$D16-I16 -> 0 | Q16: =IFERROR($D16/E16-1,0) -> -1 | R16: =IFERROR($D16/F16-1,0) -> 0 | S16: =IFERROR($D16/G16-1,0) -> 0 | T16: =IFERROR($D16/H16-1,0) -> 0 | U16: =IFERROR($D16/I16-1,0) -> 0 | W16: =SUM(W8:W15) -> 0 | X16: =SUM(X8:X15) -> 1963709.7 | Y16: =SUM(Y8:Y15) -> 0 | Z16: =SUM(Z8:Z15) -> 0 | AA16: =SUM(AA8:AA15) -> 0 | AB16: =SUM(AB8:AB15) -> 0 | AD16: =$W16-X16 -> -1963709.7 | AE16: =$W16-Y16 -> 0 | AF16: =$W16-Z16 -> 0 | AG16: =$W16-AA16 -> 0 | AH16: =$W16-AB16 -> 0 | AJ16: =IFERROR($W16/X16-1,0) -> -1 | AK16: =IFERROR($W16/Y16-1,0) -> 0 | AL16: =IFERROR($W16/Z16-1,0) -> 0 | AM16: =IFERROR($W16/AA16-1,0) -> 0 | AN16: =IFERROR($W16/AB16-1,0) -> 0
A17: SALDO_FDP | D17: {=_xlfn.XLOOKUP(1, (INDIRECT("'"&$C$6&"'!$6:$6")=D$6)* (INDIRECT("'"&$C$6&"'!$5:$5")=D$5), INDIRECT("'"&$C$6&"'!"&ROW()&":"&ROW()) )} -> 0 | E17: {=_xlfn.XLOOKUP(1, (INDIRECT("'"&$C$6&"'!$6:$6")=E$6)* (INDIRECT("'"&$C$6&"'!$5:$5")=E$5), INDIRECT("'"&$C$6&"'!"&ROW()&":"&ROW()) )} -> 0 | F17: {=_xlfn.XLOOKUP(1, (INDIRECT("'"&$C$6&"'!$6:$6")=F$6)* (INDIRECT("'"&$C$6&"'!$5:$5")=F$5), INDIRECT("'"&$C$6&"'!"&ROW()&":"&ROW()) )} -> 0 | G17: {=_xlfn.XLOOKUP(1, (INDIRECT("'"&$C$6&"'!$6:$6")=G$6)* (INDIRECT("'"&$C$6&"'!$5:$5")=G$5), INDIRECT("'"&$C$6&"'!"&ROW()&":"&ROW()) )} -> 0 | H17: {=_xlfn.XLOOKUP(1, (INDIRECT("'"&$C$6&"'!$6:$6")=H$6)* (INDIRECT("'"&$C$6&"'!$5:$5")=H$5), INDIRECT("'"&$C$6&"'!"&ROW()&":"&ROW()) )} -> 0 | I17: {=_xlfn.XLOOKUP(1, (INDIRECT("'"&$C$6&"'!$6:$6")=I$6)* (INDIRECT("'"&$C$6&"'!$5:$5")=I$5), INDIRECT("'"&$C$6&"'!"&ROW()&":"&ROW()) )} -> 0 | K17: =$D17-E17 -> 0 | L17: =$D17-F17 -> 0 | M17: =$D17-G17 -> 0 | N17: =$D17-H17 -> 0 | O17: =$D17-I17 -> 0 | Q17: =IFERROR($D17/E17-1,0) -> 0 | R17: =IFERROR($D17/F17-1,0) -> 0 | S17: =IFERROR($D17/G17-1,0) -> 0 | T17: =IFERROR($D17/H17-1,0) -> 0 | U17: =IFERROR($D17/I17-1,0) -> 0 | W17: {=INDIRECT("'"&$C$6&"'!"&ADDRESS(ROW(),COLUMN()+44))} -> 0 | X17: {=INDIRECT("'"&$C$6&"'!"&ADDRESS(ROW(),COLUMN()+44))} -> 0 | Y17: {=INDIRECT("'"&$C$6&"'!"&ADDRESS(ROW(),COLUMN()+44))} -> 0 | Z17: {=INDIRECT("'"&$C$6&"'!"&ADDRESS(ROW(),COLUMN()+44))} -> 0 | AA17: {=INDIRECT("'"&$C$6&"'!"&ADDRESS(ROW(),COLUMN()+44))} -> 0 | AB17: {=INDIRECT("'"&$C$6&"'!"&ADDRESS(ROW(),COLUMN()+44))} -> 0 | AD17: =$W17-X17 -> 0 | AE17: =$W17-Y17 -> 0 | AF17: =$W17-Z17 -> 0 | AG17: =$W17-AA17 -> 0 | AH17: =$W17-AB17 -> 0 | AJ17: =IFERROR($W17/X17-1,0) -> 0 | AK17: =IFERROR($W17/Y17-1,0) -> 0 | AL17: =IFERROR($W17/Z17-1,0) -> 0 | AM17: =IFERROR($W17/AA17-1,0) -> 0 | AN17: =IFERROR($W17/AB17-1,0) -> 0
A18: SALDO_FDP | D18: {=_xlfn.XLOOKUP(1, (INDIRECT("'"&$C$6&"'!$6:$6")=D$6)* (INDIRECT("'"&$C$6&"'!$5:$5")=D$5), INDIRECT("'"&$C$6&"'!"&ROW()&":"&ROW()) )} -> 0 | E18: {=_xlfn.XLOOKUP(1, (INDIRECT("'"&$C$6&"'!$6:$6")=E$6)* (INDIRECT("'"&$C$6&"'!$5:$5")=E$5), INDIRECT("'"&$C$6&"'!"&ROW()&":"&ROW()) )} -> 0 | F18: {=_xlfn.XLOOKUP(1, (INDIRECT("'"&$C$6&"'!$6:$6")=F$6)* (INDIRECT("'"&$C$6&"'!$5:$5")=F$5), INDIRECT("'"&$C$6&"'!"&ROW()&":"&ROW()) )} -> 0 | G18: {=_xlfn.XLOOKUP(1, (INDIRECT("'"&$C$6&"'!$6:$6")=G$6)* (INDIRECT("'"&$C$6&"'!$5:$5")=G$5), INDIRECT("'"&$C$6&"'!"&ROW()&":"&ROW()) )} -> 0 | H18: {=_xlfn.XLOOKUP(1, (INDIRECT("'"&$C$6&"'!$6:$6")=H$6)* (INDIRECT("'"&$C$6&"'!$5:$5")=H$5), INDIRECT("'"&$C$6&"'!"&ROW()&":"&ROW()) )} -> 0 | I18: {=_xlfn.XLOOKUP(1, (INDIRECT("'"&$C$6&"'!$6:$6")=I$6)* (INDIRECT("'"&$C$6&"'!$5:$5")=I$5), INDIRECT("'"&$C$6&"'!"&ROW()&":"&ROW()) )} -> 0 | K18: =$D18-E18 -> 0 | L18: =$D18-F18 -> 0 | M18: =$D18-G18 -> 0 | N18: =$D18-H18 -> 0 | O18: =$D18-I18 -> 0 | Q18: =IFERROR($D18/E18-1,0) -> 0 | R18: =IFERROR($D18/F18-1,0) -> 0 | S18: =IFERROR($D18/G18-1,0) -> 0 | T18: =IFERROR($D18/H18-1,0) -> 0 | U18: =IFERROR($D18/I18-1,0) -> 0 | W18: {=INDIRECT("'"&$C$6&"'!"&ADDRESS(ROW(),COLUMN()+44))} -> 0 | X18: {=INDIRECT("'"&$C$6&"'!"&ADDRESS(ROW(),COLUMN()+44))} -> 0 | Y18: {=INDIRECT("'"&$C$6&"'!"&ADDRESS(ROW(),COLUMN()+44))} -> 0 | Z18: {=INDIRECT("'"&$C$6&"'!"&ADDRESS(ROW(),COLUMN()+44))} -> 0 | AA18: {=INDIRECT("'"&$C$6&"'!"&ADDRESS(ROW(),COLUMN()+44))} -> 0 | AB18: {=INDIRECT("'"&$C$6&"'!"&ADDRESS(ROW(),COLUMN()+44))} -> 0 | AD18: =$W18-X18 -> 0 | AE18: =$W18-Y18 -> 0 | AF18: =$W18-Z18 -> 0 | AG18: =$W18-AA18 -> 0 | AH18: =$W18-AB18 -> 0 | AJ18: =IFERROR($W18/X18-1,0) -> 0 | AK18: =IFERROR($W18/Y18-1,0) -> 0 | AL18: =IFERROR($W18/Z18-1,0) -> 0 | AM18: =IFERROR($W18/AA18-1,0) -> 0 | AN18: =IFERROR($W18/AB18-1,0) -> 0
A19: SALDO_FDP | D19: {=_xlfn.XLOOKUP(1, (INDIRECT("'"&$C$6&"'!$6:$6")=D$6)* (INDIRECT("'"&$C$6&"'!$5:$5")=D$5), INDIRECT("'"&$C$6&"'!"&ROW()&":"&ROW()) )} -> 0 | E19: {=_xlfn.XLOOKUP(1, (INDIRECT("'"&$C$6&"'!$6:$6")=E$6)* (INDIRECT("'"&$C$6&"'!$5:$5")=E$5), INDIRECT("'"&$C$6&"'!"&ROW()&":"&ROW()) )} -> 0 | F19: {=_xlfn.XLOOKUP(1, (INDIRECT("'"&$C$6&"'!$6:$6")=F$6)* (INDIRECT("'"&$C$6&"'!$5:$5")=F$5), INDIRECT("'"&$C$6&"'!"&ROW()&":"&ROW()) )} -> 0 | G19: {=_xlfn.XLOOKUP(1, (INDIRECT("'"&$C$6&"'!$6:$6")=G$6)* (INDIRECT("'"&$C$6&"'!$5:$5")=G$5), INDIRECT("'"&$C$6&"'!"&ROW()&":"&ROW()) )} -> 0 | H19: {=_xlfn.XLOOKUP(1, (INDIRECT("'"&$C$6&"'!$6:$6")=H$6)* (INDIRECT("'"&$C$6&"'!$5:$5")=H$5), INDIRECT("'"&$C$6&"'!"&ROW()&":"&ROW()) )} -> 0 | I19: {=_xlfn.XLOOKUP(1, (INDIRECT("'"&$C$6&"'!$6:$6")=I$6)* (INDIRECT("'"&$C$6&"'!$5:$5")=I$5), INDIRECT("'"&$C$6&"'!"&ROW()&":"&ROW()) )} -> 0 | K19: =$D19-E19 -> 0 | L19: =$D19-F19 -> 0 | M19: =$D19-G19 -> 0 | N19: =$D19-H19 -> 0 | O19: =$D19-I19 -> 0 | Q19: =IFERROR($D19/E19-1,0) -> 0 | R19: =IFERROR($D19/F19-1,0) -> 0 | S19: =IFERROR($D19/G19-1,0) -> 0 | T19: =IFERROR($D19/H19-1,0) -> 0 | U19: =IFERROR($D19/I19-1,0) -> 0 | W19: {=INDIRECT("'"&$C$6&"'!"&ADDRESS(ROW(),COLUMN()+44))} -> 0 | X19: {=INDIRECT("'"&$C$6&"'!"&ADDRESS(ROW(),COLUMN()+44))} -> 0 | Y19: {=INDIRECT("'"&$C$6&"'!"&ADDRESS(ROW(),COLUMN()+44))} -> 0 | Z19: {=INDIRECT("'"&$C$6&"'!"&ADDRESS(ROW(),COLUMN()+44))} -> 0 | AA19: {=INDIRECT("'"&$C$6&"'!"&ADDRESS(ROW(),COLUMN()+44))} -> 0 | AB19: {=INDIRECT("'"&$C$6&"'!"&ADDRESS(ROW(),COLUMN()+44))} -> 0 | AD19: =$W19-X19 -> 0 | AE19: =$W19-Y19 -> 0 | AF19: =$W19-Z19 -> 0 | AG19: =$W19-AA19 -> 0 | AH19: =$W19-AB19 -> 0 | AJ19: =IFERROR($W19/X19-1,0) -> 0 | AK19: =IFERROR($W19/Y19-1,0) -> 0 | AL19: =IFERROR($W19/Z19-1,0) -> 0 | AM19: =IFERROR($W19/AA19-1,0) -> 0 | AN19: =IFERROR($W19/AB19-1,0) -> 0
A20: SALDO_FDP | D20: {=_xlfn.XLOOKUP(1, (INDIRECT("'"&$C$6&"'!$6:$6")=D$6)* (INDIRECT("'"&$C$6&"'!$5:$5")=D$5), INDIRECT("'"&$C$6&"'!"&ROW()&":"&ROW()) )} -> 0 | E20: {=_xlfn.XLOOKUP(1, (INDIRECT("'"&$C$6&"'!$6:$6")=E$6)* (INDIRECT("'"&$C$6&"'!$5:$5")=E$5), INDIRECT("'"&$C$6&"'!"&ROW()&":"&ROW()) )} -> 0 | F20: {=_xlfn.XLOOKUP(1, (INDIRECT("'"&$C$6&"'!$6:$6")=F$6)* (INDIRECT("'"&$C$6&"'!$5:$5")=F$5), INDIRECT("'"&$C$6&"'!"&ROW()&":"&ROW()) )} -> 0 | G20: {=_xlfn.XLOOKUP(1, (INDIRECT("'"&$C$6&"'!$6:$6")=G$6)* (INDIRECT("'"&$C$6&"'!$5:$5")=G$5), INDIRECT("'"&$C$6&"'!"&ROW()&":"&ROW()) )} -> 0 | H20: {=_xlfn.XLOOKUP(1, (INDIRECT("'"&$C$6&"'!$6:$6")=H$6)* (INDIRECT("'"&$C$6&"'!$5:$5")=H$5), INDIRECT("'"&$C$6&"'!"&ROW()&":"&ROW()) )} -> 0 | I20: {=_xlfn.XLOOKUP(1, (INDIRECT("'"&$C$6&"'!$6:$6")=I$6)* (INDIRECT("'"&$C$6&"'!$5:$5")=I$5), INDIRECT("'"&$C$6&"'!"&ROW()&":"&ROW()) )} -> 0 | K20: =$D20-E20 -> 0 | L20: =$D20-F20 -> 0 | M20: =$D20-G20 -> 0 | N20: =$D20-H20 -> 0 | O20: =$D20-I20 -> 0 | Q20: =IFERROR($D20/E20-1,0) -> 0 | R20: =IFERROR($D20/F20-1,0) -> 0 | S20: =IFERROR($D20/G20-1,0) -> 0 | T20: =IFERROR($D20/H20-1,0) -> 0 | U20: =IFERROR($D20/I20-1,0) -> 0 | W20: {=INDIRECT("'"&$C$6&"'!"&ADDRESS(ROW(),COLUMN()+44))} -> 0 | X20: {=INDIRECT("'"&$C$6&"'!"&ADDRESS(ROW(),COLUMN()+44))} -> 0 | Y20: {=INDIRECT("'"&$C$6&"'!"&ADDRESS(ROW(),COLUMN()+44))} -> 0 | Z20: {=INDIRECT("'"&$C$6&"'!"&ADDRESS(ROW(),COLUMN()+44))} -> 0 | AA20: {=INDIRECT("'"&$C$6&"'!"&ADDRESS(ROW(),COLUMN()+44))} -> 0 | AB20: {=INDIRECT("'"&$C$6&"'!"&ADDRESS(ROW(),COLUMN()+44))} -> 0 | AD20: =$W20-X20 -> 0 | AE20: =$W20-Y20 -> 0 | AF20: =$W20-Z20 -> 0 | AG20: =$W20-AA20 -> 0 | AH20: =$W20-AB20 -> 0 | AJ20: =IFERROR($W20/X20-1,0) -> 0 | AK20: =IFERROR($W20/Y20-1,0) -> 0 | AL20: =IFERROR($W20/Z20-1,0) -> 0 | AM20: =IFERROR($W20/AA20-1,0) -> 0 | AN20: =IFERROR($W20/AB20-1,0) -> 0
A21: SALDO_FDP | D21: {=_xlfn.XLOOKUP(1, (INDIRECT("'"&$C$6&"'!$6:$6")=D$6)* (INDIRECT("'"&$C$6&"'!$5:$5")=D$5), INDIRECT("'"&$C$6&"'!"&ROW()&":"&ROW()) )} -> 0 | E21: {=_xlfn.XLOOKUP(1, (INDIRECT("'"&$C$6&"'!$6:$6")=E$6)* (INDIRECT("'"&$C$6&"'!$5:$5")=E$5), INDIRECT("'"&$C$6&"'!"&ROW()&":"&ROW()) )} -> 0 | F21: {=_xlfn.XLOOKUP(1, (INDIRECT("'"&$C$6&"'!$6:$6")=F$6)* (INDIRECT("'"&$C$6&"'!$5:$5")=F$5), INDIRECT("'"&$C$6&"'!"&ROW()&":"&ROW()) )} -> 0 | G21: {=_xlfn.XLOOKUP(1, (INDIRECT("'"&$C$6&"'!$6:$6")=G$6)* (INDIRECT("'"&$C$6&"'!$5:$5")=G$5), INDIRECT("'"&$C$6&"'!"&ROW()&":"&ROW()) )} -> 0 | H21: {=_xlfn.XLOOKUP(1, (INDIRECT("'"&$C$6&"'!$6:$6")=H$6)* (INDIRECT("'"&$C$6&"'!$5:$5")=H$5), INDIRECT("'"&$C$6&"'!"&ROW()&":"&ROW()) )} -> 0 | I21: {=_xlfn.XLOOKUP(1, (INDIRECT("'"&$C$6&"'!$6:$6")=I$6)* (INDIRECT("'"&$C$6&"'!$5:$5")=I$5), INDIRECT("'"&$C$6&"'!"&ROW()&":"&ROW()) )} -> 0 | K21: =$D21-E21 -> 0 | L21: =$D21-F21 -> 0 | M21: =$D21-G21 -> 0 | N21: =$D21-H21 -> 0 | O21: =$D21-I21 -> 0 | Q21: =IFERROR($D21/E21-1,0) -> 0 | R21: =IFERROR($D21/F21-1,0) -> 0 | S21: =IFERROR($D21/G21-1,0) -> 0 | T21: =IFERROR($D21/H21-1,0) -> 0 | U21: =IFERROR($D21/I21-1,0) -> 0 | W21: {=INDIRECT("'"&$C$6&"'!"&ADDRESS(ROW(),COLUMN()+44))} -> 0 | X21: {=INDIRECT("'"&$C$6&"'!"&ADDRESS(ROW(),COLUMN()+44))} -> 0 | Y21: {=INDIRECT("'"&$C$6&"'!"&ADDRESS(ROW(),COLUMN()+44))} -> 0 | Z21: {=INDIRECT("'"&$C$6&"'!"&ADDRESS(ROW(),COLUMN()+44))} -> 0 | AA21: {=INDIRECT("'"&$C$6&"'!"&ADDRESS(ROW(),COLUMN()+44))} -> 0 | AB21: {=INDIRECT("'"&$C$6&"'!"&ADDRESS(ROW(),COLUMN()+44))} -> 0 | AD21: =$W21-X21 -> 0 | AE21: =$W21-Y21 -> 0 | AF21: =$W21-Z21 -> 0 | AG21: =$W21-AA21 -> 0 | AH21: =$W21-AB21 -> 0 | AJ21: =IFERROR($W21/X21-1,0) -> 0 | AK21: =IFERROR($W21/Y21-1,0) -> 0 | AL21: =IFERROR($W21/Z21-1,0) -> 0 | AM21: =IFERROR($W21/AA21-1,0) -> 0 | AN21: =IFERROR($W21/AB21-1,0) -> 0
A22: SALDO_FDP | D22: {=_xlfn.XLOOKUP(1, (INDIRECT("'"&$C$6&"'!$6:$6")=D$6)* (INDIRECT("'"&$C$6&"'!$5:$5")=D$5), INDIRECT("'"&$C$6&"'!"&ROW()&":"&ROW()) )} -> 0 | E22: {=_xlfn.XLOOKUP(1, (INDIRECT("'"&$C$6&"'!$6:$6")=E$6)* (INDIRECT("'"&$C$6&"'!$5:$5")=E$5), INDIRECT("'"&$C$6&"'!"&ROW()&":"&ROW()) )} -> 0 | F22: {=_xlfn.XLOOKUP(1, (INDIRECT("'"&$C$6&"'!$6:$6")=F$6)* (INDIRECT("'"&$C$6&"'!$5:$5")=F$5), INDIRECT("'"&$C$6&"'!"&ROW()&":"&ROW()) )} -> 0 | G22: {=_xlfn.XLOOKUP(1, (INDIRECT("'"&$C$6&"'!$6:$6")=G$6)* (INDIRECT("'"&$C$6&"'!$5:$5")=G$5), INDIRECT("'"&$C$6&"'!"&ROW()&":"&ROW()) )} -> 0 | H22: {=_xlfn.XLOOKUP(1, (INDIRECT("'"&$C$6&"'!$6:$6")=H$6)* (INDIRECT("'"&$C$6&"'!$5:$5")=H$5), INDIRECT("'"&$C$6&"'!"&ROW()&":"&ROW()) )} -> 0 | I22: {=_xlfn.XLOOKUP(1, (INDIRECT("'"&$C$6&"'!$6:$6")=I$6)* (INDIRECT("'"&$C$6&"'!$5:$5")=I$5), INDIRECT("'"&$C$6&"'!"&ROW()&":"&ROW()) )} -> 0 | K22: =$D22-E22 -> 0 | L22: =$D22-F22 -> 0 | M22: =$D22-G22 -> 0 | N22: =$D22-H22 -> 0 | O22: =$D22-I22 -> 0 | Q22: =IFERROR($D22/E22-1,0) -> 0 | R22: =IFERROR($D22/F22-1,0) -> 0 | S22: =IFERROR($D22/G22-1,0) -> 0 | T22: =IFERROR($D22/H22-1,0) -> 0 | U22: =IFERROR($D22/I22-1,0) -> 0 | W22: {=INDIRECT("'"&$C$6&"'!"&ADDRESS(ROW(),COLUMN()+44))} -> 0 | X22: {=INDIRECT("'"&$C$6&"'!"&ADDRESS(ROW(),COLUMN()+44))} -> 0 | Y22: {=INDIRECT("'"&$C$6&"'!"&ADDRESS(ROW(),COLUMN()+44))} -> 0 | Z22: {=INDIRECT("'"&$C$6&"'!"&ADDRESS(ROW(),COLUMN()+44))} -> 0 | AA22: {=INDIRECT("'"&$C$6&"'!"&ADDRESS(ROW(),COLUMN()+44))} -> 0 | AB22: {=INDIRECT("'"&$C$6&"'!"&ADDRESS(ROW(),COLUMN()+44))} -> 0 | AD22: =$W22-X22 -> 0 | AE22: =$W22-Y22 -> 0 | AF22: =$W22-Z22 -> 0 | AG22: =$W22-AA22 -> 0 | AH22: =$W22-AB22 -> 0 | AJ22: =IFERROR($W22/X22-1,0) -> 0 | AK22: =IFERROR($W22/Y22-1,0) -> 0 | AL22: =IFERROR($W22/Z22-1,0) -> 0 | AM22: =IFERROR($W22/AA22-1,0) -> 0 | AN22: =IFERROR($W22/AB22-1,0) -> 0
A23: SALDO_FDP | D23: =SUM(D21:D22) -> 0 | E23: =SUM(E21:E22) -> 0 | F23: =SUM(F21:F22) -> 0 | G23: =SUM(G21:G22) -> 0 | H23: =SUM(H21:H22) -> 0 | I23: =SUM(I21:I22) -> 0 | K23: =$D23-E23 -> 0 | L23: =$D23-F23 -> 0 | M23: =$D23-G23 -> 0 | N23: =$D23-H23 -> 0 | O23: =$D23-I23 -> 0 | Q23: =IFERROR($D23/E23-1,0) -> 0 | R23: =IFERROR($D23/F23-1,0) -> 0 | S23: =IFERROR($D23/G23-1,0) -> 0 | T23: =IFERROR($D23/H23-1,0) -> 0 | U23: =IFERROR($D23/I23-1,0) -> 0 | W23: =SUM(W21:W22) -> 0 | X23: =SUM(X21:X22) -> 0 | Y23: =SUM(Y21:Y22) -> 0 | Z23: =SUM(Z21:Z22) -> 0 | AA23: =SUM(AA21:AA22) -> 0 | AB23: =SUM(AB21:AB22) -> 0 | AD23: =$W23-X23 -> 0 | AE23: =$W23-Y23 -> 0 | AF23: =$W23-Z23 -> 0 | AG23: =$W23-AA23 -> 0 | AH23: =$W23-AB23 -> 0 | AJ23: =IFERROR($W23/X23-1,0) -> 0 | AK23: =IFERROR($W23/Y23-1,0) -> 0 | AL23: =IFERROR($W23/Z23-1,0) -> 0 | AM23: =IFERROR($W23/AA23-1,0) -> 0 | AN23: =IFERROR($W23/AB23-1,0) -> 0
C24: Saldo FdP | D24: =SUM(D16,D17:D20,D23) -> 0 | E24: =SUM(E16,E17:E20,E23) -> 1963709.7 | F24: =SUM(F16,F17:F20,F23) -> 0 | G24: =SUM(G16,G17:G20,G23) -> 0 | H24: =SUM(H16,H17:H20,H23) -> 0 | I24: =SUM(I16,I17:I20,I23) -> 0 | K24: =$D24-E24 -> -1963709.7 | L24: =$D24-F24 -> 0 | M24: =$D24-G24 -> 0 | N24: =$D24-H24 -> 0 | O24: =$D24-I24 -> 0 | Q24: =IFERROR($D24/E24-1,0) -> -1 | R24: =IFERROR($D24/F24-1,0) -> 0 | S24: =IFERROR($D24/G24-1,0) -> 0 | T24: =IFERROR($D24/H24-1,0) -> 0 | U24: =IFERROR($D24/I24-1,0) -> 0 | W24: =SUM(W16,W17:W20,W23) -> 0 | X24: =SUM(X16,X17:X20,X23) -> 1963709.7 | Y24: =SUM(Y16,Y17:Y20,Y23) -> 0 | Z24: =SUM(Z16,Z17:Z20,Z23) -> 0 | AA24: =SUM(AA16,AA17:AA20,AA23) -> 0 | AB24: =SUM(AB16,AB17:AB20,AB23) -> 0 | AD24: =$W24-X24 -> -1963709.7 | AE24: =$W24-Y24 -> 0 | AF24: =$W24-Z24 -> 0 | AG24: =$W24-AA24 -> 0 | AH24: =$W24-AB24 -> 0 | AJ24: =IFERROR($W24/X24-1,0) -> -1 | AK24: =IFERROR($W24/Y24-1,0) -> 0 | AL24: =IFERROR($W24/Z24-1,0) -> 0 | AM24: =IFERROR($W24/AA24-1,0) -> 0 | AN24: =IFERROR($W24/AB24-1,0) -> 0
A27: SALDO_PROM | C27: Cuenta Sueldo | D27: {=_xlfn.XLOOKUP(1, (INDIRECT("'"&$C$6&"'!$6:$6")=D$6)* (INDIRECT("'"&$C$6&"'!$5:$5")=D$5), INDIRECT("'"&$C$6&"'!"&ROW()&":"&ROW()) )} -> 0 | E27: {=_xlfn.XLOOKUP(1, (INDIRECT("'"&$C$6&"'!$6:$6")=E$6)* (INDIRECT("'"&$C$6&"'!$5:$5")=E$5), INDIRECT("'"&$C$6&"'!"&ROW()&":"&ROW()) )} -> 1758240.1 | F27: {=_xlfn.XLOOKUP(1, (INDIRECT("'"&$C$6&"'!$6:$6")=F$6)* (INDIRECT("'"&$C$6&"'!$5:$5")=F$5), INDIRECT("'"&$C$6&"'!"&ROW()&":"&ROW()) )} -> 0 | G27: {=_xlfn.XLOOKUP(1, (INDIRECT("'"&$C$6&"'!$6:$6")=G$6)* (INDIRECT("'"&$C$6&"'!$5:$5")=G$5), INDIRECT("'"&$C$6&"'!"&ROW()&":"&ROW()) )} -> 0 | H27: {=_xlfn.XLOOKUP(1, (INDIRECT("'"&$C$6&"'!$6:$6")=H$6)* (INDIRECT("'"&$C$6&"'!$5:$5")=H$5), INDIRECT("'"&$C$6&"'!"&ROW()&":"&ROW()) )} -> 0 | I27: {=_xlfn.XLOOKUP(1, (INDIRECT("'"&$C$6&"'!$6:$6")=I$6)* (INDIRECT("'"&$C$6&"'!$5:$5")=I$5), INDIRECT("'"&$C$6&"'!"&ROW()&":"&ROW()) )} -> 0 | K27: =$D27-E27 -> -1758240.1 | L27: =$D27-F27 -> 0 | M27: =$D27-G27 -> 0 | N27: =$D27-H27 -> 0 | O27: =$D27-I27 -> 0 | Q27: =IFERROR($D27/E27-1,0) -> -1 | R27: =IFERROR($D27/F27-1,0) -> 0 | S27: =IFERROR($D27/G27-1,0) -> 0 | T27: =IFERROR($D27/H27-1,0) -> 0 | U27: =IFERROR($D27/I27-1,0) -> 0 | W27: {=INDIRECT("'"&$C$6&"'!"&ADDRESS(ROW(),COLUMN()+44))} -> 0 | X27: {=INDIRECT("'"&$C$6&"'!"&ADDRESS(ROW(),COLUMN()+44))} -> 1777154.7 | Y27: {=INDIRECT("'"&$C$6&"'!"&ADDRESS(ROW(),COLUMN()+44))} -> 0 | Z27: {=INDIRECT("'"&$C$6&"'!"&ADDRESS(ROW(),COLUMN()+44))} -> 0 | AA27: {=INDIRECT("'"&$C$6&"'!"&ADDRESS(ROW(),COLUMN()+44))} -> 0 | AB27: {=INDIRECT("'"&$C$6&"'!"&ADDRESS(ROW(),COLUMN()+44))} -> 0 | AD27: =$W27-X27 -> -1777154.7 | AE27: =$W27-Y27 -> 0 | AF27: =$W27-Z27 -> 0 | AG27: =$W27-AA27 -> 0 | AH27: =$W27-AB27 -> 0 | AJ27: =IFERROR($W27/X27-1,0) -> -1 | AK27: =IFERROR($W27/Y27-1,0) -> 0 | AL27: =IFERROR($W27/Z27-1,0) -> 0 | AM27: =IFERROR($W27/AA27-1,0) -> 0 | AN27: =IFERROR($W27/AB27-1,0) -> 0
A28: SALDO_PROM | D28: {=_xlfn.XLOOKUP(1, (INDIRECT("'"&$C$6&"'!$6:$6")=D$6)* (INDIRECT("'"&$C$6&"'!$5:$5")=D$5), INDIRECT("'"&$C$6&"'!"&ROW()&":"&ROW()) )} -> 0 | E28: {=_xlfn.XLOOKUP(1, (INDIRECT("'"&$C$6&"'!$6:$6")=E$6)* (INDIRECT("'"&$C$6&"'!$5:$5")=E$5), INDIRECT("'"&$C$6&"'!"&ROW()&":"&ROW()) )} -> 0 | F28: {=_xlfn.XLOOKUP(1, (INDIRECT("'"&$C$6&"'!$6:$6")=F$6)* (INDIRECT("'"&$C$6&"'!$5:$5")=F$5), INDIRECT("'"&$C$6&"'!"&ROW()&":"&ROW()) )} -> 0 | G28: {=_xlfn.XLOOKUP(1, (INDIRECT("'"&$C$6&"'!$6:$6")=G$6)* (INDIRECT("'"&$C$6&"'!$5:$5")=G$5), INDIRECT("'"&$C$6&"'!"&ROW()&":"&ROW()) )} -> 0 | H28: {=_xlfn.XLOOKUP(1, (INDIRECT("'"&$C$6&"'!$6:$6")=H$6)* (INDIRECT("'"&$C$6&"'!$5:$5")=H$5), INDIRECT("'"&$C$6&"'!"&ROW()&":"&ROW()) )} -> 0 | I28: {=_xlfn.XLOOKUP(1, (INDIRECT("'"&$C$6&"'!$6:$6")=I$6)* (INDIRECT("'"&$C$6&"'!$5:$5")=I$5), INDIRECT("'"&$C$6&"'!"&ROW()&":"&ROW()) )} -> 0 | K28: =$D28-E28 -> 0 | L28: =$D28-F28 -> 0 | M28: =$D28-G28 -> 0 | N28: =$D28-H28 -> 0 | O28: =$D28-I28 -> 0 | Q28: =IFERROR($D28/E28-1,0) -> 0 | R28: =IFERROR($D28/F28-1,0) -> 0 | S28: =IFERROR($D28/G28-1,0) -> 0 | T28: =IFERROR($D28/H28-1,0) -> 0 | U28: =IFERROR($D28/I28-1,0) -> 0 | W28: {=INDIRECT("'"&$C$6&"'!"&ADDRESS(ROW(),COLUMN()+44))} -> 0 | X28: {=INDIRECT("'"&$C$6&"'!"&ADDRESS(ROW(),COLUMN()+44))} -> 0 | Y28: {=INDIRECT("'"&$C$6&"'!"&ADDRESS(ROW(),COLUMN()+44))} -> 0 | Z28: {=INDIRECT("'"&$C$6&"'!"&ADDRESS(ROW(),COLUMN()+44))} -> 0 | AA28: {=INDIRECT("'"&$C$6&"'!"&ADDRESS(ROW(),COLUMN()+44))} -> 0 | AB28: {=INDIRECT("'"&$C$6&"'!"&ADDRESS(ROW(),COLUMN()+44))} -> 0 | AD28: =$W28-X28 -> 0 | AE28: =$W28-Y28 -> 0 | AF28: =$W28-Z28 -> 0 | AG28: =$W28-AA28 -> 0 | AH28: =$W28-AB28 -> 0 | AJ28: =IFERROR($W28/X28-1,0) -> 0 | AK28: =IFERROR($W28/Y28-1,0) -> 0 | AL28: =IFERROR($W28/Z28-1,0) -> 0 | AM28: =IFERROR($W28/AA28-1,0) -> 0 | AN28: =IFERROR($W28/AB28-1,0) -> 0
A29: SALDO_PROM | D29: {=_xlfn.XLOOKUP(1, (INDIRECT("'"&$C$6&"'!$6:$6")=D$6)* (INDIRECT("'"&$C$6&"'!$5:$5")=D$5), INDIRECT("'"&$C$6&"'!"&ROW()&":"&ROW()) )} -> 0 | E29: {=_xlfn.XLOOKUP(1, (INDIRECT("'"&$C$6&"'!$6:$6")=E$6)* (INDIRECT("'"&$C$6&"'!$5:$5")=E$5), INDIRECT("'"&$C$6&"'!"&ROW()&":"&ROW()) )} -> 0 | F29: {=_xlfn.XLOOKUP(1, (INDIRECT("'"&$C$6&"'!$6:$6")=F$6)* (INDIRECT("'"&$C$6&"'!$5:$5")=F$5), INDIRECT("'"&$C$6&"'!"&ROW()&":"&ROW()) )} -> 0 | G29: {=_xlfn.XLOOKUP(1, (INDIRECT("'"&$C$6&"'!$6:$6")=G$6)* (INDIRECT("'"&$C$6&"'!$5:$5")=G$5), INDIRECT("'"&$C$6&"'!"&ROW()&":"&ROW()) )} -> 0 | H29: {=_xlfn.XLOOKUP(1, (INDIRECT("'"&$C$6&"'!$6:$6")=H$6)* (INDIRECT("'"&$C$6&"'!$5:$5")=H$5), INDIRECT("'"&$C$6&"'!"&ROW()&":"&ROW()) )} -> 0 | I29: {=_xlfn.XLOOKUP(1, (INDIRECT("'"&$C$6&"'!$6:$6")=I$6)* (INDIRECT("'"&$C$6&"'!$5:$5")=I$5), INDIRECT("'"&$C$6&"'!"&ROW()&":"&ROW()) )} -> 0 | K29: =$D29-E29 -> 0 | L29: =$D29-F29 -> 0 | M29: =$D29-G29 -> 0 | N29: =$D29-H29 -> 0 | O29: =$D29-I29 -> 0 | Q29: =IFERROR($D29/E29-1,0) -> 0 | R29: =IFERROR($D29/F29-1,0) -> 0 | S29: =IFERROR($D29/G29-1,0) -> 0 | T29: =IFERROR($D29/H29-1,0) -> 0 | U29: =IFERROR($D29/I29-1,0) -> 0 | W29: {=INDIRECT("'"&$C$6&"'!"&ADDRESS(ROW(),COLUMN()+44))} -> 0 | X29: {=INDIRECT("'"&$C$6&"'!"&ADDRESS(ROW(),COLUMN()+44))} -> 0 | Y29: {=INDIRECT("'"&$C$6&"'!"&ADDRESS(ROW(),COLUMN()+44))} -> 0 | Z29: {=INDIRECT("'"&$C$6&"'!"&ADDRESS(ROW(),COLUMN()+44))} -> 0 | AA29: {=INDIRECT("'"&$C$6&"'!"&ADDRESS(ROW(),COLUMN()+44))} -> 0 | AB29: {=INDIRECT("'"&$C$6&"'!"&ADDRESS(ROW(),COLUMN()+44))} -> 0 | AD29: =$W29-X29 -> 0 | AE29: =$W29-Y29 -> 0 | AF29: =$W29-Z29 -> 0 | AG29: =$W29-AA29 -> 0 | AH29: =$W29-AB29 -> 0 | AJ29: =IFERROR($W29/X29-1,0) -> 0 | AK29: =IFERROR($W29/Y29-1,0) -> 0 | AL29: =IFERROR($W29/Z29-1,0) -> 0 | AM29: =IFERROR($W29/AA29-1,0) -> 0 | AN29: =IFERROR($W29/AB29-1,0) -> 0
A30: SALDO_PROM | D30: {=_xlfn.XLOOKUP(1, (INDIRECT("'"&$C$6&"'!$6:$6")=D$6)* (INDIRECT("'"&$C$6&"'!$5:$5")=D$5), INDIRECT("'"&$C$6&"'!"&ROW()&":"&ROW()) )} -> 0 | E30: {=_xlfn.XLOOKUP(1, (INDIRECT("'"&$C$6&"'!$6:$6")=E$6)* (INDIRECT("'"&$C$6&"'!$5:$5")=E$5), INDIRECT("'"&$C$6&"'!"&ROW()&":"&ROW()) )} -> 0 | F30: {=_xlfn.XLOOKUP(1, (INDIRECT("'"&$C$6&"'!$6:$6")=F$6)* (INDIRECT("'"&$C$6&"'!$5:$5")=F$5), INDIRECT("'"&$C$6&"'!"&ROW()&":"&ROW()) )} -> 0 | G30: {=_xlfn.XLOOKUP(1, (INDIRECT("'"&$C$6&"'!$6:$6")=G$6)* (INDIRECT("'"&$C$6&"'!$5:$5")=G$5), INDIRECT("'"&$C$6&"'!"&ROW()&":"&ROW()) )} -> 0 | H30: {=_xlfn.XLOOKUP(1, (INDIRECT("'"&$C$6&"'!$6:$6")=H$6)* (INDIRECT("'"&$C$6&"'!$5:$5")=H$5), INDIRECT("'"&$C$6&"'!"&ROW()&":"&ROW()) )} -> 0 | I30: {=_xlfn.XLOOKUP(1, (INDIRECT("'"&$C$6&"'!$6:$6")=I$6)* (INDIRECT("'"&$C$6&"'!$5:$5")=I$5), INDIRECT("'"&$C$6&"'!"&ROW()&":"&ROW()) )} -> 0 | K30: =$D30-E30 -> 0 | L30: =$D30-F30 -> 0 | M30: =$D30-G30 -> 0 | N30: =$D30-H30 -> 0 | O30: =$D30-I30 -> 0 | Q30: =IFERROR($D30/E30-1,0) -> 0 | R30: =IFERROR($D30/F30-1,0) -> 0 | S30: =IFERROR($D30/G30-1,0) -> 0 | T30: =IFERROR($D30/H30-1,0) -> 0 | U30: =IFERROR($D30/I30-1,0) -> 0 | W30: {=INDIRECT("'"&$C$6&"'!"&ADDRESS(ROW(),COLUMN()+44))} -> 0 | X30: {=INDIRECT("'"&$C$6&"'!"&ADDRESS(ROW(),COLUMN()+44))} -> 0 | Y30: {=INDIRECT("'"&$C$6&"'!"&ADDRESS(ROW(),COLUMN()+44))} -> 0 | Z30: {=INDIRECT("'"&$C$6&"'!"&ADDRESS(ROW(),COLUMN()+44))} -> 0 | AA30: {=INDIRECT("'"&$C$6&"'!"&ADDRESS(ROW(),COLUMN()+44))} -> 0 | AB30: {=INDIRECT("'"&$C$6&"'!"&ADDRESS(ROW(),COLUMN()+44))} -> 0 | AD30: =$W30-X30 -> 0 | AE30: =$W30-Y30 -> 0 | AF30: =$W30-Z30 -> 0 | AG30: =$W30-AA30 -> 0 | AH30: =$W30-AB30 -> 0 | AJ30: =IFERROR($W30/X30-1,0) -> 0 | AK30: =IFERROR($W30/Y30-1,0) -> 0 | AL30: =IFERROR($W30/Z30-1,0) -> 0 | AM30: =IFERROR($W30/AA30-1,0) -> 0 | AN30: =IFERROR($W30/AB30-1,0) -> 0
A31: SALDO_PROM | D31: {=_xlfn.XLOOKUP(1, (INDIRECT("'"&$C$6&"'!$6:$6")=D$6)* (INDIRECT("'"&$C$6&"'!$5:$5")=D$5), INDIRECT("'"&$C$6&"'!"&ROW()&":"&ROW()) )} -> 0 | E31: {=_xlfn.XLOOKUP(1, (INDIRECT("'"&$C$6&"'!$6:$6")=E$6)* (INDIRECT("'"&$C$6&"'!$5:$5")=E$5), INDIRECT("'"&$C$6&"'!"&ROW()&":"&ROW()) )} -> 0 | F31: {=_xlfn.XLOOKUP(1, (INDIRECT("'"&$C$6&"'!$6:$6")=F$6)* (INDIRECT("'"&$C$6&"'!$5:$5")=F$5), INDIRECT("'"&$C$6&"'!"&ROW()&":"&ROW()) )} -> 0 | G31: {=_xlfn.XLOOKUP(1, (INDIRECT("'"&$C$6&"'!$6:$6")=G$6)* (INDIRECT("'"&$C$6&"'!$5:$5")=G$5), INDIRECT("'"&$C$6&"'!"&ROW()&":"&ROW()) )} -> 0 | H31: {=_xlfn.XLOOKUP(1, (INDIRECT("'"&$C$6&"'!$6:$6")=H$6)* (INDIRECT("'"&$C$6&"'!$5:$5")=H$5), INDIRECT("'"&$C$6&"'!"&ROW()&":"&ROW()) )} -> 0 | I31: {=_xlfn.XLOOKUP(1, (INDIRECT("'"&$C$6&"'!$6:$6")=I$6)* (INDIRECT("'"&$C$6&"'!$5:$5")=I$5), INDIRECT("'"&$C$6&"'!"&ROW()&":"&ROW()) )} -> 0 | K31: =$D31-E31 -> 0 | L31: =$D31-F31 -> 0 | M31: =$D31-G31 -> 0 | N31: =$D31-H31 -> 0 | O31: =$D31-I31 -> 0 | Q31: =IFERROR($D31/E31-1,0) -> 0 | R31: =IFERROR($D31/F31-1,0) -> 0 | S31: =IFERROR($D31/G31-1,0) -> 0 | T31: =IFERROR($D31/H31-1,0) -> 0 | U31: =IFERROR($D31/I31-1,0) -> 0 | W31: {=INDIRECT("'"&$C$6&"'!"&ADDRESS(ROW(),COLUMN()+44))} -> 0 | X31: {=INDIRECT("'"&$C$6&"'!"&ADDRESS(ROW(),COLUMN()+44))} -> 0 | Y31: {=INDIRECT("'"&$C$6&"'!"&ADDRESS(ROW(),COLUMN()+44))} -> 0 | Z31: {=INDIRECT("'"&$C$6&"'!"&ADDRESS(ROW(),COLUMN()+44))} -> 0 | AA31: {=INDIRECT("'"&$C$6&"'!"&ADDRESS(ROW(),COLUMN()+44))} -> 0 | AB31: {=INDIRECT("'"&$C$6&"'!"&ADDRESS(ROW(),COLUMN()+44))} -> 0 | AD31: =$W31-X31 -> 0 | AE31: =$W31-Y31 -> 0 | AF31: =$W31-Z31 -> 0 | AG31: =$W31-AA31 -> 0 | AH31: =$W31-AB31 -> 0 | AJ31: =IFERROR($W31/X31-1,0) -> 0 | AK31: =IFERROR($W31/Y31-1,0) -> 0 | AL31: =IFERROR($W31/Z31-1,0) -> 0 | AM31: =IFERROR($W31/AA31-1,0) -> 0 | AN31: =IFERROR($W31/AB31-1,0) -> 0
A32: SALDO_PROM | D32: {=_xlfn.XLOOKUP(1, (INDIRECT("'"&$C$6&"'!$6:$6")=D$6)* (INDIRECT("'"&$C$6&"'!$5:$5")=D$5), INDIRECT("'"&$C$6&"'!"&ROW()&":"&ROW()) )} -> 0 | E32: {=_xlfn.XLOOKUP(1, (INDIRECT("'"&$C$6&"'!$6:$6")=E$6)* (INDIRECT("'"&$C$6&"'!$5:$5")=E$5), INDIRECT("'"&$C$6&"'!"&ROW()&":"&ROW()) )} -> 0 | F32: {=_xlfn.XLOOKUP(1, (INDIRECT("'"&$C$6&"'!$6:$6")=F$6)* (INDIRECT("'"&$C$6&"'!$5:$5")=F$5), INDIRECT("'"&$C$6&"'!"&ROW()&":"&ROW()) )} -> 0 | G32: {=_xlfn.XLOOKUP(1, (INDIRECT("'"&$C$6&"'!$6:$6")=G$6)* (INDIRECT("'"&$C$6&"'!$5:$5")=G$5), INDIRECT("'"&$C$6&"'!"&ROW()&":"&ROW()) )} -> 0 | H32: {=_xlfn.XLOOKUP(1, (INDIRECT("'"&$C$6&"'!$6:$6")=H$6)* (INDIRECT("'"&$C$6&"'!$5:$5")=H$5), INDIRECT("'"&$C$6&"'!"&ROW()&":"&ROW()) )} -> 0 | I32: {=_xlfn.XLOOKUP(1, (INDIRECT("'"&$C$6&"'!$6:$6")=I$6)* (INDIRECT("'"&$C$6&"'!$5:$5")=I$5), INDIRECT("'"&$C$6&"'!"&ROW()&":"&ROW()) )} -> 0 | K32: =$D32-E32 -> 0 | L32: =$D32-F32 -> 0 | M32: =$D32-G32 -> 0 | N32: =$D32-H32 -> 0 | O32: =$D32-I32 -> 0 | Q32: =IFERROR($D32/E32-1,0) -> 0 | R32: =IFERROR($D32/F32-1,0) -> 0 | S32: =IFERROR($D32/G32-1,0) -> 0 | T32: =IFERROR($D32/H32-1,0) -> 0 | U32: =IFERROR($D32/I32-1,0) -> 0 | W32: {=INDIRECT("'"&$C$6&"'!"&ADDRESS(ROW(),COLUMN()+44))} -> 0 | X32: {=INDIRECT("'"&$C$6&"'!"&ADDRESS(ROW(),COLUMN()+44))} -> 0 | Y32: {=INDIRECT("'"&$C$6&"'!"&ADDRESS(ROW(),COLUMN()+44))} -> 0 | Z32: {=INDIRECT("'"&$C$6&"'!"&ADDRESS(ROW(),COLUMN()+44))} -> 0 | AA32: {=INDIRECT("'"&$C$6&"'!"&ADDRESS(ROW(),COLUMN()+44))} -> 0 | AB32: {=INDIRECT("'"&$C$6&"'!"&ADDRESS(ROW(),COLUMN()+44))} -> 0 | AD32: =$W32-X32 -> 0 | AE32: =$W32-Y32 -> 0 | AF32: =$W32-Z32 -> 0 | AG32: =$W32-AA32 -> 0 | AH32: =$W32-AB32 -> 0 | AJ32: =IFERROR($W32/X32-1,0) -> 0 | AK32: =IFERROR($W32/Y32-1,0) -> 0 | AL32: =IFERROR($W32/Z32-1,0) -> 0 | AM32: =IFERROR($W32/AA32-1,0) -> 0 | AN32: =IFERROR($W32/AB32-1,0) -> 0
A33: SALDO_PROM | D33: {=_xlfn.XLOOKUP(1, (INDIRECT("'"&$C$6&"'!$6:$6")=D$6)* (INDIRECT("'"&$C$6&"'!$5:$5")=D$5), INDIRECT("'"&$C$6&"'!"&ROW()&":"&ROW()) )} -> 0 | E33: {=_xlfn.XLOOKUP(1, (INDIRECT("'"&$C$6&"'!$6:$6")=E$6)* (INDIRECT("'"&$C$6&"'!$5:$5")=E$5), INDIRECT("'"&$C$6&"'!"&ROW()&":"&ROW()) )} -> 0 | F33: {=_xlfn.XLOOKUP(1, (INDIRECT("'"&$C$6&"'!$6:$6")=F$6)* (INDIRECT("'"&$C$6&"'!$5:$5")=F$5), INDIRECT("'"&$C$6&"'!"&ROW()&":"&ROW()) )} -> 0 | G33: {=_xlfn.XLOOKUP(1, (INDIRECT("'"&$C$6&"'!$6:$6")=G$6)* (INDIRECT("'"&$C$6&"'!$5:$5")=G$5), INDIRECT("'"&$C$6&"'!"&ROW()&":"&ROW()) )} -> 0 | H33: {=_xlfn.XLOOKUP(1, (INDIRECT("'"&$C$6&"'!$6:$6")=H$6)* (INDIRECT("'"&$C$6&"'!$5:$5")=H$5), INDIRECT("'"&$C$6&"'!"&ROW()&":"&ROW()) )} -> 0 | I33: {=_xlfn.XLOOKUP(1, (INDIRECT("'"&$C$6&"'!$6:$6")=I$6)* (INDIRECT("'"&$C$6&"'!$5:$5")=I$5), INDIRECT("'"&$C$6&"'!"&ROW()&":"&ROW()) )} -> 0 | K33: =$D33-E33 -> 0 | L33: =$D33-F33 -> 0 | M33: =$D33-G33 -> 0 | N33: =$D33-H33 -> 0 | O33: =$D33-I33 -> 0 | Q33: =IFERROR($D33/E33-1,0) -> 0 | R33: =IFERROR($D33/F33-1,0) -> 0 | S33: =IFERROR($D33/G33-1,0) -> 0 | T33: =IFERROR($D33/H33-1,0) -> 0 | U33: =IFERROR($D33/I33-1,0) -> 0 | W33: {=INDIRECT("'"&$C$6&"'!"&ADDRESS(ROW(),COLUMN()+44))} -> 0 | X33: {=INDIRECT("'"&$C$6&"'!"&ADDRESS(ROW(),COLUMN()+44))} -> 0 | Y33: {=INDIRECT("'"&$C$6&"'!"&ADDRESS(ROW(),COLUMN()+44))} -> 0 | Z33: {=INDIRECT("'"&$C$6&"'!"&ADDRESS(ROW(),COLUMN()+44))} -> 0 | AA33: {=INDIRECT("'"&$C$6&"'!"&ADDRESS(ROW(),COLUMN()+44))} -> 0 | AB33: {=INDIRECT("'"&$C$6&"'!"&ADDRESS(ROW(),COLUMN()+44))} -> 0 | AD33: =$W33-X33 -> 0 | AE33: =$W33-Y33 -> 0 | AF33: =$W33-Z33 -> 0 | AG33: =$W33-AA33 -> 0 | AH33: =$W33-AB33 -> 0 | AJ33: =IFERROR($W33/X33-1,0) -> 0 | AK33: =IFERROR($W33/Y33-1,0) -> 0 | AL33: =IFERROR($W33/Z33-1,0) -> 0 | AM33: =IFERROR($W33/AA33-1,0) -> 0 | AN33: =IFERROR($W33/AB33-1,0) -> 0
A34: SALDO_PROM | D34: {=_xlfn.XLOOKUP(1, (INDIRECT("'"&$C$6&"'!$6:$6")=D$6)* (INDIRECT("'"&$C$6&"'!$5:$5")=D$5), INDIRECT("'"&$C$6&"'!"&ROW()&":"&ROW()) )} -> 0 | E34: {=_xlfn.XLOOKUP(1, (INDIRECT("'"&$C$6&"'!$6:$6")=E$6)* (INDIRECT("'"&$C$6&"'!$5:$5")=E$5), INDIRECT("'"&$C$6&"'!"&ROW()&":"&ROW()) )} -> 0 | F34: {=_xlfn.XLOOKUP(1, (INDIRECT("'"&$C$6&"'!$6:$6")=F$6)* (INDIRECT("'"&$C$6&"'!$5:$5")=F$5), INDIRECT("'"&$C$6&"'!"&ROW()&":"&ROW()) )} -> 0 | G34: {=_xlfn.XLOOKUP(1, (INDIRECT("'"&$C$6&"'!$6:$6")=G$6)* (INDIRECT("'"&$C$6&"'!$5:$5")=G$5), INDIRECT("'"&$C$6&"'!"&ROW()&":"&ROW()) )} -> 0 | H34: {=_xlfn.XLOOKUP(1, (INDIRECT("'"&$C$6&"'!$6:$6")=H$6)* (INDIRECT("'"&$C$6&"'!$5:$5")=H$5), INDIRECT("'"&$C$6&"'!"&ROW()&":"&ROW()) )} -> 0 | I34: {=_xlfn.XLOOKUP(1, (INDIRECT("'"&$C$6&"'!$6:$6")=I$6)* (INDIRECT("'"&$C$6&"'!$5:$5")=I$5), INDIRECT("'"&$C$6&"'!"&ROW()&":"&ROW()) )} -> 0 | K34: =$D34-E34 -> 0 | L34: =$D34-F34 -> 0 | M34: =$D34-G34 -> 0 | N34: =$D34-H34 -> 0 | O34: =$D34-I34 -> 0 | Q34: =IFERROR($D34/E34-1,0) -> 0 | R34: =IFERROR($D34/F34-1,0) -> 0 | S34: =IFERROR($D34/G34-1,0) -> 0 | T34: =IFERROR($D34/H34-1,0) -> 0 | U34: =IFERROR($D34/I34-1,0) -> 0 | W34: {=INDIRECT("'"&$C$6&"'!"&ADDRESS(ROW(),COLUMN()+44))} -> 0 | X34: {=INDIRECT("'"&$C$6&"'!"&ADDRESS(ROW(),COLUMN()+44))} -> 0 | Y34: {=INDIRECT("'"&$C$6&"'!"&ADDRESS(ROW(),COLUMN()+44))} -> 0 | Z34: {=INDIRECT("'"&$C$6&"'!"&ADDRESS(ROW(),COLUMN()+44))} -> 0 | AA34: {=INDIRECT("'"&$C$6&"'!"&ADDRESS(ROW(),COLUMN()+44))} -> 0 | AB34: {=INDIRECT("'"&$C$6&"'!"&ADDRESS(ROW(),COLUMN()+44))} -> 0 | AD34: =$W34-X34 -> 0 | AE34: =$W34-Y34 -> 0 | AF34: =$W34-Z34 -> 0 | AG34: =$W34-AA34 -> 0 | AH34: =$W34-AB34 -> 0 | AJ34: =IFERROR($W34/X34-1,0) -> 0 | AK34: =IFERROR($W34/Y34-1,0) -> 0 | AL34: =IFERROR($W34/Z34-1,0) -> 0 | AM34: =IFERROR($W34/AA34-1,0) -> 0 | AN34: =IFERROR($W34/AB34-1,0) -> 0
A35: SALDO_PROM | D35: =SUM(D27:D34) -> 0 | E35: =SUM(E27:E34) -> 1758240.1 | F35: =SUM(F27:F34) -> 0 | G35: =SUM(G27:G34) -> 0 | H35: =SUM(H27:H34) -> 0 | I35: =SUM(I27:I34) -> 0 | K35: =$D35-E35 -> -1758240.1 | L35: =$D35-F35 -> 0 | M35: =$D35-G35 -> 0 | N35: =$D35-H35 -> 0 | O35: =$D35-I35 -> 0 | Q35: =IFERROR($D35/E35-1,0) -> -1 | R35: =IFERROR($D35/F35-1,0) -> 0 | S35: =IFERROR($D35/G35-1,0) -> 0 | T35: =IFERROR($D35/H35-1,0) -> 0 | U35: =IFERROR($D35/I35-1,0) -> 0 | W35: =SUM(W27:W34) -> 0 | X35: =SUM(X27:X34) -> 1777154.7 | Y35: =SUM(Y27:Y34) -> 0 | Z35: =SUM(Z27:Z34) -> 0 | AA35: =SUM(AA27:AA34) -> 0 | AB35: =SUM(AB27:AB34) -> 0 | AD35: =$W35-X35 -> -1777154.7 | AE35: =$W35-Y35 -> 0 | AF35: =$W35-Z35 -> 0 | AG35: =$W35-AA35 -> 0 | AH35: =$W35-AB35 -> 0 | AJ35: =IFERROR($W35/X35-1,0) -> -1 | AK35: =IFERROR($W35/Y35-1,0) -> 0 | AL35: =IFERROR($W35/Z35-1,0) -> 0 | AM35: =IFERROR($W35/AA35-1,0) -> 0 | AN35: =IFERROR($W35/AB35-1,0) -> 0
A36: SALDO_PROM | D36: {=_xlfn.XLOOKUP(1, (INDIRECT("'"&$C$6&"'!$6:$6")=D$6)* (INDIRECT("'"&$C$6&"'!$5:$5")=D$5), INDIRECT("'"&$C$6&"'!"&ROW()&":"&ROW()) )} -> 0 | E36: {=_xlfn.XLOOKUP(1, (INDIRECT("'"&$C$6&"'!$6:$6")=E$6)* (INDIRECT("'"&$C$6&"'!$5:$5")=E$5), INDIRECT("'"&$C$6&"'!"&ROW()&":"&ROW()) )} -> 0 | F36: {=_xlfn.XLOOKUP(1, (INDIRECT("'"&$C$6&"'!$6:$6")=F$6)* (INDIRECT("'"&$C$6&"'!$5:$5")=F$5), INDIRECT("'"&$C$6&"'!"&ROW()&":"&ROW()) )} -> 0 | G36: {=_xlfn.XLOOKUP(1, (INDIRECT("'"&$C$6&"'!$6:$6")=G$6)* (INDIRECT("'"&$C$6&"'!$5:$5")=G$5), INDIRECT("'"&$C$6&"'!"&ROW()&":"&ROW()) )} -> 0 | H36: {=_xlfn.XLOOKUP(1, (INDIRECT("'"&$C$6&"'!$6:$6")=H$6)* (INDIRECT("'"&$C$6&"'!$5:$5")=H$5), INDIRECT("'"&$C$6&"'!"&ROW()&":"&ROW()) )} -> 0 | I36: {=_xlfn.XLOOKUP(1, (INDIRECT("'"&$C$6&"'!$6:$6")=I$6)* (INDIRECT("'"&$C$6&"'!$5:$5")=I$5), INDIRECT("'"&$C$6&"'!"&ROW()&":"&ROW()) )} -> 0 | K36: =$D36-E36 -> 0 | L36: =$D36-F36 -> 0 | M36: =$D36-G36 -> 0 | N36: =$D36-H36 -> 0 | O36: =$D36-I36 -> 0 | Q36: =IFERROR($D36/E36-1,0) -> 0 | R36: =IFERROR($D36/F36-1,0) -> 0 | S36: =IFERROR($D36/G36-1,0) -> 0 | T36: =IFERROR($D36/H36-1,0) -> 0 | U36: =IFERROR($D36/I36-1,0) -> 0 | W36: {=INDIRECT("'"&$C$6&"'!"&ADDRESS(ROW(),COLUMN()+44))} -> 0 | X36: {=INDIRECT("'"&$C$6&"'!"&ADDRESS(ROW(),COLUMN()+44))} -> 0 | Y36: {=INDIRECT("'"&$C$6&"'!"&ADDRESS(ROW(),COLUMN()+44))} -> 0 | Z36: {=INDIRECT("'"&$C$6&"'!"&ADDRESS(ROW(),COLUMN()+44))} -> 0 | AA36: {=INDIRECT("'"&$C$6&"'!"&ADDRESS(ROW(),COLUMN()+44))} -> 0 | AB36: {=INDIRECT("'"&$C$6&"'!"&ADDRESS(ROW(),COLUMN()+44))} -> 0 | AD36: =$W36-X36 -> 0 | AE36: =$W36-Y36 -> 0 | AF36: =$W36-Z36 -> 0 | AG36: =$W36-AA36 -> 0 | AH36: =$W36-AB36 -> 0 | AJ36: =IFERROR($W36/X36-1,0) -> 0 | AK36: =IFERROR($W36/Y36-1,0) -> 0 | AL36: =IFERROR($W36/Z36-1,0) -> 0 | AM36: =IFERROR($W36/AA36-1,0) -> 0 | AN36: =IFERROR($W36/AB36-1,0) -> 0
A37: SALDO_PROM | D37: {=_xlfn.XLOOKUP(1, (INDIRECT("'"&$C$6&"'!$6:$6")=D$6)* (INDIRECT("'"&$C$6&"'!$5:$5")=D$5), INDIRECT("'"&$C$6&"'!"&ROW()&":"&ROW()) )} -> 0 | E37: {=_xlfn.XLOOKUP(1, (INDIRECT("'"&$C$6&"'!$6:$6")=E$6)* (INDIRECT("'"&$C$6&"'!$5:$5")=E$5), INDIRECT("'"&$C$6&"'!"&ROW()&":"&ROW()) )} -> 0 | F37: {=_xlfn.XLOOKUP(1, (INDIRECT("'"&$C$6&"'!$6:$6")=F$6)* (INDIRECT("'"&$C$6&"'!$5:$5")=F$5), INDIRECT("'"&$C$6&"'!"&ROW()&":"&ROW()) )} -> 0 | G37: {=_xlfn.XLOOKUP(1, (INDIRECT("'"&$C$6&"'!$6:$6")=G$6)* (INDIRECT("'"&$C$6&"'!$5:$5")=G$5), INDIRECT("'"&$C$6&"'!"&ROW()&":"&ROW()) )} -> 0 | H37: {=_xlfn.XLOOKUP(1, (INDIRECT("'"&$C$6&"'!$6:$6")=H$6)* (INDIRECT("'"&$C$6&"'!$5:$5")=H$5), INDIRECT("'"&$C$6&"'!"&ROW()&":"&ROW()) )} -> 0 | I37: {=_xlfn.XLOOKUP(1, (INDIRECT("'"&$C$6&"'!$6:$6")=I$6)* (INDIRECT("'"&$C$6&"'!$5:$5")=I$5), INDIRECT("'"&$C$6&"'!"&ROW()&":"&ROW()) )} -> 0 | K37: =$D37-E37 -> 0 | L37: =$D37-F37 -> 0 | M37: =$D37-G37 -> 0 | N37: =$D37-H37 -> 0 | O37: =$D37-I37 -> 0 | Q37: =IFERROR($D37/E37-1,0) -> 0 | R37: =IFERROR($D37/F37-1,0) -> 0 | S37: =IFERROR($D37/G37-1,0) -> 0 | T37: =IFERROR($D37/H37-1,0) -> 0 | U37: =IFERROR($D37/I37-1,0) -> 0 | W37: {=INDIRECT("'"&$C$6&"'!"&ADDRESS(ROW(),COLUMN()+44))} -> 0 | X37: {=INDIRECT("'"&$C$6&"'!"&ADDRESS(ROW(),COLUMN()+44))} -> 0 | Y37: {=INDIRECT("'"&$C$6&"'!"&ADDRESS(ROW(),COLUMN()+44))} -> 0 | Z37: {=INDIRECT("'"&$C$6&"'!"&ADDRESS(ROW(),COLUMN()+44))} -> 0 | AA37: {=INDIRECT("'"&$C$6&"'!"&ADDRESS(ROW(),COLUMN()+44))} -> 0 | AB37: {=INDIRECT("'"&$C$6&"'!"&ADDRESS(ROW(),COLUMN()+44))} -> 0 | AD37: =$W37-X37 -> 0 | AE37: =$W37-Y37 -> 0 | AF37: =$W37-Z37 -> 0 | AG37: =$W37-AA37 -> 0 | AH37: =$W37-AB37 -> 0 | AJ37: =IFERROR($W37/X37-1,0) -> 0 | AK37: =IFERROR($W37/Y37-1,0) -> 0 | AL37: =IFERROR($W37/Z37-1,0) -> 0 | AM37: =IFERROR($W37/AA37-1,0) -> 0 | AN37: =IFERROR($W37/AB37-1,0) -> 0
