Workbook

Sheet Parametros
B2: Producto | C2: Convenios
B4: Año | C4: 2026
B6: Lista Fechas | C6: =EOMONTH(DATE($C$4,1,1),0) -> 46053 | E6: Segmentos | F6: Renta_Alta
C7: =EOMONTH(C6,1) -> 46081 | F7: Masivo
C8: =EOMONTH(C7,1) -> 46112 | F8: Consumo_Inicial
C9: =EOMONTH(C8,1) -> 46142 | F9: Total_Producto
C10: =EOMONTH(C9,1) -> 46173
C11: =EOMONTH(C10,1) -> 46203
C12: =EOMONTH(C11,1) -> 46234
C13: =EOMONTH(C12,1) -> 46265
C14: =EOMONTH(C13,1) -> 46295
C15: =EOMONTH(C14,1) -> 46326
C16: =EOMONTH(C15,1) -> 46356
C17: =EOMONTH(C16,1) -> 46387

Sheet Total_Producto_CHECK
D1: REAL | AZ1: PRESUPUESTO | BO1: Acumulado | BW1: Saldo Prom Acumulado
BO2: =DATE(YEAR(BO6),1,1) -> 46023 | BP2: =DATE(YEAR(BP6),1,1) -> 46023 | BQ2: =DATE(YEAR(BQ6),1,1) -> 46023 | BR2: =DATE(YEAR(BR6),1,1) -> 45658 | BS2: =DATE(YEAR(BS6),1,1) -> 45292 | BT2: =DATE(YEAR(BT6),1,1) -> 44927
C3: N° dias T.Imp | D3: 30 | E3: 30 | F3: 30 | G3: 30 | H3: 30 | I3: 30 | J3: 30 | K3: 30 | L3: 30 | M3: 30 | N3: 30 | O3: 30 | P3: 30 | Q3: 30 | R3: 30 | S3: 30 | T3: 30 | U3: 30 | V3: 30 | W3: 30 | X3: 30 | Y3: 30 | Z3: 30 | AA3: 30 | AB3: 30 | AC3: 30 | AD3: 30 | AE3: 30 | AF3: 30 | AG3: 30 | AH3: 30 | AI3: 30 | AJ3: 30 | AK3: 30 | AL3: 30 | AM3: 30 | AN3: 30 | AO3: 30 | AP3: 30 | AQ3: 30 | AR3: 30 | AS3: 30 | AT3: 30 | AU3: 30 | AV3: 30 | AW3: 30 | AX3: 30 | AY3: 30 | AZ3: 30 | BA3: 30 | BB3: 30 | BC3: 30 | BD3: 30 | BE3: 30 | BF3: 30 | BG3: 30 | BH3: 30 | BI3: 30 | BJ3: 30 | BK3: 30 | BO3: =AVERAGEIFS($D3:$BM3,$D$6:$BM$6,">="&BO$2,$D$6:$BM$6,"<="&BO$6,$D$5:$BM$5,BO$5) -> 30 | BP3: =AVERAGEIFS($D3:$BM3,$D$6:$BM$6,">="&BP$2,$D$6:$BM$6,"<="&BP$6,$D$5:$BM$5,BP$5) -> 30 | BQ3: =AVERAGEIFS($D3:$BM3,$D$6:$BM$6,">="&BQ$2,$D$6:$BM$6,"<="&BQ$6,$D$5:$BM$5,BQ$5) -> 30 | BR3: =AVERAGEIFS($D3:$BM3,$D$6:$BM$6,">="&BR$2,$D$6:$BM$6,"<="&BR$6,$D$5:$BM$5,BR$5) -> 30 | BS3: =AVERAGEIFS($D3:$BM3,$D$6:$BM$6,">="&BS$2,$D$6:$BM$6,"<="&BS$6,$D$5:$BM$5,BS$5) -> 30 | BT3: =AVERAGEIFS($D3:$BM3,$D$6:$BM$6,">="&BT$2,$D$6:$BM$6,"<="&BT$6,$D$5:$BM$5,BT$5) -> 30
C4: N° dias FTP | D4: =DAY(D6) -> 31 | E4: =DAY(E6) -> 28 | F4: =DAY(F6) -> 31 | G4: =DAY(G6) -> 30 | H4: =DAY(H6) -> 31 | I4: =DAY(I6) -> 30 | J4: =DAY(J6) -> 31 | K4: =DAY(K6) -> 31 | ... BK4: =DAY(BK6) -> 31 | BO4: =AVERAGEIFS($D4:$BM4,$D$6:$BM$6,">="&BO$2,$D$6:$BM$6,"<="&BO$6,$D$5:$BM$5,BO$5) -> 30.2 | BP4: =AVERAGEIFS($D4:$BM4,$D$6:$BM$6,">="&BP$2,$D$6:$BM$6,"<="&BP$6,$D$5:$BM$5,BP$5) -> 30.2 | BQ4: =AVERAGEIFS($D4:$BM4,$D$6:$BM$6,">="&BQ$2,$D$6:$BM$6,"<="&BQ$6,$D$5:$BM$5,BQ$5) -> 30 | BR4: =AVERAGEIFS($D4:$BM4,$D$6:$BM$6,">="&BR$2,$D$6:$BM$6,"<="&BR$6,$D$5:$BM$5,BR$5) -> 30.2 | BS4: =AVERAGEIFS($D4:$BM4,$D$6:$BM$6,">="&BS$2,$D$6:$BM$6,"<="&BS$6,$D$5:$BM$5,BS$5) -> 30.4 | BT4: =AVERAGEIFS($D4:$BM4,$D$6:$BM$6,">="&BT$2,$D$6:$BM$6,"<="&BT$6,$D$5:$BM$5,BT$5) -> 30.2
C5: Tipo | D5: R | E5: R | F5: R | G5: R | H5: R | I5: R | J5: R | K5: R | L5: R | M5: R | N5: R | O5: R | P5: R | Q5: R | R5: R | S5: R | T5: R | U5: R | V5: R | W5: R | X5: R | Y5: R | Z5: R | AA5: R | AB5: R | AC5: R | AD5: R | AE5: R | AF5: R | AG5: R | AH5: R | AI5: R | AJ5: R | AK5: R | AL5: R | AM5: R | AN5: R | AO5: R | AP5: R | AQ5: R | AR5: R | AS5: R | AT5: R | AU5: R | AV5: R | AW5: R | AX5: R | AY5: R | AZ5: P | BA5: P | BB5: P | BC5: P | BD5: P | BE5: P | BF5: P | BG5: P | BH5: P | BI5: P | BJ5: P | BK5: P | BO5: R | BP5: P | BQ5: R | BR5: R | BS5: R | BT5: R
C6: Total Convenios | D6: 44957 | E6: 44985 | F6: 45016 | G6: 45046 | H6: 45077 | I6: 45107 | J6: 45138 | K6: 45169 | L6: 45199 | M6: 45230 | N6: 45260 | O6: 45291 | P6: 45322 | Q6: 45351 | R6: 45382 | S6: 45412 | T6: 45443 | U6: 45473 | V6: 45504 | W6: 45535 | X6: 45565 | Y6: 45596 | Z6: 45626 | AA6: 45657 | AB6: 45688 | AC6: 45716 | AD6: 45747 | AE6: 45777 | AF6: 45808 | AG6: 45838 | AH6: 45869 | AI6: 45900 | AJ6: 45930 | AK6: 45961 | AL6: 45991 | AM6: 46022 | AN6: 46053 | AO6: 46081 | AP6: 46112 | AQ6: 46142 | AR6: 46173 | AS6: 46203 | AT6: 46234 | AU6: 46265 | AV6: 46295 | AW6: 46326 | AX6: 46356 | AY6: 46387 | AZ6: 46053 | BA6: 46081 | BB6: 46112 | BC6: 46142 | BD6: 46173 | BE6: 46203 | BF6: 46234 | BG6: 46265 | BH6: 46295 | BI6: 46326 | BJ6: 46356 | BK6: 46387 | BO6: =Desempeño_Financiero!$B$1 -> 46173 | BP6: =BO6 -> 46173 | BQ6: =EOMONTH(BO6,-1) -> 46142 | BR6: =EOMONTH(BO6,-12) -> 45808 | BS6: =EOMONTH(BO6,-24) -> 45443 | BT6: =EOMONTH(BO6,-36) -> 45077 | BW6: =BO6 -> 46173 | BX6: =BP6 -> 46173 | BY6: =BQ6 -> 46142 | BZ6: =BR6 -> 45808 | CA6: =BS6 -> 45443 | CB6: =BT6 -> 45077
A8: SALDO_FDP | C8: Vigente | D8: =Renta_Alta!D8+Masivo!D8+Consumo_Inicial!D8 -> 4679803.2 | E8: =Renta_Alta!E8+Masivo!E8+Consumo_Inicial!E8 -> 4747839.5 | F8: =Renta_Alta!F8+Masivo!F8+Consumo_Inicial!F8 -> 4827253.4 | G8: =Renta_Alta!G8+Masivo!G8+Consumo_Inicial!G8 -> 4875774.2 | H8: =Renta_Alta!H8+Masivo!H8+Consumo_Inicial!H8 -> 4938857 | I8: =Renta_Alta!I8+Masivo!I8+Consumo_Inicial!I8 -> 5002096.2 | J8: =Renta_Alta!J8+Masivo!J8+Consumo_Inicial!J8 -> 5048290.6 | K8: =Renta_Alta!K8+Masivo!K8+Consumo_Inicial!K8 -> 5124035.4 | ... BK8: =Renta_Alta!BK8+Masivo!BK8+Consumo_Inicial!BK8 -> 6111590.2 | BO8: =_xlfn.XLOOKUP(BO$6,$D$6:$BM$6,$D8:$BM8,,0,1) -> 5562013.9 | BP8: =_xlfn.XLOOKUP(BP$6,$D$6:$BM$6,$D8:$BM8,,0,-1) -> 5902822.3 | BQ8: =_xlfn.XLOOKUP(BQ$6,$D$6:$BM$6,$D8:$BM8,,0,1) -> 5548588.7 | BR8: =_xlfn.XLOOKUP(BR$6,$D$6:$BM$6,$D8:$BM8,,0,1) -> 5643386.7 | BS8: =_xlfn.XLOOKUP(BS$6,$D$6:$BM$6,$D8:$BM8,,0,1) -> 5684127.8 | BT8: =_xlfn.XLOOKUP(BT$6,$D$6:$BM$6,$D8:$BM8,,0,1) -> 4938857
A9: SALDO_FDP | C9: Refinanciado | D9: =Renta_Alta!D9+Masivo!D9+Consumo_Inicial!D9 -> 28879.687 | E9: =Renta_Alta!E9+Masivo!E9+Consumo_Inicial!E9 -> 29227.268 | F9: =Renta_Alta!F9+Masivo!F9+Consumo_Inicial!F9 -> 29811.06 | G9: =Renta_Alta!G9+Masivo!G9+Consumo_Inicial!G9 -> 29204.003 | H9: =Renta_Alta!H9+Masivo!H9+Consumo_Inicial!H9 -> 29479.237 | I9: =Renta_Alta!I9+Masivo!I9+Consumo_Inicial!I9 -> 29701.682 | J9: =Renta_Alta!J9+Masivo!J9+Consumo_Inicial!J9 -> 29449.713 | K9: =Renta_Alta!K9+Masivo!K9+Consumo_Inicial!K9 -> 28793.924 | ... BK9: =Renta_Alta!BK9+Masivo!BK9+Consumo_Inicial!BK9 -> 32247.399 | BO9: =_xlfn.XLOOKUP(BO$6,$D$6:$BM$6,$D9:$BM9,,0,1) -> 28277.739 | BP9: =_xlfn.XLOOKUP(BP$6,$D$6:$BM$6,$D9:$BM9,,0,-1) -> 30703.861 | BQ9: =_xlfn.XLOOKUP(BQ$6,$D$6:$BM$6,$D9:$BM9,,0,1) -> 28987.813 | BR9: =_xlfn.XLOOKUP(BR$6,$D$6:$BM$6,$D9:$BM9,,0,1) -> 28019.412 | BS9: =_xlfn.XLOOKUP(BS$6,$D$6:$BM$6,$D9:$BM9,,0,1) -> 22700.678 | BT9: =_xlfn.XLOOKUP(BT$6,$D$6:$BM$6,$D9:$BM9,,0,1) -> 29479.237
A10: SALDO_FDP | C10: Vencido y Judicial | D10: =Renta_Alta!D10+Masivo!D10+Consumo_Inicial!D10 -> 72271.196 | E10: =Renta_Alta!E10+Masivo!E10+Consumo_Inicial!E10 -> 73895.678 | F10: =Renta_Alta!F10+Masivo!F10+Consumo_Inicial!F10 -> 73945.9 | G10: =Renta_Alta!G10+Masivo!G10+Consumo_Inicial!G10 -> 71847.884 | H10: =Renta_Alta!H10+Masivo!H10+Consumo_Inicial!H10 -> 67763.653 | I10: =Renta_Alta!I10+Masivo!I10+Consumo_Inicial!I10 -> 63617.764 | J10: =Renta_Alta!J10+Masivo!J10+Consumo_Inicial!J10 -> 63955.171 | K10: =Renta_Alta!K10+Masivo!K10+Consumo_Inicial!K10 -> 61241.076 | ... BK10: =Renta_Alta!BK10+Masivo!BK10+Consumo_Inicial!BK10 -> 107955.09 | BO10: =_xlfn.XLOOKUP(BO$6,$D$6:$BM$6,$D10:$BM10,,0,1) -> 118475.52 | BP10: =_xlfn.XLOOKUP(BP$6,$D$6:$BM$6,$D10:$BM10,,0,-1) -> 110380.99 | BQ10: =_xlfn.XLOOKUP(BQ$6,$D$6:$BM$6,$D10:$BM10,,0,1) -> 118196.07 | BR10: =_xlfn.XLOOKUP(BR$6,$D$6:$BM$6,$D10:$BM10,,0,1) -> 92392.453 | BS10: =_xlfn.XLOOKUP(BS$6,$D$6:$BM$6,$D10:$BM10,,0,1) -> 66766.564 | BT10: =_xlfn.XLOOKUP(BT$6,$D$6:$BM$6,$D10:$BM10,,0,1) -> 67763.653
C11: Saldo FdP | D11: =SUM(D8:D10) -> 4780954.1 | E11: =SUM(E8:E10) -> 4850962.5 | F11: =SUM(F8:F10) -> 4931010.4 | G11: =SUM(G8:G10) -> 4976826.1 | H11: =SUM(H8:H10) -> 5036099.9 | I11: =SUM(I8:I10) -> 5095415.6 | J11: =SUM(J8:J10) -> 5141695.4 | K11: =SUM(K8:K10) -> 5214070.4 | ... BK11: =SUM(BK8:BK10) -> 6251792.7 | BO11: =SUM(BO8:BO10) -> 5708767.2 | BP11: =SUM(BP8:BP10) -> 6043907.2 | BQ11: =SUM(BQ8:BQ10) -> 5695772.5 | BR11: =SUM(BR8:BR10) -> 5763798.5 | BS11: =SUM(BS8:BS10) -> 5773595 | BT11: =SUM(BT8:BT10) -> 5036099.9
D12: ='[1]Desempeño Financiero (Evol)'!BE58 -> 4780954.1 | E12: ='[1]Desempeño Financiero (Evol)'!BF58 -> 4850962.5 | F12: ='[1]Desempeño Financiero (Evol)'!BG58 -> 4931010.4 | G12: ='[1]Desempeño Financiero (Evol)'!BH58 -> 4976826.1 | H12: ='[1]Desempeño Financiero (Evol)'!BI58 -> 5036099.9 | I12: ='[1]Desempeño Financiero (Evol)'!BJ58 -> 5095415.6 | J12: ='[1]Desempeño Financiero (Evol)'!BK58 -> 5141695.4 | K12: ='[1]Desempeño Financiero (Evol)'!BL58 -> 5214070.4 | ... AO12: ='[1]Desempeño Financiero (Evol)'!CP58 -> 5659441.5 | AZ12: ='[1]Desempeño Financiero (Evol)'!DA58 -> 5946181.6 | BA12: ='[1]Desempeño Financiero (Evol)'!DB58 -> 5964284.8 | BB12: ='[1]Desempeño Financiero (Evol)'!DC58 -> 5999599 | BC12: ='[1]Desempeño Financiero (Evol)'!DD58 -> 6021580.8 | BD12: ='[1]Desempeño Financiero (Evol)'!DE58 -> 6043907.2 | BE12: ='[1]Desempeño Financiero (Evol)'!DF58 -> 6073724.5 | BF12: ='[1]Desempeño Financiero (Evol)'!DG58 -> 6103604.6 | BG12: ='[1]Desempeño Financiero (Evol)'!DH58 -> 6132821.3 | ... BK12: ='[1]Desempeño Financiero (Evol)'!DL58 -> 6251792.7
D13: =D12-D11 -> 0.00012999959 | E13: =E12-E11 -> 0.00023000035 | F13: =F12-F11 -> -0.00026999973 | G13: =G12-G11 -> 0.000479999 | H13: =H12-H11 -> 0.00023999996 | I13: =I12-I11 -> -0.00018000044 | J13: =J12-J11 -> -0.00023999903 | K13: =K12-K11 -> -0.00026999973 | ... AO13: =AO12-AO11 -> 0 | AZ13: =AZ12-AZ11 -> 0 | BA13: =BA12-BA11 -> 0 | BB13: =BB12-BB11 -> 0 | BC13: =BC12-BC11 -> 0 | BD13: =BD12-BD11 -> 0 | BE13: =BE12-BE11 -> 0 | BF13: =BF12-BF11 -> 0 | BG13: =BG12-BG11 -> 0 | ... BK13: =BK12-BK11 -> 0
A14: SALDO_PROM | C14: Vigente | D14: =Renta_Alta!D14+Masivo!D14+Consumo_Inicial!D14 -> 4629670.8 | E14: =Renta_Alta!E14+Masivo!E14+Consumo_Inicial!E14 -> 4705225.3 | F14: =Renta_Alta!F14+Masivo!F14+Consumo_Inicial!F14 -> 4769089.5 | G14: =Renta_Alta!G14+Masivo!G14+Consumo_Inicial!G14 -> 4833539.3 | H14: =Renta_Alta!H14+Masivo!H14+Consumo_Inicial!H14 -> 4884944 | I14: =Renta_Alta!I14+Masivo!I14+Consumo_Inicial!I14 -> 4948509.1 | J14: =Renta_Alta!J14+Masivo!J14+Consumo_Inicial!J14 -> 5003780.5 | K14: =Renta_Alta!K14+Masivo!K14+Consumo_Inicial!K14 -> 5059584.1 | ... BK14: =Renta_Alta!BK14+Masivo!BK14+Consumo_Inicial!BK14 -> 6065753.3 | BO14: =IFERROR(AVERAGEIFS($D14:$BM14,$D$6:$BM$6,">="&BO$2,$D$6:$BM$6,"<="&BO$6,$D$5:$BM$5,BO$5,$D14:$BM14,"<>0"),0) -> 5501093.2 | BP14: =IFERROR(AVERAGEIFS($D14:$BM14,$D$6:$BM$6,">="&BP$2,$D$6:$BM$6,"<="&BP$6,$D$5:$BM$5,BP$5,$D14:$BM14,"<>0"),0) -> 5807134.7 | BQ14: =IFERROR(AVERAGEIFS($D14:$BM14,$D$6:$BM$6,">="&BQ$2,$D$6:$BM$6,"<="&BQ$6,$D$5:$BM$5,BQ$5,$D14:$BM14,"<>0"),0) -> 5496290.7 | BR14: =IFERROR(AVERAGEIFS($D14:$BM14,$D$6:$BM$6,">="&BR$2,$D$6:$BM$6,"<="&BR$6,$D$5:$BM$5,BR$5,$D14:$BM14,"<>0"),0) -> 5603111.6 | BS14: =IFERROR(AVERAGEIFS($D14:$BM14,$D$6:$BM$6,">="&BS$2,$D$6:$BM$6,"<="&BS$6,$D$5:$BM$5,BS$5,$D14:$BM14,"<>0"),0) -> 5448981.7 | BT14: =IFERROR(AVERAGEIFS($D14:$BM14,$D$6:$BM$6,">="&BT$2,$D$6:$BM$6,"<="&BT$6,$D$5:$BM$5,BT$5,$D14:$BM14,"<>0"),0) -> 4764493.8 | BW14: =SUMIFS($D14:$BM14,$D$6:$BM$6,">="&BO$2,$D$6:$BM$6,"<="&BO$6,$D$5:$BM$5,BO$5) -> 27505466 | BX14: =SUMIFS($D14:$BM14,$D$6:$BM$6,">="&BP$2,$D$6:$BM$6,"<="&BP$6,$D$5:$BM$5,BP$5) -> 29035674 | BY14: =SUMIFS($D14:$BM14,$D$6:$BM$6,">="&BQ$2,$D$6:$BM$6,"<="&BQ$6,$D$5:$BM$5,BQ$5) -> 21985163 | BZ14: =SUMIFS($D14:$BM14,$D$6:$BM$6,">="&BR$2,$D$6:$BM$6,"<="&BR$6,$D$5:$BM$5,BR$5) -> 28015558 | CA14: =SUMIFS($D14:$BM14,$D$6:$BM$6,">="&BS$2,$D$6:$BM$6,"<="&BS$6,$D$5:$BM$5,BS$5) -> 27244909 | CB14: =SUMIFS($D14:$BM14,$D$6:$BM$6,">="&BT$2,$D$6:$BM$6,"<="&BT$6,$D$5:$BM$5,BT$5) -> 23822469
A15: SALDO_PROM | C15: Refinanciado | D15: =Renta_Alta!D15+Masivo!D15+Consumo_Inicial!D15 -> 28843.465 | E15: =Renta_Alta!E15+Masivo!E15+Consumo_Inicial!E15 -> 28777.059 | F15: =Renta_Alta!F15+Masivo!F15+Consumo_Inicial!F15 -> 29102.631 | G15: =Renta_Alta!G15+Masivo!G15+Consumo_Inicial!G15 -> 29302.208 | H15: =Renta_Alta!H15+Masivo!H15+Consumo_Inicial!H15 -> 28758.026 | I15: =Renta_Alta!I15+Masivo!I15+Consumo_Inicial!I15 -> 29379.685 | J15: =Renta_Alta!J15+Masivo!J15+Consumo_Inicial!J15 -> 29306.467 | K15: =Renta_Alta!K15+Masivo!K15+Consumo_Inicial!K15 -> 28998.535 | ... BK15: =Renta_Alta!BK15+Masivo!BK15+Consumo_Inicial!BK15 -> 32005.544 | BO15: =IFERROR(AVERAGEIFS($D15:$BM15,$D$6:$BM$6,">="&BO$2,$D$6:$BM$6,"<="&BO$6,$D$5:$BM$5,BO$5,$D15:$BM15,"<>0"),0) -> 29506.608 | BP15: =IFERROR(AVERAGEIFS($D15:$BM15,$D$6:$BM$6,">="&BP$2,$D$6:$BM$6,"<="&BP$6,$D$5:$BM$5,BP$5,$D15:$BM15,"<>0"),0) -> 29715.91 | BQ15: =IFERROR(AVERAGEIFS($D15:$BM15,$D$6:$BM$6,">="&BQ$2,$D$6:$BM$6,"<="&BQ$6,$D$5:$BM$5,BQ$5,$D15:$BM15,"<>0"),0) -> 29784.706 | BR15: =IFERROR(AVERAGEIFS($D15:$BM15,$D$6:$BM$6,">="&BR$2,$D$6:$BM$6,"<="&BR$6,$D$5:$BM$5,BR$5,$D15:$BM15,"<>0"),0) -> 24117.375 | BS15: =IFERROR(AVERAGEIFS($D15:$BM15,$D$6:$BM$6,">="&BS$2,$D$6:$BM$6,"<="&BS$6,$D$5:$BM$5,BS$5,$D15:$BM15,"<>0"),0) -> 24880.929 | BT15: =IFERROR(AVERAGEIFS($D15:$BM15,$D$6:$BM$6,">="&BT$2,$D$6:$BM$6,"<="&BT$6,$D$5:$BM$5,BT$5,$D15:$BM15,"<>0"),0) -> 28956.678 | BW15: =SUMIFS($D15:$BM15,$D$6:$BM$6,">="&BO$2,$D$6:$BM$6,"<="&BO$6,$D$5:$BM$5,BO$5) -> 147533.04 | BX15: =SUMIFS($D15:$BM15,$D$6:$BM$6,">="&BP$2,$D$6:$BM$6,"<="&BP$6,$D$5:$BM$5,BP$5) -> 148579.55 | BY15: =SUMIFS($D15:$BM15,$D$6:$BM$6,">="&BQ$2,$D$6:$BM$6,"<="&BQ$6,$D$5:$BM$5,BQ$5) -> 119138.83 | BZ15: =SUMIFS($D15:$BM15,$D$6:$BM$6,">="&BR$2,$D$6:$BM$6,"<="&BR$6,$D$5:$BM$5,BR$5) -> 120586.87 | CA15: =SUMIFS($D15:$BM15,$D$6:$BM$6,">="&BS$2,$D$6:$BM$6,"<="&BS$6,$D$5:$BM$5,BS$5) -> 124404.64 | CB15: =SUMIFS($D15:$BM15,$D$6:$BM$6,">="&BT$2,$D$6:$BM$6,"<="&BT$6,$D$5:$BM$5,BT$5) -> 144783.39
A16: SALDO_PROM | C16: Vencido y Judicial | D16: =Renta_Alta!D16+Masivo!D16+Consumo_Inicial!D16 -> 81065.629 | E16: =Renta_Alta!E16+Masivo!E16+Consumo_Inicial!E16 -> 79227.39 | F16: =Renta_Alta!F16+Masivo!F16+Consumo_Inicial!F16 -> 80124.132 | G16: =Renta_Alta!G16+Masivo!G16+Consumo_Inicial!G16 -> 78310.975 | H16: =Renta_Alta!H16+Masivo!H16+Consumo_Inicial!H16 -> 75534.137 | I16: =Renta_Alta!I16+Masivo!I16+Consumo_Inicial!I16 -> 72466.009 | J16: =Renta_Alta!J16+Masivo!J16+Consumo_Inicial!J16 -> 67677.076 | K16: =Renta_Alta!K16+Masivo!K16+Consumo_Inicial!K16 -> 69255.945 | ... BK16: =Renta_Alta!BK16+Masivo!BK16+Consumo_Inicial!BK16 -> 107145.43 | BO16: =IFERROR(AVERAGEIFS($D16:$BM16,$D$6:$BM$6,">="&BO$2,$D$6:$BM$6,"<="&BO$6,$D$5:$BM$5,BO$5,$D16:$BM16,"<>0"),0) -> 126492.98 | BP16: =IFERROR(AVERAGEIFS($D16:$BM16,$D$6:$BM$6,">="&BP$2,$D$6:$BM$6,"<="&BP$6,$D$5:$BM$5,BP$5,$D16:$BM16,"<>0"),0) -> 113056.73 | BQ16: =IFERROR(AVERAGEIFS($D16:$BM16,$D$6:$BM$6,">="&BQ$2,$D$6:$BM$6,"<="&BQ$6,$D$5:$BM$5,BQ$5,$D16:$BM16,"<>0"),0) -> 127568.35 | BR16: =IFERROR(AVERAGEIFS($D16:$BM16,$D$6:$BM$6,">="&BR$2,$D$6:$BM$6,"<="&BR$6,$D$5:$BM$5,BR$5,$D16:$BM16,"<>0"),0) -> 98315.232 | BS16: =IFERROR(AVERAGEIFS($D16:$BM16,$D$6:$BM$6,">="&BS$2,$D$6:$BM$6,"<="&BS$6,$D$5:$BM$5,BS$5,$D16:$BM16,"<>0"),0) -> 75622.418 | BT16: =IFERROR(AVERAGEIFS($D16:$BM16,$D$6:$BM$6,">="&BT$2,$D$6:$BM$6,"<="&BT$6,$D$5:$BM$5,BT$5,$D16:$BM16,"<>0"),0) -> 78852.452 | BW16: =SUMIFS($D16:$BM16,$D$6:$BM$6,">="&BO$2,$D$6:$BM$6,"<="&BO$6,$D$5:$BM$5,BO$5) -> 632464.88 | BX16: =SUMIFS($D16:$BM16,$D$6:$BM$6,">="&BP$2,$D$6:$BM$6,"<="&BP$6,$D$5:$BM$5,BP$5) -> 565283.63 | BY16: =SUMIFS($D16:$BM16,$D$6:$BM$6,">="&BQ$2,$D$6:$BM$6,"<="&BQ$6,$D$5:$BM$5,BQ$5) -> 510273.4 | BZ16: =SUMIFS($D16:$BM16,$D$6:$BM$6,">="&BR$2,$D$6:$BM$6,"<="&BR$6,$D$5:$BM$5,BR$5) -> 491576.16 | CA16: =SUMIFS($D16:$BM16,$D$6:$BM$6,">="&BS$2,$D$6:$BM$6,"<="&BS$6,$D$5:$BM$5,BS$5) -> 378112.09 | CB16: =SUMIFS($D16:$BM16,$D$6:$BM$6,">="&BT$2,$D$6:$BM$6,"<="&BT$6,$D$5:$BM$5,BT$5) -> 394262.26
C17: Saldo Prom | D17: =SUM(D14:D16) -> 4739579.9 | E17: =SUM(E14:E16) -> 4813229.7 | F17: =SUM(F14:F16) -> 4878316.3 | G17: =SUM(G14:G16) -> 4941152.5 | H17: =SUM(H14:H16) -> 4989236.1 | I17: =SUM(I14:I16) -> 5050354.8 | J17: =SUM(J14:J16) -> 5100764.1 | K17: =SUM(K14:K16) -> 5157838.5 | ... BK17: =SUM(BK14:BK16) -> 6204904.2 | BO17: =SUM(BO14:BO16) -> 5657092.8 | BP17: =SUM(BP14:BP16) -> 5949907.4 | BQ17: =SUM(BQ14:BQ16) -> 5653643.7 | BR17: =SUM(BR14:BR16) -> 5725544.3 | BS17: =SUM(BS14:BS16) -> 5549485.1 | BT17: =SUM(BT14:BT16) -> 4872302.9 | BW17: =SUM(BW14:BW16) -> 28285464 | BX17: =SUM(BX14:BX16) -> 29749537 | BY17: =SUM(BY14:BY16) -> 22614575 | BZ17: =SUM(BZ14:BZ16) -> 28627721 | CA17: =SUM(CA14:CA16) -> 27747425 | CB17: =SUM(CB14:CB16) -> 24361515
D18: ='[1]Desempeño Financiero (Evol)'!BE106 -> 4739579.9 | E18: ='[1]Desempeño Financiero (Evol)'!BF106 -> 4813229.7 | F18: ='[1]Desempeño Financiero (Evol)'!BG106 -> 4878316.3 | G18: ='[1]Desempeño Financiero (Evol)'!BH106 -> 4941152.5 | H18: ='[1]Desempeño Financiero (Evol)'!BI106 -> 4989236.1 | I18: ='[1]Desempeño Financiero (Evol)'!BJ106 -> 5050354.8 | J18: ='[1]Desempeño Financiero (Evol)'!BK106 -> 5100764.1 | K18: ='[1]Desempeño Financiero (Evol)'!BL106 -> 5157838.5 | ... AO18: ='[1]Desempeño Financiero (Evol)'!CP106 -> 5648366.1 | AZ18: ='[1]Desempeño Financiero (Evol)'!DA106 -> 5901585.2 | BA18: ='[1]Desempeño Financiero (Evol)'!DB106 -> 5919552.7 | BB18: ='[1]Desempeño Financiero (Evol)'!DC106 -> 5953402.1 | BC18: ='[1]Desempeño Financiero (Evol)'!DD106 -> 5976419 | BD18: ='[1]Desempeño Financiero (Evol)'!DE106 -> 5998577.9 | BE18: ='[1]Desempeño Financiero (Evol)'!DF106 -> 6026956.8 | BF18: ='[1]Desempeño Financiero (Evol)'!DG106 -> 6056606.8 | BG18: ='[1]Desempeño Financiero (Evol)'!DH106 -> 6086825.1 | ... BK18: ='[1]Desempeño Financiero (Evol)'!DL106 -> 6204904.2
D19: =D18-D17 -> -0.00012999959 | E19: =E18-E17 -> -0.00039000064 | F19: =F18-F17 -> 0.00028000027 | G19: =G18-G17 -> 0.00011999998 | H19: =H18-H17 -> -0.00021999981 | I19: =I18-I17 -> 0.00029999949 | J19: =J18-J17 -> -0.00050999969 | K19: =K18-K17 -> -0.00022999942 | ... AO19: =AO18-AO17 -> 0 | AZ19: =AZ18-AZ17 -> 0 | BA19: =BA18-BA17 -> 0 | BB19: =BB18-BB17 -> 0 | BC19: =BC18-BC17 -> 0 | BD19: =BD18-BD17 -> 0 | BE19: =BE18-BE17 -> 0 | BF19: =BF18-BF17 -> 0 | BG19: =BG18-BG17 -> 0 | ... BK19: =BK18-BK17 -> 0
C20: Vigente | D20: =IFERROR(((1+D38/D14)^(360/D$3))-1,0) -> 0.12197166 | E20: =IFERROR(((1+E38/E14)^(360/E$3))-1,0) -> 0.11955985 | F20: =IFERROR(((1+F38/F14)^(360/F$3))-1,0) -> 0.11942598 | G20: =IFERROR(((1+G38/G14)^(360/G$3))-1,0) -> 0.11865279 | H20: =IFERROR(((1+H38/H14)^(360/H$3))-1,0) -> 0.11933461 | I20: =IFERROR(((1+I38/I14)^(360/I$3))-1,0) -> 0.12096763 | J20: =IFERROR(((1+J38/J14)^(360/J$3))-1,0) -> 0.12028552 | K20: =IFERROR(((1+K38/K14)^(360/K$3))-1,0) -> 0.1211712 | ... BK20: =IFERROR(((1+BK38/BK14)^(360/BK$3))-1,0) -> 0.11343738 | BO20: =IFERROR(((1+BO38/BW14)^(360/BO$3))-1,0) -> 0.11401334 | BP20: =IFERROR(((1+BP38/BX14)^(360/BP$3))-1,0) -> 0.1141319 | BQ20: =IFERROR(((1+BQ38/BY14)^(360/BQ$3))-1,0) -> 0.11417123 | BR20: =IFERROR(((1+BR38/BZ14)^(360/BR$3))-1,0) -> 0.11828543 | BS20: =IFERROR(((1+BS38/CA14)^(360/BS$3))-1,0) -> 0.11880864 | BT20: =IFERROR(((1+BT38/CB14)^(360/BT$3))-1,0) -> 0.11977102
C21: Refinanciado | D21: =IFERROR(((1+D39/D15)^(360/D$3))-1,0) -> 0.11559667 | E21: =IFERROR(((1+E39/E15)^(360/E$3))-1,0) -> 0.11204084 | F21: =IFERROR(((1+F39/F15)^(360/F$3))-1,0) -> 0.10748943 | G21: =IFERROR(((1+G39/G15)^(360/G$3))-1,0) -> 0.10999219 | H21: =IFERROR(((1+H39/H15)^(360/H$3))-1,0) -> 0.10262374 | I21: =IFERROR(((1+I39/I15)^(360/I$3))-1,0) -> 0.10562023 | J21: =IFERROR(((1+J39/J15)^(360/J$3))-1,0) -> 0.12399521 | K21: =IFERROR(((1+K39/K15)^(360/K$3))-1,0) -> 0.11668802 | ... BK21: =IFERROR(((1+BK39/BK15)^(360/BK$3))-1,0) -> 0.11182969 | BO21: =IFERROR(((1+BO39/BW15)^(360/BO$3))-1,0) -> 0.110952 | BP21: =IFERROR(((1+BP39/BX15)^(360/BP$3))-1,0) -> 0.11688993 | BQ21: =IFERROR(((1+BQ39/BY15)^(360/BQ$3))-1,0) -> 0.11170696 | BR21: =IFERROR(((1+BR39/BZ15)^(360/BR$3))-1,0) -> 0.11587421 | BS21: =IFERROR(((1+BS39/CA15)^(360/BS$3))-1,0) -> 0.11264979 | BT21: =IFERROR(((1+BT39/CB15)^(360/BT$3))-1,0) -> 0.10954141
C22: Vencido y Judicial | D22: =IFERROR(((1+D40/D16)^(360/D$3))-1,0) -> 0.042797696 | E22: =IFERROR(((1+E40/E16)^(360/E$3))-1,0) -> 0.0556634 | F22: =IFERROR(((1+F40/F16)^(360/F$3))-1,0) -> 0.038293088 | G22: =IFERROR(((1+G40/G16)^(360/G$3))-1,0) -> 0.046477681 | H22: =IFERROR(((1+H40/H16)^(360/H$3))-1,0) -> 0.044821992 | I22: =IFERROR(((1+I40/I16)^(360/I$3))-1,0) -> 0.047730938 | J22: =IFERROR(((1+J40/J16)^(360/J$3))-1,0) -> 0.034929191 | K22: =IFERROR(((1+K40/K16)^(360/K$3))-1,0) -> 0.028079141 | ... BK22: =IFERROR(((1+BK40/BK16)^(360/BK$3))-1,0) -> 0.036910738 | BO22: =IFERROR(((1+BO40/BW16)^(360/BO$3))-1,0) -> 0.025773005 | BP22: =IFERROR(((1+BP40/BX16)^(360/BP$3))-1,0) -> 0.033758698 | BQ22: =IFERROR(((1+BQ40/BY16)^(360/BQ$3))-1,0) -> 0.025986147 | BR22: =IFERROR(((1+BR40/BZ16)^(360/BR$3))-1,0) -> 0.02548946 | BS22: =IFERROR(((1+BS40/CA16)^(360/BS$3))-1,0) -> 0.034623467 | BT22: =IFERROR(((1+BT40/CB16)^(360/BT$3))-1,0) -> 0.045571915
C23: Tasa Implicita | D23: =IFERROR(((1+D41/D17)^(360/D$3))-1,0) -> 0.12053354 | E23: =IFERROR(((1+E41/E17)^(360/E$3))-1,0) -> 0.11843496 | F23: =IFERROR(((1+F41/F17)^(360/F$3))-1,0) -> 0.11797628 | G23: =IFERROR(((1+G41/G17)^(360/G$3))-1,0) -> 0.1174227 | H23: =IFERROR(((1+H41/H17)^(360/H$3))-1,0) -> 0.11807424 | I23: =IFERROR(((1+I41/I17)^(360/I$3))-1,0) -> 0.11979465 | J23: =IFERROR(((1+J41/J17)^(360/J$3))-1,0) -> 0.11913324 | K23: =IFERROR(((1+K41/K17)^(360/K$3))-1,0) -> 0.11984643 | ... BK23: =IFERROR(((1+BK41/BK17)^(360/BK$3))-1,0) -> 0.11206485 | BO23: =IFERROR(((1+BO41/BW17)^(360/BO$3))-1,0) -> 0.11195056 | BP23: =IFERROR(((1+BP41/BX17)^(360/BP$3))-1,0) -> 0.11256651 | BQ23: =IFERROR(((1+BQ41/BY17)^(360/BQ$3))-1,0) -> 0.11209416 | BR23: =IFERROR(((1+BR41/BZ17)^(360/BR$3))-1,0) -> 0.11661895 | BS23: =IFERROR(((1+BS41/CA17)^(360/BS$3))-1,0) -> 0.1175928 | BT23: =IFERROR(((1+BT41/CB17)^(360/BT$3))-1,0) -> 0.11847174
C26: Vigente | D26: =-IFERROR(((1-D44/D14)^(360/D$4))-1,0) -> -0.06076307 | E26: =-IFERROR(((1-E44/E14)^(360/E$4))-1,0) -> -0.062861897 | F26: =-IFERROR(((1-F44/F14)^(360/F$4))-1,0) -> -0.065107468 | G26: =-IFERROR(((1-G44/G14)^(360/G$4))-1,0) -> -0.067267469 | H26: =-IFERROR(((1-H44/H14)^(360/H$4))-1,0) -> -0.068542711 | I26: =-IFERROR(((1-I44/I14)^(360/I$4))-1,0) -> -0.069743013 | J26: =-IFERROR(((1-J44/J14)^(360/J$4))-1,0) -> -0.070496199 | K26: =-IFERROR(((1-K44/K14)^(360/K$4))-1,0) -> -0.071403096 | ... BK26: =-IFERROR(((1-BK44/BK14)^(360/BK$4))-1,0) -> -0.054024836 | BO26: =-IFERROR(((1-BO44/BW14)^(360/BO$4))-1,0) -> -0.05826649 | BP26: =-IFERROR(((1-BP44/BX14)^(360/BP$4))-1,0) -> -0.057861332 | BQ26: =-IFERROR(((1-BQ44/BY14)^(360/BQ$4))-1,0) -> -0.058509488 | BR26: =-IFERROR(((1-BR44/BZ14)^(360/BR$4))-1,0) -> -0.066763516 | BS26: =-IFERROR(((1-BS44/CA14)^(360/BS$4))-1,0) -> -0.072994066 | BT26: =-IFERROR(((1-BT44/CB14)^(360/BT$4))-1,0) -> -0.064995088
C27: Refinanciado | D27: =-IFERROR(((1-D45/D15)^(360/D$4))-1,0) -> -0.05371836 | E27: =-IFERROR(((1-E45/E15)^(360/E$4))-1,0) -> -0.055204536 | F27: =-IFERROR(((1-F45/F15)^(360/F$4))-1,0) -> -0.056860688 | G27: =-IFERROR(((1-G45/G15)^(360/G$4))-1,0) -> -0.05869645 | H27: =-IFERROR(((1-H45/H15)^(360/H$4))-1,0) -> -0.059672081 | I27: =-IFERROR(((1-I45/I15)^(360/I$4))-1,0) -> -0.061583078 | J27: =-IFERROR(((1-J45/J15)^(360/J$4))-1,0) -> -0.061633213 | K27: =-IFERROR(((1-K45/K15)^(360/K$4))-1,0) -> -0.063296429 | ... BK27: =-IFERROR(((1-BK45/BK15)^(360/BK$4))-1,0) -> -0.053097529 | BO27: =-IFERROR(((1-BO45/BW15)^(360/BO$4))-1,0) -> -0.061453176 | BP27: =-IFERROR(((1-BP45/BX15)^(360/BP$4))-1,0) -> -0.059392367 | BQ27: =-IFERROR(((1-BQ45/BY15)^(360/BQ$4))-1,0) -> -0.061534929 | BR27: =-IFERROR(((1-BR45/BZ15)^(360/BR$4))-1,0) -> -0.066536457 | BS27: =-IFERROR(((1-BS45/CA15)^(360/BS$4))-1,0) -> -0.068231684 | BT27: =-IFERROR(((1-BT45/CB15)^(360/BT$4))-1,0) -> -0.056855971
C28: Vencido y Judicial | D28: =-IFERROR(((1-D46/D16)^(360/D$4))-1,0) -> -0.035805183 | E28: =-IFERROR(((1-E46/E16)^(360/E$4))-1,0) -> -0.037732098 | F28: =-IFERROR(((1-F46/F16)^(360/F$4))-1,0) -> -0.040647537 | G28: =-IFERROR(((1-G46/G16)^(360/G$4))-1,0) -> -0.041280073 | H28: =-IFERROR(((1-H46/H16)^(360/H$4))-1,0) -> -0.039940912 | I28: =-IFERROR(((1-I46/I16)^(360/I$4))-1,0) -> -0.041064265 | J28: =-IFERROR(((1-J46/J16)^(360/J$4))-1,0) -> -0.044588397 | K28: =-IFERROR(((1-K46/K16)^(360/K$4))-1,0) -> -0.054704211 | ... BK28: =-IFERROR(((1-BK46/BK16)^(360/BK$4))-1,0) -> -0.061344815 | BO28: =-IFERROR(((1-BO46/BW16)^(360/BO$4))-1,0) -> -0.056001442 | BP28: =-IFERROR(((1-BP46/BX16)^(360/BP$4))-1,0) -> -0.059798829 | BQ28: =-IFERROR(((1-BQ46/BY16)^(360/BQ$4))-1,0) -> -0.055885258 | BR28: =-IFERROR(((1-BR46/BZ16)^(360/BR$4))-1,0) -> -0.066820171 | BS28: =-IFERROR(((1-BS46/CA16)^(360/BS$4))-1,0) -> -0.067442074 | BT28: =-IFERROR(((1-BT46/CB16)^(360/BT$4))-1,0) -> -0.039064413
C29: Tasa FTP | D29: =-IFERROR(((1-D47/D17)^(360/D$4))-1,0) -> -0.060288627 | E29: =-IFERROR(((1-E47/E17)^(360/E$4))-1,0) -> -0.062397832 | F29: =-IFERROR(((1-F47/F17)^(360/F$4))-1,0) -> -0.064652163 | G29: =-IFERROR(((1-G47/G17)^(360/G$4))-1,0) -> -0.06680001 | H29: =-IFERROR(((1-H47/H17)^(360/H$4))-1,0) -> -0.068053085 | I29: =-IFERROR(((1-I47/I17)^(360/I$4))-1,0) -> -0.069278822 | J29: =-IFERROR(((1-J47/J17)^(360/J$4))-1,0) -> -0.070097544 | K29: =-IFERROR(((1-K47/K17)^(360/K$4))-1,0) -> -0.071131558 | ... BK29: =-IFERROR(((1-BK47/BK17)^(360/BK$4))-1,0) -> -0.054146058 | BO29: =-IFERROR(((1-BO47/BW17)^(360/BO$4))-1,0) -> -0.058232392 | BP29: =-IFERROR(((1-BP47/BX17)^(360/BP$4))-1,0) -> -0.057905758 | BQ29: =-IFERROR(((1-BQ47/BY17)^(360/BQ$4))-1,0) -> -0.058466126 | BR29: =-IFERROR(((1-BR47/BZ17)^(360/BR$4))-1,0) -> -0.066763532 | BS29: =-IFERROR(((1-BS47/CA17)^(360/BS$4))-1,0) -> -0.072896838 | BT29: =-IFERROR(((1-BT47/CB17)^(360/BT$4))-1,0) -> -0.064522231
C32: Vigente | D32: =D20+D26 -> 0.061208594 | E32: =E20+E26 -> 0.056697957 | F32: =F20+F26 -> 0.054318512 | G32: =G20+G26 -> 0.051385325 | H32: =H20+H26 -> 0.0507919 | I32: =I20+I26 -> 0.051224617 | J32: =J20+J26 -> 0.049789316 | K32: =K20+K26 -> 0.049768103 | ... BK32: =BK20+BK26 -> 0.059412541 | BO32: =BO20+BO26 -> 0.055746847 | BP32: =BP20+BP26 -> 0.056270565 | BQ32: =BQ20+BQ26 -> 0.055661745 | BR32: =BR20+BR26 -> 0.051521917 | BS32: =BS20+BS26 -> 0.045814571 | BT32: =BT20+BT26 -> 0.054775931
C33: Refinanciado | D33: =D21+D27 -> 0.061878307 | E33: =E21+E27 -> 0.056836302 | F33: =F21+F27 -> 0.050628742 | G33: =G21+G27 -> 0.051295742 | H33: =H21+H27 -> 0.042951662 | I33: =I21+I27 -> 0.044037149 | J33: =J21+J27 -> 0.062361993 | K33: =K21+K27 -> 0.053391588 | ... BK33: =BK21+BK27 -> 0.058732161 | BO33: =BO21+BO27 -> 0.049498825 | BP33: =BP21+BP27 -> 0.057497558 | BQ33: =BQ21+BQ27 -> 0.05017203 | BR33: =BR21+BR27 -> 0.049337757 | BS33: =BS21+BS27 -> 0.044418103 | BT33: =BT21+BT27 -> 0.052685437
C34: Vencido y Judicial | D34: =D22+D28 -> 0.0069925127 | E34: =E22+E28 -> 0.017931301 | F34: =F22+F28 -> -0.0023544487 | G34: =G22+G28 -> 0.0051976077 | H34: =H22+H28 -> 0.0048810798 | I34: =I22+I28 -> 0.0066666737 | J34: =J22+J28 -> -0.0096592056 | K34: =K22+K28 -> -0.02662507 | ... BK34: =BK22+BK28 -> -0.024434077 | BO34: =BO22+BO28 -> -0.030228437 | BP34: =BP22+BP28 -> -0.026040131 | BQ34: =BQ22+BQ28 -> -0.029899111 | BR34: =BR22+BR28 -> -0.041330711 | BS34: =BS22+BS28 -> -0.032818607 | BT34: =BT22+BT28 -> 0.0065075024
C35: Spread | D35: =D23+D29 -> 0.060244916 | E35: =E23+E29 -> 0.056037131 | F35: =F23+F29 -> 0.053324117 | G35: =G23+G29 -> 0.050622688 | H35: =H23+H29 -> 0.050021155 | I35: =I23+I29 -> 0.050515827 | J35: =J23+J29 -> 0.049035699 | K35: =K23+K29 -> 0.048714875 | ... BK35: =BK23+BK29 -> 0.057918793 | BO35: =BO23+BO29 -> 0.053718171 | BP35: =BP23+BP29 -> 0.054660749 | BQ35: =BQ23+BQ29 -> 0.053628029 | BR35: =BR23+BR29 -> 0.049855419 | BS35: =BS23+BS29 -> 0.044695961 | BT35: =BT23+BT29 -> 0.053949511
A38: Ingreso_Financiero | C38: Vigente | D38: =Renta_Alta!D38+Masivo!D38+Consumo_Inicial!D38 -> 44615.058 | E38: =Renta_Alta!E38+Masivo!E38+Consumo_Inicial!E38 -> 44491.327 | F38: =Renta_Alta!F38+Masivo!F38+Consumo_Inicial!F38 -> 45047.235 | G38: =Renta_Alta!G38+Masivo!G38+Consumo_Inicial!G38 -> 45375.08 | H38: =Renta_Alta!H38+Masivo!H38+Consumo_Inicial!H38 -> 46108.016 | I38: =Renta_Alta!I38+Masivo!I38+Consumo_Inicial!I38 -> 47314.891 | J38: =Renta_Alta!J38+Masivo!J38+Consumo_Inicial!J38 -> 47587.132 | K38: =Renta_Alta!K38+Masivo!K38+Consumo_Inicial!K38 -> 48454.222 | ... BK38: =Renta_Alta!BK38+Masivo!BK38+Consumo_Inicial!BK38 -> 54558.663 | BO38: =SUMIFS($D38:$BM38,$D$6:$BM$6,">="&BO$2,$D$6:$BM$6,"<="&BO$6,$D$5:$BM$5,BO$5) -> 248595.08 | BP38: =SUMIFS($D38:$BM38,$D$6:$BM$6,">="&BP$2,$D$6:$BM$6,"<="&BP$6,$D$5:$BM$5,BP$5) -> 262684.96 | BQ38: =SUMIFS($D38:$BM38,$D$6:$BM$6,">="&BQ$2,$D$6:$BM$6,"<="&BQ$6,$D$5:$BM$5,BQ$5) -> 198964.45 | BR38: =SUMIFS($D38:$BM38,$D$6:$BM$6,">="&BR$2,$D$6:$BM$6,"<="&BR$6,$D$5:$BM$5,BR$5) -> 262223.38 | BS38: =SUMIFS($D38:$BM38,$D$6:$BM$6,">="&BS$2,$D$6:$BM$6,"<="&BS$6,$D$5:$BM$5,BS$5) -> 256082.12 | BT38: =SUMIFS($D38:$BM38,$D$6:$BM$6,">="&BT$2,$D$6:$BM$6,"<="&BT$6,$D$5:$BM$5,BT$5) -> 225636.72
A39: Ingreso_Financiero | C39: Refinanciado | D39: =Renta_Alta!D39+Masivo!D39+Consumo_Inicial!D39 -> 264.13281 | E39: =Renta_Alta!E39+Masivo!E39+Consumo_Inicial!E39 -> 255.7998 | F39: =Renta_Alta!F39+Masivo!F39+Consumo_Inicial!F39 -> 248.6607 | G39: =Renta_Alta!G39+Masivo!G39+Consumo_Inicial!G39 -> 255.92556 | H39: =Renta_Alta!H39+Masivo!H39+Consumo_Inicial!H39 -> 235.07602 | I39: =Renta_Alta!I39+Masivo!I39+Consumo_Inicial!I39 -> 246.85718 | J39: =Renta_Alta!J39+Masivo!J39+Consumo_Inicial!J39 -> 286.86302 | K39: =Renta_Alta!K39+Masivo!K39+Consumo_Inicial!K39 -> 267.93746 | ... BK39: =Renta_Alta!BK39+Masivo!BK39+Consumo_Inicial!BK39 -> 283.98689 | BO39: =SUMIFS($D39:$BM39,$D$6:$BM$6,">="&BO$2,$D$6:$BM$6,"<="&BO$6,$D$5:$BM$5,BO$5) -> 1299.2735 | BP39: =SUMIFS($D39:$BM39,$D$6:$BM$6,">="&BP$2,$D$6:$BM$6,"<="&BP$6,$D$5:$BM$5,BP$5) -> 1375.0881 | BQ39: =SUMIFS($D39:$BM39,$D$6:$BM$6,">="&BQ$2,$D$6:$BM$6,"<="&BQ$6,$D$5:$BM$5,BQ$5) -> 1056.0194 | BR39: =SUMIFS($D39:$BM39,$D$6:$BM$6,">="&BR$2,$D$6:$BM$6,"<="&BR$6,$D$5:$BM$5,BR$5) -> 1106.7919 | BS39: =SUMIFS($D39:$BM39,$D$6:$BM$6,">="&BS$2,$D$6:$BM$6,"<="&BS$6,$D$5:$BM$5,BS$5) -> 1111.5611 | BT39: =SUMIFS($D39:$BM39,$D$6:$BM$6,">="&BT$2,$D$6:$BM$6,"<="&BT$6,$D$5:$BM$5,BT$5) -> 1259.5949
A40: Ingreso_Financiero | C40: Vencido y Judicial | D40: =Renta_Alta!D40+Masivo!D40+Consumo_Inicial!D40 -> 283.59766 | E40: =Renta_Alta!E40+Masivo!E40+Consumo_Inicial!E40 -> 358.45001 | F40: =Renta_Alta!F40+Masivo!F40+Consumo_Inicial!F40 -> 251.30268 | G40: =Renta_Alta!G40+Masivo!G40+Consumo_Inicial!G40 -> 297.03378 | H40: =Renta_Alta!H40+Masivo!H40+Consumo_Inicial!H40 -> 276.49731 | I40: =Renta_Alta!I40+Masivo!I40+Consumo_Inicial!I40 -> 282.11934 | J40: =Renta_Alta!J40+Masivo!J40+Consumo_Inicial!J40 -> 193.90707 | K40: =Renta_Alta!K40+Masivo!K40+Consumo_Inicial!K40 -> 160.00505 | ... BK40: =Renta_Alta!BK40+Masivo!BK40+Consumo_Inicial!BK40 -> 324.12066 | BO40: =SUMIFS($D40:$BM40,$D$6:$BM$6,">="&BO$2,$D$6:$BM$6,"<="&BO$6,$D$5:$BM$5,BO$5) -> 1342.59 | BP40: =SUMIFS($D40:$BM40,$D$6:$BM$6,">="&BP$2,$D$6:$BM$6,"<="&BP$6,$D$5:$BM$5,BP$5) -> 1566.1821 | BQ40: =SUMIFS($D40:$BM40,$D$6:$BM$6,">="&BQ$2,$D$6:$BM$6,"<="&BQ$6,$D$5:$BM$5,BQ$5) -> 1092.0568 | BR40: =SUMIFS($D40:$BM40,$D$6:$BM$6,">="&BR$2,$D$6:$BM$6,"<="&BR$6,$D$5:$BM$5,BR$5) -> 1032.1639 | BS40: =SUMIFS($D40:$BM40,$D$6:$BM$6,">="&BS$2,$D$6:$BM$6,"<="&BS$6,$D$5:$BM$5,BS$5) -> 1074.0236 | BT40: =SUMIFS($D40:$BM40,$D$6:$BM$6,">="&BT$2,$D$6:$BM$6,"<="&BT$6,$D$5:$BM$5,BT$5) -> 1466.8814
C41: Ingreso Financiero | D41: =SUM(D38:D40) -> 45162.788 | E41: =SUM(E38:E40) -> 45105.577 | F41: =SUM(F38:F40) -> 45547.199 | G41: =SUM(G38:G40) -> 45928.039 | H41: =SUM(H38:H40) -> 46619.589 | I41: =SUM(I38:I40) -> 47843.867 | J41: =SUM(J38:J40) -> 48067.902 | K41: =SUM(K38:K40) -> 48882.165 | ... BK41: =SUM(BK38:BK40) -> 55166.771 | BO41: =SUM(BO38:BO40) -> 251236.94 | BP41: =SUM(BP38:BP40) -> 265626.23 | BQ41: =SUM(BQ38:BQ40) -> 201112.52 | BR41: =SUM(BR38:BR40) -> 264362.34 | BS41: =SUM(BS38:BS40) -> 258267.7 | BT41: =SUM(BT38:BT40) -> 228363.19
D42: ='[1]Desempeño Financiero (Evol)'!BE298 -> 45162.788 | E42: ='[1]Desempeño Financiero (Evol)'!BF298 -> 45105.577 | F42: ='[1]Desempeño Financiero (Evol)'!BG298 -> 45547.199 | G42: ='[1]Desempeño Financiero (Evol)'!BH298 -> 45928.039 | H42: ='[1]Desempeño Financiero (Evol)'!BI298 -> 46619.589 | I42: ='[1]Desempeño Financiero (Evol)'!BJ298 -> 47843.867 | J42: ='[1]Desempeño Financiero (Evol)'!BK298 -> 48067.902 | K42: ='[1]Desempeño Financiero (Evol)'!BL298 -> 48882.165 | ... AO42: ='[1]Desempeño Financiero (Evol)'!CP298 -> 50060.189 | AZ42: ='[1]Desempeño Financiero (Evol)'!DA298 -> 52859.23 | BA42: ='[1]Desempeño Financiero (Evol)'!DB298 -> 53319.441 | BB42: ='[1]Desempeño Financiero (Evol)'!DC298 -> 52897.29 | BC42: ='[1]Desempeño Financiero (Evol)'!DD298 -> 53297.064 | BD42: ='[1]Desempeño Financiero (Evol)'!DE298 -> 53253.206 | BE42: ='[1]Desempeño Financiero (Evol)'!DF298 -> 53488.787 | BF42: ='[1]Desempeño Financiero (Evol)'!DG298 -> 53867.659 | BG42: ='[1]Desempeño Financiero (Evol)'!DH298 -> 54105.408 | ... BK42: ='[1]Desempeño Financiero (Evol)'!DL298 -> 55166.771
D43: =D42-D41 -> -3.170011e-06 | E43: =E42-E41 -> -1.8699939e-06 | F43: =F42-F41 -> -1.579996e-06 | G43: =G42-G41 -> -1.750006e-06 | H43: =H42-H41 -> 2.6699927e-06 | I43: =I42-I41 -> -3.6699857e-06 | J43: =J42-J41 -> -3.5299963e-06 | K43: =K42-K41 -> -2.5599948e-06 | ... AO43: =AO42-AO41 -> 0 | AZ43: =AZ42-AZ41 -> 0 | BA43: =BA42-BA41 -> 0 | BB43: =BB42-BB41 -> 0 | BC43: =BC42-BC41 -> 0 | BD43: =BD42-BD41 -> 0 | BE43: =BE42-BE41 -> 0 | BF43: =BF42-BF41 -> 0 | BG43: =BG42-BG41 -> 0 | ... BK43: =BK42-BK41 -> 0
A44: FTP | C44: Vigente | D44: =Renta_Alta!D44+Masivo!D44+Consumo_Inicial!D44 -> -23576.554 | E44: =Renta_Alta!E44+Masivo!E44+Consumo_Inicial!E44 -> -22363.914 | F44: =Renta_Alta!F44+Masivo!F44+Consumo_Inicial!F44 -> -25973.875 | G44: =Renta_Alta!G44+Masivo!G44+Consumo_Inicial!G44 -> -26293.861 | H44: =Renta_Alta!H44+Masivo!H44+Consumo_Inicial!H44 -> -27966.932 | I44: =Renta_Alta!I44+Masivo!I44+Consumo_Inicial!I44 -> -27879.977 | J44: =Renta_Alta!J44+Masivo!J44+Consumo_Inicial!J44 -> -29438.863 | K44: =Renta_Alta!K44+Masivo!K44+Consumo_Inicial!K44 -> -30138.304 | ... BK44: =Renta_Alta!BK44+Masivo!BK44+Consumo_Inicial!BK44 -> -27545.211 | BO44: =SUMIFS($D44:$BM44,$D$6:$BM$6,">="&BO$2,$D$6:$BM$6,"<="&BO$6,$D$5:$BM$5,BO$5) -> -130984.16 | BP44: =SUMIFS($D44:$BM44,$D$6:$BM$6,">="&BP$2,$D$6:$BM$6,"<="&BP$6,$D$5:$BM$5,BP$5) -> -137334.04 | BQ44: =SUMIFS($D44:$BM44,$D$6:$BM$6,">="&BQ$2,$D$6:$BM$6,"<="&BQ$6,$D$5:$BM$5,BQ$5) -> -104423.49 | BR44: =SUMIFS($D44:$BM44,$D$6:$BM$6,">="&BR$2,$D$6:$BM$6,"<="&BR$6,$D$5:$BM$5,BR$5) -> -152303.93 | BS44: =SUMIFS($D44:$BM44,$D$6:$BM$6,">="&BS$2,$D$6:$BM$6,"<="&BS$6,$D$5:$BM$5,BS$5) -> -162572.86 | BT44: =SUMIFS($D44:$BM44,$D$6:$BM$6,">="&BT$2,$D$6:$BM$6,"<="&BT$6,$D$5:$BM$5,BT$5) -> -126175.14
A45: FTP | C45: Refinanciado | D45: =Renta_Alta!D45+Masivo!D45+Consumo_Inicial!D45 -> -130.25558 | E45: =Renta_Alta!E45+Masivo!E45+Consumo_Inicial!E45 -> -120.52135 | F45: =Renta_Alta!F45+Masivo!F45+Consumo_Inicial!F45 -> -138.9229 | G45: =Renta_Alta!G45+Masivo!G45+Consumo_Inicial!G45 -> -139.61076 | H45: =Renta_Alta!H45+Masivo!H45+Consumo_Inicial!H45 -> -143.88885 | I45: =Renta_Alta!I45+Masivo!I45+Consumo_Inicial!I45 -> -146.67886 | J45: =Renta_Alta!J45+Masivo!J45+Consumo_Inicial!J45 -> -151.32278 | K45: =Renta_Alta!K45+Masivo!K45+Consumo_Inicial!K45 -> -153.66227 | ... BK45: =Renta_Alta!BK45+Masivo!BK45+Consumo_Inicial!BK45 -> -142.90379 | BO45: =SUMIFS($D45:$BM45,$D$6:$BM$6,">="&BO$2,$D$6:$BM$6,"<="&BO$6,$D$5:$BM$5,BO$5) -> -739.96321 | BP45: =SUMIFS($D45:$BM45,$D$6:$BM$6,">="&BP$2,$D$6:$BM$6,"<="&BP$6,$D$5:$BM$5,BP$5) -> -720.86989 | BQ45: =SUMIFS($D45:$BM45,$D$6:$BM$6,">="&BQ$2,$D$6:$BM$6,"<="&BQ$6,$D$5:$BM$5,BQ$5) -> -594.3512 | BR45: =SUMIFS($D45:$BM45,$D$6:$BM$6,">="&BR$2,$D$6:$BM$6,"<="&BR$6,$D$5:$BM$5,BR$5) -> -653.39404 | BS45: =SUMIFS($D45:$BM45,$D$6:$BM$6,">="&BS$2,$D$6:$BM$6,"<="&BS$6,$D$5:$BM$5,BS$5) -> -695.33339 | BT45: =SUMIFS($D45:$BM45,$D$6:$BM$6,">="&BT$2,$D$6:$BM$6,"<="&BT$6,$D$5:$BM$5,BT$5) -> -673.19944
A46: FTP | C46: Vencido y Judicial | D46: =Renta_Alta!D46+Masivo!D46+Consumo_Inicial!D46 -> -245.94522 | E46: =Renta_Alta!E46+Masivo!E46+Consumo_Inicial!E46 -> -228.55992 | F46: =Renta_Alta!F46+Masivo!F46+Consumo_Inicial!F46 -> -275.37305 | G46: =Renta_Alta!G46+Masivo!G46+Consumo_Inicial!G46 -> -264.42386 | H46: =Renta_Alta!H46+Masivo!H46+Consumo_Inicial!H46 -> -255.16487 | I46: =Renta_Alta!I46+Masivo!I46+Consumo_Inicial!I46 -> -243.43191 | J46: =Renta_Alta!J46+Masivo!J46+Consumo_Inicial!J46 -> -254.70153 | K46: =Renta_Alta!K46+Masivo!K46+Consumo_Inicial!K46 -> -318.35863 | ... BK46: =Renta_Alta!BK46+Masivo!BK46+Consumo_Inicial!BK46 -> -550.72152 | BO46: =SUMIFS($D46:$BM46,$D$6:$BM$6,">="&BO$2,$D$6:$BM$6,"<="&BO$6,$D$5:$BM$5,BO$5) -> -2897.6575 | BP46: =SUMIFS($D46:$BM46,$D$6:$BM$6,">="&BP$2,$D$6:$BM$6,"<="&BP$6,$D$5:$BM$5,BP$5) -> -2760.8905 | BQ46: =SUMIFS($D46:$BM46,$D$6:$BM$6,">="&BQ$2,$D$6:$BM$6,"<="&BQ$6,$D$5:$BM$5,BQ$5) -> -2317.616 | BR46: =SUMIFS($D46:$BM46,$D$6:$BM$6,">="&BR$2,$D$6:$BM$6,"<="&BR$6,$D$5:$BM$5,BR$5) -> -2674.6092 | BS46: =SUMIFS($D46:$BM46,$D$6:$BM$6,">="&BS$2,$D$6:$BM$6,"<="&BS$6,$D$5:$BM$5,BS$5) -> -2089.636 | BT46: =SUMIFS($D46:$BM46,$D$6:$BM$6,">="&BT$2,$D$6:$BM$6,"<="&BT$6,$D$5:$BM$5,BT$5) -> -1269.4669
C47: Costo de Fondos | D47: =SUM(D44:D46) -> -23952.755 | E47: =SUM(E44:E46) -> -22712.996 | F47: =SUM(F44:F46) -> -26388.171 | G47: =SUM(G44:G46) -> -26697.895 | H47: =SUM(H44:H46) -> -28365.986 | I47: =SUM(I44:I46) -> -28270.087 | J47: =SUM(J44:J46) -> -29844.887 | K47: =SUM(K44:K46) -> -30610.325 | ... BK47: =SUM(BK44:BK46) -> -28238.836 | BO47: =SUM(BO44:BO46) -> -134621.78 | BP47: =SUM(BP44:BP46) -> -140815.8 | BQ47: =SUM(BQ44:BQ46) -> -107335.46 | BR47: =SUM(BR44:BR46) -> -155631.93 | BS47: =SUM(BS44:BS46) -> -165357.83 | BT47: =SUM(BT44:BT46) -> -128117.8
...

Sheet Desempeño_Financiero
B1: 46173 | D1: Mensual | W1: Acumulado
B2: Desempeño Financiero
B3: En S/. Miles | C3: N° dias T.Imp | D3: 30 | E3: 30 | F3: 30 | G3: 30 | H3: 30 | I3: 30
C4: N° dias FTP | D4: =DAY(D6) -> 31 | E4: =DAY(E6) -> 31 | F4: =DAY(F6) -> 30 | G4: =DAY(G6) -> 31 | H4: =DAY(H6) -> 31 | I4: =DAY(I6) -> 31
C5: Tipo | D5: R | E5: P | F5: R | G5: R | H5: R | I5: R | K5: Variación S/. | Q5: Variación % | AD5: Variación S/. | AJ5: Variación %
C6: Total_Producto | D6: =$B$1 -> 46173 | E6: =D6 -> 46173 | F6: =EOMONTH(D6,-1) -> 46142 | G6: =EOMONTH(D6,-12) -> 45808 | H6: =EOMONTH(D6,-24) -> 45443 | I6: =EOMONTH(D6,-36) -> 45077 | K6: =E6 -> 46173 | L6: =F6 -> 46142 | M6: =G6 -> 45808 | N6: =H6 -> 45443 | O6: =I6 -> 45077 | Q6: =K6 -> 46173 | R6: =L6 -> 46142 | S6: =M6 -> 45808 | T6: =N6 -> 45443 | U6: =O6 -> 45077 | W6: =$B$1 -> 46173 | X6: =W6 -> 46173 | Y6: =EOMONTH(W6,-1) -> 46142 | Z6: =EOMONTH(W6,-12) -> 45808 | AA6: =EOMONTH(W6,-24) -> 45443 | AB6: =EOMONTH(W6,-36) -> 45077 | AD6: =X6 -> 46173 | AE6: =Y6 -> 46142 | AF6: =Z6 -> 45808 | AG6: =AA6 -> 45443 | AH6: =AB6 -> 45077 | AJ6: =AD6 -> 46173 | AK6: =AE6 -> 46142 | AL6: =AF6 -> 45808 | AM6: =AG6 -> 45443 | AN6: =AH6 -> 45077
A8: SALDO_FDP | C8: Vigente | D8: {=_xlfn.XLOOKUP(1, (INDIRECT("'"&$C$6&"'!$6:$6")=D$6)* (INDIRECT("'"&$C$6&"'!$5:$5")=D$5), INDIRECT("'"&$C$6&"'!"&ROW()&":"&ROW()) )} -> 5562013.9 | E8: {=_xlfn.XLOOKUP(1, (INDIRECT("'"&$C$6&"'!$6:$6")=E$6)* (INDIRECT("'"&$C$6&"'!$5:$5")=E$5), INDIRECT("'"&$C$6&"'!"&ROW()&":"&ROW()) )} -> 5902822.3 | F8: {=_xlfn.XLOOKUP(1, (INDIRECT("'"&$C$6&"'!$6:$6")=F$6)* (INDIRECT("'"&$C$6&"'!$5:$5")=F$5), INDIRECT("'"&$C$6&"'!"&ROW()&":"&ROW()) )} -> 5548588.7 | G8: {=_xlfn.XLOOKUP(1, (INDIRECT("'"&$C$6&"'!$6:$6")=G$6)* (INDIRECT("'"&$C$6&"'!$5:$5")=G$5), INDIRECT("'"&$C$6&"'!"&ROW()&":"&ROW()) )} -> 5643386.7 | H8: {=_xlfn.XLOOKUP(1, (INDIRECT("'"&$C$6&"'!$6:$6")=H$6)* (INDIRECT("'"&$C$6&"'!$5:$5")=H$5), INDIRECT("'"&$C$6&"'!"&ROW()&":"&ROW()) )} -> 5684127.8 | I8: {=_xlfn.XLOOKUP(1, (INDIRECT("'"&$C$6&"'!$6:$6")=I$6)* (INDIRECT("'"&$C$6&"'!$5:$5")=I$5), INDIRECT("'"&$C$6&"'!"&ROW()&":"&ROW()) )} -> 4938857 | K8: =$D8-E8 -> -340808.41 | L8: =$D8-F8 -> 13425.239 | M8: =$D8-G8 -> -81372.774 | N8: =$D8-H8 -> -122113.9 | O8: =$D8-I8 -> 623156.91 | Q8: =IFERROR($D8/E8-1,0) -> -0.057736519 | R8: =IFERROR($D8/F8-1,0) -> 0.0024195773 | S8: =IFERROR($D8/G8-1,0) -> -0.014419139 | T8: =IFERROR($D8/H8-1,0) -> -0.021483313 | U8: =IFERROR($D8/I8-1,0) -> 0.12617432 | W8: {=INDIRECT("'"&$C$6&"'!"&ADDRESS(ROW(),COLUMN()+44))} -> 5562013.9 | X8: {=INDIRECT("'"&$C$6&"'!"&ADDRESS(ROW(),COLUMN()+44))} -> 5902822.3 | Y8: {=INDIRECT("'"&$C$6&"'!"&ADDRESS(ROW(),COLUMN()+44))} -> 5548588.7 | Z8: {=INDIRECT("'"&$C$6&"'!"&ADDRESS(ROW(),COLUMN()+44))} -> 5643386.7 | AA8: {=INDIRECT("'"&$C$6&"'!"&ADDRESS(ROW(),COLUMN()+44))} -> 5684127.8 | AB8: {=INDIRECT("'"&$C$6&"'!"&ADDRESS(ROW(),COLUMN()+44))} -> 4938857 | AD8: =$W8-X8 -> -340808.41 | AE8: =$W8-Y8 -> 13425.239 | AF8: =$W8-Z8 -> -81372.774 | AG8: =$W8-AA8 -> -122113.9 | AH8: =$W8-AB8 -> 623156.91 | AJ8: =IFERROR($W8/X8-1,0) -> -0.057736519 | AK8: =IFERROR($W8/Y8-1,0) -> 0.0024195773 | AL8: =IFERROR($W8/Z8-1,0) -> -0.014419139 | AM8: =IFERROR($W8/AA8-1,0) -> -0.021483313 | AN8: =IFERROR($W8/AB8-1,0) -> 0.12617432
A9: SALDO_FDP | C9: Refinanciado | D9: {=_xlfn.XLOOKUP(1, (INDIRECT("'"&$C$6&"'!$6:$6")=D$6)* (INDIRECT("'"&$C$6&"'!$5:$5")=D$5), INDIRECT("'"&$C$6&"'!"&ROW()&":"&ROW()) )} -> 28277.739 | E9: {=_xlfn.XLOOKUP(1, (INDIRECT("'"&$C$6&"'!$6:$6")=E$6)* (INDIRECT("'"&$C$6&"'!$5:$5")=E$5), INDIRECT("'"&$C$6&"'!"&ROW()&":"&ROW()) )} -> 30703.861 | F9: {=_xlfn.XLOOKUP(1, (INDIRECT("'"&$C$6&"'!$6:$6")=F$6)* (INDIRECT("'"&$C$6&"'!$5:$5")=F$5), INDIRECT("'"&$C$6&"'!"&ROW()&":"&ROW()) )} -> 28987.813 | G9: {=_xlfn.XLOOKUP(1, (INDIRECT("'"&$C$6&"'!$6:$6")=G$6)* (INDIRECT("'"&$C$6&"'!$5:$5")=G$5), INDIRECT("'"&$C$6&"'!"&ROW()&":"&ROW()) )} -> 28019.412 | H9: {=_xlfn.XLOOKUP(1, (INDIRECT("'"&$C$6&"'!$6:$6")=H$6)* (INDIRECT("'"&$C$6&"'!$5:$5")=H$5), INDIRECT("'"&$C$6&"'!"&ROW()&":"&ROW()) )} -> 22700.678 | I9: {=_xlfn.XLOOKUP(1, (INDIRECT("'"&$C$6&"'!$6:$6")=I$6)* (INDIRECT("'"&$C$6&"'!$5:$5")=I$5), INDIRECT("'"&$C$6&"'!"&ROW()&":"&ROW()) )} -> 29479.237 | K9: =$D9-E9 -> -2426.1219 | L9: =$D9-F9 -> -710.07357 | M9: =$D9-G9 -> 258.32699 | N9: =$D9-H9 -> 5577.0609 | O9: =$D9-I9 -> -1201.4984 | Q9: =IFERROR($D9/E9-1,0) -> -0.079016834 | R9: =IFERROR($D9/F9-1,0) -> -0.02449559 | S9: =IFERROR($D9/G9-1,0) -> 0.0092195721 | T9: =IFERROR($D9/H9-1,0) -> 0.24567816 | U9: =IFERROR($D9/I9-1,0) -> -0.040757445 | W9: {=INDIRECT("'"&$C$6&"'!"&ADDRESS(ROW(),COLUMN()+44))} -> 28277.739 | X9: {=INDIRECT("'"&$C$6&"'!"&ADDRESS(ROW(),COLUMN()+44))} -> 30703.861 | Y9: {=INDIRECT("'"&$C$6&"'!"&ADDRESS(ROW(),COLUMN()+44))} -> 28987.813 | Z9: {=INDIRECT("'"&$C$6&"'!"&ADDRESS(ROW(),COLUMN()+44))} -> 28019.412 | AA9: {=INDIRECT("'"&$C$6&"'!"&ADDRESS(ROW(),COLUMN()+44))} -> 22700.678 | AB9: {=INDIRECT("'"&$C$6&"'!"&ADDRESS(ROW(),COLUMN()+44))} -> 29479.237 | AD9: =$W9-X9 -> -2426.1219 | AE9: =$W9-Y9 -> -710.07357 | AF9: =$W9-Z9 -> 258.32699 | AG9: =$W9-AA9 -> 5577.0609 | AH9: =$W9-AB9 -> -1201.4984 | AJ9: =IFERROR($W9/X9-1,0) -> -0.079016834 | AK9: =IFERROR($W9/Y9-1,0) -> -0.02449559 | AL9: =IFERROR($W9/Z9-1,0) -> 0.0092195721 | AM9: =IFERROR($W9/AA9-1,0) -> 0.24567816 | AN9: =IFERROR($W9/AB9-1,0) -> -0.040757445
A10: SALDO_FDP | C10: Vencido y Judicial | D10: {=_xlfn.XLOOKUP(1, (INDIRECT("'"&$C$6&"'!$6:$6")=D$6)* (INDIRECT("'"&$C$6&"'!$5:$5")=D$5), INDIRECT("'"&$C$6&"'!"&ROW()&":"&ROW()) )} -> 118475.52 | E10: {=_xlfn.XLOOKUP(1, (INDIRECT("'"&$C$6&"'!$6:$6")=E$6)* (INDIRECT("'"&$C$6&"'!$5:$5")=E$5), INDIRECT("'"&$C$6&"'!"&ROW()&":"&ROW()) )} -> 110380.99 | F10: {=_xlfn.XLOOKUP(1, (INDIRECT("'"&$C$6&"'!$6:$6")=F$6)* (INDIRECT("'"&$C$6&"'!$5:$5")=F$5), INDIRECT("'"&$C$6&"'!"&ROW()&":"&ROW()) )} -> 118196.07 | G10: {=_xlfn.XLOOKUP(1, (INDIRECT("'"&$C$6&"'!$6:$6")=G$6)* (INDIRECT("'"&$C$6&"'!$5:$5")=G$5), INDIRECT("'"&$C$6&"'!"&ROW()&":"&ROW()) )} -> 92392.453 | H10: {=_xlfn.XLOOKUP(1, (INDIRECT("'"&$C$6&"'!$6:$6")=H$6)* (INDIRECT("'"&$C$6&"'!$5:$5")=H$5), INDIRECT("'"&$C$6&"'!"&ROW()&":"&ROW()) )} -> 66766.564 | I10: {=_xlfn.XLOOKUP(1, (INDIRECT("'"&$C$6&"'!$6:$6")=I$6)* (INDIRECT("'"&$C$6&"'!$5:$5")=I$5), INDIRECT("'"&$C$6&"'!"&ROW()&":"&ROW()) )} -> 67763.653 | K10: =$D10-E10 -> 8094.5256 | L10: =$D10-F10 -> 279.44567 | M10: =$D10-G10 -> 26083.062 | N10: =$D10-H10 -> 51708.951 | O10: =$D10-I10 -> 50711.862 | Q10: =IFERROR($D10/E10-1,0) -> 0.073332605 | R10: =IFERROR($D10/F10-1,0) -> 0.0023642552 | S10: =IFERROR($D10/G10-1,0) -> 0.28230728 | T10: =IFERROR($D10/H10-1,0) -> 0.77447375 | U10: =IFERROR($D10/I10-1,0) -> 0.74836375 | W10: {=INDIRECT("'"&$C$6&"'!"&ADDRESS(ROW(),COLUMN()+44))} -> 118475.52 | X10: {=INDIRECT("'"&$C$6&"'!"&ADDRESS(ROW(),COLUMN()+44))} -> 110380.99 | Y10: {=INDIRECT("'"&$C$6&"'!"&ADDRESS(ROW(),COLUMN()+44))} -> 118196.07 | Z10: {=INDIRECT("'"&$C$6&"'!"&ADDRESS(ROW(),COLUMN()+44))} -> 92392.453 | AA10: {=INDIRECT("'"&$C$6&"'!"&ADDRESS(ROW(),COLUMN()+44))} -> 66766.564 | AB10: {=INDIRECT("'"&$C$6&"'!"&ADDRESS(ROW(),COLUMN()+44))} -> 67763.653 | AD10: =$W10-X10 -> 8094.5256 | AE10: =$W10-Y10 -> 279.44567 | AF10: =$W10-Z10 -> 26083.062 | AG10: =$W10-AA10 -> 51708.951 | AH10: =$W10-AB10 -> 50711.862 | AJ10: =IFERROR($W10/X10-1,0) -> 0.073332605 | AK10: =IFERROR($W10/Y10-1,0) -> 0.0023642552 | AL10: =IFERROR($W10/Z10-1,0) -> 0.28230728 | AM10: =IFERROR($W10/AA10-1,0) -> 0.77447375 | AN10: =IFERROR($W10/AB10-1,0) -> 0.74836375
C11: Saldo FdP | D11: =SUM(D8:D10) -> 5708767.2 | E11: =SUM(E8:E10) -> 6043907.2 | F11: =SUM(F8:F10) -> 5695772.5 | G11: =SUM(G8:G10) -> 5763798.5 | H11: =SUM(H8:H10) -> 5773595 | I11: =SUM(I8:I10) -> 5036099.9 | K11: =$D11-E11 -> -335140.01 | L11: =$D11-F11 -> 12994.611 | M11: =$D11-G11 -> -55031.385 | N11: =$D11-H11 -> -64827.887 | O11: =$D11-I11 -> 672667.27 | Q11: =IFERROR($D11/E11-1,0) -> -0.055450886 | R11: =IFERROR($D11/F11-1,0) -> 0.0022814485 | S11: =IFERROR($D11/G11-1,0) -> -0.0095477634 | T11: =IFERROR($D11/H11-1,0) -> -0.01122834 | U11: =IFERROR($D11/I11-1,0) -> 0.13356909 | W11: =SUM(W8:W10) -> 5708767.2 | X11: =SUM(X8:X10) -> 6043907.2 | Y11: =SUM(Y8:Y10) -> 5695772.5 | Z11: =SUM(Z8:Z10) -> 5763798.5 | AA11: =SUM(AA8:AA10) -> 5773595 | AB11: =SUM(AB8:AB10) -> 5036099.9 | AD11: =$W11-X11 -> -335140.01 | AE11: =$W11-Y11 -> 12994.611 | AF11: =$W11-Z11 -> -55031.385 | AG11: =$W11-AA11 -> -64827.887 | AH11: =$W11-AB11 -> 672667.27 | AJ11: =IFERROR($W11/X11-1,0) -> -0.055450886 | AK11: =IFERROR($W11/Y11-1,0) -> 0.0022814485 | AL11: =IFERROR($W11/Z11-1,0) -> -0.0095477634 | AM11: =IFERROR($W11/AA11-1,0) -> -0.01122834 | AN11: =IFERROR($W11/AB11-1,0) -> 0.13356909
A14: SALDO_PROM | C14: Vigente | D14: {=_xlfn.XLOOKUP(1, (INDIRECT("'"&$C$6&"'!$6:$6")=D$6)* (INDIRECT("'"&$C$6&"'!$5:$5")=D$5), INDIRECT("'"&$C$6&"'!"&ROW()&":"&ROW()) )} -> 5520303.6 | E14: {=_xlfn.XLOOKUP(1, (INDIRECT("'"&$C$6&"'!$6:$6")=E$6)* (INDIRECT("'"&$C$6&"'!$5:$5")=E$5), INDIRECT("'"&$C$6&"'!"&ROW()&":"&ROW()) )} -> 5858551.1 | F14: {=_xlfn.XLOOKUP(1, (INDIRECT("'"&$C$6&"'!$6:$6")=F$6)* (INDIRECT("'"&$C$6&"'!$5:$5")=F$5), INDIRECT("'"&$C$6&"'!"&ROW()&":"&ROW()) )} -> 5500202.2 | G14: {=_xlfn.XLOOKUP(1, (INDIRECT("'"&$C$6&"'!$6:$6")=G$6)* (INDIRECT("'"&$C$6&"'!$5:$5")=G$5), INDIRECT("'"&$C$6&"'!"&ROW()&":"&ROW()) )} -> 5598132 | H14: {=_xlfn.XLOOKUP(1, (INDIRECT("'"&$C$6&"'!$6:$6")=H$6)* (INDIRECT("'"&$C$6&"'!$5:$5")=H$5), INDIRECT("'"&$C$6&"'!"&ROW()&":"&ROW()) )} -> 5605866.8 | I14: {=_xlfn.XLOOKUP(1, (INDIRECT("'"&$C$6&"'!$6:$6")=I$6)* (INDIRECT("'"&$C$6&"'!$5:$5")=I$5), INDIRECT("'"&$C$6&"'!"&ROW()&":"&ROW()) )} -> 4884944 | K14: =$D14-E14 -> -338247.53 | L14: =$D14-F14 -> 20101.446 | M14: =$D14-G14 -> -77828.344 | N14: =$D14-H14 -> -85563.148 | O14: =$D14-I14 -> 635359.66 | Q14: =IFERROR($D14/E14-1,0) -> -0.057735696 | R14: =IFERROR($D14/F14-1,0) -> 0.0036546739 | S14: =IFERROR($D14/G14-1,0) -> -0.013902556 | T14: =IFERROR($D14/H14-1,0) -> -0.015263143 | U14: =IFERROR($D14/I14-1,0) -> 0.13006488 | W14: {=INDIRECT("'"&$C$6&"'!"&ADDRESS(ROW(),COLUMN()+44))} -> 5501093.2 | X14: {=INDIRECT("'"&$C$6&"'!"&ADDRESS(ROW(),COLUMN()+44))} -> 5807134.7 | Y14: {=INDIRECT("'"&$C$6&"'!"&ADDRESS(ROW(),COLUMN()+44))} -> 5496290.7 | Z14: {=INDIRECT("'"&$C$6&"'!"&ADDRESS(ROW(),COLUMN()+44))} -> 5603111.6 | AA14: {=INDIRECT("'"&$C$6&"'!"&ADDRESS(ROW(),COLUMN()+44))} -> 5448981.7 | AB14: {=INDIRECT("'"&$C$6&"'!"&ADDRESS(ROW(),COLUMN()+44))} -> 4764493.8 | AD14: =$W14-X14 -> -306041.49 | AE14: =$W14-Y14 -> 4802.5934 | AF14: =$W14-Z14 -> -102018.4 | AG14: =$W14-AA14 -> 52111.507 | AH14: =$W14-AB14 -> 736599.47 | AJ14: =IFERROR($W14/X14-1,0) -> -0.052700945 | AK14: =IFERROR($W14/Y14-1,0) -> 0.0008737881 | AL14: =IFERROR($W14/Z14-1,0) -> -0.018207455 | AM14: =IFERROR($W14/AA14-1,0) -> 0.0095635312 | AN14: =IFERROR($W14/AB14-1,0) -> 0.15460183
A15: SALDO_PROM | C15: Refinanciado | D15: {=_xlfn.XLOOKUP(1, (INDIRECT("'"&$C$6&"'!$6:$6")=D$6)* (INDIRECT("'"&$C$6&"'!$5:$5")=D$5), INDIRECT("'"&$C$6&"'!"&ROW()&":"&ROW()) )} -> 28394.213 | E15: {=_xlfn.XLOOKUP(1, (INDIRECT("'"&$C$6&"'!$6:$6")=E$6)* (INDIRECT("'"&$C$6&"'!$5:$5")=E$5), INDIRECT("'"&$C$6&"'!"&ROW()&":"&ROW()) )} -> 30473.582 | F15: {=_xlfn.XLOOKUP(1, (INDIRECT("'"&$C$6&"'!$6:$6")=F$6)* (INDIRECT("'"&$C$6&"'!$5:$5")=F$5), INDIRECT("'"&$C$6&"'!"&ROW()&":"&ROW()) )} -> 29285.746 | G15: {=_xlfn.XLOOKUP(1, (INDIRECT("'"&$C$6&"'!$6:$6")=G$6)* (INDIRECT("'"&$C$6&"'!$5:$5")=G$5), INDIRECT("'"&$C$6&"'!"&ROW()&":"&ROW()) )} -> 27162.268 | H15: {=_xlfn.XLOOKUP(1, (INDIRECT("'"&$C$6&"'!$6:$6")=H$6)* (INDIRECT("'"&$C$6&"'!$5:$5")=H$5), INDIRECT("'"&$C$6&"'!"&ROW()&":"&ROW()) )} -> 23089.442 | I15: {=_xlfn.XLOOKUP(1, (INDIRECT("'"&$C$6&"'!$6:$6")=I$6)* (INDIRECT("'"&$C$6&"'!$5:$5")=I$5), INDIRECT("'"&$C$6&"'!"&ROW()&":"&ROW()) )} -> 28758.026 | K15: =$D15-E15 -> -2079.369 | L15: =$D15-F15 -> -891.53279 | M15: =$D15-G15 -> 1231.945 | N15: =$D15-H15 -> 5304.7704 | O15: =$D15-I15 -> -363.81343 | Q15: =IFERROR($D15/E15-1,0) -> -0.068235136 | R15: =IFERROR($D15/F15-1,0) -> -0.03044255 | S15: =IFERROR($D15/G15-1,0) -> 0.045355014 | T15: =IFERROR($D15/H15-1,0) -> 0.22974875 | U15: =IFERROR($D15/I15-1,0) -> -0.012650848 | W15: {=INDIRECT("'"&$C$6&"'!"&ADDRESS(ROW(),COLUMN()+44))} -> 29506.608 | X15: {=INDIRECT("'"&$C$6&"'!"&ADDRESS(ROW(),COLUMN()+44))} -> 29715.91 | Y15: {=INDIRECT("'"&$C$6&"'!"&ADDRESS(ROW(),COLUMN()+44))} -> 29784.706 | Z15: {=INDIRECT("'"&$C$6&"'!"&ADDRESS(ROW(),COLUMN()+44))} -> 24117.375 | AA15: {=INDIRECT("'"&$C$6&"'!"&ADDRESS(ROW(),COLUMN()+44))} -> 24880.929 | AB15: {=INDIRECT("'"&$C$6&"'!"&ADDRESS(ROW(),COLUMN()+44))} -> 28956.678 | AD15: =$W15-X15 -> -209.30238 | AE15: =$W15-Y15 -> -278.09871 | AF15: =$W15-Z15 -> 5389.2328 | AG15: =$W15-AA15 -> 4625.6789 | AH15: =$W15-AB15 -> 549.92983 | AJ15: =IFERROR($W15/X15-1,0) -> -0.0070434452 | AK15: =IFERROR($W15/Y15-1,0) -> -0.0093369633 | AL15: =IFERROR($W15/Z15-1,0) -> 0.22345852 | AM15: =IFERROR($W15/AA15-1,0) -> 0.18591263 | AN15: =IFERROR($W15/AB15-1,0) -> 0.018991468
A16: SALDO_PROM | C16: Vencido y Judicial | D16: {=_xlfn.XLOOKUP(1, (INDIRECT("'"&$C$6&"'!$6:$6")=D$6)* (INDIRECT("'"&$C$6&"'!$5:$5")=D$5), INDIRECT("'"&$C$6&"'!"&ROW()&":"&ROW()) )} -> 122191.48 | E16: {=_xlfn.XLOOKUP(1, (INDIRECT("'"&$C$6&"'!$6:$6")=E$6)* (INDIRECT("'"&$C$6&"'!$5:$5")=E$5), INDIRECT("'"&$C$6&"'!"&ROW()&":"&ROW()) )} -> 109553.13 | F16: {=_xlfn.XLOOKUP(1, (INDIRECT("'"&$C$6&"'!$6:$6")=F$6)* (INDIRECT("'"&$C$6&"'!$5:$5")=F$5), INDIRECT("'"&$C$6&"'!"&ROW()&":"&ROW()) )} -> 120999.42 | G16: {=_xlfn.XLOOKUP(1, (INDIRECT("'"&$C$6&"'!$6:$6")=G$6)* (INDIRECT("'"&$C$6&"'!$5:$5")=G$5), INDIRECT("'"&$C$6&"'!"&ROW()&":"&ROW()) )} -> 96660.591 | H16: {=_xlfn.XLOOKUP(1, (INDIRECT("'"&$C$6&"'!$6:$6")=H$6)* (INDIRECT("'"&$C$6&"'!$5:$5")=H$5), INDIRECT("'"&$C$6&"'!"&ROW()&":"&ROW()) )} -> 74499.618 | I16: {=_xlfn.XLOOKUP(1, (INDIRECT("'"&$C$6&"'!$6:$6")=I$6)* (INDIRECT("'"&$C$6&"'!$5:$5")=I$5), INDIRECT("'"&$C$6&"'!"&ROW()&":"&ROW()) )} -> 75534.137 | K16: =$D16-E16 -> 12638.345 | L16: =$D16-F16 -> 1192.0545 | M16: =$D16-G16 -> 25530.886 | N16: =$D16-H16 -> 47691.859 | O16: =$D16-I16 -> 46657.34 | Q16: =IFERROR($D16/E16-1,0) -> 0.11536269 | R16: =IFERROR($D16/F16-1,0) -> 0.0098517368 | S16: =IFERROR($D16/G16-1,0) -> 0.26412922 | T16: =IFERROR($D16/H16-1,0) -> 0.64016246 | U16: =IFERROR($D16/I16-1,0) -> 0.61769873 | W16: {=INDIRECT("'"&$C$6&"'!"&ADDRESS(ROW(),COLUMN()+44))} -> 126492.98 | X16: {=INDIRECT("'"&$C$6&"'!"&ADDRESS(ROW(),COLUMN()+44))} -> 113056.73 | Y16: {=INDIRECT("'"&$C$6&"'!"&ADDRESS(ROW(),COLUMN()+44))} -> 127568.35 | Z16: {=INDIRECT("'"&$C$6&"'!"&ADDRESS(ROW(),COLUMN()+44))} -> 98315.232 | AA16: {=INDIRECT("'"&$C$6&"'!"&ADDRESS(ROW(),COLUMN()+44))} -> 75622.418 | AB16: {=INDIRECT("'"&$C$6&"'!"&ADDRESS(ROW(),COLUMN()+44))} -> 78852.452 | AD16: =$W16-X16 -> 13436.25 | AE16: =$W16-Y16 -> -1075.3747 | AF16: =$W16-Z16 -> 28177.744 | AG16: =$W16-AA16 -> 50870.557 | AH16: =$W16-AB16 -> 47640.524 | AJ16: =IFERROR($W16/X16-1,0) -> 0.11884521 | AK16: =IFERROR($W16/Y16-1,0) -> -0.0084297923 | AL16: =IFERROR($W16/Z16-1,0) -> 0.28660609 | AM16: =IFERROR($W16/AA16-1,0) -> 0.67269149 | AN16: =IFERROR($W16/AB16-1,0) -> 0.60417301
C17: Saldo Prom | D17: =SUM(D14:D16) -> 5670889.3 | E17: =SUM(E14:E16) -> 5998577.9 | F17: =SUM(F14:F16) -> 5650487.3 | G17: =SUM(G14:G16) -> 5721954.8 | H17: =SUM(H14:H16) -> 5703455.8 | I17: =SUM(I14:I16) -> 4989236.1 | K17: =$D17-E17 -> -327688.55 | L17: =$D17-F17 -> 20401.967 | M17: =$D17-G17 -> -51065.513 | N17: =$D17-H17 -> -32566.519 | O17: =$D17-I17 -> 681653.19 | Q17: =IFERROR($D17/E17-1,0) -> -0.054627707 | R17: =IFERROR($D17/F17-1,0) -> 0.0036106562 | S17: =IFERROR($D17/G17-1,0) -> -0.0089244872 | T17: =IFERROR($D17/H17-1,0) -> -0.0057099625 | U17: =IFERROR($D17/I17-1,0) -> 0.13662476 | W17: =SUM(W14:W16) -> 5657092.8 | X17: =SUM(X14:X16) -> 5949907.4 | Y17: =SUM(Y14:Y16) -> 5653643.7 | Z17: =SUM(Z14:Z16) -> 5725544.3 | AA17: =SUM(AA14:AA16) -> 5549485.1 | AB17: =SUM(AB14:AB16) -> 4872302.9 | AD17: =$W17-X17 -> -292814.54 | AE17: =$W17-Y17 -> 3449.12 | AF17: =$W17-Z17 -> -68451.424 | AG17: =$W17-AA17 -> 107607.74 | AH17: =$W17-AB17 -> 784789.92 | AJ17: =IFERROR($W17/X17-1,0) -> -0.049213294 | AK17: =IFERROR($W17/Y17-1,0) -> 0.00061007027 | AL17: =IFERROR($W17/Z17-1,0) -> -0.011955444 | AM17: =IFERROR($W17/AA17-1,0) -> 0.019390582 | AN17: =IFERROR($W17/AB17-1,0) -> 0.16107166
C20: Vigente | D20: =IFERROR(((1+D38/D14)^(360/D$3))-1,0) -> 0.1133847 | E20: =IFERROR(((1+E38/E14)^(360/E$3))-1,0) -> 0.11336707 | F20: =IFERROR(((1+F38/F14)^(360/F$3))-1,0) -> 0.1136305 | G20: =IFERROR(((1+G38/G14)^(360/G$3))-1,0) -> 0.11892968 | H20: =IFERROR(((1+H38/H14)^(360/H$3))-1,0) -> 0.1183404 | I20: =IFERROR(((1+I38/I14)^(360/I$3))-1,0) -> 0.11933461 | Q20: =($D20-E20)*10000 -> 0.17628857 | R20: =($D20-F20)*10000 -> -2.4580222 | S20: =($D20-G20)*10000 -> -55.449825 | T20: =($D20-H20)*10000 -> -49.557016 | U20: =($D20-I20)*10000 -> -59.499085 | W20: {=INDIRECT("'"&$C$6&"'!"&ADDRESS(ROW(),COLUMN()+44))} -> 0.11401334 | X20: {=INDIRECT("'"&$C$6&"'!"&ADDRESS(ROW(),COLUMN()+44))} -> 0.1141319 | Y20: {=INDIRECT("'"&$C$6&"'!"&ADDRESS(ROW(),COLUMN()+44))} -> 0.11417123 | Z20: {=INDIRECT("'"&$C$6&"'!"&ADDRESS(ROW(),COLUMN()+44))} -> 0.11828543 | AA20: {=INDIRECT("'"&$C$6&"'!"&ADDRESS(ROW(),COLUMN()+44))} -> 0.11880864 | AB20: {=INDIRECT("'"&$C$6&"'!"&ADDRESS(ROW(),COLUMN()+44))} -> 0.11977102 | AJ20: =($W20-X20)*10000 -> -1.185606 | AK20: =($W20-Y20)*10000 -> -1.5789626 | AL20: =($W20-Z20)*10000 -> -42.720968 | AM20: =($W20-AA20)*10000 -> -47.953007 | AN20: =($W20-AB20)*10000 -> -57.576831
C21: Refinanciado | D21: =IFERROR(((1+D39/D15)^(360/D$3))-1,0) -> 0.1077894 | E21: =IFERROR(((1+E39/E15)^(360/E$3))-1,0) -> 0.11403591 | F21: =IFERROR(((1+F39/F15)^(360/F$3))-1,0) -> 0.11098927 | G21: =IFERROR(((1+G39/G15)^(360/G$3))-1,0) -> 0.11572727 | H21: =IFERROR(((1+H39/H15)^(360/H$3))-1,0) -> 0.11670996 | I21: =IFERROR(((1+I39/I15)^(360/I$3))-1,0) -> 0.10262374 | Q21: =($D21-E21)*10000 -> -62.465045 | R21: =($D21-F21)*10000 -> -31.998685 | S21: =($D21-G21)*10000 -> -79.378647 | T21: =($D21-H21)*10000 -> -89.205514 | U21: =($D21-I21)*10000 -> 51.656611 | W21: {=INDIRECT("'"&$C$6&"'!"&ADDRESS(ROW(),COLUMN()+44))} -> 0.110952 | X21: {=INDIRECT("'"&$C$6&"'!"&ADDRESS(ROW(),COLUMN()+44))} -> 0.11688993 | Y21: {=INDIRECT("'"&$C$6&"'!"&ADDRESS(ROW(),COLUMN()+44))} -> 0.11170696 | Z21: {=INDIRECT("'"&$C$6&"'!"&ADDRESS(ROW(),COLUMN()+44))} -> 0.11587421 | AA21: {=INDIRECT("'"&$C$6&"'!"&ADDRESS(ROW(),COLUMN()+44))} -> 0.11264979 | AB21: {=INDIRECT("'"&$C$6&"'!"&ADDRESS(ROW(),COLUMN()+44))} -> 0.10954141 | AJ21: =($W21-X21)*10000 -> -59.37925 | AK21: =($W21-Y21)*10000 -> -7.5495806 | AL21: =($W21-Z21)*10000 -> -49.222138 | AM21: =($W21-AA21)*10000 -> -16.977864 | AN21: =($W21-AB21)*10000 -> 14.105921
C22: Vencido y Judicial | D22: =IFERROR(((1+D40/D16)^(360/D$3))-1,0) -> 0.024883357 | E22: =IFERROR(((1+E40/E16)^(360/E$3))-1,0) -> 0.034926112 | F22: =IFERROR(((1+F40/F16)^(360/F$3))-1,0) -> 0.022940677 | G22: =IFERROR(((1+G40/G16)^(360/G$3))-1,0) -> 0.028044434 | H22: =IFERROR(((1+H40/H16)^(360/H$3))-1,0) -> 0.038737248 | I22: =IFERROR(((1+I40/I16)^(360/I$3))-1,0) -> 0.044821992 | Q22: =($D22-E22)*10000 -> -100.42755 | R22: =($D22-F22)*10000 -> 19.426803 | S22: =($D22-G22)*10000 -> -31.610767 | T22: =($D22-H22)*10000 -> -138.53891 | U22: =($D22-I22)*10000 -> -199.38635 | W22: {=INDIRECT("'"&$C$6&"'!"&ADDRESS(ROW(),COLUMN()+44))} -> 0.025773005 | X22: {=INDIRECT("'"&$C$6&"'!"&ADDRESS(ROW(),COLUMN()+44))} -> 0.033758698 | Y22: {=INDIRECT("'"&$C$6&"'!"&ADDRESS(ROW(),COLUMN()+44))} -> 0.025986147 | Z22: {=INDIRECT("'"&$C$6&"'!"&ADDRESS(ROW(),COLUMN()+44))} -> 0.02548946 | AA22: {=INDIRECT("'"&$C$6&"'!"&ADDRESS(ROW(),COLUMN()+44))} -> 0.034623467 | AB22: {=INDIRECT("'"&$C$6&"'!"&ADDRESS(ROW(),COLUMN()+44))} -> 0.045571915 | AJ22: =($W22-X22)*10000 -> -79.856931 | AK22: =($W22-Y22)*10000 -> -2.1314242 | AL22: =($W22-Z22)*10000 -> 2.8354466 | AM22: =($W22-AA22)*10000 -> -88.504625 | AN22: =($W22-AB22)*10000 -> -197.9891
C23: Tasa Implicita | D23: =IFERROR(((1+D41/D17)^(360/D$3))-1,0) -> 0.11137811 | E23: =IFERROR(((1+E41/E17)^(360/E$3))-1,0) -> 0.11189033 | F23: =IFERROR(((1+F41/F17)^(360/F$3))-1,0) -> 0.11159997 | G23: =IFERROR(((1+G41/G17)^(360/G$3))-1,0) -> 0.1173199 | H23: =IFERROR(((1+H41/H17)^(360/H$3))-1,0) -> 0.11725894 | I23: =IFERROR(((1+I41/I17)^(360/I$3))-1,0) -> 0.11807424 | Q23: =($D23-E23)*10000 -> -5.1222257 | R23: =($D23-F23)*10000 -> -2.2186345 | S23: =($D23-G23)*10000 -> -59.417871 | T23: =($D23-H23)*10000 -> -58.808283 | U23: =($D23-I23)*10000 -> -66.961307 | W23: {=INDIRECT("'"&$C$6&"'!"&ADDRESS(ROW(),COLUMN()+44))} -> 0.11195056 | X23: {=INDIRECT("'"&$C$6&"'!"&ADDRESS(ROW(),COLUMN()+44))} -> 0.11256651 | Y23: {=INDIRECT("'"&$C$6&"'!"&ADDRESS(ROW(),COLUMN()+44))} -> 0.11209416 | Z23: {=INDIRECT("'"&$C$6&"'!"&ADDRESS(ROW(),COLUMN()+44))} -> 0.11661895 | AA23: {=INDIRECT("'"&$C$6&"'!"&ADDRESS(ROW(),COLUMN()+44))} -> 0.1175928 | AB23: {=INDIRECT("'"&$C$6&"'!"&ADDRESS(ROW(),COLUMN()+44))} -> 0.11847174 | AJ23: =($W23-X23)*10000 -> -6.1594389 | AK23: =($W23-Y23)*10000 -> -1.4359243 | AL23: =($W23-Z23)*10000 -> -46.683888 | AM23: =($W23-AA23)*10000 -> -56.422359 | AN23: =($W23-AB23)*10000 -> -65.211794
