Workbook

Sheet Parametros
B2: Producto | C2: Convenios
B4: Año | C4: 2026
B6: Lista Fechas | C6: =EOMONTH(DATE($C$4,1,1),0) -> 46053 | E6: Segmentos | F6: Renta_Alta
C7: =EOMONTH(C6,1) -> 46081 | F7: Masivo
C8: =EOMONTH(C7,1) -> 46112 | F8: Consumo_Inicial
C9: =EOMONTH(C8,1) -> 46142 | F9: Total_Producto
C10: =EOMONTH(C9,1) -> 46173
C11: =EOMONTH(C10,1) -> 46203
C12: =EOMONTH(C11,1) -> 46234
C13: =EOMONTH(C12,1) -> 46265
C14: =EOMONTH(C13,1) -> 46295
C15: =EOMONTH(C14,1) -> 46326
C16: =EOMONTH(C15,1) -> 46356
C17: =EOMONTH(C16,1) -> 46387

Sheet Total_Producto_CHECK
D1: REAL | AZ1: PRESUPUESTO | BO1: Acumulado | BW1: Saldo Prom Acumulado
BO2: =DATE(YEAR(BO6),1,1) -> 46023 | BP2: =DATE(YEAR(BP6),1,1) -> 46023 | BQ2: =DATE(YEAR(BQ6),1,1) -> 46023 | BR2: =DATE(YEAR(BR6),1,1) -> 45658 | BS2: =DATE(YEAR(BS6),1,1) -> 45292 | BT2: =DATE(YEAR(BT6),1,1) -> 44927
C3: N° dias T.Imp | D3: =DAY(D6) -> 31 | E3: =DAY(E6) -> 28 | F3: =DAY(F6) -> 31 | G3: =DAY(G6) -> 30 | H3: =DAY(H6) -> 31 | I3: =DAY(I6) -> 30 | J3: =DAY(J6) -> 31 | K3: =DAY(K6) -> 31 | ... BK3: =DAY(BK6) -> 31 | BO3: =AVERAGEIFS($D3:$BM3,$D$6:$BM$6,">="&BO$2,$D$6:$BM$6,"<="&BO$6,$D$5:$BM$5,BO$5) -> 30 | BP3: =AVERAGEIFS($D3:$BM3,$D$6:$BM$6,">="&BP$2,$D$6:$BM$6,"<="&BP$6,$D$5:$BM$5,BP$5) -> 30 | BQ3: =AVERAGEIFS($D3:$BM3,$D$6:$BM$6,">="&BQ$2,$D$6:$BM$6,"<="&BQ$6,$D$5:$BM$5,BQ$5) -> 29.5 | BR3: =AVERAGEIFS($D3:$BM3,$D$6:$BM$6,">="&BR$2,$D$6:$BM$6,"<="&BR$6,$D$5:$BM$5,BR$5) -> 30 | BS3: =AVERAGEIFS($D3:$BM3,$D$6:$BM$6,">="&BS$2,$D$6:$BM$6,"<="&BS$6,$D$5:$BM$5,BS$5) -> 30.333333 | BT3: =AVERAGEIFS($D3:$BM3,$D$6:$BM$6,">="&BT$2,$D$6:$BM$6,"<="&BT$6,$D$5:$BM$5,BT$5) -> 30
C4: N° dias FTP | D4: 30 | E4: 30 | F4: 30 | G4: 30 | H4: 30 | I4: 30 | J4: 30 | K4: 30 | L4: 30 | M4: 30 | N4: 30 | O4: 30 | P4: 30 | Q4: 30 | R4: 30 | S4: 30 | T4: 30 | U4: 30 | V4: 30 | W4: 30 | X4: 30 | Y4: 30 | Z4: 30 | AA4: 30 | AB4: 30 | AC4: 30 | AD4: 30 | AE4: 30 | AF4: 30 | AG4: 30 | AH4: 30 | AI4: 30 | AJ4: 30 | AK4: 30 | AL4: 30 | AM4: 30 | AN4: 30 | AO4: 30 | AP4: 30 | AQ4: 30 | AR4: 30 | AS4: 30 | AT4: 30 | AU4: 30 | AV4: 30 | AW4: 30 | AX4: 30 | AY4: 30 | AZ4: 30 | BA4: 30 | BB4: 30 | BC4: 30 | BD4: 30 | BE4: 30 | BF4: 30 | BG4: 30 | BH4: 30 | BI4: 30 | BJ4: 30 | BK4: 30 | BO4: =AVERAGEIFS($D4:$BM4,$D$6:$BM$6,">="&BO$2,$D$6:$BM$6,"<="&BO$6,$D$5:$BM$5,BO$5) -> 30 | BP4: =AVERAGEIFS($D4:$BM4,$D$6:$BM$6,">="&BP$2,$D$6:$BM$6,"<="&BP$6,$D$5:$BM$5,BP$5) -> 30 | BQ4: =AVERAGEIFS($D4:$BM4,$D$6:$BM$6,">="&BQ$2,$D$6:$BM$6,"<="&BQ$6,$D$5:$BM$5,BQ$5) -> 30 | BR4: =AVERAGEIFS($D4:$BM4,$D$6:$BM$6,">="&BR$2,$D$6:$BM$6,"<="&BR$6,$D$5:$BM$5,BR$5) -> 30 | BS4: =AVERAGEIFS($D4:$BM4,$D$6:$BM$6,">="&BS$2,$D$6:$BM$6,"<="&BS$6,$D$5:$BM$5,BS$5) -> 30 | BT4: =AVERAGEIFS($D4:$BM4,$D$6:$BM$6,">="&BT$2,$D$6:$BM$6,"<="&BT$6,$D$5:$BM$5,BT$5) -> 30
C5: Tipo | D5: R | E5: R | F5: R | G5: R | H5: R | I5: R | J5: R | K5: R | L5: R | M5: R | N5: R | O5: R | P5: R | Q5: R | R5: R | S5: R | T5: R | U5: R | V5: R | W5: R | X5: R | Y5: R | Z5: R | AA5: R | AB5: R | AC5: R | AD5: R | AE5: R | AF5: R | AG5: R | AH5: R | AI5: R | AJ5: R | AK5: R | AL5: R | AM5: R | AN5: R | AO5: R | AP5: R | AQ5: R | AR5: R | AS5: R | AT5: R | AU5: R | AV5: R | AW5: R | AX5: R | AY5: R | AZ5: P | BA5: P | BB5: P | BC5: P | BD5: P | BE5: P | BF5: P | BG5: P | BH5: P | BI5: P | BJ5: P | BK5: P | BO5: R | BP5: P | BQ5: R | BR5: R | BS5: R | BT5: R
C6: Total Hipotecario | D6: 44957 | E6: 44985 | F6: 45016 | G6: 45046 | H6: 45077 | I6: 45107 | J6: 45138 | K6: 45169 | L6: 45199 | M6: 45230 | N6: 45260 | O6: 45291 | P6: 45322 | Q6: 45351 | R6: 45382 | S6: 45412 | T6: 45443 | U6: 45473 | V6: 45504 | W6: 45535 | X6: 45565 | Y6: 45596 | Z6: 45626 | AA6: 45657 | AB6: 45688 | AC6: 45716 | AD6: 45747 | AE6: 45777 | AF6: 45808 | AG6: 45838 | AH6: 45869 | AI6: 45900 | AJ6: 45930 | AK6: 45961 | AL6: 45991 | AM6: 46022 | AN6: 46053 | AO6: 46081 | AP6: 46112 | AQ6: 46142 | AR6: 46173 | AS6: 46203 | AT6: 46234 | AU6: 46265 | AV6: 46295 | AW6: 46326 | AX6: 46356 | AY6: 46387 | AZ6: 46053 | BA6: 46081 | BB6: 46112 | BC6: 46142 | BD6: 46173 | BE6: 46203 | BF6: 46234 | BG6: 46265 | BH6: 46295 | BI6: 46326 | BJ6: 46356 | BK6: 46387 | BO6: =Desempeño_Financiero!$B$1 -> 46112 | BP6: =BO6 -> 46112 | BQ6: =EOMONTH(BO6,-1) -> 46081 | BR6: =EOMONTH(BO6,-12) -> 45747 | BS6: =EOMONTH(BO6,-24) -> 45382 | BT6: =EOMONTH(BO6,-36) -> 45016 | BW6: =BO6 -> 46112 | BX6: =BP6 -> 46112 | BY6: =BQ6 -> 46081 | BZ6: =BR6 -> 45747 | CA6: =BS6 -> 45382 | CB6: =BT6 -> 45016
A8: SALDO_FDP | C8: Vigente | D8: =Renta_Alta!D8+Masivo!D8+Consumo_Inicial!D8 -> 9306979.2 | E8: =Renta_Alta!E8+Masivo!E8+Consumo_Inicial!E8 -> 9343837 | F8: =Renta_Alta!F8+Masivo!F8+Consumo_Inicial!F8 -> 9379816.8 | G8: =Renta_Alta!G8+Masivo!G8+Consumo_Inicial!G8 -> 9428101.8 | H8: =Renta_Alta!H8+Masivo!H8+Consumo_Inicial!H8 -> 9463606.7 | I8: =Renta_Alta!I8+Masivo!I8+Consumo_Inicial!I8 -> 9512554.1 | J8: =Renta_Alta!J8+Masivo!J8+Consumo_Inicial!J8 -> 9520520.3 | K8: =Renta_Alta!K8+Masivo!K8+Consumo_Inicial!K8 -> 9581896.8 | ... BK8: =Renta_Alta!BK8+Masivo!BK8+Consumo_Inicial!BK8 -> 12221963 | BO8: =_xlfn.XLOOKUP(BO$6,$D$6:$BM$6,$D8:$BM8,,0,1) -> 11525777 | BP8: =_xlfn.XLOOKUP(BP$6,$D$6:$BM$6,$D8:$BM8,,0,-1) -> 11438229 | BQ8: =_xlfn.XLOOKUP(BQ$6,$D$6:$BM$6,$D8:$BM8,,0,1) -> 11478076 | BR8: =_xlfn.XLOOKUP(BR$6,$D$6:$BM$6,$D8:$BM8,,0,1) -> 10587478 | BS8: =_xlfn.XLOOKUP(BS$6,$D$6:$BM$6,$D8:$BM8,,0,1) -> 9915549.8 | BT8: =_xlfn.XLOOKUP(BT$6,$D$6:$BM$6,$D8:$BM8,,0,1) -> 9379816.8
A9: SALDO_FDP | C9: Refinanciado | D9: =Renta_Alta!D9+Masivo!D9+Consumo_Inicial!D9 -> 34450.126 | E9: =Renta_Alta!E9+Masivo!E9+Consumo_Inicial!E9 -> 33830.323 | F9: =Renta_Alta!F9+Masivo!F9+Consumo_Inicial!F9 -> 36652.88 | G9: =Renta_Alta!G9+Masivo!G9+Consumo_Inicial!G9 -> 33483.419 | H9: =Renta_Alta!H9+Masivo!H9+Consumo_Inicial!H9 -> 32226.636 | I9: =Renta_Alta!I9+Masivo!I9+Consumo_Inicial!I9 -> 32526.535 | J9: =Renta_Alta!J9+Masivo!J9+Consumo_Inicial!J9 -> 32175.432 | K9: =Renta_Alta!K9+Masivo!K9+Consumo_Inicial!K9 -> 31298.089 | ... BK9: =Renta_Alta!BK9+Masivo!BK9+Consumo_Inicial!BK9 -> 25869.388 | BO9: =_xlfn.XLOOKUP(BO$6,$D$6:$BM$6,$D9:$BM9,,0,1) -> 34203.92 | BP9: =_xlfn.XLOOKUP(BP$6,$D$6:$BM$6,$D9:$BM9,,0,-1) -> 29770.187 | BQ9: =_xlfn.XLOOKUP(BQ$6,$D$6:$BM$6,$D9:$BM9,,0,1) -> 32640.44 | BR9: =_xlfn.XLOOKUP(BR$6,$D$6:$BM$6,$D9:$BM9,,0,1) -> 29921.003 | BS9: =_xlfn.XLOOKUP(BS$6,$D$6:$BM$6,$D9:$BM9,,0,1) -> 31857.707 | BT9: =_xlfn.XLOOKUP(BT$6,$D$6:$BM$6,$D9:$BM9,,0,1) -> 36652.88
A10: SALDO_FDP | C10: Vencido y Judicial | D10: =Renta_Alta!D10+Masivo!D10+Consumo_Inicial!D10 -> 246802.44 | E10: =Renta_Alta!E10+Masivo!E10+Consumo_Inicial!E10 -> 248460.62 | F10: =Renta_Alta!F10+Masivo!F10+Consumo_Inicial!F10 -> 249639.32 | G10: =Renta_Alta!G10+Masivo!G10+Consumo_Inicial!G10 -> 253224.17 | H10: =Renta_Alta!H10+Masivo!H10+Consumo_Inicial!H10 -> 265429.48 | I10: =Renta_Alta!I10+Masivo!I10+Consumo_Inicial!I10 -> 265953.3 | J10: =Renta_Alta!J10+Masivo!J10+Consumo_Inicial!J10 -> 266312.9 | K10: =Renta_Alta!K10+Masivo!K10+Consumo_Inicial!K10 -> 270309.73 | ... BK10: =Renta_Alta!BK10+Masivo!BK10+Consumo_Inicial!BK10 -> 391039.79 | BO10: =_xlfn.XLOOKUP(BO$6,$D$6:$BM$6,$D10:$BM10,,0,1) -> 346980.86 | BP10: =_xlfn.XLOOKUP(BP$6,$D$6:$BM$6,$D10:$BM10,,0,-1) -> 375811.31 | BQ10: =_xlfn.XLOOKUP(BQ$6,$D$6:$BM$6,$D10:$BM10,,0,1) -> 338634.42 | BR10: =_xlfn.XLOOKUP(BR$6,$D$6:$BM$6,$D10:$BM10,,0,1) -> 343769.54 | BS10: =_xlfn.XLOOKUP(BS$6,$D$6:$BM$6,$D10:$BM10,,0,1) -> 294205.11 | BT10: =_xlfn.XLOOKUP(BT$6,$D$6:$BM$6,$D10:$BM10,,0,1) -> 249639.32
C11: Saldo FdP | D11: =SUM(D8:D10) -> 9588231.8 | E11: =SUM(E8:E10) -> 9626127.9 | F11: =SUM(F8:F10) -> 9666109 | G11: =SUM(G8:G10) -> 9714809.4 | H11: =SUM(H8:H10) -> 9761262.8 | I11: =SUM(I8:I10) -> 9811033.9 | J11: =SUM(J8:J10) -> 9819008.6 | K11: =SUM(K8:K10) -> 9883504.6 | ... BK11: =SUM(BK8:BK10) -> 12638872 | BO11: =SUM(BO8:BO10) -> 11906961 | BP11: =SUM(BP8:BP10) -> 11843810 | BQ11: =SUM(BQ8:BQ10) -> 11849351 | BR11: =SUM(BR8:BR10) -> 10961168 | BS11: =SUM(BS8:BS10) -> 10241613 | BT11: =SUM(BT8:BT10) -> 9666109
D12: =[1]Base_Evolutivo!BE166-D11 -> 0.00070990063 | E12: =[1]Base_Evolutivo!BF166-E11 -> -0.00050620176 | F12: =[1]Base_Evolutivo!BG166-F11 -> -0.00017984025 | G12: =[1]Base_Evolutivo!BH166-G11 -> 0.00057735108 | H12: =[1]Base_Evolutivo!BI166-H11 -> 0.00041825883 | I12: =[1]Base_Evolutivo!BJ166-I11 -> 2.16607e-05 | J12: =[1]Base_Evolutivo!BK166-J11 -> 0.00019318238 | K12: =[1]Base_Evolutivo!BL166-K11 -> -0.00086499751 | ... BK12: =[1]Base_Evolutivo!DL166-BK11 -> -12638872
A14: SALDO_PROM | C14: Vigente | D14: =Renta_Alta!D14+Masivo!D14+Consumo_Inicial!D14 -> 9257226.1 | E14: =Renta_Alta!E14+Masivo!E14+Consumo_Inicial!E14 -> 9300808 | F14: =Renta_Alta!F14+Masivo!F14+Consumo_Inicial!F14 -> 9331212.8 | G14: =Renta_Alta!G14+Masivo!G14+Consumo_Inicial!G14 -> 9371473.2 | H14: =Renta_Alta!H14+Masivo!H14+Consumo_Inicial!H14 -> 9412260.9 | I14: =Renta_Alta!I14+Masivo!I14+Consumo_Inicial!I14 -> 9461220.7 | J14: =Renta_Alta!J14+Masivo!J14+Consumo_Inicial!J14 -> 9506413.6 | K14: =Renta_Alta!K14+Masivo!K14+Consumo_Inicial!K14 -> 9526935.6 | ... BK14: =Renta_Alta!BK14+Masivo!BK14+Consumo_Inicial!BK14 -> 12122645 | BO14: =IFERROR(AVERAGEIFS($D14:$BM14,$D$6:$BM$6,">="&BO$2,$D$6:$BM$6,"<="&BO$6,$D$5:$BM$5,BO$5,$D14:$BM14,"<>0"),0) -> 11375136 | BP14: =IFERROR(AVERAGEIFS($D14:$BM14,$D$6:$BM$6,">="&BP$2,$D$6:$BM$6,"<="&BP$6,$D$5:$BM$5,BP$5,$D14:$BM14,"<>0"),0) -> 11296486 | BQ14: =IFERROR(AVERAGEIFS($D14:$BM14,$D$6:$BM$6,">="&BQ$2,$D$6:$BM$6,"<="&BQ$6,$D$5:$BM$5,BQ$5,$D14:$BM14,"<>0"),0) -> 11336870 | BR14: =IFERROR(AVERAGEIFS($D14:$BM14,$D$6:$BM$6,">="&BR$2,$D$6:$BM$6,"<="&BR$6,$D$5:$BM$5,BR$5,$D14:$BM14,"<>0"),0) -> 10480867 | BS14: =IFERROR(AVERAGEIFS($D14:$BM14,$D$6:$BM$6,">="&BS$2,$D$6:$BM$6,"<="&BS$6,$D$5:$BM$5,BS$5,$D14:$BM14,"<>0"),0) -> 9799459.6 | BT14: =IFERROR(AVERAGEIFS($D14:$BM14,$D$6:$BM$6,">="&BT$2,$D$6:$BM$6,"<="&BT$6,$D$5:$BM$5,BT$5,$D14:$BM14,"<>0"),0) -> 9296415.6 | BW14: =SUMIFS($D14:$BM14,$D$6:$BM$6,">="&BO$2,$D$6:$BM$6,"<="&BO$6,$D$5:$BM$5,BO$5) -> 34125409 | BX14: =SUMIFS($D14:$BM14,$D$6:$BM$6,">="&BP$2,$D$6:$BM$6,"<="&BP$6,$D$5:$BM$5,BP$5) -> 33889459 | BY14: =SUMIFS($D14:$BM14,$D$6:$BM$6,">="&BQ$2,$D$6:$BM$6,"<="&BQ$6,$D$5:$BM$5,BQ$5) -> 22673740 | BZ14: =SUMIFS($D14:$BM14,$D$6:$BM$6,">="&BR$2,$D$6:$BM$6,"<="&BR$6,$D$5:$BM$5,BR$5) -> 31442602 | CA14: =SUMIFS($D14:$BM14,$D$6:$BM$6,">="&BS$2,$D$6:$BM$6,"<="&BS$6,$D$5:$BM$5,BS$5) -> 29398379 | CB14: =SUMIFS($D14:$BM14,$D$6:$BM$6,">="&BT$2,$D$6:$BM$6,"<="&BT$6,$D$5:$BM$5,BT$5) -> 27889247
A15: SALDO_PROM | C15: Refinanciado | D15: =Renta_Alta!D15+Masivo!D15+Consumo_Inicial!D15 -> 33664.688 | E15: =Renta_Alta!E15+Masivo!E15+Consumo_Inicial!E15 -> 33016.354 | F15: =Renta_Alta!F15+Masivo!F15+Consumo_Inicial!F15 -> 33680.968 | G15: =Renta_Alta!G15+Masivo!G15+Consumo_Inicial!G15 -> 35462.042 | H15: =Renta_Alta!H15+Masivo!H15+Consumo_Inicial!H15 -> 32168.942 | I15: =Renta_Alta!I15+Masivo!I15+Consumo_Inicial!I15 -> 31816.475 | J15: =Renta_Alta!J15+Masivo!J15+Consumo_Inicial!J15 -> 31950.15 | K15: =Renta_Alta!K15+Masivo!K15+Consumo_Inicial!K15 -> 31049.962 | ... BK15: =Renta_Alta!BK15+Masivo!BK15+Consumo_Inicial!BK15 -> 25645.238 | BO15: =IFERROR(AVERAGEIFS($D15:$BM15,$D$6:$BM$6,">="&BO$2,$D$6:$BM$6,"<="&BO$6,$D$5:$BM$5,BO$5,$D15:$BM15,"<>0"),0) -> 32543.543 | BP15: =IFERROR(AVERAGEIFS($D15:$BM15,$D$6:$BM$6,">="&BP$2,$D$6:$BM$6,"<="&BP$6,$D$5:$BM$5,BP$5,$D15:$BM15,"<>0"),0) -> 29423.438 | BQ15: =IFERROR(AVERAGEIFS($D15:$BM15,$D$6:$BM$6,">="&BQ$2,$D$6:$BM$6,"<="&BQ$6,$D$5:$BM$5,BQ$5,$D15:$BM15,"<>0"),0) -> 31968.95 | BR15: =IFERROR(AVERAGEIFS($D15:$BM15,$D$6:$BM$6,">="&BR$2,$D$6:$BM$6,"<="&BR$6,$D$5:$BM$5,BR$5,$D15:$BM15,"<>0"),0) -> 29449.772 | BS15: =IFERROR(AVERAGEIFS($D15:$BM15,$D$6:$BM$6,">="&BS$2,$D$6:$BM$6,"<="&BS$6,$D$5:$BM$5,BS$5,$D15:$BM15,"<>0"),0) -> 31300.342 | BT15: =IFERROR(AVERAGEIFS($D15:$BM15,$D$6:$BM$6,">="&BT$2,$D$6:$BM$6,"<="&BT$6,$D$5:$BM$5,BT$5,$D15:$BM15,"<>0"),0) -> 33454.003 | BW15: =SUMIFS($D15:$BM15,$D$6:$BM$6,">="&BO$2,$D$6:$BM$6,"<="&BO$6,$D$5:$BM$5,BO$5) -> 97630.63 | BX15: =SUMIFS($D15:$BM15,$D$6:$BM$6,">="&BP$2,$D$6:$BM$6,"<="&BP$6,$D$5:$BM$5,BP$5) -> 88270.314 | BY15: =SUMIFS($D15:$BM15,$D$6:$BM$6,">="&BQ$2,$D$6:$BM$6,"<="&BQ$6,$D$5:$BM$5,BQ$5) -> 63937.9 | BZ15: =SUMIFS($D15:$BM15,$D$6:$BM$6,">="&BR$2,$D$6:$BM$6,"<="&BR$6,$D$5:$BM$5,BR$5) -> 88349.315 | CA15: =SUMIFS($D15:$BM15,$D$6:$BM$6,">="&BS$2,$D$6:$BM$6,"<="&BS$6,$D$5:$BM$5,BS$5) -> 93901.025 | CB15: =SUMIFS($D15:$BM15,$D$6:$BM$6,">="&BT$2,$D$6:$BM$6,"<="&BT$6,$D$5:$BM$5,BT$5) -> 100362.01
A16: SALDO_PROM | C16: Vencido y Judicial | D16: =Renta_Alta!D16+Masivo!D16+Consumo_Inicial!D16 -> 250475.73 | E16: =Renta_Alta!E16+Masivo!E16+Consumo_Inicial!E16 -> 250988.21 | F16: =Renta_Alta!F16+Masivo!F16+Consumo_Inicial!F16 -> 256054.8 | G16: =Renta_Alta!G16+Masivo!G16+Consumo_Inicial!G16 -> 258747.32 | H16: =Renta_Alta!H16+Masivo!H16+Consumo_Inicial!H16 -> 266957.02 | I16: =Renta_Alta!I16+Masivo!I16+Consumo_Inicial!I16 -> 269070.22 | J16: =Renta_Alta!J16+Masivo!J16+Consumo_Inicial!J16 -> 264874.7 | K16: =Renta_Alta!K16+Masivo!K16+Consumo_Inicial!K16 -> 270189.03 | ... BK16: =Renta_Alta!BK16+Masivo!BK16+Consumo_Inicial!BK16 -> 387844.3 | BO16: =IFERROR(AVERAGEIFS($D16:$BM16,$D$6:$BM$6,">="&BO$2,$D$6:$BM$6,"<="&BO$6,$D$5:$BM$5,BO$5,$D16:$BM16,"<>0"),0) -> 358023.76 | BP16: =IFERROR(AVERAGEIFS($D16:$BM16,$D$6:$BM$6,">="&BP$2,$D$6:$BM$6,"<="&BP$6,$D$5:$BM$5,BP$5,$D16:$BM16,"<>0"),0) -> 369759.67 | BQ16: =IFERROR(AVERAGEIFS($D16:$BM16,$D$6:$BM$6,">="&BQ$2,$D$6:$BM$6,"<="&BQ$6,$D$5:$BM$5,BQ$5,$D16:$BM16,"<>0"),0) -> 360564.81 | BR16: =IFERROR(AVERAGEIFS($D16:$BM16,$D$6:$BM$6,">="&BR$2,$D$6:$BM$6,"<="&BR$6,$D$5:$BM$5,BR$5,$D16:$BM16,"<>0"),0) -> 340976.31 | BS16: =IFERROR(AVERAGEIFS($D16:$BM16,$D$6:$BM$6,">="&BS$2,$D$6:$BM$6,"<="&BS$6,$D$5:$BM$5,BS$5,$D16:$BM16,"<>0"),0) -> 304066.03 | BT16: =IFERROR(AVERAGEIFS($D16:$BM16,$D$6:$BM$6,">="&BT$2,$D$6:$BM$6,"<="&BT$6,$D$5:$BM$5,BT$5,$D16:$BM16,"<>0"),0) -> 252506.24 | BW16: =SUMIFS($D16:$BM16,$D$6:$BM$6,">="&BO$2,$D$6:$BM$6,"<="&BO$6,$D$5:$BM$5,BO$5) -> 1074071.3 | BX16: =SUMIFS($D16:$BM16,$D$6:$BM$6,">="&BP$2,$D$6:$BM$6,"<="&BP$6,$D$5:$BM$5,BP$5) -> 1109279 | BY16: =SUMIFS($D16:$BM16,$D$6:$BM$6,">="&BQ$2,$D$6:$BM$6,"<="&BQ$6,$D$5:$BM$5,BQ$5) -> 721129.62 | BZ16: =SUMIFS($D16:$BM16,$D$6:$BM$6,">="&BR$2,$D$6:$BM$6,"<="&BR$6,$D$5:$BM$5,BR$5) -> 1022928.9 | CA16: =SUMIFS($D16:$BM16,$D$6:$BM$6,">="&BS$2,$D$6:$BM$6,"<="&BS$6,$D$5:$BM$5,BS$5) -> 912198.1 | CB16: =SUMIFS($D16:$BM16,$D$6:$BM$6,">="&BT$2,$D$6:$BM$6,"<="&BT$6,$D$5:$BM$5,BT$5) -> 757518.73
C17: Saldo Prom | D17: =SUM(D14:D16) -> 9541366.5 | E17: =SUM(E14:E16) -> 9584812.6 | F17: =SUM(F14:F16) -> 9620948.6 | G17: =SUM(G14:G16) -> 9665682.6 | H17: =SUM(H14:H16) -> 9711386.8 | I17: =SUM(I14:I16) -> 9762107.4 | J17: =SUM(J14:J16) -> 9803238.4 | K17: =SUM(K14:K16) -> 9828174.6 | ... BK17: =SUM(BK14:BK16) -> 12536134 | BO17: =SUM(BO14:BO16) -> 11765704 | BP17: =SUM(BP14:BP16) -> 11695669 | BQ17: =SUM(BQ14:BQ16) -> 11729404 | BR17: =SUM(BR14:BR16) -> 10851293 | BS17: =SUM(BS14:BS16) -> 10134826 | BT17: =SUM(BT14:BT16) -> 9582375.9 | BW17: =SUM(BW14:BW16) -> 35297111 | BX17: =SUM(BX14:BX16) -> 35087008 | BY17: =SUM(BY14:BY16) -> 23458807 | BZ17: =SUM(BZ14:BZ16) -> 32553880 | CA17: =SUM(CA14:CA16) -> 30404478 | CB17: =SUM(CB14:CB16) -> 28747128
D18: =[1]Base_Evolutivo!BE322-D17 -> -8.578971e-05 | E18: =[1]Base_Evolutivo!BF322-E17 -> 0.00020773336 | F18: =[1]Base_Evolutivo!BG322-F17 -> -0.0005581975 | G18: =[1]Base_Evolutivo!BH322-G17 -> 0.00067692064 | H18: =[1]Base_Evolutivo!BI322-H17 -> 0.0005341582 | I18: =[1]Base_Evolutivo!BJ322-I17 -> 0.0003280025 | J18: =[1]Base_Evolutivo!BK322-J17 -> 0.00024420023 | K18: =[1]Base_Evolutivo!BL322-K17 -> -0.00022026151 | ... BK18: =[1]Base_Evolutivo!DL322-BK17 -> -12536134
C20: Vigente | D20: =IFERROR(((1+D38/D14)^(360/D$3))-1,0) -> 0.070556703 | E20: =IFERROR(((1+E38/E14)^(360/E$3))-1,0) -> 0.070993744 | F20: =IFERROR(((1+F38/F14)^(360/F$3))-1,0) -> 0.071198038 | G20: =IFERROR(((1+G38/G14)^(360/G$3))-1,0) -> 0.071633161 | H20: =IFERROR(((1+H38/H14)^(360/H$3))-1,0) -> 0.071853462 | I20: =IFERROR(((1+I38/I14)^(360/I$3))-1,0) -> 0.07185422 | J20: =IFERROR(((1+J38/J14)^(360/J$3))-1,0) -> 0.072268829 | K20: =IFERROR(((1+K38/K14)^(360/K$3))-1,0) -> 0.072101273 | ... BK20: =IFERROR(((1+BK38/BK14)^(360/BK$3))-1,0) -> 0.074236709 | BO20: =IFERROR(((1+BO38/BW14)^(360/BO$3))-1,0) -> 0.07450647 | BP20: =IFERROR(((1+BP38/BX14)^(360/BP$3))-1,0) -> 0.073578815 | BQ20: =IFERROR(((1+BQ38/BY14)^(360/BQ$3))-1,0) -> 0.07457484 | BR20: =IFERROR(((1+BR38/BZ14)^(360/BR$3))-1,0) -> 0.074039433 | BS20: =IFERROR(((1+BS38/CA14)^(360/BS$3))-1,0) -> 0.073188903 | BT20: =IFERROR(((1+BT38/CB14)^(360/BT$3))-1,0) -> 0.070913737
C21: Refinanciado | D21: =IFERROR(((1+D39/D15)^(360/D$3))-1,0) -> 0 | E21: =IFERROR(((1+E39/E15)^(360/E$3))-1,0) -> 0 | F21: =IFERROR(((1+F39/F15)^(360/F$3))-1,0) -> 0 | G21: =IFERROR(((1+G39/G15)^(360/G$3))-1,0) -> 0 | H21: =IFERROR(((1+H39/H15)^(360/H$3))-1,0) -> 0 | I21: =IFERROR(((1+I39/I15)^(360/I$3))-1,0) -> 0 | J21: =IFERROR(((1+J39/J15)^(360/J$3))-1,0) -> 0 | K21: =IFERROR(((1+K39/K15)^(360/K$3))-1,0) -> 0 | ... BK21: =IFERROR(((1+BK39/BK15)^(360/BK$3))-1,0) -> 0 | BO21: =IFERROR(((1+BO39/BW15)^(360/BO$3))-1,0) -> 0 | BP21: =IFERROR(((1+BP39/BX15)^(360/BP$3))-1,0) -> 0 | BQ21: =IFERROR(((1+BQ39/BY15)^(360/BQ$3))-1,0) -> 0 | BR21: =IFERROR(((1+BR39/BZ15)^(360/BR$3))-1,0) -> 0 | BS21: =IFERROR(((1+BS39/CA15)^(360/BS$3))-1,0) -> 0 | BT21: =IFERROR(((1+BT39/CB15)^(360/BT$3))-1,0) -> 0
C22: Vencido y Judicial | D22: =IFERROR(((1+D40/D16)^(360/D$3))-1,0) -> 0.088464748 | E22: =IFERROR(((1+E40/E16)^(360/E$3))-1,0) -> 0.084267311 | F22: =IFERROR(((1+F40/F16)^(360/F$3))-1,0) -> 0.106308 | G22: =IFERROR(((1+G40/G16)^(360/G$3))-1,0) -> 0.082116297 | H22: =IFERROR(((1+H40/H16)^(360/H$3))-1,0) -> 0.097043008 | I22: =IFERROR(((1+I40/I16)^(360/I$3))-1,0) -> 0.10549496 | J22: =IFERROR(((1+J40/J16)^(360/J$3))-1,0) -> 0.10728553 | K22: =IFERROR(((1+K40/K16)^(360/K$3))-1,0) -> 0.096635794 | ... BK22: =IFERROR(((1+BK40/BK16)^(360/BK$3))-1,0) -> 0.12575293 | BO22: =IFERROR(((1+BO40/BW16)^(360/BO$3))-1,0) -> 0.10159883 | BP22: =IFERROR(((1+BP40/BX16)^(360/BP$3))-1,0) -> 0.11974894 | BQ22: =IFERROR(((1+BQ40/BY16)^(360/BQ$3))-1,0) -> 0.096260819 | BR22: =IFERROR(((1+BR40/BZ16)^(360/BR$3))-1,0) -> 0.10408722 | BS22: =IFERROR(((1+BS40/CA16)^(360/BS$3))-1,0) -> 0.10317897 | BT22: =IFERROR(((1+BT40/CB16)^(360/BT$3))-1,0) -> 0.093382026
C23: Tasa Implicita | D23: =IFERROR(((1+D41/D17)^(360/D$3))-1,0) -> 0.070766508 | E23: =IFERROR(((1+E41/E17)^(360/E$3))-1,0) -> 0.071087002 | F23: =IFERROR(((1+F41/F17)^(360/F$3))-1,0) -> 0.071861786 | G23: =IFERROR(((1+G41/G17)^(360/G$3))-1,0) -> 0.071641316 | H23: =IFERROR(((1+H41/H17)^(360/H$3))-1,0) -> 0.072293022 | I23: =IFERROR(((1+I41/I17)^(360/I$3))-1,0) -> 0.072526862 | J23: =IFERROR(((1+J41/J17)^(360/J$3))-1,0) -> 0.072958204 | K23: =IFERROR(((1+K41/K17)^(360/K$3))-1,0) -> 0.072533782 | ... BK23: =IFERROR(((1+BK41/BK17)^(360/BK$3))-1,0) -> 0.075640583 | BO23: =IFERROR(((1+BO41/BW17)^(360/BO$3))-1,0) -> 0.075108716 | BP23: =IFERROR(((1+BP41/BX17)^(360/BP$3))-1,0) -> 0.074819951 | BQ23: =IFERROR(((1+BQ41/BY17)^(360/BQ$3))-1,0) -> 0.075025428 | BR23: =IFERROR(((1+BR41/BZ17)^(360/BR$3))-1,0) -> 0.074764361 | BS23: =IFERROR(((1+BS41/CA17)^(360/BS$3))-1,0) -> 0.073844122 | BT23: =IFERROR(((1+BT41/CB17)^(360/BT$3))-1,0) -> 0.071244808
D24: =+'[1]Desempeño_Financiero (Evol)-Seg'!BE442-D23 -> 4.5565773e-12 | E24: =+'[1]Desempeño_Financiero (Evol)-Seg'!BF442-E23 -> -1.9890756e-12 | F24: =+'[1]Desempeño_Financiero (Evol)-Seg'!BG442-F23 -> 6.7339467e-12 | G24: =+'[1]Desempeño_Financiero (Evol)-Seg'!BH442-G23 -> 2.3074875e-12 | H24: =+'[1]Desempeño_Financiero (Evol)-Seg'!BI442-H23 -> 3.6333159e-12 | I24: =+'[1]Desempeño_Financiero (Evol)-Seg'!BJ442-I23 -> -1.0120571e-11 | J24: =+'[1]Desempeño_Financiero (Evol)-Seg'!BK442-J23 -> -9.861445e-12 | K24: =+'[1]Desempeño_Financiero (Evol)-Seg'!BL442-K23 -> 1.0227375e-12 | ... AS24: =+'[1]Desempeño_Financiero (Evol)-Seg'!CT442-AS23 -> 0
C26: Vigente | D26: =-IFERROR(((1-D44/D14)^(360/D$4))-1,0) -> -0.049635424 | E26: =-IFERROR(((1-E44/E14)^(360/E$4))-1,0) -> -0.049978926 | F26: =-IFERROR(((1-F44/F14)^(360/F$4))-1,0) -> -0.050379357 | G26: =-IFERROR(((1-G44/G14)^(360/G$4))-1,0) -> -0.050860042 | H26: =-IFERROR(((1-H44/H14)^(360/H$4))-1,0) -> -0.051126729 | I26: =-IFERROR(((1-I44/I14)^(360/I$4))-1,0) -> -0.051459916 | J26: =-IFERROR(((1-J44/J14)^(360/J$4))-1,0) -> -0.051756526 | K26: =-IFERROR(((1-K44/K14)^(360/K$4))-1,0) -> -0.051952891 | ... BK26: =-IFERROR(((1-BK44/BK14)^(360/BK$4))-1,0) -> -0.056630361 | BO26: =-IFERROR(((1-BO44/BW14)^(360/BO$4))-1,0) -> -0.056239683 | BP26: =-IFERROR(((1-BP44/BX14)^(360/BP$4))-1,0) -> -0.056482252 | BQ26: =-IFERROR(((1-BQ44/BY14)^(360/BQ$4))-1,0) -> -0.05624434 | BR26: =-IFERROR(((1-BR44/BZ14)^(360/BR$4))-1,0) -> -0.05550907 | BS26: =-IFERROR(((1-BS44/CA14)^(360/BS$4))-1,0) -> -0.053367564 | BT26: =-IFERROR(((1-BT44/CB14)^(360/BT$4))-1,0) -> -0.049998844
C27: Refinanciado | D27: =-IFERROR(((1-D45/D15)^(360/D$4))-1,0) -> -0.049774856 | E27: =-IFERROR(((1-E45/E15)^(360/E$4))-1,0) -> -0.04915199 | F27: =-IFERROR(((1-F45/F15)^(360/F$4))-1,0) -> -0.049487574 | G27: =-IFERROR(((1-G45/G15)^(360/G$4))-1,0) -> -0.049914999 | H27: =-IFERROR(((1-H45/H15)^(360/H$4))-1,0) -> -0.050471537 | I27: =-IFERROR(((1-I45/I15)^(360/I$4))-1,0) -> -0.050609898 | J27: =-IFERROR(((1-J45/J15)^(360/J$4))-1,0) -> -0.050602731 | K27: =-IFERROR(((1-K45/K15)^(360/K$4))-1,0) -> -0.050042799 | ... BK27: =-IFERROR(((1-BK45/BK15)^(360/BK$4))-1,0) -> -0.072265954 | BO27: =-IFERROR(((1-BO45/BW15)^(360/BO$4))-1,0) -> -0.054758314 | BP27: =-IFERROR(((1-BP45/BX15)^(360/BP$4))-1,0) -> -0.057133437 | BQ27: =-IFERROR(((1-BQ45/BY15)^(360/BQ$4))-1,0) -> -0.054570349 | BR27: =-IFERROR(((1-BR45/BZ15)^(360/BR$4))-1,0) -> -0.052077723 | BS27: =-IFERROR(((1-BS45/CA15)^(360/BS$4))-1,0) -> -0.04998486 | BT27: =-IFERROR(((1-BT45/CB15)^(360/BT$4))-1,0) -> -0.049473512
C28: Vencido y Judicial | D28: =-IFERROR(((1-D46/D16)^(360/D$4))-1,0) -> -0.051621537 | E28: =-IFERROR(((1-E46/E16)^(360/E$4))-1,0) -> -0.051707903 | F28: =-IFERROR(((1-F46/F16)^(360/F$4))-1,0) -> -0.051812921 | G28: =-IFERROR(((1-G46/G16)^(360/G$4))-1,0) -> -0.051979734 | H28: =-IFERROR(((1-H46/H16)^(360/H$4))-1,0) -> -0.051971154 | I28: =-IFERROR(((1-I46/I16)^(360/I$4))-1,0) -> -0.051615817 | J28: =-IFERROR(((1-J46/J16)^(360/J$4))-1,0) -> -0.051380332 | K28: =-IFERROR(((1-K46/K16)^(360/K$4))-1,0) -> -0.051678709 | ... BK28: =-IFERROR(((1-BK46/BK16)^(360/BK$4))-1,0) -> -0.058254451 | BO28: =-IFERROR(((1-BO46/BW16)^(360/BO$4))-1,0) -> -0.054860101 | BP28: =-IFERROR(((1-BP46/BX16)^(360/BP$4))-1,0) -> -0.055983092 | BQ28: =-IFERROR(((1-BQ46/BY16)^(360/BQ$4))-1,0) -> -0.054855937 | BR28: =-IFERROR(((1-BR46/BZ16)^(360/BR$4))-1,0) -> -0.053122545 | BS28: =-IFERROR(((1-BS46/CA16)^(360/BS$4))-1,0) -> -0.052963824 | BT28: =-IFERROR(((1-BT46/CB16)^(360/BT$4))-1,0) -> -0.051714841
C29: Tasa FTP | D29: =-IFERROR(((1-D47/D17)^(360/D$4))-1,0) -> -0.04968801 | E29: =-IFERROR(((1-E47/E17)^(360/E$4))-1,0) -> -0.050021318 | F29: =-IFERROR(((1-F47/F17)^(360/F$4))-1,0) -> -0.050414363 | G29: =-IFERROR(((1-G47/G17)^(360/G$4))-1,0) -> -0.050886533 | H29: =-IFERROR(((1-H47/H17)^(360/H$4))-1,0) -> -0.051147762 | I29: =-IFERROR(((1-I47/I17)^(360/I$4))-1,0) -> -0.051461441 | J29: =-IFERROR(((1-J47/J17)^(360/J$4))-1,0) -> -0.051742597 | K29: =-IFERROR(((1-K47/K17)^(360/K$4))-1,0) -> -0.051939313 | ... BK29: =-IFERROR(((1-BK47/BK17)^(360/BK$4))-1,0) -> -0.056712346 | BO29: =-IFERROR(((1-BO47/BW17)^(360/BO$4))-1,0) -> -0.056193579 | BP29: =-IFERROR(((1-BP47/BX17)^(360/BP$4))-1,0) -> -0.056468105 | BQ29: =-IFERROR(((1-BQ47/BY17)^(360/BQ$4))-1,0) -> -0.05619707 | BR29: =-IFERROR(((1-BR47/BZ17)^(360/BR$4))-1,0) -> -0.055424678 | BS29: =-IFERROR(((1-BS47/CA17)^(360/BS$4))-1,0) -> -0.053344987 | BT29: =-IFERROR(((1-BT47/CB17)^(360/BT$4))-1,0) -> -0.050042195
D30: =+'[1]Desempeño_Financiero (Evol)-Seg'!BE586-D29 -> -9.1038288e-15 | E30: =+'[1]Desempeño_Financiero (Evol)-Seg'!BF586-E29 -> 6.7723605e-13 | F30: =+'[1]Desempeño_Financiero (Evol)-Seg'!BG586-F29 -> -3.5127456e-12 | G30: =+'[1]Desempeño_Financiero (Evol)-Seg'!BH586-G29 -> 3.5171865e-12 | H30: =+'[1]Desempeño_Financiero (Evol)-Seg'!BI586-H29 -> 3.4230396e-12 | I30: =+'[1]Desempeño_Financiero (Evol)-Seg'!BJ586-I29 -> 1.7679191e-12 | J30: =+'[1]Desempeño_Financiero (Evol)-Seg'!BK586-J29 -> 9.8809849e-13 | K30: =+'[1]Desempeño_Financiero (Evol)-Seg'!BL586-K29 -> -1.2911894e-12 | ... AS30: =+'[1]Desempeño_Financiero (Evol)-Seg'!CT586-AS29 -> 0
C32: Vigente | D32: =D20+D26 -> 0.020921279 | E32: =E20+E26 -> 0.021014818 | F32: =F20+F26 -> 0.020818681 | G32: =G20+G26 -> 0.020773119 | H32: =H20+H26 -> 0.020726733 | I32: =I20+I26 -> 0.020394305 | J32: =J20+J26 -> 0.020512303 | K32: =K20+K26 -> 0.020148382 | ... BK32: =BK20+BK26 -> 0.017606348 | BO32: =BO20+BO26 -> 0.018266787 | BP32: =BP20+BP26 -> 0.017096563 | BQ32: =BQ20+BQ26 -> 0.018330499 | BR32: =BR20+BR26 -> 0.018530363 | BS32: =BS20+BS26 -> 0.019821339 | BT32: =BT20+BT26 -> 0.020914892
C33: Refinanciado | D33: =D21+D27 -> -0.049774856 | E33: =E21+E27 -> -0.04915199 | F33: =F21+F27 -> -0.049487574 | G33: =G21+G27 -> -0.049914999 | H33: =H21+H27 -> -0.050471537 | I33: =I21+I27 -> -0.050609898 | J33: =J21+J27 -> -0.050602731 | K33: =K21+K27 -> -0.050042799 | ... BK33: =BK21+BK27 -> -0.072265954 | BO33: =BO21+BO27 -> -0.054758314 | BP33: =BP21+BP27 -> -0.057133437 | BQ33: =BQ21+BQ27 -> -0.054570349 | BR33: =BR21+BR27 -> -0.052077723 | BS33: =BS21+BS27 -> -0.04998486 | BT33: =BT21+BT27 -> -0.049473512
C34: Vencido y Judicial | D34: =D22+D28 -> 0.036843211 | E34: =E22+E28 -> 0.032559408 | F34: =F22+F28 -> 0.054495077 | G34: =G22+G28 -> 0.030136563 | H34: =H22+H28 -> 0.045071853 | I34: =I22+I28 -> 0.053879145 | J34: =J22+J28 -> 0.0559052 | K34: =K22+K28 -> 0.044957086 | ... BK34: =BK22+BK28 -> 0.067498479 | BO34: =BO22+BO28 -> 0.046738726 | BP34: =BP22+BP28 -> 0.063765852 | BQ34: =BQ22+BQ28 -> 0.041404881 | BR34: =BR22+BR28 -> 0.050964675 | BS34: =BS22+BS28 -> 0.050215145 | BT34: =BT22+BT28 -> 0.041667186
C35: Spread | D35: =D23+D29 -> 0.021078497 | E35: =E23+E29 -> 0.021065683 | F35: =F23+F29 -> 0.021447423 | G35: =G23+G29 -> 0.020754783 | H35: =H23+H29 -> 0.02114526 | I35: =I23+I29 -> 0.021065421 | J35: =J23+J29 -> 0.021215607 | K35: =K23+K29 -> 0.020594469 | ... BK35: =BK23+BK29 -> 0.018928238 | BO35: =BO23+BO29 -> 0.018915137 | BP35: =BP23+BP29 -> 0.018351846 | BQ35: =BQ23+BQ29 -> 0.018828358 | BR35: =BR23+BR29 -> 0.019339683 | BS35: =BS23+BS29 -> 0.020499136 | BT35: =BT23+BT29 -> 0.021202613
A38: Ingreso_Financiero | C38: Vigente | D38: =Renta_Alta!D38+Masivo!D38+Consumo_Inicial!D38 -> 54508.581 | E38: =Renta_Alta!E38+Masivo!E38+Consumo_Inicial!E38 -> 49748.111 | F38: =Renta_Alta!F38+Masivo!F38+Consumo_Inicial!F38 -> 55428.296 | G38: =Renta_Alta!G38+Masivo!G38+Consumo_Inicial!G38 -> 54185.562 | H38: =Renta_Alta!H38+Masivo!H38+Consumo_Inicial!H38 -> 56408.449 | I38: =Renta_Alta!I38+Masivo!I38+Consumo_Inicial!I38 -> 54868.044 | J38: =Renta_Alta!J38+Masivo!J38+Consumo_Inicial!J38 -> 57291.787 | K38: =Renta_Alta!K38+Masivo!K38+Consumo_Inicial!K38 -> 57286.49 | ... BK38: =Renta_Alta!BK38+Masivo!BK38+Consumo_Inicial!BK38 -> 74984.622 | BO38: =SUMIFS($D38:$BM38,$D$6:$BM$6,">="&BO$2,$D$6:$BM$6,"<="&BO$6,$D$5:$BM$5,BO$5) -> 204971.59 | BP38: =SUMIFS($D38:$BM38,$D$6:$BM$6,">="&BP$2,$D$6:$BM$6,"<="&BP$6,$D$5:$BM$5,BP$5) -> 201100.61 | BQ38: =SUMIFS($D38:$BM38,$D$6:$BM$6,">="&BQ$2,$D$6:$BM$6,"<="&BQ$6,$D$5:$BM$5,BQ$5) -> 134030.46 | BR38: =SUMIFS($D38:$BM38,$D$6:$BM$6,">="&BR$2,$D$6:$BM$6,"<="&BR$6,$D$5:$BM$5,BR$5) -> 187711.57 | BS38: =SUMIFS($D38:$BM38,$D$6:$BM$6,">="&BS$2,$D$6:$BM$6,"<="&BS$6,$D$5:$BM$5,BS$5) -> 175489.41 | BT38: =SUMIFS($D38:$BM38,$D$6:$BM$6,">="&BT$2,$D$6:$BM$6,"<="&BT$6,$D$5:$BM$5,BT$5) -> 159684.99
A39: Ingreso_Financiero | C39: Refinanciado | D39: =Renta_Alta!D39+Masivo!D39+Consumo_Inicial!D39 -> 0 | E39: =Renta_Alta!E39+Masivo!E39+Consumo_Inicial!E39 -> 0 | F39: =Renta_Alta!F39+Masivo!F39+Consumo_Inicial!F39 -> 0 | G39: =Renta_Alta!G39+Masivo!G39+Consumo_Inicial!G39 -> 0 | H39: =Renta_Alta!H39+Masivo!H39+Consumo_Inicial!H39 -> 0 | I39: =Renta_Alta!I39+Masivo!I39+Consumo_Inicial!I39 -> 0 | J39: =Renta_Alta!J39+Masivo!J39+Consumo_Inicial!J39 -> 0 | K39: =Renta_Alta!K39+Masivo!K39+Consumo_Inicial!K39 -> 0 | ... BK39: =Renta_Alta!BK39+Masivo!BK39+Consumo_Inicial!BK39 -> 0 | BO39: =SUMIFS($D39:$BM39,$D$6:$BM$6,">="&BO$2,$D$6:$BM$6,"<="&BO$6,$D$5:$BM$5,BO$5) -> 0 | BP39: =SUMIFS($D39:$BM39,$D$6:$BM$6,">="&BP$2,$D$6:$BM$6,"<="&BP$6,$D$5:$BM$5,BP$5) -> 0 | BQ39: =SUMIFS($D39:$BM39,$D$6:$BM$6,">="&BQ$2,$D$6:$BM$6,"<="&BQ$6,$D$5:$BM$5,BQ$5) -> 0 | BR39: =SUMIFS($D39:$BM39,$D$6:$BM$6,">="&BR$2,$D$6:$BM$6,"<="&BR$6,$D$5:$BM$5,BR$5) -> 0 | BS39: =SUMIFS($D39:$BM39,$D$6:$BM$6,">="&BS$2,$D$6:$BM$6,"<="&BS$6,$D$5:$BM$5,BS$5) -> 0 | BT39: =SUMIFS($D39:$BM39,$D$6:$BM$6,">="&BT$2,$D$6:$BM$6,"<="&BT$6,$D$5:$BM$5,BT$5) -> 0
A40: Ingreso_Financiero | C40: Vencido y Judicial | D40: =Renta_Alta!D40+Masivo!D40+Consumo_Inicial!D40 -> 1835.0331 | E40: =Renta_Alta!E40+Masivo!E40+Consumo_Inicial!E40 -> 1584.3404 | F40: =Renta_Alta!F40+Masivo!F40+Consumo_Inicial!F40 -> 2237.3082 | G40: =Renta_Alta!G40+Masivo!G40+Consumo_Inicial!G40 -> 1707.2738 | H40: =Renta_Alta!H40+Masivo!H40+Consumo_Inicial!H40 -> 2137.6212 | I40: =Renta_Alta!I40+Masivo!I40+Consumo_Inicial!I40 -> 2258.2491 | J40: =Renta_Alta!J40+Masivo!J40+Consumo_Inicial!J40 -> 2334.6948 | K40: =Renta_Alta!K40+Masivo!K40+Consumo_Inicial!K40 -> 2154.7942 | ... BK40: =Renta_Alta!BK40+Masivo!BK40+Consumo_Inicial!BK40 -> 3976.2722 | BO40: =SUMIFS($D40:$BM40,$D$6:$BM$6,">="&BO$2,$D$6:$BM$6,"<="&BO$6,$D$5:$BM$5,BO$5) -> 8695.8404 | BP40: =SUMIFS($D40:$BM40,$D$6:$BM$6,">="&BP$2,$D$6:$BM$6,"<="&BP$6,$D$5:$BM$5,BP$5) -> 10504.799 | BQ40: =SUMIFS($D40:$BM40,$D$6:$BM$6,">="&BQ$2,$D$6:$BM$6,"<="&BQ$6,$D$5:$BM$5,BQ$5) -> 5451.412 | BR40: =SUMIFS($D40:$BM40,$D$6:$BM$6,">="&BR$2,$D$6:$BM$6,"<="&BR$6,$D$5:$BM$5,BR$5) -> 8475.6998 | BS40: =SUMIFS($D40:$BM40,$D$6:$BM$6,">="&BS$2,$D$6:$BM$6,"<="&BS$6,$D$5:$BM$5,BS$5) -> 7578.7647 | BT40: =SUMIFS($D40:$BM40,$D$6:$BM$6,">="&BT$2,$D$6:$BM$6,"<="&BT$6,$D$5:$BM$5,BT$5) -> 5656.6817
C41: Ingreso Financiero | D41: =SUM(D38:D40) -> 56343.614 | E41: =SUM(E38:E40) -> 51332.452 | F41: =SUM(F38:F40) -> 57665.604 | G41: =SUM(G38:G40) -> 55892.836 | H41: =SUM(H38:H40) -> 58546.07 | I41: =SUM(I38:I40) -> 57126.294 | J41: =SUM(J38:J40) -> 59626.482 | K41: =SUM(K38:K40) -> 59441.284 | ... BK41: =SUM(BK38:BK40) -> 78960.894 | BO41: =SUM(BO38:BO40) -> 213667.43 | BP41: =SUM(BP38:BP40) -> 211605.41 | BQ41: =SUM(BQ38:BQ40) -> 139481.88 | BR41: =SUM(BR38:BR40) -> 196187.27 | BS41: =SUM(BS38:BS40) -> 183068.17 | BT41: =SUM(BT38:BT40) -> 165341.67
A44: FTP | C44: Vigente | D44: =Renta_Alta!D44+Masivo!D44+Consumo_Inicial!D44 -> -37446.097 | E44: =Renta_Alta!E44+Masivo!E44+Consumo_Inicial!E44 -> -37877.024 | F44: =Renta_Alta!F44+Masivo!F44+Consumo_Inicial!F44 -> -38298.555 | G44: =Renta_Alta!G44+Masivo!G44+Consumo_Inicial!G44 -> -38822.579 | H44: =Renta_Alta!H44+Masivo!H44+Consumo_Inicial!H44 -> -39191.402 | I44: =Renta_Alta!I44+Masivo!I44+Consumo_Inicial!I44 -> -39646.187 | J44: =Renta_Alta!J44+Masivo!J44+Consumo_Inicial!J44 -> -40059.944 | K44: =Renta_Alta!K44+Masivo!K44+Consumo_Inicial!K44 -> -40295.261 | ... BK44: =Renta_Alta!BK44+Masivo!BK44+Consumo_Inicial!BK44 -> -55775.848 | BO44: =SUMIFS($D44:$BM44,$D$6:$BM$6,">="&BO$2,$D$6:$BM$6,"<="&BO$6,$D$5:$BM$5,BO$5) -> -155953.3 | BP44: =SUMIFS($D44:$BM44,$D$6:$BM$6,">="&BP$2,$D$6:$BM$6,"<="&BP$6,$D$5:$BM$5,BP$5) -> -155526.46 | BQ44: =SUMIFS($D44:$BM44,$D$6:$BM$6,">="&BQ$2,$D$6:$BM$6,"<="&BQ$6,$D$5:$BM$5,BQ$5) -> -103627.48 | BR44: =SUMIFS($D44:$BM44,$D$6:$BM$6,">="&BR$2,$D$6:$BM$6,"<="&BR$6,$D$5:$BM$5,BR$5) -> -141871.56 | BS44: =SUMIFS($D44:$BM44,$D$6:$BM$6,">="&BS$2,$D$6:$BM$6,"<="&BS$6,$D$5:$BM$5,BS$5) -> -127650.29 | BT44: =SUMIFS($D44:$BM44,$D$6:$BM$6,">="&BT$2,$D$6:$BM$6,"<="&BT$6,$D$5:$BM$5,BT$5) -> -113621.68
A45: FTP | C45: Refinanciado | D45: =Renta_Alta!D45+Masivo!D45+Consumo_Inicial!D45 -> -136.55005 | E45: =Renta_Alta!E45+Masivo!E45+Consumo_Inicial!E45 -> -132.28075 | F45: =Renta_Alta!F45+Masivo!F45+Consumo_Inicial!F45 -> -135.84478 | G45: =Renta_Alta!G45+Masivo!G45+Consumo_Inicial!G45 -> -144.23654 | H45: =Renta_Alta!H45+Masivo!H45+Consumo_Inicial!H45 -> -132.26878 | I45: =Renta_Alta!I45+Masivo!I45+Consumo_Inicial!I45 -> -131.17019 | J45: =Renta_Alta!J45+Masivo!J45+Consumo_Inicial!J45 -> -131.70305 | K45: =Renta_Alta!K45+Masivo!K45+Consumo_Inicial!K45 -> -126.60729 | ... BK45: =Renta_Alta!BK45+Masivo!BK45+Consumo_Inicial!BK45 -> -149.54885 | BO45: =SUMIFS($D45:$BM45,$D$6:$BM$6,">="&BO$2,$D$6:$BM$6,"<="&BO$6,$D$5:$BM$5,BO$5) -> -434.70243 | BP45: =SUMIFS($D45:$BM45,$D$6:$BM$6,">="&BP$2,$D$6:$BM$6,"<="&BP$6,$D$5:$BM$5,BP$5) -> -409.64609 | BQ45: =SUMIFS($D45:$BM45,$D$6:$BM$6,">="&BQ$2,$D$6:$BM$6,"<="&BQ$6,$D$5:$BM$5,BQ$5) -> -283.73102 | BR45: =SUMIFS($D45:$BM45,$D$6:$BM$6,">="&BR$2,$D$6:$BM$6,"<="&BR$6,$D$5:$BM$5,BR$5) -> -374.56083 | BS45: =SUMIFS($D45:$BM45,$D$6:$BM$6,">="&BS$2,$D$6:$BM$6,"<="&BS$6,$D$5:$BM$5,BS$5) -> -382.45111 | BT45: =SUMIFS($D45:$BM45,$D$6:$BM$6,">="&BT$2,$D$6:$BM$6,"<="&BT$6,$D$5:$BM$5,BT$5) -> -404.67559
A46: FTP | C46: Vencido y Judicial | D46: =Renta_Alta!D46+Masivo!D46+Consumo_Inicial!D46 -> -1052.8121 | E46: =Renta_Alta!E46+Masivo!E46+Consumo_Inicial!E46 -> -1056.6911 | F46: =Renta_Alta!F46+Masivo!F46+Consumo_Inicial!F46 -> -1080.1616 | G46: =Renta_Alta!G46+Masivo!G46+Consumo_Inicial!G46 -> -1094.9538 | H46: =Renta_Alta!H46+Masivo!H46+Consumo_Inicial!H46 -> -1129.513 | I46: =Renta_Alta!I46+Masivo!I46+Consumo_Inicial!I46 -> -1130.847 | J46: =Renta_Alta!J46+Masivo!J46+Consumo_Inicial!J46 -> -1108.2501 | K46: =Renta_Alta!K46+Masivo!K46+Consumo_Inicial!K46 -> -1136.9013 | ... BK46: =Renta_Alta!BK46+Masivo!BK46+Consumo_Inicial!BK46 -> -1834.3289 | BO46: =SUMIFS($D46:$BM46,$D$6:$BM$6,">="&BO$2,$D$6:$BM$6,"<="&BO$6,$D$5:$BM$5,BO$5) -> -4791.0005 | BP46: =SUMIFS($D46:$BM46,$D$6:$BM$6,">="&BP$2,$D$6:$BM$6,"<="&BP$6,$D$5:$BM$5,BP$5) -> -5046.8493 | BQ46: =SUMIFS($D46:$BM46,$D$6:$BM$6,">="&BQ$2,$D$6:$BM$6,"<="&BQ$6,$D$5:$BM$5,BQ$5) -> -3216.4313 | BR46: =SUMIFS($D46:$BM46,$D$6:$BM$6,">="&BR$2,$D$6:$BM$6,"<="&BR$6,$D$5:$BM$5,BR$5) -> -4421.7289 | BS46: =SUMIFS($D46:$BM46,$D$6:$BM$6,">="&BS$2,$D$6:$BM$6,"<="&BS$6,$D$5:$BM$5,BS$5) -> -3931.5749 | BT46: =SUMIFS($D46:$BM46,$D$6:$BM$6,">="&BT$2,$D$6:$BM$6,"<="&BT$6,$D$5:$BM$5,BT$5) -> -3189.6649
C47: Costo de Fondos | D47: =SUM(D44:D46) -> -38635.459 | E47: =SUM(E44:E46) -> -39065.996 | F47: =SUM(F44:F46) -> -39514.561 | G47: =SUM(G44:G46) -> -40061.769 | H47: =SUM(H44:H46) -> -40453.184 | I47: =SUM(I44:I46) -> -40908.204 | J47: =SUM(J44:J46) -> -41299.898 | K47: =SUM(K44:K46) -> -41558.77 | ... BK47: =SUM(BK44:BK46) -> -57759.726 | BO47: =SUM(BO44:BO46) -> -161179 | BP47: =SUM(BP44:BP46) -> -160982.96 | BQ47: =SUM(BQ44:BQ46) -> -107127.64 | BR47: =SUM(BR44:BR46) -> -146667.85 | BS47: =SUM(BS44:BS46) -> -131964.31 | BT47: =SUM(BT44:BT46) -> -117216.02
C50: Vigente | D50: =D38+D44 -> 17062.484 | E50: =E38+E44 -> 11871.088 | F50: =F38+F44 -> 17129.741 | G50: =G38+G44 -> 15362.983 | H50: =H38+H44 -> 17217.047 | I50: =I38+I44 -> 15221.858 | J50: =J38+J44 -> 17231.843 | K50: =K38+K44 -> 16991.229 | ... BK50: =BK38+BK44 -> 19208.774 | BO50: =BO38+BO44 -> 49018.297 | BP50: =BP38+BP44 -> 45574.143 | BQ50: =BQ38+BQ44 -> 30402.988 | BR50: =BR38+BR44 -> 45840.01 | BS50: =BS38+BS44 -> 47839.119 | BT50: =BT38+BT44 -> 46063.313
C51: Refinanciado | D51: =D39+D45 -> -136.55005 | E51: =E39+E45 -> -132.28075 | F51: =F39+F45 -> -135.84478 | G51: =G39+G45 -> -144.23654 | H51: =H39+H45 -> -132.26878 | I51: =I39+I45 -> -131.17019 | J51: =J39+J45 -> -131.70305 | K51: =K39+K45 -> -126.60729 | ... BK51: =BK39+BK45 -> -149.54885 | BO51: =BO39+BO45 -> -434.70243 | BP51: =BP39+BP45 -> -409.64609 | BQ51: =BQ39+BQ45 -> -283.73102 | BR51: =BR39+BR45 -> -374.56083 | BS51: =BS39+BS45 -> -382.45111 | BT51: =BT39+BT45 -> -404.67559
...

Sheet Desempeño_Financiero
B1: 46112 | D1: Mensual | W1: Acumulado
B2: Desempeño Financiero
B3: En S/. Miles | C3: N° dias T.Imp | D3: =DAY(D6) -> 31 | E3: =DAY(E6) -> 31 | F3: =DAY(F6) -> 28 | G3: =DAY(G6) -> 31 | H3: =DAY(H6) -> 31 | I3: =DAY(I6) -> 31
C4: N° dias FTP | D4: =DAY(D6) -> 31 | E4: =DAY(E6) -> 31 | F4: =DAY(F6) -> 28 | G4: =DAY(G6) -> 31 | H4: =DAY(H6) -> 31 | I4: =DAY(I6) -> 31
C5: Tipo | D5: R | E5: P | F5: R | G5: R | H5: R | I5: R | K5: Variación S/. | Q5: Variación % | AD5: Variación S/. | AJ5: Variación %
C6: Total_Producto | D6: =$B$1 -> 46112 | E6: =D6 -> 46112 | F6: =EOMONTH(D6,-1) -> 46081 | G6: =EOMONTH(D6,-12) -> 45747 | H6: =EOMONTH(D6,-24) -> 45382 | I6: =EOMONTH(D6,-36) -> 45016 | K6: =E6 -> 46112 | L6: =F6 -> 46081 | M6: =G6 -> 45747 | N6: =H6 -> 45382 | O6: =I6 -> 45016 | Q6: =K6 -> 46112 | R6: =L6 -> 46081 | S6: =M6 -> 45747 | T6: =N6 -> 45382 | U6: =O6 -> 45016 | W6: =$B$1 -> 46112 | X6: =W6 -> 46112 | Y6: =EOMONTH(W6,-1) -> 46081 | Z6: =EOMONTH(W6,-12) -> 45747 | AA6: =EOMONTH(W6,-24) -> 45382 | AB6: =EOMONTH(W6,-36) -> 45016 | AD6: =X6 -> 46112 | AE6: =Y6 -> 46081 | AF6: =Z6 -> 45747 | AG6: =AA6 -> 45382 | AH6: =AB6 -> 45016 | AJ6: =AD6 -> 46112 | AK6: =AE6 -> 46081 | AL6: =AF6 -> 45747 | AM6: =AG6 -> 45382 | AN6: =AH6 -> 45016
A8: SALDO_FDP | C8: Vigente | D8: {=_xlfn.XLOOKUP(1, (INDIRECT("'"&$C$6&"'!$6:$6")=D$6)* (INDIRECT("'"&$C$6&"'!$5:$5")=D$5), INDIRECT("'"&$C$6&"'!"&ROW()&":"&ROW()) )} -> 11525777 | E8: {=_xlfn.XLOOKUP(1, (INDIRECT("'"&$C$6&"'!$6:$6")=E$6)* (INDIRECT("'"&$C$6&"'!$5:$5")=E$5), INDIRECT("'"&$C$6&"'!"&ROW()&":"&ROW()) )} -> 11438229 | F8: {=_xlfn.XLOOKUP(1, (INDIRECT("'"&$C$6&"'!$6:$6")=F$6)* (INDIRECT("'"&$C$6&"'!$5:$5")=F$5), INDIRECT("'"&$C$6&"'!"&ROW()&":"&ROW()) )} -> 11478076 | G8: {=_xlfn.XLOOKUP(1, (INDIRECT("'"&$C$6&"'!$6:$6")=G$6)* (INDIRECT("'"&$C$6&"'!$5:$5")=G$5), INDIRECT("'"&$C$6&"'!"&ROW()&":"&ROW()) )} -> 10587478 | H8: {=_xlfn.XLOOKUP(1, (INDIRECT("'"&$C$6&"'!$6:$6")=H$6)* (INDIRECT("'"&$C$6&"'!$5:$5")=H$5), INDIRECT("'"&$C$6&"'!"&ROW()&":"&ROW()) )} -> 9915549.8 | I8: {=_xlfn.XLOOKUP(1, (INDIRECT("'"&$C$6&"'!$6:$6")=I$6)* (INDIRECT("'"&$C$6&"'!$5:$5")=I$5), INDIRECT("'"&$C$6&"'!"&ROW()&":"&ROW()) )} -> 9379816.8 | K8: =$D8-E8 -> 87547.535 | L8: =$D8-F8 -> 47700.74 | M8: =$D8-G8 -> 938298.64 | N8: =$D8-H8 -> 1610226.7 | O8: =$D8-I8 -> 2145959.7 | Q8: =IFERROR($D8/E8-1,0) -> 0.0076539415 | R8: =IFERROR($D8/F8-1,0) -> 0.0041558133 | S8: =IFERROR($D8/G8-1,0) -> 0.088623434 | T8: =IFERROR($D8/H8-1,0) -> 0.16239409 | U8: =IFERROR($D8/I8-1,0) -> 0.22878482 | W8: {=INDIRECT("'"&$C$6&"'!"&ADDRESS(ROW(),COLUMN()+44))} -> 11525777 | X8: {=INDIRECT("'"&$C$6&"'!"&ADDRESS(ROW(),COLUMN()+44))} -> 11438229 | Y8: {=INDIRECT("'"&$C$6&"'!"&ADDRESS(ROW(),COLUMN()+44))} -> 11478076 | Z8: {=INDIRECT("'"&$C$6&"'!"&ADDRESS(ROW(),COLUMN()+44))} -> 10587478 | AA8: {=INDIRECT("'"&$C$6&"'!"&ADDRESS(ROW(),COLUMN()+44))} -> 9915549.8 | AB8: {=INDIRECT("'"&$C$6&"'!"&ADDRESS(ROW(),COLUMN()+44))} -> 9379816.8 | AD8: =$W8-X8 -> 87547.535 | AE8: =$W8-Y8 -> 47700.74 | AF8: =$W8-Z8 -> 938298.64 | AG8: =$W8-AA8 -> 1610226.7 | AH8: =$W8-AB8 -> 2145959.7 | AJ8: =IFERROR($W8/X8-1,0) -> 0.0076539415 | AK8: =IFERROR($W8/Y8-1,0) -> 0.0041558133 | AL8: =IFERROR($W8/Z8-1,0) -> 0.088623434 | AM8: =IFERROR($W8/AA8-1,0) -> 0.16239409 | AN8: =IFERROR($W8/AB8-1,0) -> 0.22878482
A9: SALDO_FDP | C9: Refinanciado | D9: {=_xlfn.XLOOKUP(1, (INDIRECT("'"&$C$6&"'!$6:$6")=D$6)* (INDIRECT("'"&$C$6&"'!$5:$5")=D$5), INDIRECT("'"&$C$6&"'!"&ROW()&":"&ROW()) )} -> 34203.92 | E9: {=_xlfn.XLOOKUP(1, (INDIRECT("'"&$C$6&"'!$6:$6")=E$6)* (INDIRECT("'"&$C$6&"'!$5:$5")=E$5), INDIRECT("'"&$C$6&"'!"&ROW()&":"&ROW()) )} -> 29770.187 | F9: {=_xlfn.XLOOKUP(1, (INDIRECT("'"&$C$6&"'!$6:$6")=F$6)* (INDIRECT("'"&$C$6&"'!$5:$5")=F$5), INDIRECT("'"&$C$6&"'!"&ROW()&":"&ROW()) )} -> 32640.44 | G9: {=_xlfn.XLOOKUP(1, (INDIRECT("'"&$C$6&"'!$6:$6")=G$6)* (INDIRECT("'"&$C$6&"'!$5:$5")=G$5), INDIRECT("'"&$C$6&"'!"&ROW()&":"&ROW()) )} -> 29921.003 | H9: {=_xlfn.XLOOKUP(1, (INDIRECT("'"&$C$6&"'!$6:$6")=H$6)* (INDIRECT("'"&$C$6&"'!$5:$5")=H$5), INDIRECT("'"&$C$6&"'!"&ROW()&":"&ROW()) )} -> 31857.707 | I9: {=_xlfn.XLOOKUP(1, (INDIRECT("'"&$C$6&"'!$6:$6")=I$6)* (INDIRECT("'"&$C$6&"'!$5:$5")=I$5), INDIRECT("'"&$C$6&"'!"&ROW()&":"&ROW()) )} -> 36652.88 | K9: =$D9-E9 -> 4433.7333 | L9: =$D9-F9 -> 1563.48 | M9: =$D9-G9 -> 4282.9173 | N9: =$D9-H9 -> 2346.213 | O9: =$D9-I9 -> -2448.9601 | Q9: =IFERROR($D9/E9-1,0) -> 0.148932 | R9: =IFERROR($D9/F9-1,0) -> 0.04790009 | S9: =IFERROR($D9/G9-1,0) -> 0.14314083 | T9: =IFERROR($D9/H9-1,0) -> 0.073646639 | U9: =IFERROR($D9/I9-1,0) -> -0.066814944 | W9: {=INDIRECT("'"&$C$6&"'!"&ADDRESS(ROW(),COLUMN()+44))} -> 34203.92 | X9: {=INDIRECT("'"&$C$6&"'!"&ADDRESS(ROW(),COLUMN()+44))} -> 29770.187 | Y9: {=INDIRECT("'"&$C$6&"'!"&ADDRESS(ROW(),COLUMN()+44))} -> 32640.44 | Z9: {=INDIRECT("'"&$C$6&"'!"&ADDRESS(ROW(),COLUMN()+44))} -> 29921.003 | AA9: {=INDIRECT("'"&$C$6&"'!"&ADDRESS(ROW(),COLUMN()+44))} -> 31857.707 | AB9: {=INDIRECT("'"&$C$6&"'!"&ADDRESS(ROW(),COLUMN()+44))} -> 36652.88 | AD9: =$W9-X9 -> 4433.7333 | AE9: =$W9-Y9 -> 1563.48 | AF9: =$W9-Z9 -> 4282.9173 | AG9: =$W9-AA9 -> 2346.213 | AH9: =$W9-AB9 -> -2448.9601 | AJ9: =IFERROR($W9/X9-1,0) -> 0.148932 | AK9: =IFERROR($W9/Y9-1,0) -> 0.04790009 | AL9: =IFERROR($W9/Z9-1,0) -> 0.14314083 | AM9: =IFERROR($W9/AA9-1,0) -> 0.073646639 | AN9: =IFERROR($W9/AB9-1,0) -> -0.066814944
A10: SALDO_FDP | C10: Vencido y Judicial | D10: {=_xlfn.XLOOKUP(1, (INDIRECT("'"&$C$6&"'!$6:$6")=D$6)* (INDIRECT("'"&$C$6&"'!$5:$5")=D$5), INDIRECT("'"&$C$6&"'!"&ROW()&":"&ROW()) )} -> 346980.86 | E10: {=_xlfn.XLOOKUP(1, (INDIRECT("'"&$C$6&"'!$6:$6")=E$6)* (INDIRECT("'"&$C$6&"'!$5:$5")=E$5), INDIRECT("'"&$C$6&"'!"&ROW()&":"&ROW()) )} -> 375811.31 | F10: {=_xlfn.XLOOKUP(1, (INDIRECT("'"&$C$6&"'!$6:$6")=F$6)* (INDIRECT("'"&$C$6&"'!$5:$5")=F$5), INDIRECT("'"&$C$6&"'!"&ROW()&":"&ROW()) )} -> 338634.42 | G10: {=_xlfn.XLOOKUP(1, (INDIRECT("'"&$C$6&"'!$6:$6")=G$6)* (INDIRECT("'"&$C$6&"'!$5:$5")=G$5), INDIRECT("'"&$C$6&"'!"&ROW()&":"&ROW()) )} -> 343769.54 | H10: {=_xlfn.XLOOKUP(1, (INDIRECT("'"&$C$6&"'!$6:$6")=H$6)* (INDIRECT("'"&$C$6&"'!$5:$5")=H$5), INDIRECT("'"&$C$6&"'!"&ROW()&":"&ROW()) )} -> 294205.11 | I10: {=_xlfn.XLOOKUP(1, (INDIRECT("'"&$C$6&"'!$6:$6")=I$6)* (INDIRECT("'"&$C$6&"'!$5:$5")=I$5), INDIRECT("'"&$C$6&"'!"&ROW()&":"&ROW()) )} -> 249639.32 | K10: =$D10-E10 -> -28830.446 | L10: =$D10-F10 -> 8346.44 | M10: =$D10-G10 -> 3211.3158 | N10: =$D10-H10 -> 52775.75 | O10: =$D10-I10 -> 97341.545 | Q10: =IFERROR($D10/E10-1,0) -> -0.076715218 | R10: =IFERROR($D10/F10-1,0) -> 0.024647347 | S10: =IFERROR($D10/G10-1,0) -> 0.0093414785 | T10: =IFERROR($D10/H10-1,0) -> 0.17938421 | U10: =IFERROR($D10/I10-1,0) -> 0.38992874 | W10: {=INDIRECT("'"&$C$6&"'!"&ADDRESS(ROW(),COLUMN()+44))} -> 346980.86 | X10: {=INDIRECT("'"&$C$6&"'!"&ADDRESS(ROW(),COLUMN()+44))} -> 375811.31 | Y10: {=INDIRECT("'"&$C$6&"'!"&ADDRESS(ROW(),COLUMN()+44))} -> 338634.42 | Z10: {=INDIRECT("'"&$C$6&"'!"&ADDRESS(ROW(),COLUMN()+44))} -> 343769.54 | AA10: {=INDIRECT("'"&$C$6&"'!"&ADDRESS(ROW(),COLUMN()+44))} -> 294205.11 | AB10: {=INDIRECT("'"&$C$6&"'!"&ADDRESS(ROW(),COLUMN()+44))} -> 249639.32 | AD10: =$W10-X10 -> -28830.446 | AE10: =$W10-Y10 -> 8346.44 | AF10: =$W10-Z10 -> 3211.3158 | AG10: =$W10-AA10 -> 52775.75 | AH10: =$W10-AB10 -> 97341.545 | AJ10: =IFERROR($W10/X10-1,0) -> -0.076715218 | AK10: =IFERROR($W10/Y10-1,0) -> 0.024647347 | AL10: =IFERROR($W10/Z10-1,0) -> 0.0093414785 | AM10: =IFERROR($W10/AA10-1,0) -> 0.17938421 | AN10: =IFERROR($W10/AB10-1,0) -> 0.38992874
C11: Saldo FdP | D11: =SUM(D8:D10) -> 11906961 | E11: =SUM(E8:E10) -> 11843810 | F11: =SUM(F8:F10) -> 11849351 | G11: =SUM(G8:G10) -> 10961168 | H11: =SUM(H8:H10) -> 10241613 | I11: =SUM(I8:I10) -> 9666109 | K11: =$D11-E11 -> 63150.823 | L11: =$D11-F11 -> 57610.66 | M11: =$D11-G11 -> 945792.88 | N11: =$D11-H11 -> 1665348.7 | O11: =$D11-I11 -> 2240852.3 | Q11: =IFERROR($D11/E11-1,0) -> 0.0053319683 | R11: =IFERROR($D11/F11-1,0) -> 0.0048619255 | S11: =IFERROR($D11/G11-1,0) -> 0.086285772 | T11: =IFERROR($D11/H11-1,0) -> 0.1626061 | U11: =IFERROR($D11/I11-1,0) -> 0.23182568 | W11: =SUM(W8:W10) -> 11906961 | X11: =SUM(X8:X10) -> 11843810 | Y11: =SUM(Y8:Y10) -> 11849351 | Z11: =SUM(Z8:Z10) -> 10961168 | AA11: =SUM(AA8:AA10) -> 10241613 | AB11: =SUM(AB8:AB10) -> 9666109 | AD11: =$W11-X11 -> 63150.823 | AE11: =$W11-Y11 -> 57610.66 | AF11: =$W11-Z11 -> 945792.88 | AG11: =$W11-AA11 -> 1665348.7 | AH11: =$W11-AB11 -> 2240852.3 | AJ11: =IFERROR($W11/X11-1,0) -> 0.0053319683 | AK11: =IFERROR($W11/Y11-1,0) -> 0.0048619255 | AL11: =IFERROR($W11/Z11-1,0) -> 0.086285772 | AM11: =IFERROR($W11/AA11-1,0) -> 0.1626061 | AN11: =IFERROR($W11/AB11-1,0) -> 0.23182568
A14: SALDO_PROM | C14: Vigente | D14: {=_xlfn.XLOOKUP(1, (INDIRECT("'"&$C$6&"'!$6:$6")=D$6)* (INDIRECT("'"&$C$6&"'!$5:$5")=D$5), INDIRECT("'"&$C$6&"'!"&ROW()&":"&ROW()) )} -> 11451670 | E14: {=_xlfn.XLOOKUP(1, (INDIRECT("'"&$C$6&"'!$6:$6")=E$6)* (INDIRECT("'"&$C$6&"'!$5:$5")=E$5), INDIRECT("'"&$C$6&"'!"&ROW()&":"&ROW()) )} -> 11344716 | F14: {=_xlfn.XLOOKUP(1, (INDIRECT("'"&$C$6&"'!$6:$6")=F$6)* (INDIRECT("'"&$C$6&"'!$5:$5")=F$5), INDIRECT("'"&$C$6&"'!"&ROW()&":"&ROW()) )} -> 11375328 | G14: {=_xlfn.XLOOKUP(1, (INDIRECT("'"&$C$6&"'!$6:$6")=G$6)* (INDIRECT("'"&$C$6&"'!$5:$5")=G$5), INDIRECT("'"&$C$6&"'!"&ROW()&":"&ROW()) )} -> 10528771 | H14: {=_xlfn.XLOOKUP(1, (INDIRECT("'"&$C$6&"'!$6:$6")=H$6)* (INDIRECT("'"&$C$6&"'!$5:$5")=H$5), INDIRECT("'"&$C$6&"'!"&ROW()&":"&ROW()) )} -> 9850997.1 | I14: {=_xlfn.XLOOKUP(1, (INDIRECT("'"&$C$6&"'!$6:$6")=I$6)* (INDIRECT("'"&$C$6&"'!$5:$5")=I$5), INDIRECT("'"&$C$6&"'!"&ROW()&":"&ROW()) )} -> 9331212.8 | K14: =$D14-E14 -> 106953.22 | L14: =$D14-F14 -> 76341.22 | M14: =$D14-G14 -> 922898.23 | N14: =$D14-H14 -> 1600672.4 | O14: =$D14-I14 -> 2120456.8 | Q14: =IFERROR($D14/E14-1,0) -> 0.0094275796 | R14: =IFERROR($D14/F14-1,0) -> 0.0067111223 | S14: =IFERROR($D14/G14-1,0) -> 0.087654883 | T14: =IFERROR($D14/H14-1,0) -> 0.16248837 | U14: =IFERROR($D14/I14-1,0) -> 0.22724343 | W14: {=INDIRECT("'"&$C$6&"'!"&ADDRESS(ROW(),COLUMN()+44))} -> 11375136 | X14: {=INDIRECT("'"&$C$6&"'!"&ADDRESS(ROW(),COLUMN()+44))} -> 11296486 | Y14: {=INDIRECT("'"&$C$6&"'!"&ADDRESS(ROW(),COLUMN()+44))} -> 11336870 | Z14: {=INDIRECT("'"&$C$6&"'!"&ADDRESS(ROW(),COLUMN()+44))} -> 10480867 | AA14: {=INDIRECT("'"&$C$6&"'!"&ADDRESS(ROW(),COLUMN()+44))} -> 9799459.6 | AB14: {=INDIRECT("'"&$C$6&"'!"&ADDRESS(ROW(),COLUMN()+44))} -> 9296415.6 | AD14: =$W14-X14 -> 78650.09 | AE14: =$W14-Y14 -> 38266.585 | AF14: =$W14-Z14 -> 894268.99 | AG14: =$W14-AA14 -> 1575676.8 | AH14: =$W14-AB14 -> 2078720.8 | AJ14: =IFERROR($W14/X14-1,0) -> 0.0069623499 | AK14: =IFERROR($W14/Y14-1,0) -> 0.0033754101 | AL14: =IFERROR($W14/Z14-1,0) -> 0.085323948 | AM14: =IFERROR($W14/AA14-1,0) -> 0.16079222 | AN14: =IFERROR($W14/AB14-1,0) -> 0.22360454
A15: SALDO_PROM | C15: Refinanciado | D15: {=_xlfn.XLOOKUP(1, (INDIRECT("'"&$C$6&"'!$6:$6")=D$6)* (INDIRECT("'"&$C$6&"'!$5:$5")=D$5), INDIRECT("'"&$C$6&"'!"&ROW()&":"&ROW()) )} -> 33692.73 | E15: {=_xlfn.XLOOKUP(1, (INDIRECT("'"&$C$6&"'!$6:$6")=E$6)* (INDIRECT("'"&$C$6&"'!$5:$5")=E$5), INDIRECT("'"&$C$6&"'!"&ROW()&":"&ROW()) )} -> 29533.241 | F15: {=_xlfn.XLOOKUP(1, (INDIRECT("'"&$C$6&"'!$6:$6")=F$6)* (INDIRECT("'"&$C$6&"'!$5:$5")=F$5), INDIRECT("'"&$C$6&"'!"&ROW()&":"&ROW()) )} -> 31737.91 | G15: {=_xlfn.XLOOKUP(1, (INDIRECT("'"&$C$6&"'!$6:$6")=G$6)* (INDIRECT("'"&$C$6&"'!$5:$5")=G$5), INDIRECT("'"&$C$6&"'!"&ROW()&":"&ROW()) )} -> 29133.809 | H15: {=_xlfn.XLOOKUP(1, (INDIRECT("'"&$C$6&"'!$6:$6")=H$6)* (INDIRECT("'"&$C$6&"'!$5:$5")=H$5), INDIRECT("'"&$C$6&"'!"&ROW()&":"&ROW()) )} -> 31397.627 | I15: {=_xlfn.XLOOKUP(1, (INDIRECT("'"&$C$6&"'!$6:$6")=I$6)* (INDIRECT("'"&$C$6&"'!$5:$5")=I$5), INDIRECT("'"&$C$6&"'!"&ROW()&":"&ROW()) )} -> 33680.968 | K15: =$D15-E15 -> 4159.4893 | L15: =$D15-F15 -> 1954.82 | M15: =$D15-G15 -> 4558.9213 | N15: =$D15-H15 -> 2295.1028 | O15: =$D15-I15 -> 11.762297 | Q15: =IFERROR($D15/E15-1,0) -> 0.14084094 | R15: =IFERROR($D15/F15-1,0) -> 0.061592588 | S15: =IFERROR($D15/G15-1,0) -> 0.15648216 | T15: =IFERROR($D15/H15-1,0) -> 0.073097969 | U15: =IFERROR($D15/I15-1,0) -> 0.00034922681 | W15: {=INDIRECT("'"&$C$6&"'!"&ADDRESS(ROW(),COLUMN()+44))} -> 32543.543 | X15: {=INDIRECT("'"&$C$6&"'!"&ADDRESS(ROW(),COLUMN()+44))} -> 29423.438 | Y15: {=INDIRECT("'"&$C$6&"'!"&ADDRESS(ROW(),COLUMN()+44))} -> 31968.95 | Z15: {=INDIRECT("'"&$C$6&"'!"&ADDRESS(ROW(),COLUMN()+44))} -> 29449.772 | AA15: {=INDIRECT("'"&$C$6&"'!"&ADDRESS(ROW(),COLUMN()+44))} -> 31300.342 | AB15: {=INDIRECT("'"&$C$6&"'!"&ADDRESS(ROW(),COLUMN()+44))} -> 33454.003 | AD15: =$W15-X15 -> 3120.1052 | AE15: =$W15-Y15 -> 574.59333 | AF15: =$W15-Z15 -> 3093.7717 | AG15: =$W15-AA15 -> 1243.2017 | AH15: =$W15-AB15 -> -910.45962 | AJ15: =IFERROR($W15/X15-1,0) -> 0.10604149 | AK15: =IFERROR($W15/Y15-1,0) -> 0.017973482 | AL15: =IFERROR($W15/Z15-1,0) -> 0.10505248 | AM15: =IFERROR($W15/AA15-1,0) -> 0.03971847 | AN15: =IFERROR($W15/AB15-1,0) -> -0.027215267
A16: SALDO_PROM | C16: Vencido y Judicial | D16: {=_xlfn.XLOOKUP(1, (INDIRECT("'"&$C$6&"'!$6:$6")=D$6)* (INDIRECT("'"&$C$6&"'!$5:$5")=D$5), INDIRECT("'"&$C$6&"'!"&ROW()&":"&ROW()) )} -> 352941.66 | E16: {=_xlfn.XLOOKUP(1, (INDIRECT("'"&$C$6&"'!$6:$6")=E$6)* (INDIRECT("'"&$C$6&"'!$5:$5")=E$5), INDIRECT("'"&$C$6&"'!"&ROW()&":"&ROW()) )} -> 372710.8 | F16: {=_xlfn.XLOOKUP(1, (INDIRECT("'"&$C$6&"'!$6:$6")=F$6)* (INDIRECT("'"&$C$6&"'!$5:$5")=F$5), INDIRECT("'"&$C$6&"'!"&ROW()&":"&ROW()) )} -> 357954.66 | G16: {=_xlfn.XLOOKUP(1, (INDIRECT("'"&$C$6&"'!$6:$6")=G$6)* (INDIRECT("'"&$C$6&"'!$5:$5")=G$5), INDIRECT("'"&$C$6&"'!"&ROW()&":"&ROW()) )} -> 347248.65 | H16: {=_xlfn.XLOOKUP(1, (INDIRECT("'"&$C$6&"'!$6:$6")=H$6)* (INDIRECT("'"&$C$6&"'!$5:$5")=H$5), INDIRECT("'"&$C$6&"'!"&ROW()&":"&ROW()) )} -> 306654.19 | I16: {=_xlfn.XLOOKUP(1, (INDIRECT("'"&$C$6&"'!$6:$6")=I$6)* (INDIRECT("'"&$C$6&"'!$5:$5")=I$5), INDIRECT("'"&$C$6&"'!"&ROW()&":"&ROW()) )} -> 256054.8 | K16: =$D16-E16 -> -19769.145 | L16: =$D16-F16 -> -5013 | M16: =$D16-G16 -> 5693.0116 | N16: =$D16-H16 -> 46287.468 | O16: =$D16-I16 -> 96886.865 | Q16: =IFERROR($D16/E16-1,0) -> -0.053041512 | R16: =IFERROR($D16/F16-1,0) -> -0.014004567 | S16: =IFERROR($D16/G16-1,0) -> 0.016394626 | T16: =IFERROR($D16/H16-1,0) -> 0.15094354 | U16: =IFERROR($D16/I16-1,0) -> 0.37838332 | W16: {=INDIRECT("'"&$C$6&"'!"&ADDRESS(ROW(),COLUMN()+44))} -> 358023.76 | X16: {=INDIRECT("'"&$C$6&"'!"&ADDRESS(ROW(),COLUMN()+44))} -> 369759.67 | Y16: {=INDIRECT("'"&$C$6&"'!"&ADDRESS(ROW(),COLUMN()+44))} -> 360564.81 | Z16: {=INDIRECT("'"&$C$6&"'!"&ADDRESS(ROW(),COLUMN()+44))} -> 340976.31 | AA16: {=INDIRECT("'"&$C$6&"'!"&ADDRESS(ROW(),COLUMN()+44))} -> 304066.03 | AB16: {=INDIRECT("'"&$C$6&"'!"&ADDRESS(ROW(),COLUMN()+44))} -> 252506.24 | AD16: =$W16-X16 -> -11735.908 | AE16: =$W16-Y16 -> -2541.05 | AF16: =$W16-Z16 -> 17047.449 | AG16: =$W16-AA16 -> 53957.727 | AH16: =$W16-AB16 -> 105517.52 | AJ16: =IFERROR($W16/X16-1,0) -> -0.031739288 | AK16: =IFERROR($W16/Y16-1,0) -> -0.0070474154 | AL16: =IFERROR($W16/Z16-1,0) -> 0.049995992 | AM16: =IFERROR($W16/AA16-1,0) -> 0.17745398 | AN16: =IFERROR($W16/AB16-1,0) -> 0.41788081
C17: Saldo Prom | D17: =SUM(D14:D16) -> 11838304 | E17: =SUM(E14:E16) -> 11746960 | F17: =SUM(F14:F16) -> 11765021 | G17: =SUM(G14:G16) -> 10905154 | H17: =SUM(H14:H16) -> 10189049 | I17: =SUM(I14:I16) -> 9620948.6 | K17: =$D17-E17 -> 91343.561 | L17: =$D17-F17 -> 73283.04 | M17: =$D17-G17 -> 933150.16 | N17: =$D17-H17 -> 1649255 | O17: =$D17-I17 -> 2217355.4 | Q17: =IFERROR($D17/E17-1,0) -> 0.0077759317 | R17: =IFERROR($D17/F17-1,0) -> 0.0062288916 | S17: =IFERROR($D17/G17-1,0) -> 0.085569647 | T17: =IFERROR($D17/H17-1,0) -> 0.16186545 | U17: =IFERROR($D17/I17-1,0) -> 0.2304716 | W17: =SUM(W14:W16) -> 11765704 | X17: =SUM(X14:X16) -> 11695669 | Y17: =SUM(Y14:Y16) -> 11729404 | Z17: =SUM(Z14:Z16) -> 10851293 | AA17: =SUM(AA14:AA16) -> 10134826 | AB17: =SUM(AB14:AB16) -> 9582375.9 | AD17: =$W17-X17 -> 70034.287 | AE17: =$W17-Y17 -> 36300.128 | AF17: =$W17-Z17 -> 914410.21 | AG17: =$W17-AA17 -> 1630877.8 | AH17: =$W17-AB17 -> 2183327.8 | AJ17: =IFERROR($W17/X17-1,0) -> 0.0059880529 | AK17: =IFERROR($W17/Y17-1,0) -> 0.0030947975 | AL17: =IFERROR($W17/Z17-1,0) -> 0.084267393 | AM17: =IFERROR($W17/AA17-1,0) -> 0.16091818 | AN17: =IFERROR($W17/AB17-1,0) -> 0.22784828
C20: Vigente | D20: =IFERROR(((1+D38/D14)^(360/D$3))-1,0) -> 0.074352368 | E20: =IFERROR(((1+E38/E14)^(360/E$3))-1,0) -> 0.073317783 | F20: =IFERROR(((1+F38/F14)^(360/F$3))-1,0) -> 0.074713591 | G20: =IFERROR(((1+G38/G14)^(360/G$3))-1,0) -> 0.073833102 | H20: =IFERROR(((1+H38/H14)^(360/H$3))-1,0) -> 0.073558084 | I20: =IFERROR(((1+I38/I14)^(360/I$3))-1,0) -> 0.071198038 | Q20: =($D20-E20)*10000 -> 10.345857 | R20: =($D20-F20)*10000 -> -3.6122308 | S20: =($D20-G20)*10000 -> 5.1926654 | T20: =($D20-H20)*10000 -> 7.9428443 | U20: =($D20-I20)*10000 -> 31.543308 | W20: {=INDIRECT("'"&$C$6&"'!"&ADDRESS(ROW(),COLUMN()+44))} -> 0.07450647 | X20: {=INDIRECT("'"&$C$6&"'!"&ADDRESS(ROW(),COLUMN()+44))} -> 0.073578815 | Y20: {=INDIRECT("'"&$C$6&"'!"&ADDRESS(ROW(),COLUMN()+44))} -> 0.07457484 | Z20: {=INDIRECT("'"&$C$6&"'!"&ADDRESS(ROW(),COLUMN()+44))} -> 0.074039433 | AA20: {=INDIRECT("'"&$C$6&"'!"&ADDRESS(ROW(),COLUMN()+44))} -> 0.073188903 | AB20: {=INDIRECT("'"&$C$6&"'!"&ADDRESS(ROW(),COLUMN()+44))} -> 0.070913737 | AJ20: =($W20-X20)*10000 -> 9.2765552 | AK20: =($W20-Y20)*10000 -> -0.68369404 | AL20: =($W20-Z20)*10000 -> 4.6703774 | AM20: =($W20-AA20)*10000 -> 13.175669 | AN20: =($W20-AB20)*10000 -> 35.927338
C21: Refinanciado | D21: =IFERROR(((1+D39/D15)^(360/D$3))-1,0) -> 0 | E21: =IFERROR(((1+E39/E15)^(360/E$3))-1,0) -> 0 | F21: =IFERROR(((1+F39/F15)^(360/F$3))-1,0) -> 0 | G21: =IFERROR(((1+G39/G15)^(360/G$3))-1,0) -> 0 | H21: =IFERROR(((1+H39/H15)^(360/H$3))-1,0) -> 0 | I21: =IFERROR(((1+I39/I15)^(360/I$3))-1,0) -> 0 | Q21: =($D21-E21)*10000 -> 0 | R21: =($D21-F21)*10000 -> 0 | S21: =($D21-G21)*10000 -> 0 | T21: =($D21-H21)*10000 -> 0 | U21: =($D21-I21)*10000 -> 0 | W21: {=INDIRECT("'"&$C$6&"'!"&ADDRESS(ROW(),COLUMN()+44))} -> 0 | X21: {=INDIRECT("'"&$C$6&"'!"&ADDRESS(ROW(),COLUMN()+44))} -> 0 | Y21: {=INDIRECT("'"&$C$6&"'!"&ADDRESS(ROW(),COLUMN()+44))} -> 0 | Z21: {=INDIRECT("'"&$C$6&"'!"&ADDRESS(ROW(),COLUMN()+44))} -> 0 | AA21: {=INDIRECT("'"&$C$6&"'!"&ADDRESS(ROW(),COLUMN()+44))} -> 0 | AB21: {=INDIRECT("'"&$C$6&"'!"&ADDRESS(ROW(),COLUMN()+44))} -> 0 | AJ21: =($W21-X21)*10000 -> 0 | AK21: =($W21-Y21)*10000 -> 0 | AL21: =($W21-Z21)*10000 -> 0 | AM21: =($W21-AA21)*10000 -> 0 | AN21: =($W21-AB21)*10000 -> 0
C22: Vencido y Judicial | D22: =IFERROR(((1+D40/D16)^(360/D$3))-1,0) -> 0.11211581 | E22: =IFERROR(((1+E40/E16)^(360/E$3))-1,0) -> 0.11903353 | F22: =IFERROR(((1+F40/F16)^(360/F$3))-1,0) -> 0.098066155 | G22: =IFERROR(((1+G40/G16)^(360/G$3))-1,0) -> 0.11095813 | H22: =IFERROR(((1+H40/H16)^(360/H$3))-1,0) -> 0.10315959 | I22: =IFERROR(((1+I40/I16)^(360/I$3))-1,0) -> 0.106308 | Q22: =($D22-E22)*10000 -> -69.177165 | R22: =($D22-F22)*10000 -> 140.49657 | S22: =($D22-G22)*10000 -> 11.576859 | T22: =($D22-H22)*10000 -> 89.562183 | U22: =($D22-I22)*10000 -> 58.07814 | W22: {=INDIRECT("'"&$C$6&"'!"&ADDRESS(ROW(),COLUMN()+44))} -> 0.10159883 | X22: {=INDIRECT("'"&$C$6&"'!"&ADDRESS(ROW(),COLUMN()+44))} -> 0.11974894 | Y22: {=INDIRECT("'"&$C$6&"'!"&ADDRESS(ROW(),COLUMN()+44))} -> 0.096260819 | Z22: {=INDIRECT("'"&$C$6&"'!"&ADDRESS(ROW(),COLUMN()+44))} -> 0.10408722 | AA22: {=INDIRECT("'"&$C$6&"'!"&ADDRESS(ROW(),COLUMN()+44))} -> 0.10317897 | AB22: {=INDIRECT("'"&$C$6&"'!"&ADDRESS(ROW(),COLUMN()+44))} -> 0.093382026 | AJ22: =($W22-X22)*10000 -> -181.50118 | AK22: =($W22-Y22)*10000 -> 53.380085 | AL22: =($W22-Z22)*10000 -> -24.883933 | AM22: =($W22-AA22)*10000 -> -15.80142 | AN22: =($W22-AB22)*10000 -> 82.168005
C23: Tasa Implicita | D23: =IFERROR(((1+D41/D17)^(360/D$3))-1,0) -> 0.075242263 | E23: =IFERROR(((1+E41/E17)^(360/E$3))-1,0) -> 0.074551078 | F23: =IFERROR(((1+F41/F17)^(360/F$3))-1,0) -> 0.075208869 | G23: =IFERROR(((1+G41/G17)^(360/G$3))-1,0) -> 0.074793645 | H23: =IFERROR(((1+H41/H17)^(360/H$3))-1,0) -> 0.074204037 | I23: =IFERROR(((1+I41/I17)^(360/I$3))-1,0) -> 0.071861786 | Q23: =($D23-E23)*10000 -> 6.9118474 | R23: =($D23-F23)*10000 -> 0.3339378 | S23: =($D23-G23)*10000 -> 4.4861776 | T23: =($D23-H23)*10000 -> 10.382258 | U23: =($D23-I23)*10000 -> 33.80477 | W23: {=INDIRECT("'"&$C$6&"'!"&ADDRESS(ROW(),COLUMN()+44))} -> 0.075108716 | X23: {=INDIRECT("'"&$C$6&"'!"&ADDRESS(ROW(),COLUMN()+44))} -> 0.074819951 | Y23: {=INDIRECT("'"&$C$6&"'!"&ADDRESS(ROW(),COLUMN()+44))} -> 0.075025428 | Z23: {=INDIRECT("'"&$C$6&"'!"&ADDRESS(ROW(),COLUMN()+44))} -> 0.074764361 | AA23: {=INDIRECT("'"&$C$6&"'!"&ADDRESS(ROW(),COLUMN()+44))} -> 0.073844122 | AB23: {=INDIRECT("'"&$C$6&"'!"&ADDRESS(ROW(),COLUMN()+44))} -> 0.071244808 | AJ23: =($W23-X23)*10000 -> 2.8876539 | AK23: =($W23-Y23)*10000 -> 0.83288631 | AL23: =($W23-Z23)*10000 -> 3.4435522 | AM23: =($W23-AA23)*10000 -> 12.64594 | AN23: =($W23-AB23)*10000 -> 38.639086
C26: Vigente | D26: =-IFERROR(((1-D44/D14)^(360/D$4))-1,0) -> -0.054368153 | E26: =-IFERROR(((1-E44/E14)^(360/E$4))-1,0) -> -0.05464475 | F26: =-IFERROR(((1-F44/F14)^(360/F$4))-1,0) -> -0.060334376 | G26: =-IFERROR(((1-G44/G14)^(360/G$4))-1,0) -> -0.053830678 | H26: =-IFERROR(((1-H44/H14)^(360/H$4))-1,0) -> -0.051851671 | I26: =-IFERROR(((1-I44/I14)^(360/I$4))-1,0) -> -0.04871527 | Q26: =($D26-E26)*10000 -> 2.7659744 | R26: =($D26-F26)*10000 -> 59.662232 | S26: =($D26-G26)*10000 -> -5.3747458 | T26: =($D26-H26)*10000 -> -25.16482 | U26: =($D26-I26)*10000 -> -56.528832 | W26: {=INDIRECT("'"&$C$6&"'!"&ADDRESS(ROW(),COLUMN()+44))} -> -0.056239683 | X26: {=INDIRECT("'"&$C$6&"'!"&ADDRESS(ROW(),COLUMN()+44))} -> -0.056482252 | Y26: {=INDIRECT("'"&$C$6&"'!"&ADDRESS(ROW(),COLUMN()+44))} -> -0.05624434 | Z26: {=INDIRECT("'"&$C$6&"'!"&ADDRESS(ROW(),COLUMN()+44))} -> -0.05550907 | AA26: {=INDIRECT("'"&$C$6&"'!"&ADDRESS(ROW(),COLUMN()+44))} -> -0.053367564 | AB26: {=INDIRECT("'"&$C$6&"'!"&ADDRESS(ROW(),COLUMN()+44))} -> -0.049998844 | AJ26: =($W26-X26)*10000 -> 2.4256817 | AK26: =($W26-Y26)*10000 -> 0.046570139 | AL26: =($W26-Z26)*10000 -> -7.3061363 | AM26: =($W26-AA26)*10000 -> -28.721194 | AN26: =($W26-AB26)*10000 -> -62.408393
C27: Refinanciado | D27: =-IFERROR(((1-D45/D15)^(360/D$4))-1,0) -> -0.05329065 | E27: =-IFERROR(((1-E45/E15)^(360/E$4))-1,0) -> -0.055451064 | F27: =-IFERROR(((1-F45/F15)^(360/F$4))-1,0) -> -0.058217736 | G27: =-IFERROR(((1-G45/G15)^(360/G$4))-1,0) -> -0.050702078 | H27: =-IFERROR(((1-H45/H15)^(360/H$4))-1,0) -> -0.048797725 | I27: =-IFERROR(((1-I45/I15)^(360/I$4))-1,0) -> -0.04785361 | Q27: =($D27-E27)*10000 -> 21.604146 | R27: =($D27-F27)*10000 -> 49.270863 | S27: =($D27-G27)*10000 -> -25.885719 | T27: =($D27-H27)*10000 -> -44.929243 | U27: =($D27-I27)*10000 -> -54.370399 | W27: {=INDIRECT("'"&$C$6&"'!"&ADDRESS(ROW(),COLUMN()+44))} -> -0.054758314 | X27: {=INDIRECT("'"&$C$6&"'!"&ADDRESS(ROW(),COLUMN()+44))} -> -0.057133437 | Y27: {=INDIRECT("'"&$C$6&"'!"&ADDRESS(ROW(),COLUMN()+44))} -> -0.054570349 | Z27: {=INDIRECT("'"&$C$6&"'!"&ADDRESS(ROW(),COLUMN()+44))} -> -0.052077723 | AA27: {=INDIRECT("'"&$C$6&"'!"&ADDRESS(ROW(),COLUMN()+44))} -> -0.04998486 | AB27: {=INDIRECT("'"&$C$6&"'!"&ADDRESS(ROW(),COLUMN()+44))} -> -0.049473512 | AJ27: =($W27-X27)*10000 -> 23.75123 | AK27: =($W27-Y27)*10000 -> -1.8796512 | AL27: =($W27-Z27)*10000 -> -26.805911 | AM27: =($W27-AA27)*10000 -> -47.734543 | AN27: =($W27-AB27)*10000 -> -52.848021
