Workbook

Sheet Parametros
B2: Producto | C2: Convenios
B4: Año | C4: 2026
B6: Lista Fechas | C6: =EOMONTH(DATE($C$4,1,1),0) -> 46053 | E6: Segmentos | F6: Renta_Alta
C7: =EOMONTH(C6,1) -> 46081 | F7: Masivo
C8: =EOMONTH(C7,1) -> 46112 | F8: Consumo_Inicial
C9: =EOMONTH(C8,1) -> 46142 | F9: Total_Producto
C10: =EOMONTH(C9,1) -> 46173
C11: =EOMONTH(C10,1) -> 46203
C12: =EOMONTH(C11,1) -> 46234
C13: =EOMONTH(C12,1) -> 46265
C14: =EOMONTH(C13,1) -> 46295
C15: =EOMONTH(C14,1) -> 46326
C16: =EOMONTH(C15,1) -> 46356
C17: =EOMONTH(C16,1) -> 46387

Sheet Total_Producto_Check
D1: REAL | AZ1: PRESUPUESTO | BO1: Acumulado | BW1: Saldo Prom Acumulado
BO2: =DATE(YEAR(BO6),1,1) -> 46023 | BP2: =DATE(YEAR(BP6),1,1) -> 46023 | BQ2: =DATE(YEAR(BQ6),1,1) -> 46023 | BR2: =DATE(YEAR(BR6),1,1) -> 45658 | BS2: =DATE(YEAR(BS6),1,1) -> 45292 | BT2: =DATE(YEAR(BT6),1,1) -> 44927
C3: N° dias T.Imp | D3: =DAY(D6) -> 31 | E3: =DAY(E6) -> 28 | F3: =DAY(F6) -> 31 | G3: =DAY(G6) -> 30 | H3: =DAY(H6) -> 31 | I3: =DAY(I6) -> 30 | J3: =DAY(J6) -> 31 | K3: =DAY(K6) -> 31 | ... BK3: =DAY(BK6) -> 31 | BO3: =AVERAGEIFS($D3:$BM3,$D$6:$BM$6,">="&BO$2,$D$6:$BM$6,"<="&BO$6,$D$5:$BM$5,BO$5) -> 30 | BP3: =AVERAGEIFS($D3:$BM3,$D$6:$BM$6,">="&BP$2,$D$6:$BM$6,"<="&BP$6,$D$5:$BM$5,BP$5) -> 30 | BQ3: =AVERAGEIFS($D3:$BM3,$D$6:$BM$6,">="&BQ$2,$D$6:$BM$6,"<="&BQ$6,$D$5:$BM$5,BQ$5) -> 29.5 | BR3: =AVERAGEIFS($D3:$BM3,$D$6:$BM$6,">="&BR$2,$D$6:$BM$6,"<="&BR$6,$D$5:$BM$5,BR$5) -> 30 | BS3: =AVERAGEIFS($D3:$BM3,$D$6:$BM$6,">="&BS$2,$D$6:$BM$6,"<="&BS$6,$D$5:$BM$5,BS$5) -> 30.333333 | BT3: =AVERAGEIFS($D3:$BM3,$D$6:$BM$6,">="&BT$2,$D$6:$BM$6,"<="&BT$6,$D$5:$BM$5,BT$5) -> 30
C4: N° dias FTP | D4: =DAY(D6) -> 31 | E4: =DAY(E6) -> 28 | F4: =DAY(F6) -> 31 | G4: =DAY(G6) -> 30 | H4: =DAY(H6) -> 31 | I4: =DAY(I6) -> 30 | J4: =DAY(J6) -> 31 | K4: =DAY(K6) -> 31 | ... BK4: =DAY(BK6) -> 31 | BO4: =AVERAGEIFS($D4:$BM4,$D$6:$BM$6,">="&BO$2,$D$6:$BM$6,"<="&BO$6,$D$5:$BM$5,BO$5) -> 30 | BP4: =AVERAGEIFS($D4:$BM4,$D$6:$BM$6,">="&BP$2,$D$6:$BM$6,"<="&BP$6,$D$5:$BM$5,BP$5) -> 30 | BQ4: =AVERAGEIFS($D4:$BM4,$D$6:$BM$6,">="&BQ$2,$D$6:$BM$6,"<="&BQ$6,$D$5:$BM$5,BQ$5) -> 29.5 | BR4: =AVERAGEIFS($D4:$BM4,$D$6:$BM$6,">="&BR$2,$D$6:$BM$6,"<="&BR$6,$D$5:$BM$5,BR$5) -> 30 | BS4: =AVERAGEIFS($D4:$BM4,$D$6:$BM$6,">="&BS$2,$D$6:$BM$6,"<="&BS$6,$D$5:$BM$5,BS$5) -> 30.333333 | BT4: =AVERAGEIFS($D4:$BM4,$D$6:$BM$6,">="&BT$2,$D$6:$BM$6,"<="&BT$6,$D$5:$BM$5,BT$5) -> 30
C5: Tipo | D5: R | E5: R | F5: R | G5: R | H5: R | I5: R | J5: R | K5: R | L5: R | M5: R | N5: R | O5: R | P5: R | Q5: R | R5: R | S5: R | T5: R | U5: R | V5: R | W5: R | X5: R | Y5: R | Z5: R | AA5: R | AB5: R | AC5: R | AD5: R | AE5: R | AF5: R | AG5: R | AH5: R | AI5: R | AJ5: R | AK5: R | AL5: R | AM5: R | AN5: R | AO5: R | AP5: R | AQ5: R | AR5: R | AS5: R | AT5: R | AU5: R | AV5: R | AW5: R | AX5: R | AY5: R | AZ5: P | BA5: P | BB5: P | BC5: P | BD5: P | BE5: P | BF5: P | BG5: P | BH5: P | BI5: P | BJ5: P | BK5: P | BO5: R | BP5: P | BQ5: R | BR5: R | BS5: R | BT5: R
C6: Total Tarjetas | D6: 44957 | E6: 44985 | F6: 45016 | G6: 45046 | H6: 45077 | I6: 45107 | J6: 45138 | K6: 45169 | L6: 45199 | M6: 45230 | N6: 45260 | O6: 45291 | P6: 45322 | Q6: 45351 | R6: 45382 | S6: 45412 | T6: 45443 | U6: 45473 | V6: 45504 | W6: 45535 | X6: 45565 | Y6: 45596 | Z6: 45626 | AA6: 45657 | AB6: 45688 | AC6: 45716 | AD6: 45747 | AE6: 45777 | AF6: 45808 | AG6: 45838 | AH6: 45869 | AI6: 45900 | AJ6: 45930 | AK6: 45961 | AL6: 45991 | AM6: 46022 | AN6: 46053 | AO6: 46081 | AP6: 46112 | AQ6: 46142 | AR6: 46173 | AS6: 46203 | AT6: 46234 | AU6: 46265 | AV6: 46295 | AW6: 46326 | AX6: 46356 | AY6: 46387 | AZ6: 46053 | BA6: 46081 | BB6: 46112 | BC6: 46142 | BD6: 46173 | BE6: 46203 | BF6: 46234 | BG6: 46265 | BH6: 46295 | BI6: 46326 | BJ6: 46356 | BK6: 46387 | BO6: =Desempeño_Financiero!$B$1 -> 46112 | BP6: =BO6 -> 46112 | BQ6: =EOMONTH(BO6,-1) -> 46081 | BR6: =EOMONTH(BO6,-12) -> 45747 | BS6: =EOMONTH(BO6,-24) -> 45382 | BT6: =EOMONTH(BO6,-36) -> 45016 | BW6: =BO6 -> 46112 | BX6: =BP6 -> 46112 | BY6: =BQ6 -> 46081 | BZ6: =BR6 -> 45747 | CA6: =BS6 -> 45382 | CB6: =BT6 -> 45016
A8: SALDO_FDP | C8: Vigente | D8: =RA_TC!D8+MA_TC!D8+CI_TC!D8 -> 0 | E8: =RA_TC!E8+MA_TC!E8+CI_TC!E8 -> 0 | F8: =RA_TC!F8+MA_TC!F8+CI_TC!F8 -> 0 | G8: =RA_TC!G8+MA_TC!G8+CI_TC!G8 -> 0 | H8: =RA_TC!H8+MA_TC!H8+CI_TC!H8 -> 0 | I8: =RA_TC!I8+MA_TC!I8+CI_TC!I8 -> 0 | J8: =RA_TC!J8+MA_TC!J8+CI_TC!J8 -> 0 | K8: =RA_TC!K8+MA_TC!K8+CI_TC!K8 -> 0 | ... BK8: =RA_TC!BK8+MA_TC!BK8+CI_TC!BK8 -> 6101726.9 | BO8: =_xlfn.XLOOKUP(BO$6,$D$6:$BM$6,$D8:$BM8,,0,1) -> 0 | BP8: =_xlfn.XLOOKUP(BP$6,$D$6:$BM$6,$D8:$BM8,,0,-1) -> 5475782.9 | BQ8: =_xlfn.XLOOKUP(BQ$6,$D$6:$BM$6,$D8:$BM8,,0,1) -> 0 | BR8: =_xlfn.XLOOKUP(BR$6,$D$6:$BM$6,$D8:$BM8,,0,1) -> 0 | BS8: =_xlfn.XLOOKUP(BS$6,$D$6:$BM$6,$D8:$BM8,,0,1) -> 0 | BT8: =_xlfn.XLOOKUP(BT$6,$D$6:$BM$6,$D8:$BM8,,0,1) -> 0
A9: SALDO_FDP | C9: Refinanciado | D9: =RA_TC!D9+MA_TC!D9+CI_TC!D9 -> 0 | E9: =RA_TC!E9+MA_TC!E9+CI_TC!E9 -> 0 | F9: =RA_TC!F9+MA_TC!F9+CI_TC!F9 -> 0 | G9: =RA_TC!G9+MA_TC!G9+CI_TC!G9 -> 0 | H9: =RA_TC!H9+MA_TC!H9+CI_TC!H9 -> 0 | I9: =RA_TC!I9+MA_TC!I9+CI_TC!I9 -> 0 | J9: =RA_TC!J9+MA_TC!J9+CI_TC!J9 -> 0 | K9: =RA_TC!K9+MA_TC!K9+CI_TC!K9 -> 0 | ... BK9: =RA_TC!BK9+MA_TC!BK9+CI_TC!BK9 -> 191034.16 | BO9: =_xlfn.XLOOKUP(BO$6,$D$6:$BM$6,$D9:$BM9,,0,1) -> 0 | BP9: =_xlfn.XLOOKUP(BP$6,$D$6:$BM$6,$D9:$BM9,,0,-1) -> 187857.74 | BQ9: =_xlfn.XLOOKUP(BQ$6,$D$6:$BM$6,$D9:$BM9,,0,1) -> 0 | BR9: =_xlfn.XLOOKUP(BR$6,$D$6:$BM$6,$D9:$BM9,,0,1) -> 0 | BS9: =_xlfn.XLOOKUP(BS$6,$D$6:$BM$6,$D9:$BM9,,0,1) -> 0 | BT9: =_xlfn.XLOOKUP(BT$6,$D$6:$BM$6,$D9:$BM9,,0,1) -> 0
A10: SALDO_FDP | C10: Vencido y Judicial | D10: =RA_TC!D10+MA_TC!D10+CI_TC!D10 -> 0 | E10: =RA_TC!E10+MA_TC!E10+CI_TC!E10 -> 0 | F10: =RA_TC!F10+MA_TC!F10+CI_TC!F10 -> 0 | G10: =RA_TC!G10+MA_TC!G10+CI_TC!G10 -> 0 | H10: =RA_TC!H10+MA_TC!H10+CI_TC!H10 -> 0 | I10: =RA_TC!I10+MA_TC!I10+CI_TC!I10 -> 0 | J10: =RA_TC!J10+MA_TC!J10+CI_TC!J10 -> 0 | K10: =RA_TC!K10+MA_TC!K10+CI_TC!K10 -> 0 | ... BK10: =RA_TC!BK10+MA_TC!BK10+CI_TC!BK10 -> 255200.78 | BO10: =_xlfn.XLOOKUP(BO$6,$D$6:$BM$6,$D10:$BM10,,0,1) -> 0 | BP10: =_xlfn.XLOOKUP(BP$6,$D$6:$BM$6,$D10:$BM10,,0,-1) -> 242951.26 | BQ10: =_xlfn.XLOOKUP(BQ$6,$D$6:$BM$6,$D10:$BM10,,0,1) -> 0 | BR10: =_xlfn.XLOOKUP(BR$6,$D$6:$BM$6,$D10:$BM10,,0,1) -> 0 | BS10: =_xlfn.XLOOKUP(BS$6,$D$6:$BM$6,$D10:$BM10,,0,1) -> 0 | BT10: =_xlfn.XLOOKUP(BT$6,$D$6:$BM$6,$D10:$BM10,,0,1) -> 0
C11: Saldo FdP | D11: =SUM(D8:D10) -> 0 | E11: =SUM(E8:E10) -> 0 | F11: =SUM(F8:F10) -> 0 | G11: =SUM(G8:G10) -> 0 | H11: =SUM(H8:H10) -> 0 | I11: =SUM(I8:I10) -> 0 | J11: =SUM(J8:J10) -> 0 | K11: =SUM(K8:K10) -> 0 | ... BK11: =SUM(BK8:BK10) -> 6547961.9 | BO11: =SUM(BO8:BO10) -> 0 | BP11: =SUM(BP8:BP10) -> 5906591.9 | BQ11: =SUM(BQ8:BQ10) -> 0 | BR11: =SUM(BR8:BR10) -> 0 | BS11: =SUM(BS8:BS10) -> 0 | BT11: =SUM(BT8:BT10) -> 0
D12: ='[1]Desempeño Finan_ TC_Cartera_Evo'!AY10-D11 -> 6751883.9 | E12: ='[1]Desempeño Finan_ TC_Cartera_Evo'!AZ10-E11 -> 6868384.2 | F12: ='[1]Desempeño Finan_ TC_Cartera_Evo'!BA10-F11 -> 7072870.9 | G12: ='[1]Desempeño Finan_ TC_Cartera_Evo'!BB10-G11 -> 7128656.3 | H12: ='[1]Desempeño Finan_ TC_Cartera_Evo'!BC10-H11 -> 7315435.6 | I12: ='[1]Desempeño Finan_ TC_Cartera_Evo'!BD10-I11 -> 7388523.1 | J12: ='[1]Desempeño Finan_ TC_Cartera_Evo'!BE10-J11 -> 7356182.5 | K12: ='[1]Desempeño Finan_ TC_Cartera_Evo'!BF10-K11 -> 7370654.4 | ... BK12: ='[1]Desempeño Finan_ TC_Cartera_Evo'!DF10-BK11 -> 0
A14: SALDO_PROM | C14: Vigente | D14: =RA_TC!D14+MA_TC!D14+CI_TC!D14 -> 0 | E14: =RA_TC!E14+MA_TC!E14+CI_TC!E14 -> 0 | F14: =RA_TC!F14+MA_TC!F14+CI_TC!F14 -> 0 | G14: =RA_TC!G14+MA_TC!G14+CI_TC!G14 -> 0 | H14: =RA_TC!H14+MA_TC!H14+CI_TC!H14 -> 0 | I14: =RA_TC!I14+MA_TC!I14+CI_TC!I14 -> 0 | J14: =RA_TC!J14+MA_TC!J14+CI_TC!J14 -> 0 | K14: =RA_TC!K14+MA_TC!K14+CI_TC!K14 -> 0 | ... BK14: =RA_TC!BK14+MA_TC!BK14+CI_TC!BK14 -> 5993248.4 | BO14: =IFERROR(AVERAGEIFS($D14:$BM14,$D$6:$BM$6,">="&BO$2,$D$6:$BM$6,"<="&BO$6,$D$5:$BM$5,BO$5,$D14:$BM14,"<>0"),0) -> 0 | BP14: =IFERROR(AVERAGEIFS($D14:$BM14,$D$6:$BM$6,">="&BP$2,$D$6:$BM$6,"<="&BP$6,$D$5:$BM$5,BP$5,$D14:$BM14,"<>0"),0) -> 5394716 | BQ14: =IFERROR(AVERAGEIFS($D14:$BM14,$D$6:$BM$6,">="&BQ$2,$D$6:$BM$6,"<="&BQ$6,$D$5:$BM$5,BQ$5,$D14:$BM14,"<>0"),0) -> 0 | BR14: =IFERROR(AVERAGEIFS($D14:$BM14,$D$6:$BM$6,">="&BR$2,$D$6:$BM$6,"<="&BR$6,$D$5:$BM$5,BR$5,$D14:$BM14,"<>0"),0) -> 0 | BS14: =IFERROR(AVERAGEIFS($D14:$BM14,$D$6:$BM$6,">="&BS$2,$D$6:$BM$6,"<="&BS$6,$D$5:$BM$5,BS$5,$D14:$BM14,"<>0"),0) -> 0 | BT14: =IFERROR(AVERAGEIFS($D14:$BM14,$D$6:$BM$6,">="&BT$2,$D$6:$BM$6,"<="&BT$6,$D$5:$BM$5,BT$5,$D14:$BM14,"<>0"),0) -> 0 | BW14: =SUMIFS($D14:$BM14,$D$6:$BM$6,">="&BO$2,$D$6:$BM$6,"<="&BO$6,$D$5:$BM$5,BO$5) -> 0 | BX14: =SUMIFS($D14:$BM14,$D$6:$BM$6,">="&BP$2,$D$6:$BM$6,"<="&BP$6,$D$5:$BM$5,BP$5) -> 16184148 | BY14: =SUMIFS($D14:$BM14,$D$6:$BM$6,">="&BQ$2,$D$6:$BM$6,"<="&BQ$6,$D$5:$BM$5,BQ$5) -> 0 | BZ14: =SUMIFS($D14:$BM14,$D$6:$BM$6,">="&BR$2,$D$6:$BM$6,"<="&BR$6,$D$5:$BM$5,BR$5) -> 0 | CA14: =SUMIFS($D14:$BM14,$D$6:$BM$6,">="&BS$2,$D$6:$BM$6,"<="&BS$6,$D$5:$BM$5,BS$5) -> 0 | CB14: =SUMIFS($D14:$BM14,$D$6:$BM$6,">="&BT$2,$D$6:$BM$6,"<="&BT$6,$D$5:$BM$5,BT$5) -> 0
A15: SALDO_PROM | C15: Refinanciado | D15: =RA_TC!D15+MA_TC!D15+CI_TC!D15 -> 0 | E15: =RA_TC!E15+MA_TC!E15+CI_TC!E15 -> 0 | F15: =RA_TC!F15+MA_TC!F15+CI_TC!F15 -> 0 | G15: =RA_TC!G15+MA_TC!G15+CI_TC!G15 -> 0 | H15: =RA_TC!H15+MA_TC!H15+CI_TC!H15 -> 0 | I15: =RA_TC!I15+MA_TC!I15+CI_TC!I15 -> 0 | J15: =RA_TC!J15+MA_TC!J15+CI_TC!J15 -> 0 | K15: =RA_TC!K15+MA_TC!K15+CI_TC!K15 -> 0 | ... BK15: =RA_TC!BK15+MA_TC!BK15+CI_TC!BK15 -> 183040.35 | BO15: =IFERROR(AVERAGEIFS($D15:$BM15,$D$6:$BM$6,">="&BO$2,$D$6:$BM$6,"<="&BO$6,$D$5:$BM$5,BO$5,$D15:$BM15,"<>0"),0) -> 0 | BP15: =IFERROR(AVERAGEIFS($D15:$BM15,$D$6:$BM$6,">="&BP$2,$D$6:$BM$6,"<="&BP$6,$D$5:$BM$5,BP$5,$D15:$BM15,"<>0"),0) -> 183585.17 | BQ15: =IFERROR(AVERAGEIFS($D15:$BM15,$D$6:$BM$6,">="&BQ$2,$D$6:$BM$6,"<="&BQ$6,$D$5:$BM$5,BQ$5,$D15:$BM15,"<>0"),0) -> 0 | BR15: =IFERROR(AVERAGEIFS($D15:$BM15,$D$6:$BM$6,">="&BR$2,$D$6:$BM$6,"<="&BR$6,$D$5:$BM$5,BR$5,$D15:$BM15,"<>0"),0) -> 0 | BS15: =IFERROR(AVERAGEIFS($D15:$BM15,$D$6:$BM$6,">="&BS$2,$D$6:$BM$6,"<="&BS$6,$D$5:$BM$5,BS$5,$D15:$BM15,"<>0"),0) -> 0 | BT15: =IFERROR(AVERAGEIFS($D15:$BM15,$D$6:$BM$6,">="&BT$2,$D$6:$BM$6,"<="&BT$6,$D$5:$BM$5,BT$5,$D15:$BM15,"<>0"),0) -> 0 | BW15: =SUMIFS($D15:$BM15,$D$6:$BM$6,">="&BO$2,$D$6:$BM$6,"<="&BO$6,$D$5:$BM$5,BO$5) -> 0 | BX15: =SUMIFS($D15:$BM15,$D$6:$BM$6,">="&BP$2,$D$6:$BM$6,"<="&BP$6,$D$5:$BM$5,BP$5) -> 550755.5 | BY15: =SUMIFS($D15:$BM15,$D$6:$BM$6,">="&BQ$2,$D$6:$BM$6,"<="&BQ$6,$D$5:$BM$5,BQ$5) -> 0 | BZ15: =SUMIFS($D15:$BM15,$D$6:$BM$6,">="&BR$2,$D$6:$BM$6,"<="&BR$6,$D$5:$BM$5,BR$5) -> 0 | CA15: =SUMIFS($D15:$BM15,$D$6:$BM$6,">="&BS$2,$D$6:$BM$6,"<="&BS$6,$D$5:$BM$5,BS$5) -> 0 | CB15: =SUMIFS($D15:$BM15,$D$6:$BM$6,">="&BT$2,$D$6:$BM$6,"<="&BT$6,$D$5:$BM$5,BT$5) -> 0
A16: SALDO_PROM | C16: Vencido y Judicial | D16: =RA_TC!D16+MA_TC!D16+CI_TC!D16 -> 0 | E16: =RA_TC!E16+MA_TC!E16+CI_TC!E16 -> 0 | F16: =RA_TC!F16+MA_TC!F16+CI_TC!F16 -> 0 | G16: =RA_TC!G16+MA_TC!G16+CI_TC!G16 -> 0 | H16: =RA_TC!H16+MA_TC!H16+CI_TC!H16 -> 0 | I16: =RA_TC!I16+MA_TC!I16+CI_TC!I16 -> 0 | J16: =RA_TC!J16+MA_TC!J16+CI_TC!J16 -> 0 | K16: =RA_TC!K16+MA_TC!K16+CI_TC!K16 -> 0 | ... BK16: =RA_TC!BK16+MA_TC!BK16+CI_TC!BK16 -> 276079.3 | BO16: =IFERROR(AVERAGEIFS($D16:$BM16,$D$6:$BM$6,">="&BO$2,$D$6:$BM$6,"<="&BO$6,$D$5:$BM$5,BO$5,$D16:$BM16,"<>0"),0) -> 0 | BP16: =IFERROR(AVERAGEIFS($D16:$BM16,$D$6:$BM$6,">="&BP$2,$D$6:$BM$6,"<="&BP$6,$D$5:$BM$5,BP$5,$D16:$BM16,"<>0"),0) -> 269886.41 | BQ16: =IFERROR(AVERAGEIFS($D16:$BM16,$D$6:$BM$6,">="&BQ$2,$D$6:$BM$6,"<="&BQ$6,$D$5:$BM$5,BQ$5,$D16:$BM16,"<>0"),0) -> 0 | BR16: =IFERROR(AVERAGEIFS($D16:$BM16,$D$6:$BM$6,">="&BR$2,$D$6:$BM$6,"<="&BR$6,$D$5:$BM$5,BR$5,$D16:$BM16,"<>0"),0) -> 0 | BS16: =IFERROR(AVERAGEIFS($D16:$BM16,$D$6:$BM$6,">="&BS$2,$D$6:$BM$6,"<="&BS$6,$D$5:$BM$5,BS$5,$D16:$BM16,"<>0"),0) -> 0 | BT16: =IFERROR(AVERAGEIFS($D16:$BM16,$D$6:$BM$6,">="&BT$2,$D$6:$BM$6,"<="&BT$6,$D$5:$BM$5,BT$5,$D16:$BM16,"<>0"),0) -> 0 | BW16: =SUMIFS($D16:$BM16,$D$6:$BM$6,">="&BO$2,$D$6:$BM$6,"<="&BO$6,$D$5:$BM$5,BO$5) -> 0 | BX16: =SUMIFS($D16:$BM16,$D$6:$BM$6,">="&BP$2,$D$6:$BM$6,"<="&BP$6,$D$5:$BM$5,BP$5) -> 809659.23 | BY16: =SUMIFS($D16:$BM16,$D$6:$BM$6,">="&BQ$2,$D$6:$BM$6,"<="&BQ$6,$D$5:$BM$5,BQ$5) -> 0 | BZ16: =SUMIFS($D16:$BM16,$D$6:$BM$6,">="&BR$2,$D$6:$BM$6,"<="&BR$6,$D$5:$BM$5,BR$5) -> 0 | CA16: =SUMIFS($D16:$BM16,$D$6:$BM$6,">="&BS$2,$D$6:$BM$6,"<="&BS$6,$D$5:$BM$5,BS$5) -> 0 | CB16: =SUMIFS($D16:$BM16,$D$6:$BM$6,">="&BT$2,$D$6:$BM$6,"<="&BT$6,$D$5:$BM$5,BT$5) -> 0
C17: Saldo Prom | D17: =SUM(D14:D16) -> 0 | E17: =SUM(E14:E16) -> 0 | F17: =SUM(F14:F16) -> 0 | G17: =SUM(G14:G16) -> 0 | H17: =SUM(H14:H16) -> 0 | I17: =SUM(I14:I16) -> 0 | J17: =SUM(J14:J16) -> 0 | K17: =SUM(K14:K16) -> 0 | ... BK17: =SUM(BK14:BK16) -> 6452368.1 | BO17: =SUM(BO14:BO16) -> 0 | BP17: =SUM(BP14:BP16) -> 5848187.6 | BQ17: =SUM(BQ14:BQ16) -> 0 | BR17: =SUM(BR14:BR16) -> 0 | BS17: =SUM(BS14:BS16) -> 0 | BT17: =SUM(BT14:BT16) -> 0 | BW17: =SUM(BW14:BW16) -> 0 | BX17: =SUM(BX14:BX16) -> 17544563 | BY17: =SUM(BY14:BY16) -> 0 | BZ17: =SUM(BZ14:BZ16) -> 0 | CA17: =SUM(CA14:CA16) -> 0 | CB17: =SUM(CB14:CB16) -> 0
D18: ='[1]Desempeño Finan_ TC_Cartera_Evo'!AY15-D17 -> 6606767.9 | E18: ='[1]Desempeño Finan_ TC_Cartera_Evo'!AZ15-E17 -> 6718626.3 | F18: ='[1]Desempeño Finan_ TC_Cartera_Evo'!BA15-F17 -> 6908092.8 | G18: ='[1]Desempeño Finan_ TC_Cartera_Evo'!BB15-G17 -> 7032104.8 | H18: ='[1]Desempeño Finan_ TC_Cartera_Evo'!BC15-H17 -> 7150778.6 | I18: ='[1]Desempeño Finan_ TC_Cartera_Evo'!BD15-I17 -> 7292178.2 | J18: ='[1]Desempeño Finan_ TC_Cartera_Evo'!BE15-J17 -> 7258431.2 | K18: ='[1]Desempeño Finan_ TC_Cartera_Evo'!BF15-K17 -> 7293848.5 | ... BK18: ='[1]Desempeño Finan_ TC_Cartera_Evo'!DF15-BK17 -> 0
C20: Vigente | D20: =IFERROR(((1+D38/D14)^(360/D$3))-1,0) -> 0 | E20: =IFERROR(((1+E38/E14)^(360/E$3))-1,0) -> 0 | F20: =IFERROR(((1+F38/F14)^(360/F$3))-1,0) -> 0 | G20: =IFERROR(((1+G38/G14)^(360/G$3))-1,0) -> 0 | H20: =IFERROR(((1+H38/H14)^(360/H$3))-1,0) -> 0 | I20: =IFERROR(((1+I38/I14)^(360/I$3))-1,0) -> 0 | J20: =IFERROR(((1+J38/J14)^(360/J$3))-1,0) -> 0 | K20: =IFERROR(((1+K38/K14)^(360/K$3))-1,0) -> 0 | ... BK20: =IFERROR(((1+BK38/BK14)^(360/BK$3))-1,0) -> 0.26667291 | BO20: =IFERROR(((1+BO38/BW14)^(360/BO$3))-1,0) -> 0 | BP20: =IFERROR(((1+BP38/BX14)^(360/BP$3))-1,0) -> 0.25696584 | BQ20: =IFERROR(((1+BQ38/BY14)^(360/BQ$3))-1,0) -> 0 | BR20: =IFERROR(((1+BR38/BZ14)^(360/BR$3))-1,0) -> 0 | BS20: =IFERROR(((1+BS38/CA14)^(360/BS$3))-1,0) -> 0 | BT20: =IFERROR(((1+BT38/CB14)^(360/BT$3))-1,0) -> 0
C21: Refinanciado | D21: =IFERROR(((1+D39/D15)^(360/D$3))-1,0) -> 0 | E21: =IFERROR(((1+E39/E15)^(360/E$3))-1,0) -> 0 | F21: =IFERROR(((1+F39/F15)^(360/F$3))-1,0) -> 0 | G21: =IFERROR(((1+G39/G15)^(360/G$3))-1,0) -> 0 | H21: =IFERROR(((1+H39/H15)^(360/H$3))-1,0) -> 0 | I21: =IFERROR(((1+I39/I15)^(360/I$3))-1,0) -> 0 | J21: =IFERROR(((1+J39/J15)^(360/J$3))-1,0) -> 0 | K21: =IFERROR(((1+K39/K15)^(360/K$3))-1,0) -> 0 | ... BK21: =IFERROR(((1+BK39/BK15)^(360/BK$3))-1,0) -> 0.10692987 | BO21: =IFERROR(((1+BO39/BW15)^(360/BO$3))-1,0) -> 0 | BP21: =IFERROR(((1+BP39/BX15)^(360/BP$3))-1,0) -> 0.10616469 | BQ21: =IFERROR(((1+BQ39/BY15)^(360/BQ$3))-1,0) -> 0 | BR21: =IFERROR(((1+BR39/BZ15)^(360/BR$3))-1,0) -> 0 | BS21: =IFERROR(((1+BS39/CA15)^(360/BS$3))-1,0) -> 0 | BT21: =IFERROR(((1+BT39/CB15)^(360/BT$3))-1,0) -> 0
C22: Vencido y Judicial | D22: =IFERROR(((1+D40/D16)^(360/D$3))-1,0) -> 0 | E22: =IFERROR(((1+E40/E16)^(360/E$3))-1,0) -> 0 | F22: =IFERROR(((1+F40/F16)^(360/F$3))-1,0) -> 0 | G22: =IFERROR(((1+G40/G16)^(360/G$3))-1,0) -> 0 | H22: =IFERROR(((1+H40/H16)^(360/H$3))-1,0) -> 0 | I22: =IFERROR(((1+I40/I16)^(360/I$3))-1,0) -> 0 | J22: =IFERROR(((1+J40/J16)^(360/J$3))-1,0) -> 0 | K22: =IFERROR(((1+K40/K16)^(360/K$3))-1,0) -> 0 | ... BK22: =IFERROR(((1+BK40/BK16)^(360/BK$3))-1,0) -> 0.19048324 | BO22: =IFERROR(((1+BO40/BW16)^(360/BO$3))-1,0) -> 0 | BP22: =IFERROR(((1+BP40/BX16)^(360/BP$3))-1,0) -> 0.20328197 | BQ22: =IFERROR(((1+BQ40/BY16)^(360/BQ$3))-1,0) -> 0 | BR22: =IFERROR(((1+BR40/BZ16)^(360/BR$3))-1,0) -> 0 | BS22: =IFERROR(((1+BS40/CA16)^(360/BS$3))-1,0) -> 0 | BT22: =IFERROR(((1+BT40/CB16)^(360/BT$3))-1,0) -> 0
C23: Tasa Implicita | D23: =IFERROR(((1+D41/D17)^(360/D$3))-1,0) -> 0 | E23: =IFERROR(((1+E41/E17)^(360/E$3))-1,0) -> 0 | F23: =IFERROR(((1+F41/F17)^(360/F$3))-1,0) -> 0 | G23: =IFERROR(((1+G41/G17)^(360/G$3))-1,0) -> 0 | H23: =IFERROR(((1+H41/H17)^(360/H$3))-1,0) -> 0 | I23: =IFERROR(((1+I41/I17)^(360/I$3))-1,0) -> 0 | J23: =IFERROR(((1+J41/J17)^(360/J$3))-1,0) -> 0 | K23: =IFERROR(((1+K41/K17)^(360/K$3))-1,0) -> 0 | ... BK23: =IFERROR(((1+BK41/BK17)^(360/BK$3))-1,0) -> 0.25852793 | BO23: =IFERROR(((1+BO41/BW17)^(360/BO$3))-1,0) -> 0 | BP23: =IFERROR(((1+BP41/BX17)^(360/BP$3))-1,0) -> 0.24944315 | BQ23: =IFERROR(((1+BQ41/BY17)^(360/BQ$3))-1,0) -> 0 | BR23: =IFERROR(((1+BR41/BZ17)^(360/BR$3))-1,0) -> 0 | BS23: =IFERROR(((1+BS41/CA17)^(360/BS$3))-1,0) -> 0 | BT23: =IFERROR(((1+BT41/CB17)^(360/BT$3))-1,0) -> 0
C26: Vigente | D26: =-IFERROR(((1-D44/D14)^(360/D$4))-1,0) -> 0 | E26: =-IFERROR(((1-E44/E14)^(360/E$4))-1,0) -> 0 | F26: =-IFERROR(((1-F44/F14)^(360/F$4))-1,0) -> 0 | G26: =-IFERROR(((1-G44/G14)^(360/G$4))-1,0) -> 0 | H26: =-IFERROR(((1-H44/H14)^(360/H$4))-1,0) -> 0 | I26: =-IFERROR(((1-I44/I14)^(360/I$4))-1,0) -> 0 | J26: =-IFERROR(((1-J44/J14)^(360/J$4))-1,0) -> 0 | K26: =-IFERROR(((1-K44/K14)^(360/K$4))-1,0) -> 0 | ... BK26: =-IFERROR(((1-BK44/BK14)^(360/BK$4))-1,0) -> -0.047972923 | BO26: =-IFERROR(((1-BO44/BW14)^(360/BO$4))-1,0) -> 0 | BP26: =-IFERROR(((1-BP44/BX14)^(360/BP$4))-1,0) -> -0.049891884 | BQ26: =-IFERROR(((1-BQ44/BY14)^(360/BQ$4))-1,0) -> 0 | BR26: =-IFERROR(((1-BR44/BZ14)^(360/BR$4))-1,0) -> 0 | BS26: =-IFERROR(((1-BS44/CA14)^(360/BS$4))-1,0) -> 0 | BT26: =-IFERROR(((1-BT44/CB14)^(360/BT$4))-1,0) -> 0
C27: Refinanciado | D27: =-IFERROR(((1-D45/D15)^(360/D$4))-1,0) -> 0 | E27: =-IFERROR(((1-E45/E15)^(360/E$4))-1,0) -> 0 | F27: =-IFERROR(((1-F45/F15)^(360/F$4))-1,0) -> 0 | G27: =-IFERROR(((1-G45/G15)^(360/G$4))-1,0) -> 0 | H27: =-IFERROR(((1-H45/H15)^(360/H$4))-1,0) -> 0 | I27: =-IFERROR(((1-I45/I15)^(360/I$4))-1,0) -> 0 | J27: =-IFERROR(((1-J45/J15)^(360/J$4))-1,0) -> 0 | K27: =-IFERROR(((1-K45/K15)^(360/K$4))-1,0) -> 0 | ... BK27: =-IFERROR(((1-BK45/BK15)^(360/BK$4))-1,0) -> -0.051397622 | BO27: =-IFERROR(((1-BO45/BW15)^(360/BO$4))-1,0) -> 0 | BP27: =-IFERROR(((1-BP45/BX15)^(360/BP$4))-1,0) -> -0.049363761 | BQ27: =-IFERROR(((1-BQ45/BY15)^(360/BQ$4))-1,0) -> 0 | BR27: =-IFERROR(((1-BR45/BZ15)^(360/BR$4))-1,0) -> 0 | BS27: =-IFERROR(((1-BS45/CA15)^(360/BS$4))-1,0) -> 0 | BT27: =-IFERROR(((1-BT45/CB15)^(360/BT$4))-1,0) -> 0
C28: Vencido y Judicial | D28: =-IFERROR(((1-D46/D16)^(360/D$4))-1,0) -> 0 | E28: =-IFERROR(((1-E46/E16)^(360/E$4))-1,0) -> 0 | F28: =-IFERROR(((1-F46/F16)^(360/F$4))-1,0) -> 0 | G28: =-IFERROR(((1-G46/G16)^(360/G$4))-1,0) -> 0 | H28: =-IFERROR(((1-H46/H16)^(360/H$4))-1,0) -> 0 | I28: =-IFERROR(((1-I46/I16)^(360/I$4))-1,0) -> 0 | J28: =-IFERROR(((1-J46/J16)^(360/J$4))-1,0) -> 0 | K28: =-IFERROR(((1-K46/K16)^(360/K$4))-1,0) -> 0 | ... BK28: =-IFERROR(((1-BK46/BK16)^(360/BK$4))-1,0) -> -0.048039665 | BO28: =-IFERROR(((1-BO46/BW16)^(360/BO$4))-1,0) -> 0 | BP28: =-IFERROR(((1-BP46/BX16)^(360/BP$4))-1,0) -> -0.047114159 | BQ28: =-IFERROR(((1-BQ46/BY16)^(360/BQ$4))-1,0) -> 0 | BR28: =-IFERROR(((1-BR46/BZ16)^(360/BR$4))-1,0) -> 0 | BS28: =-IFERROR(((1-BS46/CA16)^(360/BS$4))-1,0) -> 0 | BT28: =-IFERROR(((1-BT46/CB16)^(360/BT$4))-1,0) -> 0
C29: Tasa FTP | D29: =-IFERROR(((1-D47/D17)^(360/D$4))-1,0) -> 0 | E29: =-IFERROR(((1-E47/E17)^(360/E$4))-1,0) -> 0 | F29: =-IFERROR(((1-F47/F17)^(360/F$4))-1,0) -> 0 | G29: =-IFERROR(((1-G47/G17)^(360/G$4))-1,0) -> 0 | H29: =-IFERROR(((1-H47/H17)^(360/H$4))-1,0) -> 0 | I29: =-IFERROR(((1-I47/I17)^(360/I$4))-1,0) -> 0 | J29: =-IFERROR(((1-J47/J17)^(360/J$4))-1,0) -> 0 | K29: =-IFERROR(((1-K47/K17)^(360/K$4))-1,0) -> 0 | ... BK29: =-IFERROR(((1-BK47/BK17)^(360/BK$4))-1,0) -> -0.04807279 | BO29: =-IFERROR(((1-BO47/BW17)^(360/BO$4))-1,0) -> 0 | BP29: =-IFERROR(((1-BP47/BX17)^(360/BP$4))-1,0) -> -0.049746966 | BQ29: =-IFERROR(((1-BQ47/BY17)^(360/BQ$4))-1,0) -> 0 | BR29: =-IFERROR(((1-BR47/BZ17)^(360/BR$4))-1,0) -> 0 | BS29: =-IFERROR(((1-BS47/CA17)^(360/BS$4))-1,0) -> 0 | BT29: =-IFERROR(((1-BT47/CB17)^(360/BT$4))-1,0) -> 0
C32: Vigente | D32: =D20+D26 -> 0 | E32: =E20+E26 -> 0 | F32: =F20+F26 -> 0 | G32: =G20+G26 -> 0 | H32: =H20+H26 -> 0 | I32: =I20+I26 -> 0 | J32: =J20+J26 -> 0 | K32: =K20+K26 -> 0 | ... BK32: =BK20+BK26 -> 0.21869999 | BO32: =BO20+BO26 -> 0 | BP32: =BP20+BP26 -> 0.20707396 | BQ32: =BQ20+BQ26 -> 0 | BR32: =BR20+BR26 -> 0 | BS32: =BS20+BS26 -> 0 | BT32: =BT20+BT26 -> 0
C33: Refinanciado | D33: =D21+D27 -> 0 | E33: =E21+E27 -> 0 | F33: =F21+F27 -> 0 | G33: =G21+G27 -> 0 | H33: =H21+H27 -> 0 | I33: =I21+I27 -> 0 | J33: =J21+J27 -> 0 | K33: =K21+K27 -> 0 | ... BK33: =BK21+BK27 -> 0.055532249 | BO33: =BO21+BO27 -> 0 | BP33: =BP21+BP27 -> 0.05680093 | BQ33: =BQ21+BQ27 -> 0 | BR33: =BR21+BR27 -> 0 | BS33: =BS21+BS27 -> 0 | BT33: =BT21+BT27 -> 0
C34: Vencido y Judicial | D34: =D22+D28 -> 0 | E34: =E22+E28 -> 0 | F34: =F22+F28 -> 0 | G34: =G22+G28 -> 0 | H34: =H22+H28 -> 0 | I34: =I22+I28 -> 0 | J34: =J22+J28 -> 0 | K34: =K22+K28 -> 0 | ... BK34: =BK22+BK28 -> 0.14244358 | BO34: =BO22+BO28 -> 0 | BP34: =BP22+BP28 -> 0.15616781 | BQ34: =BQ22+BQ28 -> 0 | BR34: =BR22+BR28 -> 0 | BS34: =BS22+BS28 -> 0 | BT34: =BT22+BT28 -> 0
C35: Spread | D35: =D23+D29 -> 0 | E35: =E23+E29 -> 0 | F35: =F23+F29 -> 0 | G35: =G23+G29 -> 0 | H35: =H23+H29 -> 0 | I35: =I23+I29 -> 0 | J35: =J23+J29 -> 0 | K35: =K23+K29 -> 0 | ... BK35: =BK23+BK29 -> 0.21045514 | BO35: =BO23+BO29 -> 0 | BP35: =BP23+BP29 -> 0.19969618 | BQ35: =BQ23+BQ29 -> 0 | BR35: =BR23+BR29 -> 0 | BS35: =BS23+BS29 -> 0 | BT35: =BT23+BT29 -> 0
A38: Ingreso_Financiero | C38: Vigente | D38: =RA_TC!D38+MA_TC!D38+CI_TC!D38 -> 0 | E38: =RA_TC!E38+MA_TC!E38+CI_TC!E38 -> 0 | F38: =RA_TC!F38+MA_TC!F38+CI_TC!F38 -> 0 | G38: =RA_TC!G38+MA_TC!G38+CI_TC!G38 -> 0 | H38: =RA_TC!H38+MA_TC!H38+CI_TC!H38 -> 0 | I38: =RA_TC!I38+MA_TC!I38+CI_TC!I38 -> 0 | J38: =RA_TC!J38+MA_TC!J38+CI_TC!J38 -> 0 | K38: =RA_TC!K38+MA_TC!K38+CI_TC!K38 -> 0 | ... BK38: =RA_TC!BK38+MA_TC!BK38+CI_TC!BK38 -> 123249.5 | BO38: =SUMIFS($D38:$BM38,$D$6:$BM$6,">="&BO$2,$D$6:$BM$6,"<="&BO$6,$D$5:$BM$5,BO$5) -> 0 | BP38: =SUMIFS($D38:$BM38,$D$6:$BM$6,">="&BP$2,$D$6:$BM$6,"<="&BP$6,$D$5:$BM$5,BP$5) -> 311401.9 | BQ38: =SUMIFS($D38:$BM38,$D$6:$BM$6,">="&BQ$2,$D$6:$BM$6,"<="&BQ$6,$D$5:$BM$5,BQ$5) -> 0 | BR38: =SUMIFS($D38:$BM38,$D$6:$BM$6,">="&BR$2,$D$6:$BM$6,"<="&BR$6,$D$5:$BM$5,BR$5) -> 0 | BS38: =SUMIFS($D38:$BM38,$D$6:$BM$6,">="&BS$2,$D$6:$BM$6,"<="&BS$6,$D$5:$BM$5,BS$5) -> 0 | BT38: =SUMIFS($D38:$BM38,$D$6:$BM$6,">="&BT$2,$D$6:$BM$6,"<="&BT$6,$D$5:$BM$5,BT$5) -> 0
A39: Ingreso_Financiero | C39: Refinanciado | D39: =RA_TC!D39+MA_TC!D39+CI_TC!D39 -> 0 | E39: =RA_TC!E39+MA_TC!E39+CI_TC!E39 -> 0 | F39: =RA_TC!F39+MA_TC!F39+CI_TC!F39 -> 0 | G39: =RA_TC!G39+MA_TC!G39+CI_TC!G39 -> 0 | H39: =RA_TC!H39+MA_TC!H39+CI_TC!H39 -> 0 | I39: =RA_TC!I39+MA_TC!I39+CI_TC!I39 -> 0 | J39: =RA_TC!J39+MA_TC!J39+CI_TC!J39 -> 0 | K39: =RA_TC!K39+MA_TC!K39+CI_TC!K39 -> 0 | ... BK39: =RA_TC!BK39+MA_TC!BK39+CI_TC!BK39 -> 1608.2712 | BO39: =SUMIFS($D39:$BM39,$D$6:$BM$6,">="&BO$2,$D$6:$BM$6,"<="&BO$6,$D$5:$BM$5,BO$5) -> 0 | BP39: =SUMIFS($D39:$BM39,$D$6:$BM$6,">="&BP$2,$D$6:$BM$6,"<="&BP$6,$D$5:$BM$5,BP$5) -> 4650.4042 | BQ39: =SUMIFS($D39:$BM39,$D$6:$BM$6,">="&BQ$2,$D$6:$BM$6,"<="&BQ$6,$D$5:$BM$5,BQ$5) -> 0 | BR39: =SUMIFS($D39:$BM39,$D$6:$BM$6,">="&BR$2,$D$6:$BM$6,"<="&BR$6,$D$5:$BM$5,BR$5) -> 0 | BS39: =SUMIFS($D39:$BM39,$D$6:$BM$6,">="&BS$2,$D$6:$BM$6,"<="&BS$6,$D$5:$BM$5,BS$5) -> 0 | BT39: =SUMIFS($D39:$BM39,$D$6:$BM$6,">="&BT$2,$D$6:$BM$6,"<="&BT$6,$D$5:$BM$5,BT$5) -> 0
A40: Ingreso_Financiero | C40: Vencido y Judicial | D40: =RA_TC!D40+MA_TC!D40+CI_TC!D40 -> 0 | E40: =RA_TC!E40+MA_TC!E40+CI_TC!E40 -> 0 | F40: =RA_TC!F40+MA_TC!F40+CI_TC!F40 -> 0 | G40: =RA_TC!G40+MA_TC!G40+CI_TC!G40 -> 0 | H40: =RA_TC!H40+MA_TC!H40+CI_TC!H40 -> 0 | I40: =RA_TC!I40+MA_TC!I40+CI_TC!I40 -> 0 | J40: =RA_TC!J40+MA_TC!J40+CI_TC!J40 -> 0 | K40: =RA_TC!K40+MA_TC!K40+CI_TC!K40 -> 0 | ... BK40: =RA_TC!BK40+MA_TC!BK40+CI_TC!BK40 -> 4176.4046 | BO40: =SUMIFS($D40:$BM40,$D$6:$BM$6,">="&BO$2,$D$6:$BM$6,"<="&BO$6,$D$5:$BM$5,BO$5) -> 0 | BP40: =SUMIFS($D40:$BM40,$D$6:$BM$6,">="&BP$2,$D$6:$BM$6,"<="&BP$6,$D$5:$BM$5,BP$5) -> 12582.578 | BQ40: =SUMIFS($D40:$BM40,$D$6:$BM$6,">="&BQ$2,$D$6:$BM$6,"<="&BQ$6,$D$5:$BM$5,BQ$5) -> 0 | BR40: =SUMIFS($D40:$BM40,$D$6:$BM$6,">="&BR$2,$D$6:$BM$6,"<="&BR$6,$D$5:$BM$5,BR$5) -> 0 | BS40: =SUMIFS($D40:$BM40,$D$6:$BM$6,">="&BS$2,$D$6:$BM$6,"<="&BS$6,$D$5:$BM$5,BS$5) -> 0 | BT40: =SUMIFS($D40:$BM40,$D$6:$BM$6,">="&BT$2,$D$6:$BM$6,"<="&BT$6,$D$5:$BM$5,BT$5) -> 0
C41: Ingreso Financiero | D41: =SUM(D38:D40) -> 0 | E41: =SUM(E38:E40) -> 0 | F41: =SUM(F38:F40) -> 0 | G41: =SUM(G38:G40) -> 0 | H41: =SUM(H38:H40) -> 0 | I41: =SUM(I38:I40) -> 0 | J41: =SUM(J38:J40) -> 0 | K41: =SUM(K38:K40) -> 0 | ... BK41: =SUM(BK38:BK40) -> 129034.17 | BO41: =SUM(BO38:BO40) -> 0 | BP41: =SUM(BP38:BP40) -> 328634.88 | BQ41: =SUM(BQ38:BQ40) -> 0 | BR41: =SUM(BR38:BR40) -> 0 | BS41: =SUM(BS38:BS40) -> 0 | BT41: =SUM(BT38:BT40) -> 0
A44: FTP | C44: Vigente | D44: =RA_TC!D44+MA_TC!D44+CI_TC!D44 -> 0 | E44: =RA_TC!E44+MA_TC!E44+CI_TC!E44 -> 0 | F44: =RA_TC!F44+MA_TC!F44+CI_TC!F44 -> 0 | G44: =RA_TC!G44+MA_TC!G44+CI_TC!G44 -> 0 | H44: =RA_TC!H44+MA_TC!H44+CI_TC!H44 -> 0 | I44: =RA_TC!I44+MA_TC!I44+CI_TC!I44 -> 0 | J44: =RA_TC!J44+MA_TC!J44+CI_TC!J44 -> 0 | K44: =RA_TC!K44+MA_TC!K44+CI_TC!K44 -> 0 | ... BK44: =RA_TC!BK44+MA_TC!BK44+CI_TC!BK44 -> -24231.448 | BO44: =SUMIFS($D44:$BM44,$D$6:$BM$6,">="&BO$2,$D$6:$BM$6,"<="&BO$6,$D$5:$BM$5,BO$5) -> 0 | BP44: =SUMIFS($D44:$BM44,$D$6:$BM$6,">="&BP$2,$D$6:$BM$6,"<="&BP$6,$D$5:$BM$5,BP$5) -> -65796.78 | BQ44: =SUMIFS($D44:$BM44,$D$6:$BM$6,">="&BQ$2,$D$6:$BM$6,"<="&BQ$6,$D$5:$BM$5,BQ$5) -> 0 | BR44: =SUMIFS($D44:$BM44,$D$6:$BM$6,">="&BR$2,$D$6:$BM$6,"<="&BR$6,$D$5:$BM$5,BR$5) -> 0 | BS44: =SUMIFS($D44:$BM44,$D$6:$BM$6,">="&BS$2,$D$6:$BM$6,"<="&BS$6,$D$5:$BM$5,BS$5) -> 0 | BT44: =SUMIFS($D44:$BM44,$D$6:$BM$6,">="&BT$2,$D$6:$BM$6,"<="&BT$6,$D$5:$BM$5,BT$5) -> 0
A45: FTP | C45: Refinanciado | D45: =RA_TC!D45+MA_TC!D45+CI_TC!D45 -> 0 | E45: =RA_TC!E45+MA_TC!E45+CI_TC!E45 -> 0 | F45: =RA_TC!F45+MA_TC!F45+CI_TC!F45 -> 0 | G45: =RA_TC!G45+MA_TC!G45+CI_TC!G45 -> 0 | H45: =RA_TC!H45+MA_TC!H45+CI_TC!H45 -> 0 | I45: =RA_TC!I45+MA_TC!I45+CI_TC!I45 -> 0 | J45: =RA_TC!J45+MA_TC!J45+CI_TC!J45 -> 0 | K45: =RA_TC!K45+MA_TC!K45+CI_TC!K45 -> 0 | ... BK45: =RA_TC!BK45+MA_TC!BK45+CI_TC!BK45 -> -791.69451 | BO45: =SUMIFS($D45:$BM45,$D$6:$BM$6,">="&BO$2,$D$6:$BM$6,"<="&BO$6,$D$5:$BM$5,BO$5) -> 0 | BP45: =SUMIFS($D45:$BM45,$D$6:$BM$6,">="&BP$2,$D$6:$BM$6,"<="&BP$6,$D$5:$BM$5,BP$5) -> -2215.9145 | BQ45: =SUMIFS($D45:$BM45,$D$6:$BM$6,">="&BQ$2,$D$6:$BM$6,"<="&BQ$6,$D$5:$BM$5,BQ$5) -> 0 | BR45: =SUMIFS($D45:$BM45,$D$6:$BM$6,">="&BR$2,$D$6:$BM$6,"<="&BR$6,$D$5:$BM$5,BR$5) -> 0 | BS45: =SUMIFS($D45:$BM45,$D$6:$BM$6,">="&BS$2,$D$6:$BM$6,"<="&BS$6,$D$5:$BM$5,BS$5) -> 0 | BT45: =SUMIFS($D45:$BM45,$D$6:$BM$6,">="&BT$2,$D$6:$BM$6,"<="&BT$6,$D$5:$BM$5,BT$5) -> 0
A46: FTP | C46: Vencido y Judicial | D46: =RA_TC!D46+MA_TC!D46+CI_TC!D46 -> 0 | E46: =RA_TC!E46+MA_TC!E46+CI_TC!E46 -> 0 | F46: =RA_TC!F46+MA_TC!F46+CI_TC!F46 -> 0 | G46: =RA_TC!G46+MA_TC!G46+CI_TC!G46 -> 0 | H46: =RA_TC!H46+MA_TC!H46+CI_TC!H46 -> 0 | I46: =RA_TC!I46+MA_TC!I46+CI_TC!I46 -> 0 | J46: =RA_TC!J46+MA_TC!J46+CI_TC!J46 -> 0 | K46: =RA_TC!K46+MA_TC!K46+CI_TC!K46 -> 0 | ... BK46: =RA_TC!BK46+MA_TC!BK46+CI_TC!BK46 -> -1117.7431 | BO46: =SUMIFS($D46:$BM46,$D$6:$BM$6,">="&BO$2,$D$6:$BM$6,"<="&BO$6,$D$5:$BM$5,BO$5) -> 0 | BP46: =SUMIFS($D46:$BM46,$D$6:$BM$6,">="&BP$2,$D$6:$BM$6,"<="&BP$6,$D$5:$BM$5,BP$5) -> -3112.2211 | BQ46: =SUMIFS($D46:$BM46,$D$6:$BM$6,">="&BQ$2,$D$6:$BM$6,"<="&BQ$6,$D$5:$BM$5,BQ$5) -> 0 | BR46: =SUMIFS($D46:$BM46,$D$6:$BM$6,">="&BR$2,$D$6:$BM$6,"<="&BR$6,$D$5:$BM$5,BR$5) -> 0 | BS46: =SUMIFS($D46:$BM46,$D$6:$BM$6,">="&BS$2,$D$6:$BM$6,"<="&BS$6,$D$5:$BM$5,BS$5) -> 0 | BT46: =SUMIFS($D46:$BM46,$D$6:$BM$6,">="&BT$2,$D$6:$BM$6,"<="&BT$6,$D$5:$BM$5,BT$5) -> 0
C47: Costo de Fondos | D47: =SUM(D44:D46) -> 0 | E47: =SUM(E44:E46) -> 0 | F47: =SUM(F44:F46) -> 0 | G47: =SUM(G44:G46) -> 0 | H47: =SUM(H44:H46) -> 0 | I47: =SUM(I44:I46) -> 0 | J47: =SUM(J44:J46) -> 0 | K47: =SUM(K44:K46) -> 0 | ... BK47: =SUM(BK44:BK46) -> -26140.886 | BO47: =SUM(BO44:BO46) -> 0 | BP47: =SUM(BP44:BP46) -> -71124.915 | BQ47: =SUM(BQ44:BQ46) -> 0 | BR47: =SUM(BR44:BR46) -> 0 | BS47: =SUM(BS44:BS46) -> 0 | BT47: =SUM(BT44:BT46) -> 0
C50: Vigente | D50: =D38+D44 -> 0 | E50: =E38+E44 -> 0 | F50: =F38+F44 -> 0 | G50: =G38+G44 -> 0 | H50: =H38+H44 -> 0 | I50: =I38+I44 -> 0 | J50: =J38+J44 -> 0 | K50: =K38+K44 -> 0 | ... BK50: =BK38+BK44 -> 99018.049 | BO50: =BO38+BO44 -> 0 | BP50: =BP38+BP44 -> 245605.12 | BQ50: =BQ38+BQ44 -> 0 | BR50: =BR38+BR44 -> 0 | BS50: =BS38+BS44 -> 0 | BT50: =BT38+BT44 -> 0
C51: Refinanciado | D51: =D39+D45 -> 0 | E51: =E39+E45 -> 0 | F51: =F39+F45 -> 0 | G51: =G39+G45 -> 0 | H51: =H39+H45 -> 0 | I51: =I39+I45 -> 0 | J51: =J39+J45 -> 0 | K51: =K39+K45 -> 0 | ... BK51: =BK39+BK45 -> 816.57668 | BO51: =BO39+BO45 -> 0 | BP51: =BP39+BP45 -> 2434.4896 | BQ51: =BQ39+BQ45 -> 0 | BR51: =BR39+BR45 -> 0 | BS51: =BS39+BS45 -> 0 | BT51: =BT39+BT45 -> 0
C52: Vencido y Judicial | D52: =D40+D46 -> 0 | E52: =E40+E46 -> 0 | F52: =F40+F46 -> 0 | G52: =G40+G46 -> 0 | H52: =H40+H46 -> 0 | I52: =I40+I46 -> 0 | J52: =J40+J46 -> 0 | K52: =K40+K46 -> 0 | ... BK52: =BK40+BK46 -> 3058.6616 | BO52: =BO40+BO46 -> 0 | BP52: =BP40+BP46 -> 9470.3565 | BQ52: =BQ40+BQ46 -> 0 | BR52: =BR40+BR46 -> 0 | BS52: =BS40+BS46 -> 0 | BT52: =BT40+BT46 -> 0
C53: Resultado Financiero Bruto | D53: =D41+D47 -> 0 | E53: =E41+E47 -> 0 | F53: =F41+F47 -> 0 | G53: =G41+G47 -> 0 | H53: =H41+H47 -> 0 | I53: =I41+I47 -> 0 | J53: =J41+J47 -> 0 | K53: =K41+K47 -> 0 | ... BK53: =BK41+BK47 -> 102893.29 | BO53: =SUM(BO50:BO52) -> 0 | BP53: =SUM(BP50:BP52) -> 257509.96 | BQ53: =SUM(BQ50:BQ52) -> 0 | BR53: =SUM(BR50:BR52) -> 0 | BS53: =SUM(BS50:BS52) -> 0 | BT53: =SUM(BT50:BT52) -> 0
...

Sheet Desempeño_Financiero
B1: 46112 | D1: Mensual | W1: Acumulado
B2: Desempeño Financiero
B3: En S/. Miles | C3: N° dias T.Imp | D3: =DAY(D6) -> 31 | E3: =DAY(E6) -> 31 | F3: =DAY(F6) -> 28 | G3: =DAY(G6) -> 31 | H3: =DAY(H6) -> 31 | I3: =DAY(I6) -> 31
C4: N° dias FTP | D4: =DAY(D6) -> 31 | E4: =DAY(E6) -> 31 | F4: =DAY(F6) -> 28 | G4: =DAY(G6) -> 31 | H4: =DAY(H6) -> 31 | I4: =DAY(I6) -> 31
C5: Tipo | D5: R | E5: P | F5: R | G5: R | H5: R | I5: R | K5: Variación S/. | Q5: Variación % | AD5: Variación S/. | AJ5: Variación %
C6: Total_Producto | D6: =$B$1 -> 46112 | E6: =D6 -> 46112 | F6: =EOMONTH(D6,-1) -> 46081 | G6: =EOMONTH(D6,-12) -> 45747 | H6: =EOMONTH(D6,-24) -> 45382 | I6: =EOMONTH(D6,-36) -> 45016 | K6: =E6 -> 46112 | L6: =F6 -> 46081 | M6: =G6 -> 45747 | N6: =H6 -> 45382 | O6: =I6 -> 45016 | Q6: =K6 -> 46112 | R6: =L6 -> 46081 | S6: =M6 -> 45747 | T6: =N6 -> 45382 | U6: =O6 -> 45016 | W6: =$B$1 -> 46112 | X6: =W6 -> 46112 | Y6: =EOMONTH(W6,-1) -> 46081 | Z6: =EOMONTH(W6,-12) -> 45747 | AA6: =EOMONTH(W6,-24) -> 45382 | AB6: =EOMONTH(W6,-36) -> 45016 | AD6: =X6 -> 46112 | AE6: =Y6 -> 46081 | AF6: =Z6 -> 45747 | AG6: =AA6 -> 45382 | AH6: =AB6 -> 45016 | AJ6: =AD6 -> 46112 | AK6: =AE6 -> 46081 | AL6: =AF6 -> 45747 | AM6: =AG6 -> 45382 | AN6: =AH6 -> 45016
A8: SALDO_FDP | C8: Vigente | D8: {=_xlfn.XLOOKUP(1, (INDIRECT("'"&$C$6&"'!$6:$6")=D$6)* (INDIRECT("'"&$C$6&"'!$5:$5")=D$5), INDIRECT("'"&$C$6&"'!"&ROW()&":"&ROW()) )} -> 0 | E8: {=_xlfn.XLOOKUP(1, (INDIRECT("'"&$C$6&"'!$6:$6")=E$6)* (INDIRECT("'"&$C$6&"'!$5:$5")=E$5), INDIRECT("'"&$C$6&"'!"&ROW()&":"&ROW()) )} -> 5475782.9 | F8: {=_xlfn.XLOOKUP(1, (INDIRECT("'"&$C$6&"'!$6:$6")=F$6)* (INDIRECT("'"&$C$6&"'!$5:$5")=F$5), INDIRECT("'"&$C$6&"'!"&ROW()&":"&ROW()) )} -> 0 | G8: {=_xlfn.XLOOKUP(1, (INDIRECT("'"&$C$6&"'!$6:$6")=G$6)* (INDIRECT("'"&$C$6&"'!$5:$5")=G$5), INDIRECT("'"&$C$6&"'!"&ROW()&":"&ROW()) )} -> 0 | H8: {=_xlfn.XLOOKUP(1, (INDIRECT("'"&$C$6&"'!$6:$6")=H$6)* (INDIRECT("'"&$C$6&"'!$5:$5")=H$5), INDIRECT("'"&$C$6&"'!"&ROW()&":"&ROW()) )} -> 0 | I8: {=_xlfn.XLOOKUP(1, (INDIRECT("'"&$C$6&"'!$6:$6")=I$6)* (INDIRECT("'"&$C$6&"'!$5:$5")=I$5), INDIRECT("'"&$C$6&"'!"&ROW()&":"&ROW()) )} -> 0 | K8: =$D8-E8 -> -5475782.9 | L8: =$D8-F8 -> 0 | M8: =$D8-G8 -> 0 | N8: =$D8-H8 -> 0 | O8: =$D8-I8 -> 0 | Q8: =IFERROR($D8/E8-1,0) -> -1 | R8: =IFERROR($D8/F8-1,0) -> 0 | S8: =IFERROR($D8/G8-1,0) -> 0 | T8: =IFERROR($D8/H8-1,0) -> 0 | U8: =IFERROR($D8/I8-1,0) -> 0 | W8: {=INDIRECT("'"&$C$6&"'!"&ADDRESS(ROW(),COLUMN()+44))} -> 0 | X8: {=INDIRECT("'"&$C$6&"'!"&ADDRESS(ROW(),COLUMN()+44))} -> 5475782.9 | Y8: {=INDIRECT("'"&$C$6&"'!"&ADDRESS(ROW(),COLUMN()+44))} -> 0 | Z8: {=INDIRECT("'"&$C$6&"'!"&ADDRESS(ROW(),COLUMN()+44))} -> 0 | AA8: {=INDIRECT("'"&$C$6&"'!"&ADDRESS(ROW(),COLUMN()+44))} -> 0 | AB8: {=INDIRECT("'"&$C$6&"'!"&ADDRESS(ROW(),COLUMN()+44))} -> 0 | AD8: =$W8-X8 -> -5475782.9 | AE8: =$W8-Y8 -> 0 | AF8: =$W8-Z8 -> 0 | AG8: =$W8-AA8 -> 0 | AH8: =$W8-AB8 -> 0 | AJ8: =IFERROR($W8/X8-1,0) -> -1 | AK8: =IFERROR($W8/Y8-1,0) -> 0 | AL8: =IFERROR($W8/Z8-1,0) -> 0 | AM8: =IFERROR($W8/AA8-1,0) -> 0 | AN8: =IFERROR($W8/AB8-1,0) -> 0
A9: SALDO_FDP | C9: Refinanciado | D9: {=_xlfn.XLOOKUP(1, (INDIRECT("'"&$C$6&"'!$6:$6")=D$6)* (INDIRECT("'"&$C$6&"'!$5:$5")=D$5), INDIRECT("'"&$C$6&"'!"&ROW()&":"&ROW()) )} -> 0 | E9: {=_xlfn.XLOOKUP(1, (INDIRECT("'"&$C$6&"'!$6:$6")=E$6)* (INDIRECT("'"&$C$6&"'!$5:$5")=E$5), INDIRECT("'"&$C$6&"'!"&ROW()&":"&ROW()) )} -> 187857.74 | F9: {=_xlfn.XLOOKUP(1, (INDIRECT("'"&$C$6&"'!$6:$6")=F$6)* (INDIRECT("'"&$C$6&"'!$5:$5")=F$5), INDIRECT("'"&$C$6&"'!"&ROW()&":"&ROW()) )} -> 0 | G9: {=_xlfn.XLOOKUP(1, (INDIRECT("'"&$C$6&"'!$6:$6")=G$6)* (INDIRECT("'"&$C$6&"'!$5:$5")=G$5), INDIRECT("'"&$C$6&"'!"&ROW()&":"&ROW()) )} -> 0 | H9: {=_xlfn.XLOOKUP(1, (INDIRECT("'"&$C$6&"'!$6:$6")=H$6)* (INDIRECT("'"&$C$6&"'!$5:$5")=H$5), INDIRECT("'"&$C$6&"'!"&ROW()&":"&ROW()) )} -> 0 | I9: {=_xlfn.XLOOKUP(1, (INDIRECT("'"&$C$6&"'!$6:$6")=I$6)* (INDIRECT("'"&$C$6&"'!$5:$5")=I$5), INDIRECT("'"&$C$6&"'!"&ROW()&":"&ROW()) )} -> 0 | K9: =$D9-E9 -> -187857.74 | L9: =$D9-F9 -> 0 | M9: =$D9-G9 -> 0 | N9: =$D9-H9 -> 0 | O9: =$D9-I9 -> 0 | Q9: =IFERROR($D9/E9-1,0) -> -1 | R9: =IFERROR($D9/F9-1,0) -> 0 | S9: =IFERROR($D9/G9-1,0) -> 0 | T9: =IFERROR($D9/H9-1,0) -> 0 | U9: =IFERROR($D9/I9-1,0) -> 0 | W9: {=INDIRECT("'"&$C$6&"'!"&ADDRESS(ROW(),COLUMN()+44))} -> 0 | X9: {=INDIRECT("'"&$C$6&"'!"&ADDRESS(ROW(),COLUMN()+44))} -> 187857.74 | Y9: {=INDIRECT("'"&$C$6&"'!"&ADDRESS(ROW(),COLUMN()+44))} -> 0 | Z9: {=INDIRECT("'"&$C$6&"'!"&ADDRESS(ROW(),COLUMN()+44))} -> 0 | AA9: {=INDIRECT("'"&$C$6&"'!"&ADDRESS(ROW(),COLUMN()+44))} -> 0 | AB9: {=INDIRECT("'"&$C$6&"'!"&ADDRESS(ROW(),COLUMN()+44))} -> 0 | AD9: =$W9-X9 -> -187857.74 | AE9: =$W9-Y9 -> 0 | AF9: =$W9-Z9 -> 0 | AG9: =$W9-AA9 -> 0 | AH9: =$W9-AB9 -> 0 | AJ9: =IFERROR($W9/X9-1,0) -> -1 | AK9: =IFERROR($W9/Y9-1,0) -> 0 | AL9: =IFERROR($W9/Z9-1,0) -> 0 | AM9: =IFERROR($W9/AA9-1,0) -> 0 | AN9: =IFERROR($W9/AB9-1,0) -> 0
A10: SALDO_FDP | C10: Vencido y Judicial | D10: {=_xlfn.XLOOKUP(1, (INDIRECT("'"&$C$6&"'!$6:$6")=D$6)* (INDIRECT("'"&$C$6&"'!$5:$5")=D$5), INDIRECT("'"&$C$6&"'!"&ROW()&":"&ROW()) )} -> 0 | E10: {=_xlfn.XLOOKUP(1, (INDIRECT("'"&$C$6&"'!$6:$6")=E$6)* (INDIRECT("'"&$C$6&"'!$5:$5")=E$5), INDIRECT("'"&$C$6&"'!"&ROW()&":"&ROW()) )} -> 242951.26 | F10: {=_xlfn.XLOOKUP(1, (INDIRECT("'"&$C$6&"'!$6:$6")=F$6)* (INDIRECT("'"&$C$6&"'!$5:$5")=F$5), INDIRECT("'"&$C$6&"'!"&ROW()&":"&ROW()) )} -> 0 | G10: {=_xlfn.XLOOKUP(1, (INDIRECT("'"&$C$6&"'!$6:$6")=G$6)* (INDIRECT("'"&$C$6&"'!$5:$5")=G$5), INDIRECT("'"&$C$6&"'!"&ROW()&":"&ROW()) )} -> 0 | H10: {=_xlfn.XLOOKUP(1, (INDIRECT("'"&$C$6&"'!$6:$6")=H$6)* (INDIRECT("'"&$C$6&"'!$5:$5")=H$5), INDIRECT("'"&$C$6&"'!"&ROW()&":"&ROW()) )} -> 0 | I10: {=_xlfn.XLOOKUP(1, (INDIRECT("'"&$C$6&"'!$6:$6")=I$6)* (INDIRECT("'"&$C$6&"'!$5:$5")=I$5), INDIRECT("'"&$C$6&"'!"&ROW()&":"&ROW()) )} -> 0 | K10: =$D10-E10 -> -242951.26 | L10: =$D10-F10 -> 0 | M10: =$D10-G10 -> 0 | N10: =$D10-H10 -> 0 | O10: =$D10-I10 -> 0 | Q10: =IFERROR($D10/E10-1,0) -> -1 | R10: =IFERROR($D10/F10-1,0) -> 0 | S10: =IFERROR($D10/G10-1,0) -> 0 | T10: =IFERROR($D10/H10-1,0) -> 0 | U10: =IFERROR($D10/I10-1,0) -> 0 | W10: {=INDIRECT("'"&$C$6&"'!"&ADDRESS(ROW(),COLUMN()+44))} -> 0 | X10: {=INDIRECT("'"&$C$6&"'!"&ADDRESS(ROW(),COLUMN()+44))} -> 242951.26 | Y10: {=INDIRECT("'"&$C$6&"'!"&ADDRESS(ROW(),COLUMN()+44))} -> 0 | Z10: {=INDIRECT("'"&$C$6&"'!"&ADDRESS(ROW(),COLUMN()+44))} -> 0 | AA10: {=INDIRECT("'"&$C$6&"'!"&ADDRESS(ROW(),COLUMN()+44))} -> 0 | AB10: {=INDIRECT("'"&$C$6&"'!"&ADDRESS(ROW(),COLUMN()+44))} -> 0 | AD10: =$W10-X10 -> -242951.26 | AE10: =$W10-Y10 -> 0 | AF10: =$W10-Z10 -> 0 | AG10: =$W10-AA10 -> 0 | AH10: =$W10-AB10 -> 0 | AJ10: =IFERROR($W10/X10-1,0) -> -1 | AK10: =IFERROR($W10/Y10-1,0) -> 0 | AL10: =IFERROR($W10/Z10-1,0) -> 0 | AM10: =IFERROR($W10/AA10-1,0) -> 0 | AN10: =IFERROR($W10/AB10-1,0) -> 0
C11: Saldo FdP | D11: =SUM(D8:D10) -> 0 | E11: =SUM(E8:E10) -> 5906591.9 | F11: =SUM(F8:F10) -> 0 | G11: =SUM(G8:G10) -> 0 | H11: =SUM(H8:H10) -> 0 | I11: =SUM(I8:I10) -> 0 | K11: =$D11-E11 -> -5906591.9 | L11: =$D11-F11 -> 0 | M11: =$D11-G11 -> 0 | N11: =$D11-H11 -> 0 | O11: =$D11-I11 -> 0 | Q11: =IFERROR($D11/E11-1,0) -> -1 | R11: =IFERROR($D11/F11-1,0) -> 0 | S11: =IFERROR($D11/G11-1,0) -> 0 | T11: =IFERROR($D11/H11-1,0) -> 0 | U11: =IFERROR($D11/I11-1,0) -> 0 | W11: =SUM(W8:W10) -> 0 | X11: =SUM(X8:X10) -> 5906591.9 | Y11: =SUM(Y8:Y10) -> 0 | Z11: =SUM(Z8:Z10) -> 0 | AA11: =SUM(AA8:AA10) -> 0 | AB11: =SUM(AB8:AB10) -> 0 | AD11: =$W11-X11 -> -5906591.9 | AE11: =$W11-Y11 -> 0 | AF11: =$W11-Z11 -> 0 | AG11: =$W11-AA11 -> 0 | AH11: =$W11-AB11 -> 0 | AJ11: =IFERROR($W11/X11-1,0) -> -1 | AK11: =IFERROR($W11/Y11-1,0) -> 0 | AL11: =IFERROR($W11/Z11-1,0) -> 0 | AM11: =IFERROR($W11/AA11-1,0) -> 0 | AN11: =IFERROR($W11/AB11-1,0) -> 0
A14: SALDO_PROM | C14: Vigente | D14: {=_xlfn.XLOOKUP(1, (INDIRECT("'"&$C$6&"'!$6:$6")=D$6)* (INDIRECT("'"&$C$6&"'!$5:$5")=D$5), INDIRECT("'"&$C$6&"'!"&ROW()&":"&ROW()) )} -> 0 | E14: {=_xlfn.XLOOKUP(1, (INDIRECT("'"&$C$6&"'!$6:$6")=E$6)* (INDIRECT("'"&$C$6&"'!$5:$5")=E$5), INDIRECT("'"&$C$6&"'!"&ROW()&":"&ROW()) )} -> 5396941.1 | F14: {=_xlfn.XLOOKUP(1, (INDIRECT("'"&$C$6&"'!$6:$6")=F$6)* (INDIRECT("'"&$C$6&"'!$5:$5")=F$5), INDIRECT("'"&$C$6&"'!"&ROW()&":"&ROW()) )} -> 0 | G14: {=_xlfn.XLOOKUP(1, (INDIRECT("'"&$C$6&"'!$6:$6")=G$6)* (INDIRECT("'"&$C$6&"'!$5:$5")=G$5), INDIRECT("'"&$C$6&"'!"&ROW()&":"&ROW()) )} -> 0 | H14: {=_xlfn.XLOOKUP(1, (INDIRECT("'"&$C$6&"'!$6:$6")=H$6)* (INDIRECT("'"&$C$6&"'!$5:$5")=H$5), INDIRECT("'"&$C$6&"'!"&ROW()&":"&ROW()) )} -> 0 | I14: {=_xlfn.XLOOKUP(1, (INDIRECT("'"&$C$6&"'!$6:$6")=I$6)* (INDIRECT("'"&$C$6&"'!$5:$5")=I$5), INDIRECT("'"&$C$6&"'!"&ROW()&":"&ROW()) )} -> 0 | K14: =$D14-E14 -> -5396941.1 | L14: =$D14-F14 -> 0 | M14: =$D14-G14 -> 0 | N14: =$D14-H14 -> 0 | O14: =$D14-I14 -> 0 | Q14: =IFERROR($D14/E14-1,0) -> -1 | R14: =IFERROR($D14/F14-1,0) -> 0 | S14: =IFERROR($D14/G14-1,0) -> 0 | T14: =IFERROR($D14/H14-1,0) -> 0 | U14: =IFERROR($D14/I14-1,0) -> 0 | W14: {=INDIRECT("'"&$C$6&"'!"&ADDRESS(ROW(),COLUMN()+44))} -> 0 | X14: {=INDIRECT("'"&$C$6&"'!"&ADDRESS(ROW(),COLUMN()+44))} -> 5394716 | Y14: {=INDIRECT("'"&$C$6&"'!"&ADDRESS(ROW(),COLUMN()+44))} -> 0 | Z14: {=INDIRECT("'"&$C$6&"'!"&ADDRESS(ROW(),COLUMN()+44))} -> 0 | AA14: {=INDIRECT("'"&$C$6&"'!"&ADDRESS(ROW(),COLUMN()+44))} -> 0 | AB14: {=INDIRECT("'"&$C$6&"'!"&ADDRESS(ROW(),COLUMN()+44))} -> 0 | AD14: =$W14-X14 -> -5394716 | AE14: =$W14-Y14 -> 0 | AF14: =$W14-Z14 -> 0 | AG14: =$W14-AA14 -> 0 | AH14: =$W14-AB14 -> 0 | AJ14: =IFERROR($W14/X14-1,0) -> -1 | AK14: =IFERROR($W14/Y14-1,0) -> 0 | AL14: =IFERROR($W14/Z14-1,0) -> 0 | AM14: =IFERROR($W14/AA14-1,0) -> 0 | AN14: =IFERROR($W14/AB14-1,0) -> 0
A15: SALDO_PROM | C15: Refinanciado | D15: {=_xlfn.XLOOKUP(1, (INDIRECT("'"&$C$6&"'!$6:$6")=D$6)* (INDIRECT("'"&$C$6&"'!$5:$5")=D$5), INDIRECT("'"&$C$6&"'!"&ROW()&":"&ROW()) )} -> 0 | E15: {=_xlfn.XLOOKUP(1, (INDIRECT("'"&$C$6&"'!$6:$6")=E$6)* (INDIRECT("'"&$C$6&"'!$5:$5")=E$5), INDIRECT("'"&$C$6&"'!"&ROW()&":"&ROW()) )} -> 182009.82 | F15: {=_xlfn.XLOOKUP(1, (INDIRECT("'"&$C$6&"'!$6:$6")=F$6)* (INDIRECT("'"&$C$6&"'!$5:$5")=F$5), INDIRECT("'"&$C$6&"'!"&ROW()&":"&ROW()) )} -> 0 | G15: {=_xlfn.XLOOKUP(1, (INDIRECT("'"&$C$6&"'!$6:$6")=G$6)* (INDIRECT("'"&$C$6&"'!$5:$5")=G$5), INDIRECT("'"&$C$6&"'!"&ROW()&":"&ROW()) )} -> 0 | H15: {=_xlfn.XLOOKUP(1, (INDIRECT("'"&$C$6&"'!$6:$6")=H$6)* (INDIRECT("'"&$C$6&"'!$5:$5")=H$5), INDIRECT("'"&$C$6&"'!"&ROW()&":"&ROW()) )} -> 0 | I15: {=_xlfn.XLOOKUP(1, (INDIRECT("'"&$C$6&"'!$6:$6")=I$6)* (INDIRECT("'"&$C$6&"'!$5:$5")=I$5), INDIRECT("'"&$C$6&"'!"&ROW()&":"&ROW()) )} -> 0 | K15: =$D15-E15 -> -182009.82 | L15: =$D15-F15 -> 0 | M15: =$D15-G15 -> 0 | N15: =$D15-H15 -> 0 | O15: =$D15-I15 -> 0 | Q15: =IFERROR($D15/E15-1,0) -> -1 | R15: =IFERROR($D15/F15-1,0) -> 0 | S15: =IFERROR($D15/G15-1,0) -> 0 | T15: =IFERROR($D15/H15-1,0) -> 0 | U15: =IFERROR($D15/I15-1,0) -> 0 | W15: {=INDIRECT("'"&$C$6&"'!"&ADDRESS(ROW(),COLUMN()+44))} -> 0 | X15: {=INDIRECT("'"&$C$6&"'!"&ADDRESS(ROW(),COLUMN()+44))} -> 183585.17 | Y15: {=INDIRECT("'"&$C$6&"'!"&ADDRESS(ROW(),COLUMN()+44))} -> 0 | Z15: {=INDIRECT("'"&$C$6&"'!"&ADDRESS(ROW(),COLUMN()+44))} -> 0 | AA15: {=INDIRECT("'"&$C$6&"'!"&ADDRESS(ROW(),COLUMN()+44))} -> 0 | AB15: {=INDIRECT("'"&$C$6&"'!"&ADDRESS(ROW(),COLUMN()+44))} -> 0 | AD15: =$W15-X15 -> -183585.17 | AE15: =$W15-Y15 -> 0 | AF15: =$W15-Z15 -> 0 | AG15: =$W15-AA15 -> 0 | AH15: =$W15-AB15 -> 0 | AJ15: =IFERROR($W15/X15-1,0) -> -1 | AK15: =IFERROR($W15/Y15-1,0) -> 0 | AL15: =IFERROR($W15/Z15-1,0) -> 0 | AM15: =IFERROR($W15/AA15-1,0) -> 0 | AN15: =IFERROR($W15/AB15-1,0) -> 0
A16: SALDO_PROM | C16: Vencido y Judicial | D16: {=_xlfn.XLOOKUP(1, (INDIRECT("'"&$C$6&"'!$6:$6")=D$6)* (INDIRECT("'"&$C$6&"'!$5:$5")=D$5), INDIRECT("'"&$C$6&"'!"&ROW()&":"&ROW()) )} -> 0 | E16: {=_xlfn.XLOOKUP(1, (INDIRECT("'"&$C$6&"'!$6:$6")=E$6)* (INDIRECT("'"&$C$6&"'!$5:$5")=E$5), INDIRECT("'"&$C$6&"'!"&ROW()&":"&ROW()) )} -> 271222.21 | F16: {=_xlfn.XLOOKUP(1, (INDIRECT("'"&$C$6&"'!$6:$6")=F$6)* (INDIRECT("'"&$C$6&"'!$5:$5")=F$5), INDIRECT("'"&$C$6&"'!"&ROW()&":"&ROW()) )} -> 0 | G16: {=_xlfn.XLOOKUP(1, (INDIRECT("'"&$C$6&"'!$6:$6")=G$6)* (INDIRECT("'"&$C$6&"'!$5:$5")=G$5), INDIRECT("'"&$C$6&"'!"&ROW()&":"&ROW()) )} -> 0 | H16: {=_xlfn.XLOOKUP(1, (INDIRECT("'"&$C$6&"'!$6:$6")=H$6)* (INDIRECT("'"&$C$6&"'!$5:$5")=H$5), INDIRECT("'"&$C$6&"'!"&ROW()&":"&ROW()) )} -> 0 | I16: {=_xlfn.XLOOKUP(1, (INDIRECT("'"&$C$6&"'!$6:$6")=I$6)* (INDIRECT("'"&$C$6&"'!$5:$5")=I$5), INDIRECT("'"&$C$6&"'!"&ROW()&":"&ROW()) )} -> 0 | K16: =$D16-E16 -> -271222.21 | L16: =$D16-F16 -> 0 | M16: =$D16-G16 -> 0 | N16: =$D16-H16 -> 0 | O16: =$D16-I16 -> 0 | Q16: =IFERROR($D16/E16-1,0) -> -1 | R16: =IFERROR($D16/F16-1,0) -> 0 | S16: =IFERROR($D16/G16-1,0) -> 0 | T16: =IFERROR($D16/H16-1,0) -> 0 | U16: =IFERROR($D16/I16-1,0) -> 0 | W16: {=INDIRECT("'"&$C$6&"'!"&ADDRESS(ROW(),COLUMN()+44))} -> 0 | X16: {=INDIRECT("'"&$C$6&"'!"&ADDRESS(ROW(),COLUMN()+44))} -> 269886.41 | Y16: {=INDIRECT("'"&$C$6&"'!"&ADDRESS(ROW(),COLUMN()+44))} -> 0 | Z16: {=INDIRECT("'"&$C$6&"'!"&ADDRESS(ROW(),COLUMN()+44))} -> 0 | AA16: {=INDIRECT("'"&$C$6&"'!"&ADDRESS(ROW(),COLUMN()+44))} -> 0 | AB16: {=INDIRECT("'"&$C$6&"'!"&ADDRESS(ROW(),COLUMN()+44))} -> 0 | AD16: =$W16-X16 -> -269886.41 | AE16: =$W16-Y16 -> 0 | AF16: =$W16-Z16 -> 0 | AG16: =$W16-AA16 -> 0 | AH16: =$W16-AB16 -> 0 | AJ16: =IFERROR($W16/X16-1,0) -> -1 | AK16: =IFERROR($W16/Y16-1,0) -> 0 | AL16: =IFERROR($W16/Z16-1,0) -> 0 | AM16: =IFERROR($W16/AA16-1,0) -> 0 | AN16: =IFERROR($W16/AB16-1,0) -> 0
C17: Saldo Prom | D17: =SUM(D14:D16) -> 0 | E17: =SUM(E14:E16) -> 5850173.1 | F17: =SUM(F14:F16) -> 0 | G17: =SUM(G14:G16) -> 0 | H17: =SUM(H14:H16) -> 0 | I17: =SUM(I14:I16) -> 0 | K17: =$D17-E17 -> -5850173.1 | L17: =$D17-F17 -> 0 | M17: =$D17-G17 -> 0 | N17: =$D17-H17 -> 0 | O17: =$D17-I17 -> 0 | Q17: =IFERROR($D17/E17-1,0) -> -1 | R17: =IFERROR($D17/F17-1,0) -> 0 | S17: =IFERROR($D17/G17-1,0) -> 0 | T17: =IFERROR($D17/H17-1,0) -> 0 | U17: =IFERROR($D17/I17-1,0) -> 0 | W17: =SUM(W14:W16) -> 0 | X17: =SUM(X14:X16) -> 5848187.6 | Y17: =SUM(Y14:Y16) -> 0 | Z17: =SUM(Z14:Z16) -> 0 | AA17: =SUM(AA14:AA16) -> 0 | AB17: =SUM(AB14:AB16) -> 0 | AD17: =$W17-X17 -> -5848187.6 | AE17: =$W17-Y17 -> 0 | AF17: =$W17-Z17 -> 0 | AG17: =$W17-AA17 -> 0 | AH17: =$W17-AB17 -> 0 | AJ17: =IFERROR($W17/X17-1,0) -> -1 | AK17: =IFERROR($W17/Y17-1,0) -> 0 | AL17: =IFERROR($W17/Z17-1,0) -> 0 | AM17: =IFERROR($W17/AA17-1,0) -> 0 | AN17: =IFERROR($W17/AB17-1,0) -> 0
C20: Vigente | D20: =IFERROR(((1+D38/D14)^(360/D$3))-1,0) -> 0 | E20: =IFERROR(((1+E38/E14)^(360/E$3))-1,0) -> 0.26524722 | F20: =IFERROR(((1+F38/F14)^(360/F$3))-1,0) -> 0 | G20: =IFERROR(((1+G38/G14)^(360/G$3))-1,0) -> 0 | H20: =IFERROR(((1+H38/H14)^(360/H$3))-1,0) -> 0 | I20: =IFERROR(((1+I38/I14)^(360/I$3))-1,0) -> 0 | Q20: =($D20-E20)*10000 -> -2652.4722 | R20: =($D20-F20)*10000 -> 0 | S20: =($D20-G20)*10000 -> 0 | T20: =($D20-H20)*10000 -> 0 | U20: =($D20-I20)*10000 -> 0 | W20: {=INDIRECT("'"&$C$6&"'!"&ADDRESS(ROW(),COLUMN()+44))} -> 0 | X20: {=INDIRECT("'"&$C$6&"'!"&ADDRESS(ROW(),COLUMN()+44))} -> 0.25696584 | Y20: {=INDIRECT("'"&$C$6&"'!"&ADDRESS(ROW(),COLUMN()+44))} -> 0 | Z20: {=INDIRECT("'"&$C$6&"'!"&ADDRESS(ROW(),COLUMN()+44))} -> 0 | AA20: {=INDIRECT("'"&$C$6&"'!"&ADDRESS(ROW(),COLUMN()+44))} -> 0 | AB20: {=INDIRECT("'"&$C$6&"'!"&ADDRESS(ROW(),COLUMN()+44))} -> 0 | AJ20: =($W20-X20)*10000 -> -2569.6584 | AK20: =($W20-Y20)*10000 -> 0 | AL20: =($W20-Z20)*10000 -> 0 | AM20: =($W20-AA20)*10000 -> 0 | AN20: =($W20-AB20)*10000 -> 0
C21: Refinanciado | D21: =IFERROR(((1+D39/D15)^(360/D$3))-1,0) -> 0 | E21: =IFERROR(((1+E39/E15)^(360/E$3))-1,0) -> 0.10621592 | F21: =IFERROR(((1+F39/F15)^(360/F$3))-1,0) -> 0 | G21: =IFERROR(((1+G39/G15)^(360/G$3))-1,0) -> 0 | H21: =IFERROR(((1+H39/H15)^(360/H$3))-1,0) -> 0 | I21: =IFERROR(((1+I39/I15)^(360/I$3))-1,0) -> 0 | Q21: =($D21-E21)*10000 -> -1062.1592 | R21: =($D21-F21)*10000 -> 0 | S21: =($D21-G21)*10000 -> 0 | T21: =($D21-H21)*10000 -> 0 | U21: =($D21-I21)*10000 -> 0 | W21: {=INDIRECT("'"&$C$6&"'!"&ADDRESS(ROW(),COLUMN()+44))} -> 0 | X21: {=INDIRECT("'"&$C$6&"'!"&ADDRESS(ROW(),COLUMN()+44))} -> 0.10616469 | Y21: {=INDIRECT("'"&$C$6&"'!"&ADDRESS(ROW(),COLUMN()+44))} -> 0 | Z21: {=INDIRECT("'"&$C$6&"'!"&ADDRESS(ROW(),COLUMN()+44))} -> 0 | AA21: {=INDIRECT("'"&$C$6&"'!"&ADDRESS(ROW(),COLUMN()+44))} -> 0 | AB21: {=INDIRECT("'"&$C$6&"'!"&ADDRESS(ROW(),COLUMN()+44))} -> 0 | AJ21: =($W21-X21)*10000 -> -1061.6469 | AK21: =($W21-Y21)*10000 -> 0 | AL21: =($W21-Z21)*10000 -> 0 | AM21: =($W21-AA21)*10000 -> 0 | AN21: =($W21-AB21)*10000 -> 0
C22: Vencido y Judicial | D22: =IFERROR(((1+D40/D16)^(360/D$3))-1,0) -> 0 | E22: =IFERROR(((1+E40/E16)^(360/E$3))-1,0) -> 0.185023 | F22: =IFERROR(((1+F40/F16)^(360/F$3))-1,0) -> 0 | G22: =IFERROR(((1+G40/G16)^(360/G$3))-1,0) -> 0 | H22: =IFERROR(((1+H40/H16)^(360/H$3))-1,0) -> 0 | I22: =IFERROR(((1+I40/I16)^(360/I$3))-1,0) -> 0 | Q22: =($D22-E22)*10000 -> -1850.23 | R22: =($D22-F22)*10000 -> 0 | S22: =($D22-G22)*10000 -> 0 | T22: =($D22-H22)*10000 -> 0 | U22: =($D22-I22)*10000 -> 0 | W22: {=INDIRECT("'"&$C$6&"'!"&ADDRESS(ROW(),COLUMN()+44))} -> 0 | X22: {=INDIRECT("'"&$C$6&"'!"&ADDRESS(ROW(),COLUMN()+44))} -> 0.20328197 | Y22: {=INDIRECT("'"&$C$6&"'!"&ADDRESS(ROW(),COLUMN()+44))} -> 0 | Z22: {=INDIRECT("'"&$C$6&"'!"&ADDRESS(ROW(),COLUMN()+44))} -> 0 | AA22: {=INDIRECT("'"&$C$6&"'!"&ADDRESS(ROW(),COLUMN()+44))} -> 0 | AB22: {=INDIRECT("'"&$C$6&"'!"&ADDRESS(ROW(),COLUMN()+44))} -> 0 | AJ22: =($W22-X22)*10000 -> -2032.8197 | AK22: =($W22-Y22)*10000 -> 0 | AL22: =($W22-Z22)*10000 -> 0 | AM22: =($W22-AA22)*10000 -> 0 | AN22: =($W22-AB22)*10000 -> 0
C23: Tasa Implicita | D23: =IFERROR(((1+D41/D17)^(360/D$3))-1,0) -> 0 | E23: =IFERROR(((1+E41/E17)^(360/E$3))-1,0) -> 0.25618833 | F23: =IFERROR(((1+F41/F17)^(360/F$3))-1,0) -> 0 | G23: =IFERROR(((1+G41/G17)^(360/G$3))-1,0) -> 0 | H23: =IFERROR(((1+H41/H17)^(360/H$3))-1,0) -> 0 | I23: =IFERROR(((1+I41/I17)^(360/I$3))-1,0) -> 0 | Q23: =($D23-E23)*10000 -> -2561.8833 | R23: =($D23-F23)*10000 -> 0 | S23: =($D23-G23)*10000 -> 0 | T23: =($D23-H23)*10000 -> 0 | U23: =($D23-I23)*10000 -> 0 | W23: {=INDIRECT("'"&$C$6&"'!"&ADDRESS(ROW(),COLUMN()+44))} -> 0 | X23: {=INDIRECT("'"&$C$6&"'!"&ADDRESS(ROW(),COLUMN()+44))} -> 0.24944315 | Y23: {=INDIRECT("'"&$C$6&"'!"&ADDRESS(ROW(),COLUMN()+44))} -> 0 | Z23: {=INDIRECT("'"&$C$6&"'!"&ADDRESS(ROW(),COLUMN()+44))} -> 0 | AA23: {=INDIRECT("'"&$C$6&"'!"&ADDRESS(ROW(),COLUMN()+44))} -> 0 | AB23: {=INDIRECT("'"&$C$6&"'!"&ADDRESS(ROW(),COLUMN()+44))} -> 0 | AJ23: =($W23-X23)*10000 -> -2494.4315 | AK23: =($W23-Y23)*10000 -> 0 | AL23: =($W23-Z23)*10000 -> 0 | AM23: =($W23-AA23)*10000 -> 0 | AN23: =($W23-AB23)*10000 -> 0
C26: Vigente | D26: =-IFERROR(((1-D44/D14)^(360/D$4))-1,0) -> 0 | E26: =-IFERROR(((1-E44/E14)^(360/E$4))-1,0) -> -0.049630555 | F26: =-IFERROR(((1-F44/F14)^(360/F$4))-1,0) -> 0 | G26: =-IFERROR(((1-G44/G14)^(360/G$4))-1,0) -> 0 | H26: =-IFERROR(((1-H44/H14)^(360/H$4))-1,0) -> 0 | I26: =-IFERROR(((1-I44/I14)^(360/I$4))-1,0) -> 0 | Q26: =($D26-E26)*10000 -> 496.30555 | R26: =($D26-F26)*10000 -> 0 | S26: =($D26-G26)*10000 -> 0 | T26: =($D26-H26)*10000 -> 0 | U26: =($D26-I26)*10000 -> 0 | W26: {=INDIRECT("'"&$C$6&"'!"&ADDRESS(ROW(),COLUMN()+44))} -> 0 | X26: {=INDIRECT("'"&$C$6&"'!"&ADDRESS(ROW(),COLUMN()+44))} -> -0.049891884 | Y26: {=INDIRECT("'"&$C$6&"'!"&ADDRESS(ROW(),COLUMN()+44))} -> 0 | Z26: {=INDIRECT("'"&$C$6&"'!"&ADDRESS(ROW(),COLUMN()+44))} -> 0 | AA26: {=INDIRECT("'"&$C$6&"'!"&ADDRESS(ROW(),COLUMN()+44))} -> 0 | AB26: {=INDIRECT("'"&$C$6&"'!"&ADDRESS(ROW(),COLUMN()+44))} -> 0 | AJ26: =($W26-X26)*10000 -> 498.91884 | AK26: =($W26-Y26)*10000 -> 0 | AL26: =($W26-Z26)*10000 -> 0 | AM26: =($W26-AA26)*10000 -> 0 | AN26: =($W26-AB26)*10000 -> 0
C27: Refinanciado | D27: =-IFERROR(((1-D45/D15)^(360/D$4))-1,0) -> 0 | E27: =-IFERROR(((1-E45/E15)^(360/E$4))-1,0) -> -0.050547378 | F27: =-IFERROR(((1-F45/F15)^(360/F$4))-1,0) -> 0 | G27: =-IFERROR(((1-G45/G15)^(360/G$4))-1,0) -> 0 | H27: =-IFERROR(((1-H45/H15)^(360/H$4))-1,0) -> 0 | I27: =-IFERROR(((1-I45/I15)^(360/I$4))-1,0) -> 0 | Q27: =($D27-E27)*10000 -> 505.47378 | R27: =($D27-F27)*10000 -> 0 | S27: =($D27-G27)*10000 -> 0 | T27: =($D27-H27)*10000 -> 0 | U27: =($D27-I27)*10000 -> 0 | W27: {=INDIRECT("'"&$C$6&"'!"&ADDRESS(ROW(),COLUMN()+44))} -> 0 | X27: {=INDIRECT("'"&$C$6&"'!"&ADDRESS(ROW(),COLUMN()+44))} -> -0.049363761 | Y27: {=INDIRECT("'"&$C$6&"'!"&ADDRESS(ROW(),COLUMN()+44))} -> 0 | Z27: {=INDIRECT("'"&$C$6&"'!"&ADDRESS(ROW(),COLUMN()+44))} -> 0 | AA27: {=INDIRECT("'"&$C$6&"'!"&ADDRESS(ROW(),COLUMN()+44))} -> 0 | AB27: {=INDIRECT("'"&$C$6&"'!"&ADDRESS(ROW(),COLUMN()+44))} -> 0 | AJ27: =($W27-X27)*10000 -> 493.63761 | AK27: =($W27-Y27)*10000 -> 0 | AL27: =($W27-Z27)*10000 -> 0 | AM27: =($W27-AA27)*10000 -> 0 | AN27: =($W27-AB27)*10000 -> 0
C28: Vencido y Judicial | D28: =-IFERROR(((1-D46/D16)^(360/D$4))-1,0) -> 0 | E28: =-IFERROR(((1-E46/E16)^(360/E$4))-1,0) -> -0.046641557 | F28: =-IFERROR(((1-F46/F16)^(360/F$4))-1,0) -> 0 | G28: =-IFERROR(((1-G46/G16)^(360/G$4))-1,0) -> 0 | H28: =-IFERROR(((1-H46/H16)^(360/H$4))-1,0) -> 0 | I28: =-IFERROR(((1-I46/I16)^(360/I$4))-1,0) -> 0 | Q28: =($D28-E28)*10000 -> 466.41557 | R28: =($D28-F28)*10000 -> 0 | S28: =($D28-G28)*10000 -> 0 | T28: =($D28-H28)*10000 -> 0 | U28: =($D28-I28)*10000 -> 0 | W28: {=INDIRECT("'"&$C$6&"'!"&ADDRESS(ROW(),COLUMN()+44))} -> 0 | X28: {=INDIRECT("'"&$C$6&"'!"&ADDRESS(ROW(),COLUMN()+44))} -> -0.047114159 | Y28: {=INDIRECT("'"&$C$6&"'!"&ADDRESS(ROW(),COLUMN()+44))} -> 0 | Z28: {=INDIRECT("'"&$C$6&"'!"&ADDRESS(ROW(),COLUMN()+44))} -> 0 | AA28: {=INDIRECT("'"&$C$6&"'!"&ADDRESS(ROW(),COLUMN()+44))} -> 0 | AB28: {=INDIRECT("'"&$C$6&"'!"&ADDRESS(ROW(),COLUMN()+44))} -> 0 | AJ28: =($W28-X28)*10000 -> 471.14159 | AK28: =($W28-Y28)*10000 -> 0 | AL28: =($W28-Z28)*10000 -> 0 | AM28: =($W28-AA28)*10000 -> 0 | AN28: =($W28-AB28)*10000 -> 0
C29: Tasa FTP | D29: =-IFERROR(((1-D47/D17)^(360/D$4))-1,0) -> 0 | E29: =-IFERROR(((1-E47/E17)^(360/E$4))-1,0) -> -0.049520319 | F29: =-IFERROR(((1-F47/F17)^(360/F$4))-1,0) -> 0 | G29: =-IFERROR(((1-G47/G17)^(360/G$4))-1,0) -> 0 | H29: =-IFERROR(((1-H47/H17)^(360/H$4))-1,0) -> 0 | I29: =-IFERROR(((1-I47/I17)^(360/I$4))-1,0) -> 0 | Q29: =($D29-E29)*10000 -> 495.20319 | R29: =($D29-F29)*10000 -> 0 | S29: =($D29-G29)*10000 -> 0 | T29: =($D29-H29)*10000 -> 0 | U29: =($D29-I29)*10000 -> 0 | W29: {=INDIRECT("'"&$C$6&"'!"&ADDRESS(ROW(),COLUMN()+44))} -> 0 | X29: {=INDIRECT("'"&$C$6&"'!"&ADDRESS(ROW(),COLUMN()+44))} -> -0.049746966 | Y29: {=INDIRECT("'"&$C$6&"'!"&ADDRESS(ROW(),COLUMN()+44))} -> 0 | Z29: {=INDIRECT("'"&$C$6&"'!"&ADDRESS(ROW(),COLUMN()+44))} -> 0 | AA29: {=INDIRECT("'"&$C$6&"'!"&ADDRESS(ROW(),COLUMN()+44))} -> 0 | AB29: {=INDIRECT("'"&$C$6&"'!"&ADDRESS(ROW(),COLUMN()+44))} -> 0 | AJ29: =($W29-X29)*10000 -> 497.46966 | AK29: =($W29-Y29)*10000 -> 0 | AL29: =($W29-Z29)*10000 -> 0 | AM29: =($W29-AA29)*10000 -> 0 | AN29: =($W29-AB29)*10000 -> 0
C32: Vigente | D32: =D20+D26 -> 0 | E32: =E20+E26 -> 0.21561667 | F32: =F20+F26 -> 0 | G32: =G20+G26 -> 0 | H32: =H20+H26 -> 0 | I32: =I20+I26 -> 0 | Q32: =($D32-E32)*10000 -> -2156.1667 | R32: =($D32-F32)*10000 -> 0 | S32: =($D32-G32)*10000 -> 0 | T32: =($D32-H32)*10000 -> 0 | U32: =($D32-I32)*10000 -> 0 | W32: =W20+W26 -> 0 | X32: =X20+X26 -> 0.20707396 | Y32: =Y20+Y26 -> 0 | Z32: =Z20+Z26 -> 0 | AA32: =AA20+AA26 -> 0 | AB32: =AB20+AB26 -> 0 | AJ32: =($W32-X32)*10000 -> -2070.7396 | AK32: =($W32-Y32)*10000 -> 0 | AL32: =($W32-Z32)*10000 -> 0 | AM32: =($W32-AA32)*10000 -> 0 | AN32: =($W32-AB32)*10000 -> 0
C33: Refinanciado | D33: =D21+D27 -> 0 | E33: =E21+E27 -> 0.055668542 | F33: =F21+F27 -> 0 | G33: =G21+G27 -> 0 | H33: =H21+H27 -> 0 | I33: =I21+I27 -> 0 | Q33: =($D33-E33)*10000 -> -556.68542 | R33: =($D33-F33)*10000 -> 0 | S33: =($D33-G33)*10000 -> 0 | T33: =($D33-H33)*10000 -> 0 | U33: =($D33-I33)*10000 -> 0 | W33: =W21+W27 -> 0 | X33: =X21+X27 -> 0.05680093 | Y33: =Y21+Y27 -> 0 | Z33: =Z21+Z27 -> 0 | AA33: =AA21+AA27 -> 0 | AB33: =AB21+AB27 -> 0 | AJ33: =($W33-X33)*10000 -> -568.0093 | AK33: =($W33-Y33)*10000 -> 0 | AL33: =($W33-Z33)*10000 -> 0 | AM33: =($W33-AA33)*10000 -> 0 | AN33: =($W33-AB33)*10000 -> 0
C34: Vencido y Judicial | D34: =D22+D28 -> 0 | E34: =E22+E28 -> 0.13838144 | F34: =F22+F28 -> 0 | G34: =G22+G28 -> 0 | H34: =H22+H28 -> 0 | I34: =I22+I28 -> 0 | Q34: =($D34-E34)*10000 -> -1383.8144 | R34: =($D34-F34)*10000 -> 0 | S34: =($D34-G34)*10000 -> 0 | T34: =($D34-H34)*10000 -> 0 | U34: =($D34-I34)*10000 -> 0 | W34: =W22+W28 -> 0 | X34: =X22+X28 -> 0.15616781 | Y34: =Y22+Y28 -> 0 | Z34: =Z22+Z28 -> 0 | AA34: =AA22+AA28 -> 0 | AB34: =AB22+AB28 -> 0 | AJ34: =($W34-X34)*10000 -> -1561.6781 | AK34: =($W34-Y34)*10000 -> 0 | AL34: =($W34-Z34)*10000 -> 0 | AM34: =($W34-AA34)*10000 -> 0 | AN34: =($W34-AB34)*10000 -> 0
C35: Spread | D35: =D23+D29 -> 0 | E35: =E23+E29 -> 0.20666801 | F35: =F23+F29 -> 0 | G35: =G23+G29 -> 0 | H35: =H23+H29 -> 0 | I35: =I23+I29 -> 0 | Q35: =($D35-E35)*10000 -> -2066.6801 | R35: =($D35-F35)*10000 -> 0 | S35: =($D35-G35)*10000 -> 0 | T35: =($D35-H35)*10000 -> 0 | U35: =($D35-I35)*10000 -> 0 | W35: =W23+W29 -> 0 | X35: =X23+X29 -> 0.19969618 | Y35: =Y23+Y29 -> 0 | Z35: =Z23+Z29 -> 0 | AA35: =AA23+AA29 -> 0 | AB35: =AB23+AB29 -> 0 | AJ35: =($W35-X35)*10000 -> -1996.9618 | AK35: =($W35-Y35)*10000 -> 0 | AL35: =($W35-Z35)*10000 -> 0 | AM35: =($W35-AA35)*10000 -> 0 | AN35: =($W35-AB35)*10000 -> 0
A38: Ingreso_Financiero | C38: Vigente | D38: {=_xlfn.XLOOKUP(1, (INDIRECT("'"&$C$6&"'!$6:$6")=D$6)* (INDIRECT("'"&$C$6&"'!$5:$5")=D$5), INDIRECT("'"&$C$6&"'!"&ROW()&":"&ROW()) )} -> 0 | E38: {=_xlfn.XLOOKUP(1, (INDIRECT("'"&$C$6&"'!$6:$6")=E$6)* (INDIRECT("'"&$C$6&"'!$5:$5")=E$5), INDIRECT("'"&$C$6&"'!"&ROW()&":"&ROW()) )} -> 110452.49 | F38: {=_xlfn.XLOOKUP(1, (INDIRECT("'"&$C$6&"'!$6:$6")=F$6)* (INDIRECT("'"&$C$6&"'!$5:$5")=F$5), INDIRECT("'"&$C$6&"'!"&ROW()&":"&ROW()) )} -> 0 | G38: {=_xlfn.XLOOKUP(1, (INDIRECT("'"&$C$6&"'!$6:$6")=G$6)* (INDIRECT("'"&$C$6&"'!$5:$5")=G$5), INDIRECT("'"&$C$6&"'!"&ROW()&":"&ROW()) )} -> 0 | H38: {=_xlfn.XLOOKUP(1, (INDIRECT("'"&$C$6&"'!$6:$6")=H$6)* (INDIRECT("'"&$C$6&"'!$5:$5")=H$5), INDIRECT("'"&$C$6&"'!"&ROW()&":"&ROW()) )} -> 0 | I38: {=_xlfn.XLOOKUP(1, (INDIRECT("'"&$C$6&"'!$6:$6")=I$6)* (INDIRECT("'"&$C$6&"'!$5:$5")=I$5), INDIRECT("'"&$C$6&"'!"&ROW()&":"&ROW()) )} -> 0 | K38: =$D38-E38 -> -110452.49 | L38: =$D38-F38 -> 0 | M38: =$D38-G38 -> 0 | N38: =$D38-H38 -> 0 | O38: =$D38-I38 -> 0 | Q38: =IFERROR($D38/E38-1,0) -> -1 | R38: =IFERROR($D38/F38-1,0) -> 0 | S38: =IFERROR($D38/G38-1,0) -> 0 | T38: =IFERROR($D38/H38-1,0) -> 0 | U38: =IFERROR($D38/I38-1,0) -> 0 | W38: {=INDIRECT("'"&$C$6&"'!"&ADDRESS(ROW(),COLUMN()+44))} -> 0 | X38: {=INDIRECT("'"&$C$6&"'!"&ADDRESS(ROW(),COLUMN()+44))} -> 311401.9 | Y38: {=INDIRECT("'"&$C$6&"'!"&ADDRESS(ROW(),COLUMN()+44))} -> 0 | Z38: {=INDIRECT("'"&$C$6&"'!"&ADDRESS(ROW(),COLUMN()+44))} -> 0 | AA38: {=INDIRECT("'"&$C$6&"'!"&ADDRESS(ROW(),COLUMN()+44))} -> 0 | AB38: {=INDIRECT("'"&$C$6&"'!"&ADDRESS(ROW(),COLUMN()+44))} -> 0 | AD38: =$W38-X38 -> -311401.9 | AE38: =$W38-Y38 -> 0 | AF38: =$W38-Z38 -> 0 | AG38: =$W38-AA38 -> 0 | AH38: =$W38-AB38 -> 0 | AJ38: =IFERROR($W38/X38-1,0) -> -1 | AK38: =IFERROR($W38/Y38-1,0) -> 0 | AL38: =IFERROR($W38/Z38-1,0) -> 0 | AM38: =IFERROR($W38/AA38-1,0) -> 0 | AN38: =IFERROR($W38/AB38-1,0) -> 0
A39: Ingreso_Financiero | C39: Refinanciado | D39: {=_xlfn.XLOOKUP(1, (INDIRECT("'"&$C$6&"'!$6:$6")=D$6)* (INDIRECT("'"&$C$6&"'!$5:$5")=D$5), INDIRECT("'"&$C$6&"'!"&ROW()&":"&ROW()) )} -> 0 | E39: {=_xlfn.XLOOKUP(1, (INDIRECT("'"&$C$6&"'!$6:$6")=E$6)* (INDIRECT("'"&$C$6&"'!$5:$5")=E$5), INDIRECT("'"&$C$6&"'!"&ROW()&":"&ROW()) )} -> 1589.0159 | F39: {=_xlfn.XLOOKUP(1, (INDIRECT("'"&$C$6&"'!$6:$6")=F$6)* (INDIRECT("'"&$C$6&"'!$5:$5")=F$5), INDIRECT("'"&$C$6&"'!"&ROW()&":"&ROW()) )} -> 0 | G39: {=_xlfn.XLOOKUP(1, (INDIRECT("'"&$C$6&"'!$6:$6")=G$6)* (INDIRECT("'"&$C$6&"'!$5:$5")=G$5), INDIRECT("'"&$C$6&"'!"&ROW()&":"&ROW()) )} -> 0 | H39: {=_xlfn.XLOOKUP(1, (INDIRECT("'"&$C$6&"'!$6:$6")=H$6)* (INDIRECT("'"&$C$6&"'!$5:$5")=H$5), INDIRECT("'"&$C$6&"'!"&ROW()&":"&ROW()) )} -> 0 | I39: {=_xlfn.XLOOKUP(1, (INDIRECT("'"&$C$6&"'!$6:$6")=I$6)* (INDIRECT("'"&$C$6&"'!$5:$5")=I$5), INDIRECT("'"&$C$6&"'!"&ROW()&":"&ROW()) )} -> 0 | K39: =$D39-E39 -> -1589.0159 | L39: =$D39-F39 -> 0 | M39: =$D39-G39 -> 0 | N39: =$D39-H39 -> 0 | O39: =$D39-I39 -> 0 | Q39: =IFERROR($D39/E39-1,0) -> -1 | R39: =IFERROR($D39/F39-1,0) -> 0 | S39: =IFERROR($D39/G39-1,0) -> 0 | T39: =IFERROR($D39/H39-1,0) -> 0 | U39: =IFERROR($D39/I39-1,0) -> 0 | W39: {=INDIRECT("'"&$C$6&"'!"&ADDRESS(ROW(),COLUMN()+44))} -> 0 | X39: {=INDIRECT("'"&$C$6&"'!"&ADDRESS(ROW(),COLUMN()+44))} -> 4650.4042 | Y39: {=INDIRECT("'"&$C$6&"'!"&ADDRESS(ROW(),COLUMN()+44))} -> 0 | Z39: {=INDIRECT("'"&$C$6&"'!"&ADDRESS(ROW(),COLUMN()+44))} -> 0 | AA39: {=INDIRECT("'"&$C$6&"'!"&ADDRESS(ROW(),COLUMN()+44))} -> 0 | AB39: {=INDIRECT("'"&$C$6&"'!"&ADDRESS(ROW(),COLUMN()+44))} -> 0 | AD39: =$W39-X39 -> -4650.4042 | AE39: =$W39-Y39 -> 0 | AF39: =$W39-Z39 -> 0 | AG39: =$W39-AA39 -> 0 | AH39: =$W39-AB39 -> 0 | AJ39: =IFERROR($W39/X39-1,0) -> -1 | AK39: =IFERROR($W39/Y39-1,0) -> 0 | AL39: =IFERROR($W39/Z39-1,0) -> 0 | AM39: =IFERROR($W39/AA39-1,0) -> 0 | AN39: =IFERROR($W39/AB39-1,0) -> 0
