Workbook

Sheet Parametros
B2: Producto | C2: Convenios
B4: Año | C4: 2026
B6: Lista Fechas | C6: =EOMONTH(DATE($C$4,1,1),0) -> 46053 | E6: Segmentos | F6: Renta_Alta
C7: =EOMONTH(C6,1) -> 46081 | F7: Masivo
C8: =EOMONTH(C7,1) -> 46112 | F8: Consumo_Inicial
C9: =EOMONTH(C8,1) -> 46142 | F9: Total_Producto
C10: =EOMONTH(C9,1) -> 46173
C11: =EOMONTH(C10,1) -> 46203
C12: =EOMONTH(C11,1) -> 46234
C13: =EOMONTH(C12,1) -> 46265
C14: =EOMONTH(C13,1) -> 46295
C15: =EOMONTH(C14,1) -> 46326
C16: =EOMONTH(C15,1) -> 46356
C17: =EOMONTH(C16,1) -> 46387

Sheet Total_Producto_CHECK
D1: REAL | AZ1: PRESUPUESTO | BO1: Acumulado | BW1: Saldo Prom Acumulado
BO2: =DATE(YEAR(BO6),1,1) -> 46023 | BP2: =DATE(YEAR(BP6),1,1) -> 46023 | BQ2: =DATE(YEAR(BQ6),1,1) -> 46023 | BR2: =DATE(YEAR(BR6),1,1) -> 45658 | BS2: =DATE(YEAR(BS6),1,1) -> 45292 | BT2: =DATE(YEAR(BT6),1,1) -> 44927
C3: N° dias T.Imp | D3: =DAY(D6) -> 31 | E3: =DAY(E6) -> 28 | F3: =DAY(F6) -> 31 | G3: =DAY(G6) -> 30 | H3: =DAY(H6) -> 31 | I3: =DAY(I6) -> 30 | J3: =DAY(J6) -> 31 | K3: =DAY(K6) -> 31 | ... BK3: =DAY(BK6) -> 31 | BO3: =AVERAGEIFS($D3:$BM3,$D$6:$BM$6,">="&BO$2,$D$6:$BM$6,"<="&BO$6,$D$5:$BM$5,BO$5) -> 30 | BP3: =AVERAGEIFS($D3:$BM3,$D$6:$BM$6,">="&BP$2,$D$6:$BM$6,"<="&BP$6,$D$5:$BM$5,BP$5) -> 30 | BQ3: =AVERAGEIFS($D3:$BM3,$D$6:$BM$6,">="&BQ$2,$D$6:$BM$6,"<="&BQ$6,$D$5:$BM$5,BQ$5) -> 29.5 | BR3: =AVERAGEIFS($D3:$BM3,$D$6:$BM$6,">="&BR$2,$D$6:$BM$6,"<="&BR$6,$D$5:$BM$5,BR$5) -> 30 | BS3: =AVERAGEIFS($D3:$BM3,$D$6:$BM$6,">="&BS$2,$D$6:$BM$6,"<="&BS$6,$D$5:$BM$5,BS$5) -> 30.333333 | BT3: =AVERAGEIFS($D3:$BM3,$D$6:$BM$6,">="&BT$2,$D$6:$BM$6,"<="&BT$6,$D$5:$BM$5,BT$5) -> 30
C4: N° dias FTP | D4: =DAY(D6) -> 31 | E4: =DAY(E6) -> 28 | F4: =DAY(F6) -> 31 | G4: =DAY(G6) -> 30 | H4: =DAY(H6) -> 31 | I4: =DAY(I6) -> 30 | J4: =DAY(J6) -> 31 | K4: =DAY(K6) -> 31 | ... BK4: =DAY(BK6) -> 31 | BO4: =AVERAGEIFS($D4:$BM4,$D$6:$BM$6,">="&BO$2,$D$6:$BM$6,"<="&BO$6,$D$5:$BM$5,BO$5) -> 30 | BP4: =AVERAGEIFS($D4:$BM4,$D$6:$BM$6,">="&BP$2,$D$6:$BM$6,"<="&BP$6,$D$5:$BM$5,BP$5) -> 30 | BQ4: =AVERAGEIFS($D4:$BM4,$D$6:$BM$6,">="&BQ$2,$D$6:$BM$6,"<="&BQ$6,$D$5:$BM$5,BQ$5) -> 29.5 | BR4: =AVERAGEIFS($D4:$BM4,$D$6:$BM$6,">="&BR$2,$D$6:$BM$6,"<="&BR$6,$D$5:$BM$5,BR$5) -> 30 | BS4: =AVERAGEIFS($D4:$BM4,$D$6:$BM$6,">="&BS$2,$D$6:$BM$6,"<="&BS$6,$D$5:$BM$5,BS$5) -> 30.333333 | BT4: =AVERAGEIFS($D4:$BM4,$D$6:$BM$6,">="&BT$2,$D$6:$BM$6,"<="&BT$6,$D$5:$BM$5,BT$5) -> 30
C5: Tipo | D5: R | E5: R | F5: R | G5: R | H5: R | I5: R | J5: R | K5: R | L5: R | M5: R | N5: R | O5: R | P5: R | Q5: R | R5: R | S5: R | T5: R | U5: R | V5: R | W5: R | X5: R | Y5: R | Z5: R | AA5: R | AB5: R | AC5: R | AD5: R | AE5: R | AF5: R | AG5: R | AH5: R | AI5: R | AJ5: R | AK5: R | AL5: R | AM5: R | AN5: R | AO5: R | AP5: R | AQ5: R | AR5: R | AS5: R | AT5: R | AU5: R | AV5: R | AW5: R | AX5: R | AY5: R | AZ5: P | BA5: P | BB5: P | BC5: P | BD5: P | BE5: P | BF5: P | BG5: P | BH5: P | BI5: P | BJ5: P | BK5: P | BO5: R | BP5: P | BQ5: R | BR5: R | BS5: R | BT5: R
C6: Total Préstamos | D6: 44957 | E6: 44985 | F6: 45016 | G6: 45046 | H6: 45077 | I6: 45107 | J6: 45138 | K6: 45169 | L6: 45199 | M6: 45230 | N6: 45260 | O6: 45291 | P6: 45322 | Q6: 45351 | R6: 45382 | S6: 45412 | T6: 45443 | U6: 45473 | V6: 45504 | W6: 45535 | X6: 45565 | Y6: 45596 | Z6: 45626 | AA6: 45657 | AB6: 45688 | AC6: 45716 | AD6: 45747 | AE6: 45777 | AF6: 45808 | AG6: 45838 | AH6: 45869 | AI6: 45900 | AJ6: 45930 | AK6: 45961 | AL6: 45991 | AM6: 46022 | AN6: 46053 | AO6: 46081 | AP6: 46112 | AQ6: 46142 | AR6: 46173 | AS6: 46203 | AT6: 46234 | AU6: 46265 | AV6: 46295 | AW6: 46326 | AX6: 46356 | AY6: 46387 | AZ6: 46053 | BA6: 46081 | BB6: 46112 | BC6: 46142 | BD6: 46173 | BE6: 46203 | BF6: 46234 | BG6: 46265 | BH6: 46295 | BI6: 46326 | BJ6: 46356 | BK6: 46387 | BO6: =Desempeño_Financiero!$B$1 -> 46112 | BP6: =BO6 -> 46112 | BQ6: =EOMONTH(BO6,-1) -> 46081 | BR6: =EOMONTH(BO6,-12) -> 45747 | BS6: =EOMONTH(BO6,-24) -> 45382 | BT6: =EOMONTH(BO6,-36) -> 45016 | BW6: =BO6 -> 46112 | BX6: =BP6 -> 46112 | BY6: =BQ6 -> 46081 | BZ6: =BR6 -> 45747 | CA6: =BS6 -> 45382 | CB6: =BT6 -> 45016
A8: SALDO_FDP | C8: Vigente | D8: =Renta_Alta!D8+Masivo!D8+Consumo_Inicial!D8 -> 3209375.3 | E8: =Renta_Alta!E8+Masivo!E8+Consumo_Inicial!E8 -> 3300088.8 | F8: =Renta_Alta!F8+Masivo!F8+Consumo_Inicial!F8 -> 3421266.2 | G8: =Renta_Alta!G8+Masivo!G8+Consumo_Inicial!G8 -> 3499038.9 | H8: =Renta_Alta!H8+Masivo!H8+Consumo_Inicial!H8 -> 3573142.6 | I8: =Renta_Alta!I8+Masivo!I8+Consumo_Inicial!I8 -> 3630227.9 | J8: =Renta_Alta!J8+Masivo!J8+Consumo_Inicial!J8 -> 3660638.8 | K8: =Renta_Alta!K8+Masivo!K8+Consumo_Inicial!K8 -> 3748310.6 | ... BK8: =Renta_Alta!BK8+Masivo!BK8+Consumo_Inicial!BK8 -> 3478386.4 | BO8: =_xlfn.XLOOKUP(BO$6,$D$6:$BM$6,$D8:$BM8,,0,1) -> 3199553.1 | BP8: =_xlfn.XLOOKUP(BP$6,$D$6:$BM$6,$D8:$BM8,,0,-1) -> 3121000.5 | BQ8: =_xlfn.XLOOKUP(BQ$6,$D$6:$BM$6,$D8:$BM8,,0,1) -> 3154129 | BR8: =_xlfn.XLOOKUP(BR$6,$D$6:$BM$6,$D8:$BM8,,0,1) -> 2864120.5 | BS8: =_xlfn.XLOOKUP(BS$6,$D$6:$BM$6,$D8:$BM8,,0,1) -> 3428790.2 | BT8: =_xlfn.XLOOKUP(BT$6,$D$6:$BM$6,$D8:$BM8,,0,1) -> 3421266.2
A9: SALDO_FDP | C9: Refinanciado | D9: =Renta_Alta!D9+Masivo!D9+Consumo_Inicial!D9 -> 12463.798 | E9: =Renta_Alta!E9+Masivo!E9+Consumo_Inicial!E9 -> 12950.203 | F9: =Renta_Alta!F9+Masivo!F9+Consumo_Inicial!F9 -> 12918.972 | G9: =Renta_Alta!G9+Masivo!G9+Consumo_Inicial!G9 -> 11884.581 | H9: =Renta_Alta!H9+Masivo!H9+Consumo_Inicial!H9 -> 11239.857 | I9: =Renta_Alta!I9+Masivo!I9+Consumo_Inicial!I9 -> 10375.034 | J9: =Renta_Alta!J9+Masivo!J9+Consumo_Inicial!J9 -> 9473.513 | K9: =Renta_Alta!K9+Masivo!K9+Consumo_Inicial!K9 -> 8668.61 | ... BK9: =Renta_Alta!BK9+Masivo!BK9+Consumo_Inicial!BK9 -> 24436.883 | BO9: =_xlfn.XLOOKUP(BO$6,$D$6:$BM$6,$D9:$BM9,,0,1) -> 36825.6 | BP9: =_xlfn.XLOOKUP(BP$6,$D$6:$BM$6,$D9:$BM9,,0,-1) -> 32170.33 | BQ9: =_xlfn.XLOOKUP(BQ$6,$D$6:$BM$6,$D9:$BM9,,0,1) -> 37846.73 | BR9: =_xlfn.XLOOKUP(BR$6,$D$6:$BM$6,$D9:$BM9,,0,1) -> 47040.751 | BS9: =_xlfn.XLOOKUP(BS$6,$D$6:$BM$6,$D9:$BM9,,0,1) -> 8619.8673 | BT9: =_xlfn.XLOOKUP(BT$6,$D$6:$BM$6,$D9:$BM9,,0,1) -> 12918.972
A10: SALDO_FDP | C10: Vencido y Judicial | D10: =Renta_Alta!D10+Masivo!D10+Consumo_Inicial!D10 -> 75075.645 | E10: =Renta_Alta!E10+Masivo!E10+Consumo_Inicial!E10 -> 72983.439 | F10: =Renta_Alta!F10+Masivo!F10+Consumo_Inicial!F10 -> 66041.883 | G10: =Renta_Alta!G10+Masivo!G10+Consumo_Inicial!G10 -> 60991.925 | H10: =Renta_Alta!H10+Masivo!H10+Consumo_Inicial!H10 -> 57791.376 | I10: =Renta_Alta!I10+Masivo!I10+Consumo_Inicial!I10 -> 64002.308 | J10: =Renta_Alta!J10+Masivo!J10+Consumo_Inicial!J10 -> 88094.936 | K10: =Renta_Alta!K10+Masivo!K10+Consumo_Inicial!K10 -> 128190.78 | ... BK10: =Renta_Alta!BK10+Masivo!BK10+Consumo_Inicial!BK10 -> 94244.001 | BO10: =_xlfn.XLOOKUP(BO$6,$D$6:$BM$6,$D10:$BM10,,0,1) -> 84810.02 | BP10: =_xlfn.XLOOKUP(BP$6,$D$6:$BM$6,$D10:$BM10,,0,-1) -> 92303.295 | BQ10: =_xlfn.XLOOKUP(BQ$6,$D$6:$BM$6,$D10:$BM10,,0,1) -> 88358.85 | BR10: =_xlfn.XLOOKUP(BR$6,$D$6:$BM$6,$D10:$BM10,,0,1) -> 109573.14 | BS10: =_xlfn.XLOOKUP(BS$6,$D$6:$BM$6,$D10:$BM10,,0,1) -> 171673.77 | BT10: =_xlfn.XLOOKUP(BT$6,$D$6:$BM$6,$D10:$BM10,,0,1) -> 66041.883
C11: Saldo FdP | D11: =SUM(D8:D10) -> 3296914.8 | E11: =SUM(E8:E10) -> 3386022.5 | F11: =SUM(F8:F10) -> 3500227.1 | G11: =SUM(G8:G10) -> 3571915.4 | H11: =SUM(H8:H10) -> 3642173.9 | I11: =SUM(I8:I10) -> 3704605.2 | J11: =SUM(J8:J10) -> 3758207.2 | K11: =SUM(K8:K10) -> 3885170 | ... BK11: =SUM(BK8:BK10) -> 3597067.3 | BO11: =SUM(BO8:BO10) -> 3321188.7 | BP11: =SUM(BP8:BP10) -> 3245474.1 | BQ11: =SUM(BQ8:BQ10) -> 3280334.6 | BR11: =SUM(BR8:BR10) -> 3020734.4 | BS11: =SUM(BS8:BS10) -> 3609083.8 | BT11: =SUM(BT8:BT10) -> 3500227.1
D12: =[1]Desempeño_Financiero_Evol!BA50-D11 -> -6.0379505e-05 | E12: =[1]Desempeño_Financiero_Evol!BB50-E11 -> 0.00044076005 | F12: =[1]Desempeño_Financiero_Evol!BC50-F11 -> 0.00015937956 | G12: =[1]Desempeño_Financiero_Evol!BD50-G11 -> -0.00044045085 | H12: =[1]Desempeño_Financiero_Evol!BE50-H11 -> -8.0738217e-05 | I12: =[1]Desempeño_Financiero_Evol!BF50-I11 -> 0.00036987895 | J12: =[1]Desempeño_Financiero_Evol!BG50-J11 -> 0.00022914167 | K12: =[1]Desempeño_Financiero_Evol!BH50-K11 -> -4.0450599e-05 | ... AZ12: =[1]Desempeño_Financiero_Evol!CW50-AZ11 -> 0
A14: SALDO_PROM | C14: Vigente | D14: =Renta_Alta!D14+Masivo!D14+Consumo_Inicial!D14 -> 3158143.9 | E14: =Renta_Alta!E14+Masivo!E14+Consumo_Inicial!E14 -> 3223471.9 | F14: =Renta_Alta!F14+Masivo!F14+Consumo_Inicial!F14 -> 3343878.5 | G14: =Renta_Alta!G14+Masivo!G14+Consumo_Inicial!G14 -> 3446583.5 | H14: =Renta_Alta!H14+Masivo!H14+Consumo_Inicial!H14 -> 3525126.4 | I14: =Renta_Alta!I14+Masivo!I14+Consumo_Inicial!I14 -> 3573798.3 | J14: =Renta_Alta!J14+Masivo!J14+Consumo_Inicial!J14 -> 3616394 | K14: =Renta_Alta!K14+Masivo!K14+Consumo_Inicial!K14 -> 3651568.9 | ... BK14: =Renta_Alta!BK14+Masivo!BK14+Consumo_Inicial!BK14 -> 3447409.6 | BO14: =IFERROR(AVERAGEIFS($D14:$BM14,$D$6:$BM$6,">="&BO$2,$D$6:$BM$6,"<="&BO$6,$D$5:$BM$5,BO$5,$D14:$BM14,"<>0"),0) -> 3101496 | BP14: =IFERROR(AVERAGEIFS($D14:$BM14,$D$6:$BM$6,">="&BP$2,$D$6:$BM$6,"<="&BP$6,$D$5:$BM$5,BP$5,$D14:$BM14,"<>0"),0) -> 3059754.3 | BQ14: =IFERROR(AVERAGEIFS($D14:$BM14,$D$6:$BM$6,">="&BQ$2,$D$6:$BM$6,"<="&BQ$6,$D$5:$BM$5,BQ$5,$D14:$BM14,"<>0"),0) -> 3069509.7 | BR14: =IFERROR(AVERAGEIFS($D14:$BM14,$D$6:$BM$6,">="&BR$2,$D$6:$BM$6,"<="&BR$6,$D$5:$BM$5,BR$5,$D14:$BM14,"<>0"),0) -> 2830433.6 | BS14: =IFERROR(AVERAGEIFS($D14:$BM14,$D$6:$BM$6,">="&BS$2,$D$6:$BM$6,"<="&BS$6,$D$5:$BM$5,BS$5,$D14:$BM14,"<>0"),0) -> 3524089.4 | BT14: =IFERROR(AVERAGEIFS($D14:$BM14,$D$6:$BM$6,">="&BT$2,$D$6:$BM$6,"<="&BT$6,$D$5:$BM$5,BT$5,$D14:$BM14,"<>0"),0) -> 3241831.4 | BW14: =SUMIFS($D14:$BM14,$D$6:$BM$6,">="&BO$2,$D$6:$BM$6,"<="&BO$6,$D$5:$BM$5,BO$5) -> 9304488 | BX14: =SUMIFS($D14:$BM14,$D$6:$BM$6,">="&BP$2,$D$6:$BM$6,"<="&BP$6,$D$5:$BM$5,BP$5) -> 9179262.9 | BY14: =SUMIFS($D14:$BM14,$D$6:$BM$6,">="&BQ$2,$D$6:$BM$6,"<="&BQ$6,$D$5:$BM$5,BQ$5) -> 6139019.5 | BZ14: =SUMIFS($D14:$BM14,$D$6:$BM$6,">="&BR$2,$D$6:$BM$6,"<="&BR$6,$D$5:$BM$5,BR$5) -> 8491300.7 | CA14: =SUMIFS($D14:$BM14,$D$6:$BM$6,">="&BS$2,$D$6:$BM$6,"<="&BS$6,$D$5:$BM$5,BS$5) -> 10572268 | CB14: =SUMIFS($D14:$BM14,$D$6:$BM$6,">="&BT$2,$D$6:$BM$6,"<="&BT$6,$D$5:$BM$5,BT$5) -> 9725494.3
A15: SALDO_PROM | C15: Refinanciado | D15: =Renta_Alta!D15+Masivo!D15+Consumo_Inicial!D15 -> 11558.805 | E15: =Renta_Alta!E15+Masivo!E15+Consumo_Inicial!E15 -> 12005.69 | F15: =Renta_Alta!F15+Masivo!F15+Consumo_Inicial!F15 -> 12441.221 | G15: =Renta_Alta!G15+Masivo!G15+Consumo_Inicial!G15 -> 11919.025 | H15: =Renta_Alta!H15+Masivo!H15+Consumo_Inicial!H15 -> 10988.538 | I15: =Renta_Alta!I15+Masivo!I15+Consumo_Inicial!I15 -> 10143.944 | J15: =Renta_Alta!J15+Masivo!J15+Consumo_Inicial!J15 -> 9514.0316 | K15: =Renta_Alta!K15+Masivo!K15+Consumo_Inicial!K15 -> 8636.6127 | ... BK15: =Renta_Alta!BK15+Masivo!BK15+Consumo_Inicial!BK15 -> 23625.138 | BO15: =IFERROR(AVERAGEIFS($D15:$BM15,$D$6:$BM$6,">="&BO$2,$D$6:$BM$6,"<="&BO$6,$D$5:$BM$5,BO$5,$D15:$BM15,"<>0"),0) -> 37137.887 | BP15: =IFERROR(AVERAGEIFS($D15:$BM15,$D$6:$BM$6,">="&BP$2,$D$6:$BM$6,"<="&BP$6,$D$5:$BM$5,BP$5,$D15:$BM15,"<>0"),0) -> 33358.564 | BQ15: =IFERROR(AVERAGEIFS($D15:$BM15,$D$6:$BM$6,">="&BQ$2,$D$6:$BM$6,"<="&BQ$6,$D$5:$BM$5,BQ$5,$D15:$BM15,"<>0"),0) -> 37573.085 | BR15: =IFERROR(AVERAGEIFS($D15:$BM15,$D$6:$BM$6,">="&BR$2,$D$6:$BM$6,"<="&BR$6,$D$5:$BM$5,BR$5,$D15:$BM15,"<>0"),0) -> 44410.208 | BS15: =IFERROR(AVERAGEIFS($D15:$BM15,$D$6:$BM$6,">="&BS$2,$D$6:$BM$6,"<="&BS$6,$D$5:$BM$5,BS$5,$D15:$BM15,"<>0"),0) -> 5713.7241 | BT15: =IFERROR(AVERAGEIFS($D15:$BM15,$D$6:$BM$6,">="&BT$2,$D$6:$BM$6,"<="&BT$6,$D$5:$BM$5,BT$5,$D15:$BM15,"<>0"),0) -> 12001.905 | BW15: =SUMIFS($D15:$BM15,$D$6:$BM$6,">="&BO$2,$D$6:$BM$6,"<="&BO$6,$D$5:$BM$5,BO$5) -> 111413.66 | BX15: =SUMIFS($D15:$BM15,$D$6:$BM$6,">="&BP$2,$D$6:$BM$6,"<="&BP$6,$D$5:$BM$5,BP$5) -> 100075.69 | BY15: =SUMIFS($D15:$BM15,$D$6:$BM$6,">="&BQ$2,$D$6:$BM$6,"<="&BQ$6,$D$5:$BM$5,BQ$5) -> 75146.17 | BZ15: =SUMIFS($D15:$BM15,$D$6:$BM$6,">="&BR$2,$D$6:$BM$6,"<="&BR$6,$D$5:$BM$5,BR$5) -> 133230.62 | CA15: =SUMIFS($D15:$BM15,$D$6:$BM$6,">="&BS$2,$D$6:$BM$6,"<="&BS$6,$D$5:$BM$5,BS$5) -> 17141.172 | CB15: =SUMIFS($D15:$BM15,$D$6:$BM$6,">="&BT$2,$D$6:$BM$6,"<="&BT$6,$D$5:$BM$5,BT$5) -> 36005.715
A16: SALDO_PROM | C16: Vencido y Judicial | D16: =Renta_Alta!D16+Masivo!D16+Consumo_Inicial!D16 -> 87323.449 | E16: =Renta_Alta!E16+Masivo!E16+Consumo_Inicial!E16 -> 87859.363 | F16: =Renta_Alta!F16+Masivo!F16+Consumo_Inicial!F16 -> 78613.723 | G16: =Renta_Alta!G16+Masivo!G16+Consumo_Inicial!G16 -> 75931.779 | H16: =Renta_Alta!H16+Masivo!H16+Consumo_Inicial!H16 -> 68785.835 | I16: =Renta_Alta!I16+Masivo!I16+Consumo_Inicial!I16 -> 75827.007 | J16: =Renta_Alta!J16+Masivo!J16+Consumo_Inicial!J16 -> 90692.774 | K16: =Renta_Alta!K16+Masivo!K16+Consumo_Inicial!K16 -> 138012.13 | ... BK16: =Renta_Alta!BK16+Masivo!BK16+Consumo_Inicial!BK16 -> 107280.77 | BO16: =IFERROR(AVERAGEIFS($D16:$BM16,$D$6:$BM$6,">="&BO$2,$D$6:$BM$6,"<="&BO$6,$D$5:$BM$5,BO$5,$D16:$BM16,"<>0"),0) -> 100528.69 | BP16: =IFERROR(AVERAGEIFS($D16:$BM16,$D$6:$BM$6,">="&BP$2,$D$6:$BM$6,"<="&BP$6,$D$5:$BM$5,BP$5,$D16:$BM16,"<>0"),0) -> 110684.55 | BQ16: =IFERROR(AVERAGEIFS($D16:$BM16,$D$6:$BM$6,">="&BQ$2,$D$6:$BM$6,"<="&BQ$6,$D$5:$BM$5,BQ$5,$D16:$BM16,"<>0"),0) -> 102470.95 | BR16: =IFERROR(AVERAGEIFS($D16:$BM16,$D$6:$BM$6,">="&BR$2,$D$6:$BM$6,"<="&BR$6,$D$5:$BM$5,BR$5,$D16:$BM16,"<>0"),0) -> 133756.47 | BS16: =IFERROR(AVERAGEIFS($D16:$BM16,$D$6:$BM$6,">="&BS$2,$D$6:$BM$6,"<="&BS$6,$D$5:$BM$5,BS$5,$D16:$BM16,"<>0"),0) -> 178374.56 | BT16: =IFERROR(AVERAGEIFS($D16:$BM16,$D$6:$BM$6,">="&BT$2,$D$6:$BM$6,"<="&BT$6,$D$5:$BM$5,BT$5,$D16:$BM16,"<>0"),0) -> 84598.845 | BW16: =SUMIFS($D16:$BM16,$D$6:$BM$6,">="&BO$2,$D$6:$BM$6,"<="&BO$6,$D$5:$BM$5,BO$5) -> 301586.06 | BX16: =SUMIFS($D16:$BM16,$D$6:$BM$6,">="&BP$2,$D$6:$BM$6,"<="&BP$6,$D$5:$BM$5,BP$5) -> 332053.64 | BY16: =SUMIFS($D16:$BM16,$D$6:$BM$6,">="&BQ$2,$D$6:$BM$6,"<="&BQ$6,$D$5:$BM$5,BQ$5) -> 204941.9 | BZ16: =SUMIFS($D16:$BM16,$D$6:$BM$6,">="&BR$2,$D$6:$BM$6,"<="&BR$6,$D$5:$BM$5,BR$5) -> 401269.42 | CA16: =SUMIFS($D16:$BM16,$D$6:$BM$6,">="&BS$2,$D$6:$BM$6,"<="&BS$6,$D$5:$BM$5,BS$5) -> 535123.68 | CB16: =SUMIFS($D16:$BM16,$D$6:$BM$6,">="&BT$2,$D$6:$BM$6,"<="&BT$6,$D$5:$BM$5,BT$5) -> 253796.54
C17: Saldo Prom | D17: =SUM(D14:D16) -> 3257026.1 | E17: =SUM(E14:E16) -> 3323336.9 | F17: =SUM(F14:F16) -> 3434933.5 | G17: =SUM(G14:G16) -> 3534434.3 | H17: =SUM(H14:H16) -> 3604900.7 | I17: =SUM(I14:I16) -> 3659769.2 | J17: =SUM(J14:J16) -> 3716600.8 | K17: =SUM(K14:K16) -> 3798217.6 | ... BK17: =SUM(BK14:BK16) -> 3578315.5 | BO17: =SUM(BO14:BO16) -> 3239162.6 | BP17: =SUM(BP14:BP16) -> 3203797.4 | BQ17: =SUM(BQ14:BQ16) -> 3209553.8 | BR17: =SUM(BR14:BR16) -> 3008600.2 | BS17: =SUM(BS14:BS16) -> 3708177.7 | BT17: =SUM(BT14:BT16) -> 3338432.2 | BW17: =SUM(BW14:BW16) -> 9717487.8 | BX17: =SUM(BX14:BX16) -> 9611392.3 | BY17: =SUM(BY14:BY16) -> 6419107.6 | BZ17: =SUM(BZ14:BZ16) -> 9025800.7 | CA17: =SUM(CA14:CA16) -> 11124533 | CB17: =SUM(CB14:CB16) -> 10015297
D18: =[1]Desempeño_Financiero_Evol!BA95-D17 -> 0.00010901969 | E18: =[1]Desempeño_Financiero_Evol!BB95-E17 -> 0.00057051983 | F18: =[1]Desempeño_Financiero_Evol!BC95-F17 -> 0.00040940102 | G18: =[1]Desempeño_Financiero_Evol!BD95-G17 -> -0.00050120056 | H18: =[1]Desempeño_Financiero_Evol!BE95-H17 -> 0.00011985935 | I18: =[1]Desempeño_Financiero_Evol!BF95-I17 -> -0.00047100056 | J18: =[1]Desempeño_Financiero_Evol!BG95-J17 -> 0.00043020025 | K18: =[1]Desempeño_Financiero_Evol!BH95-K17 -> 0.00027984008 | ... AZ18: =[1]Desempeño_Financiero_Evol!CW95-AZ17 -> 0
C20: Vigente | D20: =IFERROR(((1+D38/D14)^(360/D$3))-1,0) -> 0.18688844 | E20: =IFERROR(((1+E38/E14)^(360/E$3))-1,0) -> 0.18929111 | F20: =IFERROR(((1+F38/F14)^(360/F$3))-1,0) -> 0.18709846 | G20: =IFERROR(((1+G38/G14)^(360/G$3))-1,0) -> 0.18094853 | H20: =IFERROR(((1+H38/H14)^(360/H$3))-1,0) -> 0.19026482 | I20: =IFERROR(((1+I38/I14)^(360/I$3))-1,0) -> 0.18959246 | J20: =IFERROR(((1+J38/J14)^(360/J$3))-1,0) -> 0.18872508 | K20: =IFERROR(((1+K38/K14)^(360/K$3))-1,0) -> 0.18941062 | ... BK20: =IFERROR(((1+BK38/BK14)^(360/BK$3))-1,0) -> 0.17626555 | BO20: =IFERROR(((1+BO38/BW14)^(360/BO$3))-1,0) -> 0.16764934 | BP20: =IFERROR(((1+BP38/BX14)^(360/BP$3))-1,0) -> 0.16628708 | BQ20: =IFERROR(((1+BQ38/BY14)^(360/BQ$3))-1,0) -> 0.16803228 | BR20: =IFERROR(((1+BR38/BZ14)^(360/BR$3))-1,0) -> 0.17002459 | BS20: =IFERROR(((1+BS38/CA14)^(360/BS$3))-1,0) -> 0.17330211 | BT20: =IFERROR(((1+BT38/CB14)^(360/BT$3))-1,0) -> 0.18774684
C21: Refinanciado | D21: =IFERROR(((1+D39/D15)^(360/D$3))-1,0) -> 0.07153226 | E21: =IFERROR(((1+E39/E15)^(360/E$3))-1,0) -> 0.080577761 | F21: =IFERROR(((1+F39/F15)^(360/F$3))-1,0) -> 0.060315445 | G21: =IFERROR(((1+G39/G15)^(360/G$3))-1,0) -> 0.052107325 | H21: =IFERROR(((1+H39/H15)^(360/H$3))-1,0) -> 0.05691557 | I21: =IFERROR(((1+I39/I15)^(360/I$3))-1,0) -> 0.057134391 | J21: =IFERROR(((1+J39/J15)^(360/J$3))-1,0) -> 0.065817453 | K21: =IFERROR(((1+K39/K15)^(360/K$3))-1,0) -> 0.067622921 | ... BK21: =IFERROR(((1+BK39/BK15)^(360/BK$3))-1,0) -> 0.072416048 | BO21: =IFERROR(((1+BO39/BW15)^(360/BO$3))-1,0) -> 0.077494623 | BP21: =IFERROR(((1+BP39/BX15)^(360/BP$3))-1,0) -> 0.072375067 | BQ21: =IFERROR(((1+BQ39/BY15)^(360/BQ$3))-1,0) -> 0.077073241 | BR21: =IFERROR(((1+BR39/BZ15)^(360/BR$3))-1,0) -> 0.065973937 | BS21: =IFERROR(((1+BS39/CA15)^(360/BS$3))-1,0) -> 0.074294711 | BT21: =IFERROR(((1+BT39/CB15)^(360/BT$3))-1,0) -> 0.070310613
C22: Vencido y Judicial | D22: =IFERROR(((1+D40/D16)^(360/D$3))-1,0) -> 0.063222147 | E22: =IFERROR(((1+E40/E16)^(360/E$3))-1,0) -> 0.036767038 | F22: =IFERROR(((1+F40/F16)^(360/F$3))-1,0) -> 0.055202672 | G22: =IFERROR(((1+G40/G16)^(360/G$3))-1,0) -> 0.059740187 | H22: =IFERROR(((1+H40/H16)^(360/H$3))-1,0) -> 0.097736874 | I22: =IFERROR(((1+I40/I16)^(360/I$3))-1,0) -> 0.078366095 | J22: =IFERROR(((1+J40/J16)^(360/J$3))-1,0) -> 0.090724347 | K22: =IFERROR(((1+K40/K16)^(360/K$3))-1,0) -> 0.062407939 | ... BK22: =IFERROR(((1+BK40/BK16)^(360/BK$3))-1,0) -> 0.088150151 | BO22: =IFERROR(((1+BO40/BW16)^(360/BO$3))-1,0) -> 0.092717636 | BP22: =IFERROR(((1+BP40/BX16)^(360/BP$3))-1,0) -> 0.090299602 | BQ22: =IFERROR(((1+BQ40/BY16)^(360/BQ$3))-1,0) -> 0.094298888 | BR22: =IFERROR(((1+BR40/BZ16)^(360/BR$3))-1,0) -> 0.095011803 | BS22: =IFERROR(((1+BS40/CA16)^(360/BS$3))-1,0) -> 0.062221607 | BT22: =IFERROR(((1+BT40/CB16)^(360/BT$3))-1,0) -> 0.051973131
C23: Tasa Implicita | D23: =IFERROR(((1+D41/D17)^(360/D$3))-1,0) -> 0.18298074 | E23: =IFERROR(((1+E41/E17)^(360/E$3))-1,0) -> 0.18459697 | F23: =IFERROR(((1+F41/F17)^(360/F$3))-1,0) -> 0.18343664 | G23: =IFERROR(((1+G41/G17)^(360/G$3))-1,0) -> 0.17775947 | H23: =IFERROR(((1+H41/H17)^(360/H$3))-1,0) -> 0.18800632 | I23: =IFERROR(((1+I41/I17)^(360/I$3))-1,0) -> 0.18679854 | J23: =IFERROR(((1+J41/J17)^(360/J$3))-1,0) -> 0.18591102 | K23: =IFERROR(((1+K41/K17)^(360/K$3))-1,0) -> 0.18427341 | ... BK23: =IFERROR(((1+BK41/BK17)^(360/BK$3))-1,0) -> 0.17281843 | BO23: =IFERROR(((1+BO41/BW17)^(360/BO$3))-1,0) -> 0.16418505 | BP23: =IFERROR(((1+BP41/BX17)^(360/BP$3))-1,0) -> 0.1625696 | BQ23: =IFERROR(((1+BQ41/BY17)^(360/BQ$3))-1,0) -> 0.1645071 | BR23: =IFERROR(((1+BR41/BZ17)^(360/BR$3))-1,0) -> 0.16499509 | BS23: =IFERROR(((1+BS41/CA17)^(360/BS$3))-1,0) -> 0.16756622 | BT23: =IFERROR(((1+BT41/CB17)^(360/BT$3))-1,0) -> 0.18367537
C26: Vigente | D26: =-IFERROR(((1-D44/D14)^(360/D$4))-1,0) -> -0.069457728 | E26: =-IFERROR(((1-E44/E14)^(360/E$4))-1,0) -> -0.072006399 | F26: =-IFERROR(((1-F44/F14)^(360/F$4))-1,0) -> -0.073901929 | G26: =-IFERROR(((1-G44/G14)^(360/G$4))-1,0) -> -0.075135078 | H26: =-IFERROR(((1-H44/H14)^(360/H$4))-1,0) -> -0.075853357 | I26: =-IFERROR(((1-I44/I14)^(360/I$4))-1,0) -> -0.077094293 | J26: =-IFERROR(((1-J44/J14)^(360/J$4))-1,0) -> -0.07695435 | K26: =-IFERROR(((1-K44/K14)^(360/K$4))-1,0) -> -0.076826417 | ... BK26: =-IFERROR(((1-BK44/BK14)^(360/BK$4))-1,0) -> -0.060135204 | BO26: =-IFERROR(((1-BO44/BW14)^(360/BO$4))-1,0) -> -0.061733011 | BP26: =-IFERROR(((1-BP44/BX14)^(360/BP$4))-1,0) -> -0.063725702 | BQ26: =-IFERROR(((1-BQ44/BY14)^(360/BQ$4))-1,0) -> -0.062110866 | BR26: =-IFERROR(((1-BR44/BZ14)^(360/BR$4))-1,0) -> -0.07018776 | BS26: =-IFERROR(((1-BS44/CA14)^(360/BS$4))-1,0) -> -0.077652319 | BT26: =-IFERROR(((1-BT44/CB14)^(360/BT$4))-1,0) -> -0.071837695
C27: Refinanciado | D27: =-IFERROR(((1-D45/D15)^(360/D$4))-1,0) -> -0.072502366 | E27: =-IFERROR(((1-E45/E15)^(360/E$4))-1,0) -> -0.075540719 | F27: =-IFERROR(((1-F45/F15)^(360/F$4))-1,0) -> -0.077408172 | G27: =-IFERROR(((1-G45/G15)^(360/G$4))-1,0) -> -0.078030669 | H27: =-IFERROR(((1-H45/H15)^(360/H$4))-1,0) -> -0.078639826 | I27: =-IFERROR(((1-I45/I15)^(360/I$4))-1,0) -> -0.078234923 | J27: =-IFERROR(((1-J45/J15)^(360/J$4))-1,0) -> -0.077147722 | K27: =-IFERROR(((1-K45/K15)^(360/K$4))-1,0) -> -0.075473063 | ... BK27: =-IFERROR(((1-BK45/BK15)^(360/BK$4))-1,0) -> -0.01409196 | BO27: =-IFERROR(((1-BO45/BW15)^(360/BO$4))-1,0) -> -0.062334564 | BP27: =-IFERROR(((1-BP45/BX15)^(360/BP$4))-1,0) -> -0.0098278781 | BQ27: =-IFERROR(((1-BQ45/BY15)^(360/BQ$4))-1,0) -> -0.062503812 | BR27: =-IFERROR(((1-BR45/BZ15)^(360/BR$4))-1,0) -> -0.066453036 | BS27: =-IFERROR(((1-BS45/CA15)^(360/BS$4))-1,0) -> -0.075895307 | BT27: =-IFERROR(((1-BT45/CB15)^(360/BT$4))-1,0) -> -0.075197445
C28: Vencido y Judicial | D28: =-IFERROR(((1-D46/D16)^(360/D$4))-1,0) -> -0.043371127 | E28: =-IFERROR(((1-E46/E16)^(360/E$4))-1,0) -> -0.043510018 | F28: =-IFERROR(((1-F46/F16)^(360/F$4))-1,0) -> -0.044435647 | G28: =-IFERROR(((1-G46/G16)^(360/G$4))-1,0) -> -0.045703919 | H28: =-IFERROR(((1-H46/H16)^(360/H$4))-1,0) -> -0.048523676 | I28: =-IFERROR(((1-I46/I16)^(360/I$4))-1,0) -> -0.074620188 | J28: =-IFERROR(((1-J46/J16)^(360/J$4))-1,0) -> -0.058808875 | K28: =-IFERROR(((1-K46/K16)^(360/K$4))-1,0) -> -0.077288629 | ... BK28: =-IFERROR(((1-BK46/BK16)^(360/BK$4))-1,0) -> -0.051043832 | BO28: =-IFERROR(((1-BO46/BW16)^(360/BO$4))-1,0) -> -0.0695619 | BP28: =-IFERROR(((1-BP46/BX16)^(360/BP$4))-1,0) -> -0.049273724 | BQ28: =-IFERROR(((1-BQ46/BY16)^(360/BQ$4))-1,0) -> -0.069947202 | BR28: =-IFERROR(((1-BR46/BZ16)^(360/BR$4))-1,0) -> -0.076444819 | BS28: =-IFERROR(((1-BS46/CA16)^(360/BS$4))-1,0) -> -0.072862045 | BT28: =-IFERROR(((1-BT46/CB16)^(360/BT$4))-1,0) -> -0.043699913
C29: Tasa FTP | D29: =-IFERROR(((1-D47/D17)^(360/D$4))-1,0) -> -0.068761404 | E29: =-IFERROR(((1-E47/E17)^(360/E$4))-1,0) -> -0.071256634 | F29: =-IFERROR(((1-F47/F17)^(360/F$4))-1,0) -> -0.073231814 | G29: =-IFERROR(((1-G47/G17)^(360/G$4))-1,0) -> -0.074504643 | H29: =-IFERROR(((1-H47/H17)^(360/H$4))-1,0) -> -0.075334319 | I29: =-IFERROR(((1-I47/I17)^(360/I$4))-1,0) -> -0.077046139 | J29: =-IFERROR(((1-J47/J17)^(360/J$4))-1,0) -> -0.076508696 | K29: =-IFERROR(((1-K47/K17)^(360/K$4))-1,0) -> -0.07684013 | ... BK29: =-IFERROR(((1-BK47/BK17)^(360/BK$4))-1,0) -> -0.059551513 | BO29: =-IFERROR(((1-BO47/BW17)^(360/BO$4))-1,0) -> -0.061982088 | BP29: =-IFERROR(((1-BP47/BX17)^(360/BP$4))-1,0) -> -0.062649114 | BQ29: =-IFERROR(((1-BQ47/BY17)^(360/BQ$4))-1,0) -> -0.06236484 | BR29: =-IFERROR(((1-BR47/BZ17)^(360/BR$4))-1,0) -> -0.070409998 | BS29: =-IFERROR(((1-BS47/CA17)^(360/BS$4))-1,0) -> -0.077418736 | BT29: =-IFERROR(((1-BT47/CB17)^(360/BT$4))-1,0) -> -0.071128209
C32: Vigente | D32: =D20+D26 -> 0.11743071 | E32: =E20+E26 -> 0.11728471 | F32: =F20+F26 -> 0.11319653 | G32: =G20+G26 -> 0.10581345 | H32: =H20+H26 -> 0.11441147 | I32: =I20+I26 -> 0.11249816 | J32: =J20+J26 -> 0.11177073 | K32: =K20+K26 -> 0.1125842 | ... BK32: =BK20+BK26 -> 0.11613035 | BO32: =BO20+BO26 -> 0.10591633 | BP32: =BP20+BP26 -> 0.10256137 | BQ32: =BQ20+BQ26 -> 0.10592141 | BR32: =BR20+BR26 -> 0.099836833 | BS32: =BS20+BS26 -> 0.09564979 | BT32: =BT20+BT26 -> 0.11590915
C33: Refinanciado | D33: =D21+D27 -> -0.00097010657 | E33: =E21+E27 -> 0.0050370413 | F33: =F21+F27 -> -0.017092727 | G33: =G21+G27 -> -0.025923344 | H33: =H21+H27 -> -0.021724256 | I33: =I21+I27 -> -0.021100532 | J33: =J21+J27 -> -0.011330269 | K33: =K21+K27 -> -0.0078501421 | ... BK33: =BK21+BK27 -> 0.058324088 | BO33: =BO21+BO27 -> 0.015160059 | BP33: =BP21+BP27 -> 0.062547189 | BQ33: =BQ21+BQ27 -> 0.014569429 | BR33: =BR21+BR27 -> -0.00047909846 | BS33: =BS21+BS27 -> -0.0016005962 | BT33: =BT21+BT27 -> -0.0048868324
C34: Vencido y Judicial | D34: =D22+D28 -> 0.01985102 | E34: =E22+E28 -> -0.0067429794 | F34: =F22+F28 -> 0.010767026 | G34: =G22+G28 -> 0.014036268 | H34: =H22+H28 -> 0.049213197 | I34: =I22+I28 -> 0.0037459069 | J34: =J22+J28 -> 0.031915472 | K34: =K22+K28 -> -0.014880689 | ... BK34: =BK22+BK28 -> 0.037106319 | BO34: =BO22+BO28 -> 0.023155736 | BP34: =BP22+BP28 -> 0.041025878 | BQ34: =BQ22+BQ28 -> 0.024351687 | BR34: =BR22+BR28 -> 0.018566984 | BS34: =BS22+BS28 -> -0.010640438 | BT34: =BT22+BT28 -> 0.0082732183
C35: Spread | D35: =D23+D29 -> 0.11421934 | E35: =E23+E29 -> 0.11334033 | F35: =F23+F29 -> 0.11020483 | G35: =G23+G29 -> 0.10325483 | H35: =H23+H29 -> 0.112672 | I35: =I23+I29 -> 0.10975241 | J35: =J23+J29 -> 0.10940233 | K35: =K23+K29 -> 0.10743328 | ... BK35: =BK23+BK29 -> 0.11326692 | BO35: =BO23+BO29 -> 0.10220296 | BP35: =BP23+BP29 -> 0.099920484 | BQ35: =BQ23+BQ29 -> 0.10214226 | BR35: =BR23+BR29 -> 0.094585094 | BS35: =BS23+BS29 -> 0.090147487 | BT35: =BT23+BT29 -> 0.11254716
A38: Ingreso_Financiero | C38: Vigente | D38: =Renta_Alta!D38+Masivo!D38+Consumo_Inicial!D38 -> 46940.23 | E38: =Renta_Alta!E38+Masivo!E38+Consumo_Inicial!E38 -> 43757.553 | F38: =Renta_Alta!F38+Masivo!F38+Consumo_Inicial!F38 -> 49752.553 | G38: =Renta_Alta!G38+Masivo!G38+Consumo_Inicial!G38 -> 48101.629 | H38: =Renta_Alta!H38+Masivo!H38+Consumo_Inicial!H38 -> 53270 | I38: =Renta_Alta!I38+Masivo!I38+Consumo_Inicial!I38 -> 52079.985 | J38: =Renta_Alta!J38+Masivo!J38+Consumo_Inicial!J38 -> 54240.017 | K38: =Renta_Alta!K38+Masivo!K38+Consumo_Inicial!K38 -> 54951.593 | ... BK38: =Renta_Alta!BK38+Masivo!BK38+Consumo_Inicial!BK38 -> 48532.114 | BO38: =SUMIFS($D38:$BM38,$D$6:$BM$6,">="&BO$2,$D$6:$BM$6,"<="&BO$6,$D$5:$BM$5,BO$5) -> 120956.71 | BP38: =SUMIFS($D38:$BM38,$D$6:$BM$6,">="&BP$2,$D$6:$BM$6,"<="&BP$6,$D$5:$BM$5,BP$5) -> 118424.28 | BQ38: =SUMIFS($D38:$BM38,$D$6:$BM$6,">="&BQ$2,$D$6:$BM$6,"<="&BQ$6,$D$5:$BM$5,BQ$5) -> 78634.669 | BR38: =SUMIFS($D38:$BM38,$D$6:$BM$6,">="&BR$2,$D$6:$BM$6,"<="&BR$6,$D$5:$BM$5,BR$5) -> 111842.2 | BS38: =SUMIFS($D38:$BM38,$D$6:$BM$6,">="&BS$2,$D$6:$BM$6,"<="&BS$6,$D$5:$BM$5,BS$5) -> 143334.29 | BT38: =SUMIFS($D38:$BM38,$D$6:$BM$6,">="&BT$2,$D$6:$BM$6,"<="&BT$6,$D$5:$BM$5,BT$5) -> 140450.34
A39: Ingreso_Financiero | C39: Refinanciado | D39: =Renta_Alta!D39+Masivo!D39+Consumo_Inicial!D39 -> 68.97276 | E39: =Renta_Alta!E39+Masivo!E39+Consumo_Inicial!E39 -> 72.58229 | F39: =Renta_Alta!F39+Masivo!F39+Consumo_Inicial!F39 -> 62.902324 | G39: =Renta_Alta!G39+Masivo!G39+Consumo_Inicial!G39 -> 50.5593 | H39: =Renta_Alta!H39+Masivo!H39+Consumo_Inicial!H39 -> 52.503721 | I39: =Renta_Alta!I39+Masivo!I39+Consumo_Inicial!I39 -> 47.076919 | J39: =Renta_Alta!J39+Masivo!J39+Consumo_Inicial!J39 -> 52.365151 | K39: =Renta_Alta!K39+Masivo!K39+Consumo_Inicial!K39 -> 48.801623 | ... BK39: =Renta_Alta!BK39+Masivo!BK39+Consumo_Inicial!BK39 -> 142.66132 | BO39: =SUMIFS($D39:$BM39,$D$6:$BM$6,">="&BO$2,$D$6:$BM$6,"<="&BO$6,$D$5:$BM$5,BO$5) -> 695.13913 | BP39: =SUMIFS($D39:$BM39,$D$6:$BM$6,">="&BP$2,$D$6:$BM$6,"<="&BP$6,$D$5:$BM$5,BP$5) -> 584.43966 | BQ39: =SUMIFS($D39:$BM39,$D$6:$BM$6,">="&BQ$2,$D$6:$BM$6,"<="&BQ$6,$D$5:$BM$5,BQ$5) -> 458.59514 | BR39: =SUMIFS($D39:$BM39,$D$6:$BM$6,">="&BR$2,$D$6:$BM$6,"<="&BR$6,$D$5:$BM$5,BR$5) -> 711.22118 | BS39: =SUMIFS($D39:$BM39,$D$6:$BM$6,">="&BS$2,$D$6:$BM$6,"<="&BS$6,$D$5:$BM$5,BS$5) -> 103.81815 | BT39: =SUMIFS($D39:$BM39,$D$6:$BM$6,">="&BT$2,$D$6:$BM$6,"<="&BT$6,$D$5:$BM$5,BT$5) -> 204.45737
A40: Ingreso_Financiero | C40: Vencido y Judicial | D40: =Renta_Alta!D40+Masivo!D40+Consumo_Inicial!D40 -> 462.19593 | E40: =Renta_Alta!E40+Masivo!E40+Consumo_Inicial!E40 -> 247.08593 | F40: =Renta_Alta!F40+Masivo!F40+Consumo_Inicial!F40 -> 364.58819 | G40: =Renta_Alta!G40+Masivo!G40+Consumo_Inicial!G40 -> 368.0431 | H40: =Renta_Alta!H40+Masivo!H40+Consumo_Inicial!H40 -> 554.56828 | I40: =Renta_Alta!I40+Masivo!I40+Consumo_Inicial!I40 -> 478.24533 | J40: =Renta_Alta!J40+Masivo!J40+Consumo_Inicial!J40 -> 680.74838 | K40: =Renta_Alta!K40+Masivo!K40+Consumo_Inicial!K40 -> 721.33468 | ... BK40: =Renta_Alta!BK40+Masivo!BK40+Consumo_Inicial!BK40 -> 783.26951 | BO40: =SUMIFS($D40:$BM40,$D$6:$BM$6,">="&BO$2,$D$6:$BM$6,"<="&BO$6,$D$5:$BM$5,BO$5) -> 2236.6685 | BP40: =SUMIFS($D40:$BM40,$D$6:$BM$6,">="&BP$2,$D$6:$BM$6,"<="&BP$6,$D$5:$BM$5,BP$5) -> 2400.8776 | BQ40: =SUMIFS($D40:$BM40,$D$6:$BM$6,">="&BQ$2,$D$6:$BM$6,"<="&BQ$6,$D$5:$BM$5,BQ$5) -> 1518.9602 | BR40: =SUMIFS($D40:$BM40,$D$6:$BM$6,">="&BR$2,$D$6:$BM$6,"<="&BR$6,$D$5:$BM$5,BR$5) -> 3046.6137 | BS40: =SUMIFS($D40:$BM40,$D$6:$BM$6,">="&BS$2,$D$6:$BM$6,"<="&BS$6,$D$5:$BM$5,BS$5) -> 2728.6286 | BT40: =SUMIFS($D40:$BM40,$D$6:$BM$6,">="&BT$2,$D$6:$BM$6,"<="&BT$6,$D$5:$BM$5,BT$5) -> 1073.8701
C41: Ingreso Financiero | D41: =SUM(D38:D40) -> 47471.399 | E41: =SUM(E38:E40) -> 44077.222 | F41: =SUM(F38:F40) -> 50180.044 | G41: =SUM(G38:G40) -> 48520.232 | H41: =SUM(H38:H40) -> 53877.072 | I41: =SUM(I38:I40) -> 52605.307 | J41: =SUM(J38:J40) -> 54973.13 | K41: =SUM(K38:K40) -> 55721.729 | ... BK41: =SUM(BK38:BK40) -> 49458.045 | BO41: =SUM(BO38:BO40) -> 123888.52 | BP41: =SUM(BP38:BP40) -> 121409.6 | BQ41: =SUM(BQ38:BQ40) -> 80612.224 | BR41: =SUM(BR38:BR40) -> 115600.03 | BS41: =SUM(BS38:BS40) -> 146166.74 | BT41: =SUM(BT38:BT40) -> 141728.66
A44: FTP | C44: Vigente | D44: =Renta_Alta!D44+Masivo!D44+Consumo_Inicial!D44 -> -18314.899 | E44: =Renta_Alta!E44+Masivo!E44+Consumo_Inicial!E44 -> -17479.911 | F44: =Renta_Alta!F44+Masivo!F44+Consumo_Inicial!F44 -> -20593.257 | G44: =Renta_Alta!G44+Masivo!G44+Consumo_Inicial!G44 -> -20870.624 | H44: =Renta_Alta!H44+Masivo!H44+Consumo_Inicial!H44 -> -22264.005 | I44: =Renta_Alta!I44+Masivo!I44+Consumo_Inicial!I44 -> -22186.508 | J44: =Renta_Alta!J44+Masivo!J44+Consumo_Inicial!J44 -> -23160.984 | K44: =Renta_Alta!K44+Masivo!K44+Consumo_Inicial!K44 -> -23348.666 | ... BK44: =Renta_Alta!BK44+Masivo!BK44+Consumo_Inicial!BK44 -> -17379.246 | BO44: =SUMIFS($D44:$BM44,$D$6:$BM$6,">="&BO$2,$D$6:$BM$6,"<="&BO$6,$D$5:$BM$5,BO$5) -> -46562.954 | BP44: =SUMIFS($D44:$BM44,$D$6:$BM$6,">="&BP$2,$D$6:$BM$6,"<="&BP$6,$D$5:$BM$5,BP$5) -> -47377.887 | BQ44: =SUMIFS($D44:$BM44,$D$6:$BM$6,">="&BQ$2,$D$6:$BM$6,"<="&BQ$6,$D$5:$BM$5,BQ$5) -> -30388.423 | BR44: =SUMIFS($D44:$BM44,$D$6:$BM$6,">="&BR$2,$D$6:$BM$6,"<="&BR$6,$D$5:$BM$5,BR$5) -> -48135.909 | BS44: =SUMIFS($D44:$BM44,$D$6:$BM$6,">="&BS$2,$D$6:$BM$6,"<="&BS$6,$D$5:$BM$5,BS$5) -> -66829.581 | BT44: =SUMIFS($D44:$BM44,$D$6:$BM$6,">="&BT$2,$D$6:$BM$6,"<="&BT$6,$D$5:$BM$5,BT$5) -> -56388.067
A45: FTP | C45: Refinanciado | D45: =Renta_Alta!D45+Masivo!D45+Consumo_Inicial!D45 -> -69.87889 | E45: =Renta_Alta!E45+Masivo!E45+Consumo_Inicial!E45 -> -68.1938 | F45: =Renta_Alta!F45+Masivo!F45+Consumo_Inicial!F45 -> -80.133327 | G45: =Renta_Alta!G45+Masivo!G45+Consumo_Inicial!G45 -> -74.863039 | H45: =Renta_Alta!H45+Masivo!H45+Consumo_Inicial!H45 -> -71.864765 | I45: =Renta_Alta!I45+Masivo!I45+Consumo_Inicial!I45 -> -63.874961 | J45: =Renta_Alta!J45+Masivo!J45+Consumo_Inicial!J45 -> -61.080093 | K45: =Renta_Alta!K45+Masivo!K45+Consumo_Inicial!K45 -> -54.282557 | ... BK45: =Renta_Alta!BK45+Masivo!BK45+Consumo_Inicial!BK45 -> -28.485538 | BO45: =SUMIFS($D45:$BM45,$D$6:$BM$6,">="&BO$2,$D$6:$BM$6,"<="&BO$6,$D$5:$BM$5,BO$5) -> -562.83874 | BP45: =SUMIFS($D45:$BM45,$D$6:$BM$6,">="&BP$2,$D$6:$BM$6,"<="&BP$6,$D$5:$BM$5,BP$5) -> -81.594087 | BQ45: =SUMIFS($D45:$BM45,$D$6:$BM$6,">="&BQ$2,$D$6:$BM$6,"<="&BQ$6,$D$5:$BM$5,BQ$5) -> -374.266 | BR45: =SUMIFS($D45:$BM45,$D$6:$BM$6,">="&BR$2,$D$6:$BM$6,"<="&BR$6,$D$5:$BM$5,BR$5) -> -716.23679 | BS45: =SUMIFS($D45:$BM45,$D$6:$BM$6,">="&BS$2,$D$6:$BM$6,"<="&BS$6,$D$5:$BM$5,BS$5) -> -105.98158 | BT45: =SUMIFS($D45:$BM45,$D$6:$BM$6,">="&BT$2,$D$6:$BM$6,"<="&BT$6,$D$5:$BM$5,BT$5) -> -218.20602
A46: FTP | C46: Vencido y Judicial | D46: =Renta_Alta!D46+Masivo!D46+Consumo_Inicial!D46 -> -319.84008 | E46: =Renta_Alta!E46+Masivo!E46+Consumo_Inicial!E46 -> -291.52192 | F46: =Renta_Alta!F46+Masivo!F46+Consumo_Inicial!F46 -> -294.86772 | G46: =Renta_Alta!G46+Masivo!G46+Consumo_Inicial!G46 -> -283.31151 | H46: =Renta_Alta!H46+Masivo!H46+Consumo_Inicial!H46 -> -281.23442 | I46: =Renta_Alta!I46+Masivo!I46+Consumo_Inicial!I46 -> -456.1217 | J46: =Renta_Alta!J46+Masivo!J46+Consumo_Inicial!J46 -> -447.37926 | K46: =Renta_Alta!K46+Masivo!K46+Consumo_Inicial!K46 -> -887.60258 | ... BK46: =Renta_Alta!BK46+Masivo!BK46+Consumo_Inicial!BK46 -> -460.89323 | BO46: =SUMIFS($D46:$BM46,$D$6:$BM$6,">="&BO$2,$D$6:$BM$6,"<="&BO$6,$D$5:$BM$5,BO$5) -> -1694.8612 | BP46: =SUMIFS($D46:$BM46,$D$6:$BM$6,">="&BP$2,$D$6:$BM$6,"<="&BP$6,$D$5:$BM$5,BP$5) -> -1333.6037 | BQ46: =SUMIFS($D46:$BM46,$D$6:$BM$6,">="&BQ$2,$D$6:$BM$6,"<="&BQ$6,$D$5:$BM$5,BQ$5) -> -1138.5715 | BR46: =SUMIFS($D46:$BM46,$D$6:$BM$6,">="&BR$2,$D$6:$BM$6,"<="&BR$6,$D$5:$BM$5,BR$5) -> -2470.8278 | BS46: =SUMIFS($D46:$BM46,$D$6:$BM$6,">="&BS$2,$D$6:$BM$6,"<="&BS$6,$D$5:$BM$5,BS$5) -> -3180.5275 | BT46: =SUMIFS($D46:$BM46,$D$6:$BM$6,">="&BT$2,$D$6:$BM$6,"<="&BT$6,$D$5:$BM$5,BT$5) -> -906.22973
C47: Costo de Fondos | D47: =SUM(D44:D46) -> -18704.618 | E47: =SUM(E44:E46) -> -17839.626 | F47: =SUM(F44:F46) -> -20968.258 | G47: =SUM(G44:G46) -> -21228.799 | H47: =SUM(H44:H46) -> -22617.104 | I47: =SUM(I44:I46) -> -22706.505 | J47: =SUM(J44:J46) -> -23669.444 | K47: =SUM(K44:K46) -> -24290.551 | ... BK47: =SUM(BK44:BK46) -> -17868.625 | BO47: =SUM(BO44:BO46) -> -48820.654 | BP47: =SUM(BP44:BP46) -> -48793.085 | BQ47: =SUM(BQ44:BQ46) -> -31901.26 | BR47: =SUM(BR44:BR46) -> -51322.974 | BS47: =SUM(BS44:BS46) -> -70116.09 | BT47: =SUM(BT44:BT46) -> -57512.503
C50: Vigente | D50: =D38+D44 -> 28625.331 | E50: =E38+E44 -> 26277.643 | F50: =F38+F44 -> 29159.296 | G50: =G38+G44 -> 27231.005 | H50: =H38+H44 -> 31005.996 | I50: =I38+I44 -> 29893.477 | J50: =J38+J44 -> 31079.032 | K50: =K38+K44 -> 31602.927 | ... BK50: =BK38+BK44 -> 31152.868 | BO50: =BO38+BO44 -> 74393.754 | BP50: =BP38+BP44 -> 71046.397 | BQ50: =BQ38+BQ44 -> 48246.246 | BR50: =BR38+BR44 -> 63706.288 | BS50: =BS38+BS44 -> 76504.711 | BT50: =BT38+BT44 -> 84062.27
C51: Refinanciado | D51: =D39+D45 -> -0.90613 | E51: =E39+E45 -> 4.38849 | F51: =F39+F45 -> -17.231003 | G51: =G39+G45 -> -24.303739 | H51: =H39+H45 -> -19.361045 | I51: =I39+I45 -> -16.798041 | J51: =J39+J45 -> -8.7149414 | K51: =K39+K45 -> -5.4809338 | ... BK51: =BK39+BK45 -> 114.17578 | BO51: =BO39+BO45 -> 132.30039 | BP51: =BP39+BP45 -> 502.84558 | BQ51: =BQ39+BQ45 -> 84.32914 | BR51: =BR39+BR45 -> -5.0156101 | BS51: =BS39+BS45 -> -2.16343 | BT51: =BT39+BT45 -> -13.748643
C52: Vencido y Judicial | D52: =D40+D46 -> 142.35585 | E52: =E40+E46 -> -44.435994 | F52: =F40+F46 -> 69.720474 | G52: =G40+G46 -> 84.731595 | H52: =H40+H46 -> 273.33386 | I52: =I40+I46 -> 22.123629 | J52: =J40+J46 -> 233.36912 | K52: =K40+K46 -> -166.2679 | ... BK52: =BK40+BK46 -> 322.37627 | BO52: =BO40+BO46 -> 541.80728 | BP52: =BP40+BP46 -> 1067.2739 | BQ52: =BQ40+BQ46 -> 380.38869 | BR52: =BR40+BR46 -> 575.78597 | BS52: =BS40+BS46 -> -451.89887 | BT52: =BT40+BT46 -> 167.64033
C53: Resultado Financiero Bruto | D53: =D41+D47 -> 28766.781 | E53: =E41+E47 -> 26237.595 | F53: =F41+F47 -> 29211.785 | G53: =G41+G47 -> 27291.433 | H53: =H41+H47 -> 31259.968 | I53: =I41+I47 -> 29898.802 | J53: =J41+J47 -> 31303.687 | K53: =K41+K47 -> 31431.178 | ... BK53: =BK41+BK47 -> 31589.42 | BO53: =SUM(BO50:BO52) -> 75067.861 | BP53: =SUM(BP50:BP52) -> 72616.517 | BQ53: =SUM(BQ50:BQ52) -> 48710.964 | BR53: =SUM(BR50:BR52) -> 64277.059 | BS53: =SUM(BS50:BS52) -> 76050.649 | BT53: =SUM(BT50:BT52) -> 84216.161
...

Sheet Desempeño_Financiero
B1: 46112 | D1: Mensual | W1: Acumulado
B2: Desempeño Financiero
B3: En S/. Miles | C3: N° dias T.Imp | D3: =DAY(D6) -> 31 | E3: =DAY(E6) -> 31 | F3: =DAY(F6) -> 28 | G3: =DAY(G6) -> 31 | H3: =DAY(H6) -> 31 | I3: =DAY(I6) -> 31
C4: N° dias FTP | D4: =DAY(D6) -> 31 | E4: =DAY(E6) -> 31 | F4: =DAY(F6) -> 28 | G4: =DAY(G6) -> 31 | H4: =DAY(H6) -> 31 | I4: =DAY(I6) -> 31
C5: Tipo | D5: R | E5: P | F5: R | G5: R | H5: R | I5: R | K5: Variación S/. | Q5: Variación % | AD5: Variación S/. | AJ5: Variación %
C6: Total_Producto | D6: =$B$1 -> 46112 | E6: =D6 -> 46112 | F6: =EOMONTH(D6,-1) -> 46081 | G6: =EOMONTH(D6,-12) -> 45747 | H6: =EOMONTH(D6,-24) -> 45382 | I6: =EOMONTH(D6,-36) -> 45016 | K6: =E6 -> 46112 | L6: =F6 -> 46081 | M6: =G6 -> 45747 | N6: =H6 -> 45382 | O6: =I6 -> 45016 | Q6: =K6 -> 46112 | R6: =L6 -> 46081 | S6: =M6 -> 45747 | T6: =N6 -> 45382 | U6: =O6 -> 45016 | W6: =$B$1 -> 46112 | X6: =W6 -> 46112 | Y6: =EOMONTH(W6,-1) -> 46081 | Z6: =EOMONTH(W6,-12) -> 45747 | AA6: =EOMONTH(W6,-24) -> 45382 | AB6: =EOMONTH(W6,-36) -> 45016 | AD6: =X6 -> 46112 | AE6: =Y6 -> 46081 | AF6: =Z6 -> 45747 | AG6: =AA6 -> 45382 | AH6: =AB6 -> 45016 | AJ6: =AD6 -> 46112 | AK6: =AE6 -> 46081 | AL6: =AF6 -> 45747 | AM6: =AG6 -> 45382 | AN6: =AH6 -> 45016
A8: SALDO_FDP | C8: Vigente | D8: {=_xlfn.XLOOKUP(1, (INDIRECT("'"&$C$6&"'!$6:$6")=D$6)* (INDIRECT("'"&$C$6&"'!$5:$5")=D$5), INDIRECT("'"&$C$6&"'!"&ROW()&":"&ROW()) )} -> 3199553.1 | E8: {=_xlfn.XLOOKUP(1, (INDIRECT("'"&$C$6&"'!$6:$6")=E$6)* (INDIRECT("'"&$C$6&"'!$5:$5")=E$5), INDIRECT("'"&$C$6&"'!"&ROW()&":"&ROW()) )} -> 3121000.5 | F8: {=_xlfn.XLOOKUP(1, (INDIRECT("'"&$C$6&"'!$6:$6")=F$6)* (INDIRECT("'"&$C$6&"'!$5:$5")=F$5), INDIRECT("'"&$C$6&"'!"&ROW()&":"&ROW()) )} -> 3154129 | G8: {=_xlfn.XLOOKUP(1, (INDIRECT("'"&$C$6&"'!$6:$6")=G$6)* (INDIRECT("'"&$C$6&"'!$5:$5")=G$5), INDIRECT("'"&$C$6&"'!"&ROW()&":"&ROW()) )} -> 2864120.5 | H8: {=_xlfn.XLOOKUP(1, (INDIRECT("'"&$C$6&"'!$6:$6")=H$6)* (INDIRECT("'"&$C$6&"'!$5:$5")=H$5), INDIRECT("'"&$C$6&"'!"&ROW()&":"&ROW()) )} -> 3428790.2 | I8: {=_xlfn.XLOOKUP(1, (INDIRECT("'"&$C$6&"'!$6:$6")=I$6)* (INDIRECT("'"&$C$6&"'!$5:$5")=I$5), INDIRECT("'"&$C$6&"'!"&ROW()&":"&ROW()) )} -> 3421266.2 | K8: =$D8-E8 -> 78552.563 | L8: =$D8-F8 -> 45424.07 | M8: =$D8-G8 -> 335432.56 | N8: =$D8-H8 -> -229237.14 | O8: =$D8-I8 -> -221713.16 | Q8: =IFERROR($D8/E8-1,0) -> 0.025169033 | R8: =IFERROR($D8/F8-1,0) -> 0.014401462 | S8: =IFERROR($D8/G8-1,0) -> 0.11711538 | T8: =IFERROR($D8/H8-1,0) -> -0.066856565 | U8: =IFERROR($D8/I8-1,0) -> -0.064804415 | W8: {=INDIRECT("'"&$C$6&"'!"&ADDRESS(ROW(),COLUMN()+44))} -> 3199553.1 | X8: {=INDIRECT("'"&$C$6&"'!"&ADDRESS(ROW(),COLUMN()+44))} -> 3121000.5 | Y8: {=INDIRECT("'"&$C$6&"'!"&ADDRESS(ROW(),COLUMN()+44))} -> 3154129 | Z8: {=INDIRECT("'"&$C$6&"'!"&ADDRESS(ROW(),COLUMN()+44))} -> 2864120.5 | AA8: {=INDIRECT("'"&$C$6&"'!"&ADDRESS(ROW(),COLUMN()+44))} -> 3428790.2 | AB8: {=INDIRECT("'"&$C$6&"'!"&ADDRESS(ROW(),COLUMN()+44))} -> 3421266.2 | AD8: =$W8-X8 -> 78552.563 | AE8: =$W8-Y8 -> 45424.07 | AF8: =$W8-Z8 -> 335432.56 | AG8: =$W8-AA8 -> -229237.14 | AH8: =$W8-AB8 -> -221713.16 | AJ8: =IFERROR($W8/X8-1,0) -> 0.025169033 | AK8: =IFERROR($W8/Y8-1,0) -> 0.014401462 | AL8: =IFERROR($W8/Z8-1,0) -> 0.11711538 | AM8: =IFERROR($W8/AA8-1,0) -> -0.066856565 | AN8: =IFERROR($W8/AB8-1,0) -> -0.064804415
A9: SALDO_FDP | C9: Refinanciado | D9: {=_xlfn.XLOOKUP(1, (INDIRECT("'"&$C$6&"'!$6:$6")=D$6)* (INDIRECT("'"&$C$6&"'!$5:$5")=D$5), INDIRECT("'"&$C$6&"'!"&ROW()&":"&ROW()) )} -> 36825.6 | E9: {=_xlfn.XLOOKUP(1, (INDIRECT("'"&$C$6&"'!$6:$6")=E$6)* (INDIRECT("'"&$C$6&"'!$5:$5")=E$5), INDIRECT("'"&$C$6&"'!"&ROW()&":"&ROW()) )} -> 32170.33 | F9: {=_xlfn.XLOOKUP(1, (INDIRECT("'"&$C$6&"'!$6:$6")=F$6)* (INDIRECT("'"&$C$6&"'!$5:$5")=F$5), INDIRECT("'"&$C$6&"'!"&ROW()&":"&ROW()) )} -> 37846.73 | G9: {=_xlfn.XLOOKUP(1, (INDIRECT("'"&$C$6&"'!$6:$6")=G$6)* (INDIRECT("'"&$C$6&"'!$5:$5")=G$5), INDIRECT("'"&$C$6&"'!"&ROW()&":"&ROW()) )} -> 47040.751 | H9: {=_xlfn.XLOOKUP(1, (INDIRECT("'"&$C$6&"'!$6:$6")=H$6)* (INDIRECT("'"&$C$6&"'!$5:$5")=H$5), INDIRECT("'"&$C$6&"'!"&ROW()&":"&ROW()) )} -> 8619.8673 | I9: {=_xlfn.XLOOKUP(1, (INDIRECT("'"&$C$6&"'!$6:$6")=I$6)* (INDIRECT("'"&$C$6&"'!$5:$5")=I$5), INDIRECT("'"&$C$6&"'!"&ROW()&":"&ROW()) )} -> 12918.972 | K9: =$D9-E9 -> 4655.2696 | L9: =$D9-F9 -> -1021.13 | M9: =$D9-G9 -> -10215.151 | N9: =$D9-H9 -> 28205.733 | O9: =$D9-I9 -> 23906.628 | Q9: =IFERROR($D9/E9-1,0) -> 0.14470692 | R9: =IFERROR($D9/F9-1,0) -> -0.026980666 | S9: =IFERROR($D9/G9-1,0) -> -0.21715535 | T9: =IFERROR($D9/H9-1,0) -> 3.2721771 | U9: =IFERROR($D9/I9-1,0) -> 1.8505053 | W9: {=INDIRECT("'"&$C$6&"'!"&ADDRESS(ROW(),COLUMN()+44))} -> 36825.6 | X9: {=INDIRECT("'"&$C$6&"'!"&ADDRESS(ROW(),COLUMN()+44))} -> 32170.33 | Y9: {=INDIRECT("'"&$C$6&"'!"&ADDRESS(ROW(),COLUMN()+44))} -> 37846.73 | Z9: {=INDIRECT("'"&$C$6&"'!"&ADDRESS(ROW(),COLUMN()+44))} -> 47040.751 | AA9: {=INDIRECT("'"&$C$6&"'!"&ADDRESS(ROW(),COLUMN()+44))} -> 8619.8673 | AB9: {=INDIRECT("'"&$C$6&"'!"&ADDRESS(ROW(),COLUMN()+44))} -> 12918.972 | AD9: =$W9-X9 -> 4655.2696 | AE9: =$W9-Y9 -> -1021.13 | AF9: =$W9-Z9 -> -10215.151 | AG9: =$W9-AA9 -> 28205.733 | AH9: =$W9-AB9 -> 23906.628 | AJ9: =IFERROR($W9/X9-1,0) -> 0.14470692 | AK9: =IFERROR($W9/Y9-1,0) -> -0.026980666 | AL9: =IFERROR($W9/Z9-1,0) -> -0.21715535 | AM9: =IFERROR($W9/AA9-1,0) -> 3.2721771 | AN9: =IFERROR($W9/AB9-1,0) -> 1.8505053
A10: SALDO_FDP | C10: Vencido y Judicial | D10: {=_xlfn.XLOOKUP(1, (INDIRECT("'"&$C$6&"'!$6:$6")=D$6)* (INDIRECT("'"&$C$6&"'!$5:$5")=D$5), INDIRECT("'"&$C$6&"'!"&ROW()&":"&ROW()) )} -> 84810.02 | E10: {=_xlfn.XLOOKUP(1, (INDIRECT("'"&$C$6&"'!$6:$6")=E$6)* (INDIRECT("'"&$C$6&"'!$5:$5")=E$5), INDIRECT("'"&$C$6&"'!"&ROW()&":"&ROW()) )} -> 92303.295 | F10: {=_xlfn.XLOOKUP(1, (INDIRECT("'"&$C$6&"'!$6:$6")=F$6)* (INDIRECT("'"&$C$6&"'!$5:$5")=F$5), INDIRECT("'"&$C$6&"'!"&ROW()&":"&ROW()) )} -> 88358.85 | G10: {=_xlfn.XLOOKUP(1, (INDIRECT("'"&$C$6&"'!$6:$6")=G$6)* (INDIRECT("'"&$C$6&"'!$5:$5")=G$5), INDIRECT("'"&$C$6&"'!"&ROW()&":"&ROW()) )} -> 109573.14 | H10: {=_xlfn.XLOOKUP(1, (INDIRECT("'"&$C$6&"'!$6:$6")=H$6)* (INDIRECT("'"&$C$6&"'!$5:$5")=H$5), INDIRECT("'"&$C$6&"'!"&ROW()&":"&ROW()) )} -> 171673.77 | I10: {=_xlfn.XLOOKUP(1, (INDIRECT("'"&$C$6&"'!$6:$6")=I$6)* (INDIRECT("'"&$C$6&"'!$5:$5")=I$5), INDIRECT("'"&$C$6&"'!"&ROW()&":"&ROW()) )} -> 66041.883 | K10: =$D10-E10 -> -7493.2753 | L10: =$D10-F10 -> -3548.83 | M10: =$D10-G10 -> -24763.117 | N10: =$D10-H10 -> -86863.754 | O10: =$D10-I10 -> 18768.137 | Q10: =IFERROR($D10/E10-1,0) -> -0.081181016 | R10: =IFERROR($D10/F10-1,0) -> -0.040163832 | S10: =IFERROR($D10/G10-1,0) -> -0.22599624 | T10: =IFERROR($D10/H10-1,0) -> -0.5059815 | U10: =IFERROR($D10/I10-1,0) -> 0.28418537 | W10: {=INDIRECT("'"&$C$6&"'!"&ADDRESS(ROW(),COLUMN()+44))} -> 84810.02 | X10: {=INDIRECT("'"&$C$6&"'!"&ADDRESS(ROW(),COLUMN()+44))} -> 92303.295 | Y10: {=INDIRECT("'"&$C$6&"'!"&ADDRESS(ROW(),COLUMN()+44))} -> 88358.85 | Z10: {=INDIRECT("'"&$C$6&"'!"&ADDRESS(ROW(),COLUMN()+44))} -> 109573.14 | AA10: {=INDIRECT("'"&$C$6&"'!"&ADDRESS(ROW(),COLUMN()+44))} -> 171673.77 | AB10: {=INDIRECT("'"&$C$6&"'!"&ADDRESS(ROW(),COLUMN()+44))} -> 66041.883 | AD10: =$W10-X10 -> -7493.2753 | AE10: =$W10-Y10 -> -3548.83 | AF10: =$W10-Z10 -> -24763.117 | AG10: =$W10-AA10 -> -86863.754 | AH10: =$W10-AB10 -> 18768.137 | AJ10: =IFERROR($W10/X10-1,0) -> -0.081181016 | AK10: =IFERROR($W10/Y10-1,0) -> -0.040163832 | AL10: =IFERROR($W10/Z10-1,0) -> -0.22599624 | AM10: =IFERROR($W10/AA10-1,0) -> -0.5059815 | AN10: =IFERROR($W10/AB10-1,0) -> 0.28418537
C11: Saldo FdP | D11: =SUM(D8:D10) -> 3321188.7 | E11: =SUM(E8:E10) -> 3245474.1 | F11: =SUM(F8:F10) -> 3280334.6 | G11: =SUM(G8:G10) -> 3020734.4 | H11: =SUM(H8:H10) -> 3609083.8 | I11: =SUM(I8:I10) -> 3500227.1 | K11: =$D11-E11 -> 75714.557 | L11: =$D11-F11 -> 40854.11 | M11: =$D11-G11 -> 300454.3 | N11: =$D11-H11 -> -287895.16 | O11: =$D11-I11 -> -179038.39 | Q11: =IFERROR($D11/E11-1,0) -> 0.023329275 | R11: =IFERROR($D11/F11-1,0) -> 0.012454251 | S11: =IFERROR($D11/G11-1,0) -> 0.099463991 | T11: =IFERROR($D11/H11-1,0) -> -0.079769595 | U11: =IFERROR($D11/I11-1,0) -> -0.051150508 | W11: =SUM(W8:W10) -> 3321188.7 | X11: =SUM(X8:X10) -> 3245474.1 | Y11: =SUM(Y8:Y10) -> 3280334.6 | Z11: =SUM(Z8:Z10) -> 3020734.4 | AA11: =SUM(AA8:AA10) -> 3609083.8 | AB11: =SUM(AB8:AB10) -> 3500227.1 | AD11: =$W11-X11 -> 75714.557 | AE11: =$W11-Y11 -> 40854.11 | AF11: =$W11-Z11 -> 300454.3 | AG11: =$W11-AA11 -> -287895.16 | AH11: =$W11-AB11 -> -179038.39 | AJ11: =IFERROR($W11/X11-1,0) -> 0.023329275 | AK11: =IFERROR($W11/Y11-1,0) -> 0.012454251 | AL11: =IFERROR($W11/Z11-1,0) -> 0.099463991 | AM11: =IFERROR($W11/AA11-1,0) -> -0.079769595 | AN11: =IFERROR($W11/AB11-1,0) -> -0.051150508
A14: SALDO_PROM | C14: Vigente | D14: {=_xlfn.XLOOKUP(1, (INDIRECT("'"&$C$6&"'!$6:$6")=D$6)* (INDIRECT("'"&$C$6&"'!$5:$5")=D$5), INDIRECT("'"&$C$6&"'!"&ROW()&":"&ROW()) )} -> 3165468.5 | E14: {=_xlfn.XLOOKUP(1, (INDIRECT("'"&$C$6&"'!$6:$6")=E$6)* (INDIRECT("'"&$C$6&"'!$5:$5")=E$5), INDIRECT("'"&$C$6&"'!"&ROW()&":"&ROW()) )} -> 3078694.6 | F14: {=_xlfn.XLOOKUP(1, (INDIRECT("'"&$C$6&"'!$6:$6")=F$6)* (INDIRECT("'"&$C$6&"'!$5:$5")=F$5), INDIRECT("'"&$C$6&"'!"&ROW()&":"&ROW()) )} -> 3096567.5 | G14: {=_xlfn.XLOOKUP(1, (INDIRECT("'"&$C$6&"'!$6:$6")=G$6)* (INDIRECT("'"&$C$6&"'!$5:$5")=G$5), INDIRECT("'"&$C$6&"'!"&ROW()&":"&ROW()) )} -> 2841610 | H14: {=_xlfn.XLOOKUP(1, (INDIRECT("'"&$C$6&"'!$6:$6")=H$6)* (INDIRECT("'"&$C$6&"'!$5:$5")=H$5), INDIRECT("'"&$C$6&"'!"&ROW()&":"&ROW()) )} -> 3450850.9 | I14: {=_xlfn.XLOOKUP(1, (INDIRECT("'"&$C$6&"'!$6:$6")=I$6)* (INDIRECT("'"&$C$6&"'!$5:$5")=I$5), INDIRECT("'"&$C$6&"'!"&ROW()&":"&ROW()) )} -> 3343878.5 | K14: =$D14-E14 -> 86773.955 | L14: =$D14-F14 -> 68900.99 | M14: =$D14-G14 -> 323858.5 | N14: =$D14-H14 -> -285382.35 | O14: =$D14-I14 -> -178409.98 | Q14: =IFERROR($D14/E14-1,0) -> 0.028185308 | R14: =IFERROR($D14/F14-1,0) -> 0.022250763 | S14: =IFERROR($D14/G14-1,0) -> 0.11397007 | T14: =IFERROR($D14/H14-1,0) -> -0.082699126 | U14: =IFERROR($D14/I14-1,0) -> -0.053354206 | W14: {=INDIRECT("'"&$C$6&"'!"&ADDRESS(ROW(),COLUMN()+44))} -> 3101496 | X14: {=INDIRECT("'"&$C$6&"'!"&ADDRESS(ROW(),COLUMN()+44))} -> 3059754.3 | Y14: {=INDIRECT("'"&$C$6&"'!"&ADDRESS(ROW(),COLUMN()+44))} -> 3069509.7 | Z14: {=INDIRECT("'"&$C$6&"'!"&ADDRESS(ROW(),COLUMN()+44))} -> 2830433.6 | AA14: {=INDIRECT("'"&$C$6&"'!"&ADDRESS(ROW(),COLUMN()+44))} -> 3524089.4 | AB14: {=INDIRECT("'"&$C$6&"'!"&ADDRESS(ROW(),COLUMN()+44))} -> 3241831.4 | AD14: =$W14-X14 -> 41741.697 | AE14: =$W14-Y14 -> 31986.265 | AF14: =$W14-Z14 -> 271062.45 | AG14: =$W14-AA14 -> -422593.4 | AH14: =$W14-AB14 -> -140335.41 | AJ14: =IFERROR($W14/X14-1,0) -> 0.013642173 | AK14: =IFERROR($W14/Y14-1,0) -> 0.010420643 | AL14: =IFERROR($W14/Z14-1,0) -> 0.095767114 | AM14: =IFERROR($W14/AA14-1,0) -> -0.11991563 | AN14: =IFERROR($W14/AB14-1,0) -> -0.04328893
A15: SALDO_PROM | C15: Refinanciado | D15: {=_xlfn.XLOOKUP(1, (INDIRECT("'"&$C$6&"'!$6:$6")=D$6)* (INDIRECT("'"&$C$6&"'!$5:$5")=D$5), INDIRECT("'"&$C$6&"'!"&ROW()&":"&ROW()) )} -> 36267.49 | E15: {=_xlfn.XLOOKUP(1, (INDIRECT("'"&$C$6&"'!$6:$6")=E$6)* (INDIRECT("'"&$C$6&"'!$5:$5")=E$5), INDIRECT("'"&$C$6&"'!"&ROW()&":"&ROW()) )} -> 31668.279 | F15: {=_xlfn.XLOOKUP(1, (INDIRECT("'"&$C$6&"'!$6:$6")=F$6)* (INDIRECT("'"&$C$6&"'!$5:$5")=F$5), INDIRECT("'"&$C$6&"'!"&ROW()&":"&ROW()) )} -> 37148 | G15: {=_xlfn.XLOOKUP(1, (INDIRECT("'"&$C$6&"'!$6:$6")=G$6)* (INDIRECT("'"&$C$6&"'!$5:$5")=G$5), INDIRECT("'"&$C$6&"'!"&ROW()&":"&ROW()) )} -> 44237.049 | H15: {=_xlfn.XLOOKUP(1, (INDIRECT("'"&$C$6&"'!$6:$6")=H$6)* (INDIRECT("'"&$C$6&"'!$5:$5")=H$5), INDIRECT("'"&$C$6&"'!"&ROW()&":"&ROW()) )} -> 6162.1973 | I15: {=_xlfn.XLOOKUP(1, (INDIRECT("'"&$C$6&"'!$6:$6")=I$6)* (INDIRECT("'"&$C$6&"'!$5:$5")=I$5), INDIRECT("'"&$C$6&"'!"&ROW()&":"&ROW()) )} -> 12441.221 | K15: =$D15-E15 -> 4599.211 | L15: =$D15-F15 -> -880.51 | M15: =$D15-G15 -> -7969.5594 | N15: =$D15-H15 -> 30105.293 | O15: =$D15-I15 -> 23826.269 | Q15: =IFERROR($D15/E15-1,0) -> 0.14523085 | R15: =IFERROR($D15/F15-1,0) -> -0.023702757 | S15: =IFERROR($D15/G15-1,0) -> -0.18015576 | T15: =IFERROR($D15/H15-1,0) -> 4.8854801 | U15: =IFERROR($D15/I15-1,0) -> 1.915107 | W15: {=INDIRECT("'"&$C$6&"'!"&ADDRESS(ROW(),COLUMN()+44))} -> 37137.887 | X15: {=INDIRECT("'"&$C$6&"'!"&ADDRESS(ROW(),COLUMN()+44))} -> 33358.564 | Y15: {=INDIRECT("'"&$C$6&"'!"&ADDRESS(ROW(),COLUMN()+44))} -> 37573.085 | Z15: {=INDIRECT("'"&$C$6&"'!"&ADDRESS(ROW(),COLUMN()+44))} -> 44410.208 | AA15: {=INDIRECT("'"&$C$6&"'!"&ADDRESS(ROW(),COLUMN()+44))} -> 5713.7241 | AB15: {=INDIRECT("'"&$C$6&"'!"&ADDRESS(ROW(),COLUMN()+44))} -> 12001.905 | AD15: =$W15-X15 -> 3779.3231 | AE15: =$W15-Y15 -> -435.19833 | AF15: =$W15-Z15 -> -7272.3209 | AG15: =$W15-AA15 -> 31424.163 | AH15: =$W15-AB15 -> 25135.982 | AJ15: =IFERROR($W15/X15-1,0) -> 0.11329394 | AK15: =IFERROR($W15/Y15-1,0) -> -0.011582715 | AL15: =IFERROR($W15/Z15-1,0) -> -0.16375336 | AM15: =IFERROR($W15/AA15-1,0) -> 5.499769 | AN15: =IFERROR($W15/AB15-1,0) -> 2.0943326
A16: SALDO_PROM | C16: Vencido y Judicial | D16: {=_xlfn.XLOOKUP(1, (INDIRECT("'"&$C$6&"'!$6:$6")=D$6)* (INDIRECT("'"&$C$6&"'!$5:$5")=D$5), INDIRECT("'"&$C$6&"'!"&ROW()&":"&ROW()) )} -> 96644.16 | E16: {=_xlfn.XLOOKUP(1, (INDIRECT("'"&$C$6&"'!$6:$6")=E$6)* (INDIRECT("'"&$C$6&"'!$5:$5")=E$5), INDIRECT("'"&$C$6&"'!"&ROW()&":"&ROW()) )} -> 108022.07 | F16: {=_xlfn.XLOOKUP(1, (INDIRECT("'"&$C$6&"'!$6:$6")=F$6)* (INDIRECT("'"&$C$6&"'!$5:$5")=F$5), INDIRECT("'"&$C$6&"'!"&ROW()&":"&ROW()) )} -> 101854.37 | G16: {=_xlfn.XLOOKUP(1, (INDIRECT("'"&$C$6&"'!$6:$6")=G$6)* (INDIRECT("'"&$C$6&"'!$5:$5")=G$5), INDIRECT("'"&$C$6&"'!"&ROW()&":"&ROW()) )} -> 122146.45 | H16: {=_xlfn.XLOOKUP(1, (INDIRECT("'"&$C$6&"'!$6:$6")=H$6)* (INDIRECT("'"&$C$6&"'!$5:$5")=H$5), INDIRECT("'"&$C$6&"'!"&ROW()&":"&ROW()) )} -> 178129.15 | I16: {=_xlfn.XLOOKUP(1, (INDIRECT("'"&$C$6&"'!$6:$6")=I$6)* (INDIRECT("'"&$C$6&"'!$5:$5")=I$5), INDIRECT("'"&$C$6&"'!"&ROW()&":"&ROW()) )} -> 78613.723 | K16: =$D16-E16 -> -11377.914 | L16: =$D16-F16 -> -5210.21 | M16: =$D16-G16 -> -25502.287 | N16: =$D16-H16 -> -81484.989 | O16: =$D16-I16 -> 18030.437 | Q16: =IFERROR($D16/E16-1,0) -> -0.10532953 | R16: =IFERROR($D16/F16-1,0) -> -0.051153524 | S16: =IFERROR($D16/G16-1,0) -> -0.20878452 | T16: =IFERROR($D16/H16-1,0) -> -0.45744893 | U16: =IFERROR($D16/I16-1,0) -> 0.22935483 | W16: {=INDIRECT("'"&$C$6&"'!"&ADDRESS(ROW(),COLUMN()+44))} -> 100528.69 | X16: {=INDIRECT("'"&$C$6&"'!"&ADDRESS(ROW(),COLUMN()+44))} -> 110684.55 | Y16: {=INDIRECT("'"&$C$6&"'!"&ADDRESS(ROW(),COLUMN()+44))} -> 102470.95 | Z16: {=INDIRECT("'"&$C$6&"'!"&ADDRESS(ROW(),COLUMN()+44))} -> 133756.47 | AA16: {=INDIRECT("'"&$C$6&"'!"&ADDRESS(ROW(),COLUMN()+44))} -> 178374.56 | AB16: {=INDIRECT("'"&$C$6&"'!"&ADDRESS(ROW(),COLUMN()+44))} -> 84598.845 | AD16: =$W16-X16 -> -10155.86 | AE16: =$W16-Y16 -> -1942.2633 | AF16: =$W16-Z16 -> -33227.787 | AG16: =$W16-AA16 -> -77845.873 | AH16: =$W16-AB16 -> 15929.842 | AJ16: =IFERROR($W16/X16-1,0) -> -0.091754995 | AK16: =IFERROR($W16/Y16-1,0) -> -0.018954282 | AL16: =IFERROR($W16/Z16-1,0) -> -0.24842003 | AM16: =IFERROR($W16/AA16-1,0) -> -0.43641803 | AN16: =IFERROR($W16/AB16-1,0) -> 0.18829857
C17: Saldo Prom | D17: =SUM(D14:D16) -> 3298380.2 | E17: =SUM(E14:E16) -> 3218384.9 | F17: =SUM(F14:F16) -> 3235569.9 | G17: =SUM(G14:G16) -> 3007993.5 | H17: =SUM(H14:H16) -> 3635142.2 | I17: =SUM(I14:I16) -> 3434933.5 | K17: =$D17-E17 -> 79995.252 | L17: =$D17-F17 -> 62810.27 | M17: =$D17-G17 -> 290386.65 | N17: =$D17-H17 -> -336762.05 | O17: =$D17-I17 -> -136553.28 | Q17: =IFERROR($D17/E17-1,0) -> 0.024855713 | R17: =IFERROR($D17/F17-1,0) -> 0.019412429 | S17: =IFERROR($D17/G17-1,0) -> 0.096538322 | T17: =IFERROR($D17/H17-1,0) -> -0.09264068 | U17: =IFERROR($D17/I17-1,0) -> -0.039754271 | W17: =SUM(W14:W16) -> 3239162.6 | X17: =SUM(X14:X16) -> 3203797.4 | Y17: =SUM(Y14:Y16) -> 3209553.8 | Z17: =SUM(Z14:Z16) -> 3008600.2 | AA17: =SUM(AA14:AA16) -> 3708177.7 | AB17: =SUM(AB14:AB16) -> 3338432.2 | AD17: =$W17-X17 -> 35365.161 | AE17: =$W17-Y17 -> 29608.803 | AF17: =$W17-Z17 -> 230562.34 | AG17: =$W17-AA17 -> -469015.11 | AH17: =$W17-AB17 -> -99269.591 | AJ17: =IFERROR($W17/X17-1,0) -> 0.011038513 | AK17: =IFERROR($W17/Y17-1,0) -> 0.0092252087 | AL17: =IFERROR($W17/Z17-1,0) -> 0.076634423 | AM17: =IFERROR($W17/AA17-1,0) -> -0.12648129 | AN17: =IFERROR($W17/AB17-1,0) -> -0.029735392
C20: Vigente | D20: =IFERROR(((1+D38/D14)^(360/D$3))-1,0) -> 0.16676474 | E20: =IFERROR(((1+E38/E14)^(360/E$3))-1,0) -> 0.16679745 | F20: =IFERROR(((1+F38/F14)^(360/F$3))-1,0) -> 0.16819333 | G20: =IFERROR(((1+G38/G14)^(360/G$3))-1,0) -> 0.16916884 | H20: =IFERROR(((1+H38/H14)^(360/H$3))-1,0) -> 0.17166177 | I20: =IFERROR(((1+I38/I14)^(360/I$3))-1,0) -> 0.18709846 | Q20: =($D20-E20)*10000 -> -0.32708434 | R20: =($D20-F20)*10000 -> -14.285908 | S20: =($D20-G20)*10000 -> -24.041055 | T20: =($D20-H20)*10000 -> -48.970353 | U20: =($D20-I20)*10000 -> -203.33726 | W20: {=INDIRECT("'"&$C$6&"'!"&ADDRESS(ROW(),COLUMN()+44))} -> 0.16764934 | X20: {=INDIRECT("'"&$C$6&"'!"&ADDRESS(ROW(),COLUMN()+44))} -> 0.16628708 | Y20: {=INDIRECT("'"&$C$6&"'!"&ADDRESS(ROW(),COLUMN()+44))} -> 0.16803228 | Z20: {=INDIRECT("'"&$C$6&"'!"&ADDRESS(ROW(),COLUMN()+44))} -> 0.17002459 | AA20: {=INDIRECT("'"&$C$6&"'!"&ADDRESS(ROW(),COLUMN()+44))} -> 0.17330211 | AB20: {=INDIRECT("'"&$C$6&"'!"&ADDRESS(ROW(),COLUMN()+44))} -> 0.18774684 | AJ20: =($W20-X20)*10000 -> 13.622664 | AK20: =($W20-Y20)*10000 -> -3.8293202 | AL20: =($W20-Z20)*10000 -> -23.752493 | AM20: =($W20-AA20)*10000 -> -56.52765 | AN20: =($W20-AB20)*10000 -> -200.975
C21: Refinanciado | D21: =IFERROR(((1+D39/D15)^(360/D$3))-1,0) -> 0.078418696 | E21: =IFERROR(((1+E39/E15)^(360/E$3))-1,0) -> 0.072561465 | F21: =IFERROR(((1+F39/F15)^(360/F$3))-1,0) -> 0.0784327 | G21: =IFERROR(((1+G39/G15)^(360/G$3))-1,0) -> 0.059813869 | H21: =IFERROR(((1+H39/H15)^(360/H$3))-1,0) -> 0.064599699 | I21: =IFERROR(((1+I39/I15)^(360/I$3))-1,0) -> 0.060315445 | Q21: =($D21-E21)*10000 -> 58.572311 | R21: =($D21-F21)*10000 -> -0.14003364 | S21: =($D21-G21)*10000 -> 186.04827 | T21: =($D21-H21)*10000 -> 138.18998 | U21: =($D21-I21)*10000 -> 181.03252 | W21: {=INDIRECT("'"&$C$6&"'!"&ADDRESS(ROW(),COLUMN()+44))} -> 0.077494623 | X21: {=INDIRECT("'"&$C$6&"'!"&ADDRESS(ROW(),COLUMN()+44))} -> 0.072375067 | Y21: {=INDIRECT("'"&$C$6&"'!"&ADDRESS(ROW(),COLUMN()+44))} -> 0.077073241 | Z21: {=INDIRECT("'"&$C$6&"'!"&ADDRESS(ROW(),COLUMN()+44))} -> 0.065973937 | AA21: {=INDIRECT("'"&$C$6&"'!"&ADDRESS(ROW(),COLUMN()+44))} -> 0.074294711 | AB21: {=INDIRECT("'"&$C$6&"'!"&ADDRESS(ROW(),COLUMN()+44))} -> 0.070310613 | AJ21: =($W21-X21)*10000 -> 51.195564 | AK21: =($W21-Y21)*10000 -> 4.2138223 | AL21: =($W21-Z21)*10000 -> 115.20686 | AM21: =($W21-AA21)*10000 -> 31.99912 | AN21: =($W21-AB21)*10000 -> 71.840104
C22: Vencido y Judicial | D22: =IFERROR(((1+D40/D16)^(360/D$3))-1,0) -> 0.08972157 | E22: =IFERROR(((1+E40/E16)^(360/E$3))-1,0) -> 0.087265586 | F22: =IFERROR(((1+F40/F16)^(360/F$3))-1,0) -> 0.097956684 | G22: =IFERROR(((1+G40/G16)^(360/G$3))-1,0) -> 0.11208224 | H22: =IFERROR(((1+H40/H16)^(360/H$3))-1,0) -> 0.064649014 | I22: =IFERROR(((1+I40/I16)^(360/I$3))-1,0) -> 0.055202672 | Q22: =($D22-E22)*10000 -> 24.55984 | R22: =($D22-F22)*10000 -> -82.351146 | S22: =($D22-G22)*10000 -> -223.60672 | T22: =($D22-H22)*10000 -> 250.72556 | U22: =($D22-I22)*10000 -> 345.18897 | W22: {=INDIRECT("'"&$C$6&"'!"&ADDRESS(ROW(),COLUMN()+44))} -> 0.092717636 | X22: {=INDIRECT("'"&$C$6&"'!"&ADDRESS(ROW(),COLUMN()+44))} -> 0.090299602 | Y22: {=INDIRECT("'"&$C$6&"'!"&ADDRESS(ROW(),COLUMN()+44))} -> 0.094298888 | Z22: {=INDIRECT("'"&$C$6&"'!"&ADDRESS(ROW(),COLUMN()+44))} -> 0.095011803 | AA22: {=INDIRECT("'"&$C$6&"'!"&ADDRESS(ROW(),COLUMN()+44))} -> 0.062221607 | AB22: {=INDIRECT("'"&$C$6&"'!"&ADDRESS(ROW(),COLUMN()+44))} -> 0.051973131 | AJ22: =($W22-X22)*10000 -> 24.180344 | AK22: =($W22-Y22)*10000 -> -15.812517 | AL22: =($W22-Z22)*10000 -> -22.941666 | AM22: =($W22-AA22)*10000 -> 304.96029 | AN22: =($W22-AB22)*10000 -> 407.44505
C23: Tasa Implicita | D23: =IFERROR(((1+D41/D17)^(360/D$3))-1,0) -> 0.16343382 | E23: =IFERROR(((1+E41/E17)^(360/E$3))-1,0) -> 0.16308314 | F23: =IFERROR(((1+F41/F17)^(360/F$3))-1,0) -> 0.16485398 | G23: =IFERROR(((1+G41/G17)^(360/G$3))-1,0) -> 0.16512237 | H23: =IFERROR(((1+H41/H17)^(360/H$3))-1,0) -> 0.16600838 | I23: =IFERROR(((1+I41/I17)^(360/I$3))-1,0) -> 0.18343664 | Q23: =($D23-E23)*10000 -> 3.5067804 | R23: =($D23-F23)*10000 -> -14.20159 | S23: =($D23-G23)*10000 -> -16.885491 | T23: =($D23-H23)*10000 -> -25.745644 | U23: =($D23-I23)*10000 -> -200.02825 | W23: {=INDIRECT("'"&$C$6&"'!"&ADDRESS(ROW(),COLUMN()+44))} -> 0.16418505 | X23: {=INDIRECT("'"&$C$6&"'!"&ADDRESS(ROW(),COLUMN()+44))} -> 0.1625696 | Y23: {=INDIRECT("'"&$C$6&"'!"&ADDRESS(ROW(),COLUMN()+44))} -> 0.1645071 | Z23: {=INDIRECT("'"&$C$6&"'!"&ADDRESS(ROW(),COLUMN()+44))} -> 0.16499509 | AA23: {=INDIRECT("'"&$C$6&"'!"&ADDRESS(ROW(),COLUMN()+44))} -> 0.16756622 | AB23: {=INDIRECT("'"&$C$6&"'!"&ADDRESS(ROW(),COLUMN()+44))} -> 0.18367537 | AJ23: =($W23-X23)*10000 -> 16.154471 | AK23: =($W23-Y23)*10000 -> -3.2205072 | AL23: =($W23-Z23)*10000 -> -8.1004627 | AM23: =($W23-AA23)*10000 -> -33.811769 | AN23: =($W23-AB23)*10000 -> -194.90319
C26: Vigente | D26: =-IFERROR(((1-D44/D14)^(360/D$4))-1,0) -> -0.060973767 | E26: =-IFERROR(((1-E44/E14)^(360/E$4))-1,0) -> -0.063250996 | F26: =-IFERROR(((1-F44/F14)^(360/F$4))-1,0) -> -0.061716172 | G26: =-IFERROR(((1-G44/G14)^(360/G$4))-1,0) -> -0.068847077 | H26: =-IFERROR(((1-H44/H14)^(360/H$4))-1,0) -> -0.077250829 | I26: =-IFERROR(((1-I44/I14)^(360/I$4))-1,0) -> -0.073901929 | Q26: =($D26-E26)*10000 -> 22.772293 | R26: =($D26-F26)*10000 -> 7.4240492 | S26: =($D26-G26)*10000 -> 78.733098 | T26: =($D26-H26)*10000 -> 162.77062 | U26: =($D26-I26)*10000 -> 129.28162 | W26: {=INDIRECT("'"&$C$6&"'!"&ADDRESS(ROW(),COLUMN()+44))} -> -0.061733011 | X26: {=INDIRECT("'"&$C$6&"'!"&ADDRESS(ROW(),COLUMN()+44))} -> -0.063725702 | Y26: {=INDIRECT("'"&$C$6&"'!"&ADDRESS(ROW(),COLUMN()+44))} -> -0.062110866 | Z26: {=INDIRECT("'"&$C$6&"'!"&ADDRESS(ROW(),COLUMN()+44))} -> -0.07018776 | AA26: {=INDIRECT("'"&$C$6&"'!"&ADDRESS(ROW(),COLUMN()+44))} -> -0.077652319 | AB26: {=INDIRECT("'"&$C$6&"'!"&ADDRESS(ROW(),COLUMN()+44))} -> -0.071837695 | AJ26: =($W26-X26)*10000 -> 19.926914 | AK26: =($W26-Y26)*10000 -> 3.7785527 | AL26: =($W26-Z26)*10000 -> 84.547486 | AM26: =($W26-AA26)*10000 -> 159.19308 | AN26: =($W26-AB26)*10000 -> 101.04684
C27: Refinanciado | D27: =-IFERROR(((1-D45/D15)^(360/D$4))-1,0) -> -0.062075309 | E27: =-IFERROR(((1-E45/E15)^(360/E$4))-1,0) -> -0.010266522 | F27: =-IFERROR(((1-F45/F15)^(360/F$4))-1,0) -> -0.062335948 | G27: =-IFERROR(((1-G45/G15)^(360/G$4))-1,0) -> -0.06580727 | H27: =-IFERROR(((1-H45/H15)^(360/H$4))-1,0) -> -0.074922107 | I27: =-IFERROR(((1-I45/I15)^(360/I$4))-1,0) -> -0.077408172 | Q27: =($D27-E27)*10000 -> -518.08787 | R27: =($D27-F27)*10000 -> 2.6063922 | S27: =($D27-G27)*10000 -> 37.319613 | T27: =($D27-H27)*10000 -> 128.46798 | U27: =($D27-I27)*10000 -> 153.32863 | W27: {=INDIRECT("'"&$C$6&"'!"&ADDRESS(ROW(),COLUMN()+44))} -> -0.062334564 | X27: {=INDIRECT("'"&$C$6&"'!"&ADDRESS(ROW(),COLUMN()+44))} -> -0.0098278781 | Y27: {=INDIRECT("'"&$C$6&"'!"&ADDRESS(ROW(),COLUMN()+44))} -> -0.062503812 | Z27: {=INDIRECT("'"&$C$6&"'!"&ADDRESS(ROW(),COLUMN()+44))} -> -0.066453036 | AA27: {=INDIRECT("'"&$C$6&"'!"&ADDRESS(ROW(),COLUMN()+44))} -> -0.075895307 | AB27: {=INDIRECT("'"&$C$6&"'!"&ADDRESS(ROW(),COLUMN()+44))} -> -0.075197445 | AJ27: =($W27-X27)*10000 -> -525.06686 | AK27: =($W27-Y27)*10000 -> 1.6924811 | AL27: =($W27-Z27)*10000 -> 41.184716 | AM27: =($W27-AA27)*10000 -> 135.60743 | AN27: =($W27-AB27)*10000 -> 128.62881
